Workbook
Name Ak: #REF!
Name NOB: #REF!
Name Source: #REF!
Name SRCE: #REF!
Name Style: #REF!
Name TOS: #REF!
Name Type: #REF!
Name VLOOKUP: #REF!

Sheet daily
B2: =UPPER(_xlfn.CONCAT(TEXT(F3,"MMMM YYYY "),"COLLECTION SUMMARY")) -> MAY 2026 COLLECTION SUMMARY
E3: As on | F3: 46149 | G3: "=MAX(gcdump!X:X)"
C4: Collection Due | D4: New sales | E4: Total
A5: Target | C5: =_xlfn.XLOOKUP(TEXT($F$3,"MMM"),month_target!$5:$5,month_target!$6:$6,0,0) -> 8.6042919e+08 | D5: =_xlfn.XLOOKUP(TEXT($F$3,"MMM"),month_target!$12:$12,month_target!$13:$13,0,0) -> 563625000 | E5: =SUM(C5:D5) -> 1.4240542e+09
A6: MTD Pro-rata Target | C6: 2.5306741e+08 | D6: 1.6577206e+08 | E6: =SUM(C6:D6) -> 4.1883947e+08
A8: Sno. | B8: Day & Date | C8: Collection Due | D8: New sales | E8: Total | F8: DLD/Oqood | AE8: AR Tracker Rows -2261
A9: 1 | B9: 46143 | C9: 53938555 | D9: =E9-C9 -> 1465167.3 | E9: 55403722 | F9: 1213745.4 | AF9: 518637.46 | AJ9: =C9-AH9 -> 53938555 | AK9: =D9-AI9 -> 1465167.3
A10: 2 | B10: 46144 | C10: 0 | D10: =E10-C10 -> 0 | E10: 0 | F10: 715605.91 | AE10: =_xlfn.XLOOKUP(daily!$F3,B:B,D:D)-AE11 -> 73321 | AF10: 303910.97 | AH10: 25259161 | AI10: 1183126 | AJ10: =C10-AH10 -> -25259161 | AK10: =D10-AI10 -> -1183126
A11: 3 | B11: 46145 | C11: 0 | D11: =E11-C11 -> 0 | E11: 0 | F11: 0 | AE11: 1772621.1 | AF11: 0 | AH11: 39474332 | AI11: 1778245 | AJ11: =C11-AH11 -> -39474332 | AK11: =D11-AI11 -> -1778245
A12: 4 | B12: 46146 | C12: 63640347 | D12: =E12-C12 -> 10452008 | E12: 74092355 | F12: 1330933.7 | AF12: 587342.5 | AH12: 41314431 | AI12: 1804177 | AJ12: =C12-AH12 -> 22325916 | AK12: =D12-AI12 -> 8647830.7
A13: 5 | B13: 46147 | C13: 56488256 | D13: =E13-C13 -> 19203093 | E13: 75691349 | F13: 503367.4 | AF13: 194042 | AJ13: =C13-AH13 -> 56488256 | AK13: =D13-AI13 -> 19203093
B14: 46148 | C14: 54618539 | D14: =E14-C14 -> 12493235 | E14: 67111774 | F14: 698181.3 | AF14: 350651 | AJ14: =C14-AH14 -> 54618539 | AK14: =D14-AI14 -> 12493235
B15: 46149 | C15: 56771371 | D15: =E15-C15 -> 1845942.1 | E15: 58617314 | F15: 311975.9 | AF15: 368901.5 | AJ15: =C15-AH15 -> 56771371 | AK15: =D15-AI15 -> 1845942.1
A16: 6 | B16: 46150 | C16: 0 | D16: =E16-C16 -> 0 | E16: 0 | F16: 0 | AF16: 0 | AJ16: =C16-AH16 -> 0 | AK16: =D16-AI16 -> 0
A17: 7 | B17: 46151 | C17: 0 | D17: =E17-C17 -> 0 | E17: 0 | F17: 0 | AF17: 0 | AJ17: =C17-AH17 -> 0 | AK17: =D17-AI17 -> 0
A18: 8 | B18: 46152 | C18: 0 | D18: =E18-C18 -> 0 | E18: 0 | F18: 0 | I18: 0 | J18: 0 | K18: =C18-I18 -> 0 | L18: =J18-D18 -> 0 | M18: 45056 | AF18: 0 | AJ18: =C18-AH18 -> 0 | AK18: =D18-AI18 -> 0
A19: 9 | B19: 46153 | C19: 0 | D19: =E19-C19 -> 0 | E19: 0 | F19: 0 | I19: 0 | J19: 0 | K19: =C19-I19 -> 0 | L19: =J19-D19 -> 0 | M19: 45057 | AF19: 0 | AJ19: =C19-AH19 -> 0 | AK19: =D19-AI19 -> 0
A20: 10 | B20: 46154 | C20: 0 | D20: =E20-C20 -> 0 | E20: 0 | F20: 0 | I20: 19090565 | J20: 26755176 | K20: =C20-I20 -> -19090565 | L20: =J20-D20 -> 26755176 | M20: 45058 | AF20: 0 | AJ20: =C20-AH20 -> 0 | AK20: =D20-AI20 -> 0
B21: 46155 | C21: 0 | D21: =E21-C21 -> 0 | E21: 0 | F21: 0 | G21: =C21+$AE$10 -> 73321 | I21: 0 | J21: 0 | K21: =C21-I21 -> 0 | L21: =J21-D21 -> 0 | M21: 45059 | AF21: 0 | AJ21: =C21-AH21 -> 0 | AK21: =D21-AI21 -> 0
B22: 46156 | C22: 0 | D22: =E22-C22 -> 0 | E22: 0 | F22: 0 | G22: =C22+$AE$10 -> 73321 | I22: 0 | J22: 0 | K22: =C22-I22 -> 0 | L22: =J22-D22 -> 0 | M22: 45060 | AF22: 0 | AJ22: =C22-AH22 -> 0 | AK22: =D22-AI22 -> 0
A23: 11 | B23: 46157 | C23: 0 | D23: =E23-C23 -> 0 | E23: 0 | F23: 0 | I23: 0 | J23: 0 | K23: =C23-I23 -> 0 | L23: =J23-D23 -> 0 | M23: 45061 | AF23: 0 | AJ23: =C23-AH23 -> 0 | AK23: =D23-AI23 -> 0
A24: 12 | B24: 46158 | C24: 0 | D24: =E24-C24 -> 0 | E24: 0 | F24: 0 | I24: 0 | J24: 0 | K24: =C24-I24 -> 0 | L24: =J24-D24 -> 0 | M24: 45062 | AF24: 0 | AJ24: =C24-AH24 -> 0 | AK24: =D24-AI24 -> 0
A25: 13 | B25: 46159 | C25: 0 | D25: =E25-C25 -> 0 | E25: 0 | F25: 0 | I25: 0 | J25: 0 | K25: =C25-I25 -> 0 | L25: =J25-D25 -> 0 | M25: 45063 | V25: =SUM(V23,V17) -> 0 | AF25: 0 | AJ25: =C25-AH25 -> 0 | AK25: =D25-AI25 -> 0
A26: 14 | B26: 46160 | C26: 0 | D26: =E26-C26 -> 0 | E26: 0 | F26: 0 | AF26: 0 | AJ26: =C26-AH26 -> 0 | AK26: =D26-AI26 -> 0
A27: 15 | B27: 46161 | C27: 0 | D27: =E27-C27 -> 0 | E27: 0 | F27: 0 | AF27: 0 | AJ27: =C27-AH27 -> 0 | AK27: =D27-AI27 -> 0
B28: 46162 | C28: 0 | D28: =E28-C28 -> 0 | E28: 0 | F28: 0 | I28: 0 | J28: 0 | K28: =C28-I28 -> 0 | L28: =J28-D28 -> 0 | M28: 45066 | AF28: 0 | AJ28: =C28-AH28 -> 0 | AK28: =D28-AI28 -> 0
B29: 46163 | C29: 0 | D29: =E29-C29 -> 0 | E29: 0 | F29: 0 | I29: 0 | J29: 0 | K29: =C29-I29 -> 0 | L29: =J29-D29 -> 0 | M29: 45067 | AF29: 0 | AJ29: =C29-AH29 -> 0 | AK29: =D29-AI29 -> 0
A30: 16 | B30: 46164 | C30: 0 | D30: =E30-C30 -> 0 | E30: 0 | F30: 0 | I30: 0 | J30: 0 | K30: =C30-I30 -> 0 | L30: =J30-D30 -> 0 | M30: 45068 | AF30: 0 | AJ30: =C30-AH30 -> 0 | AK30: =D30-AI30 -> 0
A31: 17 | B31: 46165 | C31: 0 | D31: =E31-C31 -> 0 | E31: 0 | F31: 0 | I31: 0 | J31: 0 | K31: =C31-I31 -> 0 | L31: =J31-D31 -> 0 | M31: 45069 | AF31: 0 | AJ31: =C31-AH31 -> 0 | AK31: =D31-AI31 -> 0
A32: 18 | B32: 46166 | C32: 0 | D32: =E32-C32 -> 0 | E32: 0 | F32: 0 | I32: 0 | J32: 0 | K32: =C32-I32 -> 0 | L32: =J32-D32 -> 0 | M32: 45070 | AF32: 0 | AJ32: =C32-AH32 -> 0 | AK32: =D32-AI32 -> 0
A33: 19 | B33: 46167 | C33: 0 | D33: =E33-C33 -> 0 | E33: 0 | F33: 0 | I33: 0 | J33: 0 | K33: =C33-I33 -> 0 | L33: =J33-D33 -> 0 | M33: 45071 | AF33: 0 | AJ33: =C33-AH33 -> 0 | AK33: =D33-AI33 -> 0
A34: 20 | B34: 46168 | C34: 0 | D34: =E34-C34 -> 0 | E34: 0 | F34: 0 | I34: 0 | J34: 0 | K34: =C34-I34 -> 0 | L34: =J34-D34 -> 0 | M34: 45072 | AF34: 0 | AJ34: =C34-AH34 -> 0 | AK34: =D34-AI34 -> 0
B35: 46169 | C35: 0 | D35: =E35-C35 -> 0 | E35: 0 | F35: 0 | I35: 0 | J35: 0 | K35: =C35-I35 -> 0 | L35: =J35-D35 -> 0 | M35: 45071 | AF35: 0 | AJ35: =C35-AH35 -> 0 | AK35: =D35-AI35 -> 0
B36: 46170 | C36: 0 | D36: =E36-C36 -> 0 | E36: 0 | F36: 0 | I36: 0 | J36: k | K36: =C36-I36 -> 0 | L36: =J36-D36 -> #VALUE! | M36: 45071 | AF36: 0 | AJ36: =C36-AH36 -> 0 | AK36: =D36-AI36 -> 0
A37: 21 | B37: 46171 | C37: 0 | D37: =E37-C37 -> 0 | E37: 0 | F37: 0 | I37: 18395701 | J37: 13990864 | K37: =C37-I37 -> -18395701 | L37: =J37-D37 -> 13990864 | M37: 45075 | AF37: 0 | AJ37: =C37-AH37 -> 0 | AK37: =D37-AI37 -> 0
A38: 22 | B38: 46172 | C38: 0 | D38: =E38-C38 -> 0 | E38: 0 | F38: 0 | I38: 17773941 | J38: 873706 | AF38: 0 | AJ38: =C38-AH38 -> 0 | AK38: =D38-AI38 -> 0
A39: 23 | B39: 46173 | C39: 0 | D39: =E39-C39 -> 0 | E39: 0 | F39: 0 | AF39: 0
A40: Total MTD | C40: =SUM(C9:C39) -> 2.8545707e+08 | D40: =SUM(D9:D39) -> 45459445 | E40: =SUM(E9:E39) -> 3.3091651e+08 | F40: =SUM(F9:F39) -> 4773809.6 | AE40: =E40-G40 -> 3.3091651e+08 | AF40: =SUM(AF9:AF39) -> 2323485.4
A42: YTD Collection
A43: Particulars | C43: Collection Due | D43: New sales | E43: Total
...

Sheet month_target
B2: MONTHLY COLLECTIONS SNAPSHOT 2026
S3: =daily!F3 -> 46149
B4: Collections from dues
B5: 2026 | C5: Jan | D5: Feb | E5: Mar | F5: Q1 | G5: Apr | H5: May | I5: Jun | J5: Q2 | K5: H1 | L5: July | M5: Aug | N5: Sept | O5: Q3 | P5: Oct | Q5: Nov | R5: Dec | S5: Total
B6: Target | C6: 9.0909422e+08 | D6: 9.0505657e+08 | E6: 8.721722e+08 | F6: =SUM(C6:E6) -> 2.686323e+09 | G6: 9.433853e+08 | H6: 8.6042919e+08 | I6: 9.5770968e+08 | J6: =SUM(G6:I6) -> 2.7615242e+09 | K6: =SUM(J6,F6) -> 5.4478472e+09 | L6: 1.0012451e+09 | M6: 1.012913e+09 | N6: 1.160537e+09 | O6: =SUM(L6:N6) -> 3.1746951e+09 | P6: 1.1017887e+09 | Q6: 1.0087406e+09 | R6: 7.9836855e+08 | S6: =SUM(K6,O6:R6) -> 1.153144e+10
B7: MTD Target | C7: 9.0909422e+08 | D7: 9.0505657e+08 | E7: 8.721722e+08 | F7: =SUM(C7:E7) -> 2.686323e+09 | G7: 9.433853e+08 | H7: =daily!$C$6 -> 2.5306741e+08 | I7: 0 | J7: =SUM(G7:I7) -> 1.1964527e+09 | K7: =F7+J7 -> 3.8827757e+09 | L7: 0 | M7: 0 | N7: 0 | O7: =SUM(L7:N7) -> 0 | P7: 0 | Q7: 0 | R7: 0 | S7: =SUM(K7,O7:R7) -> 3.8827757e+09
B8: MTD Collections | C8: 1.1028177e+09 | D8: 1.0067082e+09 | E8: 8.2441712e+08 | F8: =SUM(C8:E8) -> 2.933943e+09 | G8: 1.0643151e+09 | H8: =daily!$C$40 -> 2.8545707e+08 | I8: 0 | J8: =SUM(G8:I8) -> 1.3497721e+09 | K8: =F8+J8 -> 4.2837152e+09 | L8: 0 | M8: 0 | N8: 0 | O8: =SUM(L8:N8) -> 0 | P8: 0 | Q8: 0 | R8: 0 | S8: =SUM(K8,O8:R8) -> 4.2837152e+09
B9: Achieved % | C9: =IFERROR(C8/C7,0) -> 1.213095 | D9: =IFERROR(D8/D7,0) -> 1.1123153 | E9: =IFERROR(E8/E7,0) -> 0.94524582 | F9: =IFERROR(F8/F7,0) -> 1.0921781 | G9: =IFERROR(G8/G7,0) -> 1.128187 | H9: =IFERROR(H8/H7,0) -> 1.1279883 | I9: =IFERROR(I8/I7,0) -> 0 | J9: =IFERROR(J8/J7,0) -> 1.128145 | K9: =K8/K7 -> 1.103261 | L9: =IFERROR(L8/L7,0) -> 0 | M9: =IFERROR(M8/M7,0) -> 0 | N9: =IFERROR(N8/N7,0) -> 0 | O9: =IFERROR(O8/O7,0) -> 0 | P9: =IFERROR(P8/P7,0) -> 0 | Q9: =IFERROR(Q8/Q7,0) -> 0 | R9: =IFERROR(R8/R7,0) -> 0 | S9: =S8/S7 -> 1.103261
B11: Collections from new sales
B12: 2026 | C12: Jan | D12: Feb | E12: Mar | F12: Q1 | G12: Apr | H12: May | I12: Jun | J12: Q2 | K12: H1 | L12: July | M12: Aug | N12: Sept | O12: Q3 | P12: Oct | Q12: Nov | R12: Dec | S12: Total | AH12: Jan | AI12: Feb
B13: Target | C13: 507262500 | D13: 507262500 | E13: 507262500 | F13: =SUM(C13:E13) -> 1521787500 | G13: 563625000 | H13: 563625000 | I13: 563625000 | J13: =SUM(G13:I13) -> 1690875000 | K13: =SUM(J13,F13) -> 3212662500 | L13: 563625000 | M13: 563625000 | N13: 563625000 | O13: =SUM(L13:N13) -> 1690875000 | P13: 619987500 | Q13: 619987500 | R13: 619987500 | S13: =SUM(K13,O13:R13) -> 6763500000
B14: MTD Target | C14: 507262500 | D14: 507262500 | E14: 507262500 | F14: =SUM(C14:E14) -> 1521787500 | G14: 563625000 | H14: =daily!$D$6 -> 1.6577206e+08 | I14: 0 | J14: =SUM(G14:I14) -> 7.2939706e+08 | K14: =F14+J14 -> 2.2511846e+09 | L14: 0 | M14: 0 | N14: 0 | O14: =SUM(L14:N14) -> 0 | P14: 0 | Q14: 0 | R14: 0 | S14: =SUM(K14,O14:R14) -> 2.2511846e+09
B15: MTD Collections | C15: 2.3548553e+08 | D15: 2.5588038e+08 | E15: 76359585 | F15: =SUM(C15:E15) -> 5.6772549e+08 | G15: 1.2511851e+08 | H15: =daily!$D$40 -> 45459445 | I15: 0 | J15: =SUM(G15:I15) -> 1.7057796e+08 | K15: =F15+J15 -> 7.3830345e+08 | L15: 0 | M15: 0 | N15: 0 | O15: =SUM(L15:N15) -> 0 | P15: 0 | Q15: 0 | R15: 0 | S15: =SUM(K15,O15:R15) -> 7.3830345e+08
B16: Achieved % | C16: =C15/C14 -> 0.46422814 | D16: =IFERROR(D15/D14,0) -> 0.50443385 | E16: =IFERROR(E15/E14,0) -> 0.15053268 | F16: =F15/F14 -> 0.37306489 | G16: =IFERROR(G15/G14,0) -> 0.22198893 | H16: =IFERROR(H15/H14,0) -> 0.27422863 | I16: =IFERROR(I15/I14,0) -> 0 | J16: =IFERROR(J15/J14,0) -> 0.23386159 | K16: =K15/K14 -> 0.3279622 | L16: =IFERROR(L15/L14,0) -> 0 | M16: =IFERROR(M15/M14,0) -> 0 | N16: =IFERROR(N15/N14,0) -> 0 | O16: =IFERROR(O15/O14,0) -> 0 | P16: =IFERROR(P15/P14,0) -> 0 | Q16: =IFERROR(Q15/Q14,0) -> 0 | R16: =IFERROR(R15/R14,0) -> 0 | S16: =S15/S14 -> 0.3279622
D17: =E17-C17 -> 0
B18: Total collections
B19: 2026 | C19: Jan | D19: Feb | E19: Mar | F19: Q1 | G19: Apr | H19: May | I19: Jun | J19: Q2 | K19: H1 | L19: July | M19: Aug | N19: Sept | O19: Q3 | P19: Oct | Q19: Nov | R19: Dec | S19: Total
B20: Target | C20: =C13+C6 -> 1.4163567e+09 | D20: =D13+D6 -> 1.4123191e+09 | E20: =E13+E6 -> 1.3794347e+09 | F20: =F13+F6 -> 4.2081105e+09 | G20: =G13+G6 -> 1.5070103e+09 | H20: =H13+H6 -> 1.4240542e+09 | I20: =I13+I6 -> 1.5213347e+09 | J20: =J13+J6 -> 4.4523992e+09 | ... R20: =R13+R6 -> 1.4183561e+09 | S20: =SUM(K20,O20:R20) -> 1.829494e+10
B21: MTD Target | C21: =C7+C14 -> 1.4163567e+09 | D21: =SUM(D14,D7) -> 1.4123191e+09 | E21: =SUM(E14,E7) -> 1.3794347e+09 | F21: =SUM(C21:E21) -> 4.2081105e+09 | G21: =SUM(G14,G7) -> 1.5070103e+09 | H21: =SUM(H14,H7) -> 4.1883947e+08 | I21: =SUM(I14,I7) -> 0 | J21: =SUM(G21:I21) -> 1.9258498e+09 | K21: =F21+J21 -> 6.1339603e+09 | L21: =SUM(L14,L7) -> 0 | M21: =SUM(M14,M7) -> 0 | N21: =SUM(N14,N7) -> 0 | O21: =SUM(L21:N21) -> 0 | P21: =SUM(P14,P7) -> 0 | Q21: =SUM(Q14,Q7) -> 0 | R21: =SUM(R14,R7) -> 0 | S21: =SUM(K21,O21:R21) -> 6.1339603e+09
B22: MTD Collections | C22: =C8+C15 -> 1.3383032e+09 | D22: =SUM(D15,D8) -> 1.2625886e+09 | E22: =SUM(E15,E8) -> 9.0077671e+08 | F22: =SUM(C22:E22) -> 3.5016685e+09 | G22: =SUM(G15,G8) -> 1.1894336e+09 | H22: =SUM(H15,H8) -> 3.3091651e+08 | I22: =SUM(I15,I8) -> 0 | J22: =SUM(G22:I22) -> 1.5203501e+09 | K22: =F22+J22 -> 5.0220186e+09 | L22: =SUM(L15,L8) -> 0 | M22: =SUM(M15,M8) -> 0 | N22: =SUM(N15,N8) -> 0 | O22: =SUM(L22:N22) -> 0 | P22: =SUM(P15,P8) -> 0 | Q22: =SUM(Q15,Q8) -> 0 | R22: =SUM(R15,R8) -> 0 | S22: =SUM(K22,O22:R22) -> 5.0220186e+09
B23: Achieved % | C23: =C22/C21 -> 0.94489135 | D23: =IFERROR(D22/D21,0) -> 0.89398255 | E23: =IFERROR(E22/E21,0) -> 0.65300424 | F23: =F22/F21 -> 0.83212372 | G23: =IFERROR(G22/G21,0) -> 0.78926705 | H23: =IFERROR(H22/H21,0) -> 0.79007959 | I23: =IFERROR(I22/I21,0) -> 0 | J23: =IFERROR(J22/J21,0) -> 0.78944376 | K23: =K22/K21 -> 0.8187237 | L23: =IFERROR(L22/L21,0) -> 0 | M23: =IFERROR(M22/M21,0) -> 0 | N23: =IFERROR(N22/N21,0) -> 0 | O23: =IFERROR(O22/O21,0) -> 0 | P23: =IFERROR(P22/P21,0) -> 0 | Q23: =IFERROR(Q22/Q21,0) -> 0 | R23: =IFERROR(R22/R21,0) -> 0 | S23: =S22/S21 -> 0.8187237
B24: Account_2 | C24: 6.7687027e+08 | D24: 5.8601397e+08 | E24: 4.8753354e+08 | F24: =SUM(C24:E24) -> 1.7504178e+09 | G24: 4.4025633e+08 | H24: 61506554 | I24: 0 | J24: =SUM(G24:I24) -> 5.0176288e+08 | K24: =F24+J24 -> 2.2521807e+09 | L24: 0 | M24: 0 | N24: 0 | O24: =SUM(L24:N24) -> 0 | P24: 0 | Q24: 0 | R24: 0 | S24: =SUM(K24,O24:R24) -> 2.2521807e+09
B25: Account_1 | C25: =C22-C24 -> 6.6143294e+08 | D25: =D22-D24 -> 6.7657464e+08 | E25: =E22-E24 -> 4.1324317e+08 | F25: =SUM(C25:E25) -> 1.7512507e+09 | G25: =G22-G24 -> 7.4917725e+08 | H25: =H22-H24 -> 2.6940996e+08 | I25: =I22-I24 -> 0 | J25: =SUM(G25:I25) -> 1.0185872e+09 | K25: =F25+J25 -> 2.769838e+09 | L25: =L22-L24 -> 0 | M25: =M22-M24 -> 0 | N25: =N22-N24 -> 0 | O25: =SUM(L25:N25) -> 0 | P25: =P22-P24 -> 0 | Q25: =Q22-Q24 -> 0 | R25: =R22-R24 -> 0 | S25: =SUM(K25,O25:R25) -> 2.769838e+09
B26: Total | C26: =C22 -> 1.3383032e+09 | D26: =D22 -> 1.2625886e+09 | E26: =E22 -> 9.0077671e+08 | F26: =F22 -> 3.5016685e+09 | G26: =G22 -> 1.1894336e+09 | H26: =H22 -> 3.3091651e+08 | I26: =I22 -> 0 | J26: =J22 -> 1.5203501e+09 | ... R26: =R22 -> 0 | S26: =SUM(K26,O26:R26) -> 5.0220186e+09
B27: As per SF report on 07-May | S27: ='2025 PROJECTWISE'!N152 -> 4.7390351e+09
B29: Siniya & Downtown Total Collections
B30: 2026 | C30: Jan | D30: Feb | E30: March | F30: Q1 | G30: Apr | H30: May | I30: Jun | J30: Q2 | K30: H1 | L30: July | M30: Aug | N30: Sept | O30: Q3 | P30: Oct | Q30: Nov | R30: Dec | S30: Total
B31: Dues Target | C31: 1.5364001e+08 | D31: 1.5223973e+08 | E31: 1.7401297e+08 | F31: =SUM(C31:E31) -> 4.7989271e+08 | G31: 1.6359146e+08 | H31: 1.5754607e+08 | I31: 1.5989575e+08 | J31: =SUM(G31:I31) -> 4.8103328e+08 | K31: =SUM(J31,F31) -> 9.6092599e+08 | L31: 1.4882083e+08 | M31: 1.6685182e+08 | N31: 2.1529745e+08 | O31: =SUM(L31:N31) -> 5.309701e+08 | P31: 1.7914945e+08 | Q31: 1.8001273e+08 | R31: 1.5189081e+08 | S31: =SUM(K31,O31:R31) -> 2.0029491e+09
B32: Dues Collections | C32: 178631453 | D32: 1.8295026e+08 | E32: 1.3499267e+08 | F32: =SUM(C32:E32) -> 4.9657438e+08 | G32: 1.7057676e+08 | H32: 51482684 | I32: 0 | J32: =SUM(G32:I32) -> 2.2205945e+08 | K32: =F32+J32 -> 7.1863383e+08 | L32: 0 | M32: 0 | N32: 0 | O32: =SUM(L32:N32) -> 0 | P32: 0 | Q32: 0 | R32: 0 | S32: =SUM(K32,O32:R32) -> 7.1863383e+08
B33: New Sales Target | C33: 113512500 | D33: 113512500 | E33: 113512500 | F33: =SUM(C33:E33) -> 340537500 | G33: 126125000 | H33: 126125000 | I33: 126125000 | J33: =SUM(G33:I33) -> 378375000 | K33: =SUM(J33,F33) -> 718912500 | L33: 126125000 | M33: 126125000 | N33: 126125000 | O33: =SUM(L33:N33) -> 378375000 | P33: 1.387375e+08 | Q33: 1.387375e+08 | R33: 1.387375e+08 | S33: =SUM(K33,O33:R33) -> 1513500000
B34: New Sales Collections | C34: 37653757 | D34: 36603286 | E34: 13051024 | F34: =SUM(C34:E34) -> 87308067 | G34: 6600608.8 | H34: 1455483.5 | I34: 0 | J34: =SUM(G34:I34) -> 8056092.3 | K34: =F34+J34 -> 95364159 | L34: 0 | M34: 0 | N34: 0 | O34: =SUM(L34:N34) -> 0 | P34: 0 | Q34: 0 | R34: 0 | S34: =SUM(K34,O34:R34) -> 95364159
B35: Total Siniya Target | C35: =SUM(C31,C33) -> 2.6715251e+08 | D35: =SUM(D31,D33) -> 2.6575223e+08 | E35: =SUM(E31,E33) -> 2.8752547e+08 | F35: =SUM(F31,F33) -> 8.2043021e+08 | G35: =SUM(G31,G33) -> 2.8971646e+08 | H35: =SUM(H31,H33) -> 2.8367107e+08 | I35: =SUM(I31,I33) -> 2.8602075e+08 | J35: =SUM(J31,J33) -> 8.5940828e+08 | ... S35: =SUM(S31,S33) -> 3.5164491e+09
B36: Total Collections | C36: =SUM(C32,C34) -> 216285210 | D36: =SUM(D32,D34) -> 2.1955355e+08 | E36: =SUM(E32,E34) -> 1.4804369e+08 | F36: =SUM(F32,F34) -> 5.8388245e+08 | G36: =SUM(G32,G34) -> 1.7717737e+08 | H36: =SUM(H32,H34) -> 52938168 | I36: =SUM(I32,I34) -> 0 | J36: =SUM(J32,J34) -> 2.3011554e+08 | ... S36: =SUM(S32,S34) -> 8.1399799e+08
B37: Account_2 | C37: 1.9474683e+08 | D37: 1.9048075e+08 | E37: 1.3116918e+08 | F37: =SUM(C37:E37) -> 5.1639675e+08 | G37: 1.0960534e+08 | H37: 13710968 | I37: 0 | J37: =SUM(G37:I37) -> 1.2331631e+08 | K37: =F37+J37 -> 6.3971307e+08 | L37: 0 | M37: 0 | N37: 0 | O37: =SUM(L37:N37) -> 0 | P37: 0 | Q37: 0 | R37: 0 | S37: =SUM(K37,O37:R37) -> 6.3971307e+08
B38: Account_1 | C38: =C36-C37 -> 21538383 | D38: =D36-D37 -> 29072801 | E38: =E36-E37 -> 16874510 | F38: =SUM(C38:E38) -> 67485694 | G38: =G36-G37 -> 67572028 | H38: =H36-H37 -> 39227200 | I38: =I36-I37 -> 0 | J38: =SUM(G38:I38) -> 1.0679923e+08 | K38: =F38+J38 -> 1.7428492e+08 | L38: =L36-L37 -> 0 | M38: =M36-M37 -> 0 | N38: =N36-N37 -> 0 | O38: =SUM(L38:N38) -> 0 | P38: =P36-P37 -> 0 | Q38: =Q36-Q37 -> 0 | R38: =R36-R37 -> 0 | S38: =SUM(K38,O38:R38) -> 1.7428492e+08
B40: *Note:- Q1 months have been adjusted against actual collection figures. The values are subject to reconciliation based on clearing of unidentifieds.
C41: 46023 | D41: 46054 | E41: 46082 | G41: 46113 | H41: 46143 | I41: 46174 | L41: 46204 | M41: 46235 | N41: 46266 | P41: 46296 | Q41: 46327 | R41: 46357 | S41: 46388
C46: 9.2418623e+08 | D46: 8.2375797e+08 | E46: 6.8942446e+08 | F46: 2.4373687e+09 | G46: 8.913036e+08 | H46: 2.3272049e+08 | I46: 0 | J46: 1.1240241e+09 | K46: 3.5613928e+09 | L46: 0 | M46: 0 | N46: 0 | O46: 0 | P46: 0 | Q46: 0
C47: 1.9710685e+08 | D47: 2.1886683e+08 | E47: 63257146 | F47: 4.7923082e+08 | G47: 61974368 | H47: 26285911 | I47: 0 | J47: 88260279 | K47: 5.674911e+08 | L47: 0 | M47: 0 | N47: 0 | O47: 0 | P47: 0 | Q47: 0
L48: =SUM(L46:L47) -> 0 | M48: =SUM(M46:M47) -> 0 | N48: =SUM(N46:N47) -> 0 | O48: =SUM(O46:O47) -> 0 | P48: =SUM(P46:P47) -> 0
...

Sheet 2025 PROJECTWISE
B1: 46023 | C1: 46054 | D1: 46082 | E1: 46113 | F1: 46143 | G1: 46174 | H1: 46204 | I1: 46235 | J1: 46266 | K1: 46296 | L1: 46327 | M1: 46357 | N1: 46388
A4: 2025 | B4: =TEXT(daily!F3,"YYYY") & " collections from units sold in 2024" -> 2026 collections from units sold in 2024
A5: Project | B5: January | C5: February | D5: March | E5: April | F5: May | G5: June | H5: July | I5: Aug | J5: Sep | K5: Oct | L5: Nov | M5: Dec | N5: Collected till date
B6: Total collections
A7: Greens-Phase I | B7: 0 | C7: 0 | D7: 0 | E7: 0 | F7: 0 | G7: 0 | H7: 0 | I7: 0 | J7: 0 | K7: 0 | L7: 0 | M7: 0 | N7: =SUM(B7:M7) -> 0
A8: Greens-Phase II | B8: 0 | C8: 0 | D8: 0 | E8: 0 | F8: 0 | G8: 0 | H8: 0 | I8: 0 | J8: 0 | K8: 0 | L8: 0 | M8: 0 | N8: =SUM(B8:M8) -> 0
A9: Greens-Phase III | B9: 0 | C9: 0 | D9: 0 | E9: 0 | F9: 0 | G9: 0 | H9: 0 | I9: 0 | J9: 0 | K9: 0 | L9: 0 | M9: 0 | N9: =SUM(B9:M9) -> 0
A10: Creek Vistas | B10: 0 | C10: 0 | D10: 0 | E10: 0 | F10: 0 | G10: 0 | H10: 0 | I10: 0 | J10: 0 | K10: 0 | L10: 0 | M10: 0 | N10: =SUM(B10:M10) -> 0 | AH10: 0 | AI10: 0
A11: One Park Avenue | B11: 0 | C11: 0 | D11: 0 | E11: 0 | F11: 0 | G11: 0 | H11: 0 | I11: 0 | J11: 0 | K11: 0 | L11: 0 | M11: 0 | N11: =SUM(B11:M11) -> 0 | AH11: 0 | AI11: 0
A12: Creek Vistas Reserve | B12: 0 | C12: 158282 | D12: 653.12 | E12: 915.59 | F12: 0 | G12: 0 | H12: 0 | I12: 0 | J12: 0 | K12: 0 | L12: 0 | M12: 0 | N12: =SUM(B12:M12) -> 159850.71 | AH12: 158282 | AI12: 0
A13: Townhouses | B13: 0 | C13: 0 | D13: 0 | E13: 0 | F13: 0 | G13: 0 | H13: 0 | I13: 0 | J13: 0 | K13: 0 | L13: 0 | M13: 0 | N13: =SUM(B13:M13) -> 0
A14: Villas-Phase I | B14: 0 | C14: 0 | D14: 0 | E14: 0 | F14: 0 | G14: 0 | H14: 0 | I14: 0 | J14: 0 | K14: 0 | L14: 0 | M14: 0 | N14: =SUM(B14:M14) -> 0
A15: Villas-Phase II | B15: 0 | C15: 0 | D15: 0 | E15: 0 | F15: 0 | G15: 0 | H15: 0 | I15: 0 | J15: 0 | K15: 0 | L15: 0 | M15: 0 | N15: =SUM(B15:M15) -> 0
A16: Villas - Phase III | B16: 0 | C16: 0 | D16: 0 | E16: 0 | F16: 0 | G16: 0 | H16: 0 | I16: 0 | J16: 0 | K16: 0 | L16: 0 | M16: 0 | N16: =SUM(B16:M16) -> 0
A17: Villas - Phase IV | B17: 0 | C17: 0 | D17: 0 | E17: 0 | F17: 0 | G17: 0 | H17: 0 | I17: 0 | J17: 0 | K17: 0 | L17: 0 | M17: 0 | N17: =SUM(B17:M17) -> 0
A18: Waves | B18: 0 | C18: 0 | D18: 0 | E18: 0 | F18: 0 | G18: 0 | H18: 0 | I18: 0 | J18: 0 | K18: 0 | L18: 0 | M18: 0 | N18: =SUM(B18:M18) -> 0
A19: Waves Grande | B19: 162139 | C19: 0 | D19: 0 | E19: 0 | F19: 0 | G19: 0 | H19: 0 | I19: 0 | J19: 0 | K19: 0 | L19: 0 | M19: 0 | N19: =SUM(B19:M19) -> 162139
A20: The S | B20: 0 | C20: 0 | D20: 0 | E20: 0 | F20: 0 | G20: 0 | H20: 0 | I20: 0 | J20: 0 | K20: 0 | L20: 0 | M20: 0 | N20: =SUM(B20:M20) -> 0
A21: The Crest | B21: 2089232.8 | C21: 2585045.6 | D21: 880.3 | E21: 481 | F21: 0 | G21: 0 | H21: 0 | I21: 0 | J21: 0 | K21: 0 | L21: 0 | M21: 0 | N21: =SUM(B21:M21) -> 4675639.6
A22: CV Grande | B22: 11222.35 | C22: 185000 | D22: 0 | E22: 0 | F22: 0 | G22: 0 | H22: 0 | I22: 0 | J22: 0 | K22: 0 | L22: 0 | M22: 0 | N22: =SUM(B22:M22) -> 196222.35
A23: Crest Grande | B23: 0 | C23: 34341 | D23: 18425 | E23: 1843316 | F23: 1855 | G23: 0 | H23: 0 | I23: 0 | J23: 0 | K23: 0 | L23: 0 | M23: 0 | N23: =SUM(B23:M23) -> 1897937
A24: Creek Vista Heights | B24: 2315147.6 | C24: 680000 | D24: 1550000 | E24: 7886655.6 | F24: 530000 | G24: 0 | H24: 0 | I24: 0 | J24: 0 | K24: 0 | L24: 0 | M24: 0 | N24: =SUM(B24:M24) -> 12961803
... A51: Coastline Beach Residences | B51: 13806585 | C51: 12175449 | D51: 6869813.7 | E51: 3716961.5 | F51: 571507.02 | G51: 0 | H51: 0 | I51: 0 | J51: 0 | K51: 0 | L51: 0 | M51: 0 | N51: =SUM(B51:M51) -> 37140316
A52: Total (excl. plots) | B52: =SUM(B7:B50) -> 2.936985e+08 | C52: =SUM(C7:C50) -> 1.9562172e+08 | D52: =SUM(D7:D50) -> 1.5021675e+08 | E52: =SUM(E7:E50) -> 1.772009e+08 | F52: =SUM(F7:F50) -> 23562710 | G52: =SUM(G7:G50) -> 0 | H52: =SUM(H7:H50) -> 0 | I52: =SUM(I7:I50) -> 0 | ... N52: =SUM(N7:N50) -> 8.4030058e+08
A53: Tranquility Plots | B53: 0 | C53: 0 | D53: 0 | E53: 0 | F53: 0 | G53: 0 | H53: 0 | I53: 0 | J53: 0 | K53: 0 | L53: 0 | M53: 0 | N53: =SUM(B53:M53) -> 0
A54: Hartland extension | B54: 0 | C54: 0 | D54: 0 | E54: 0 | F54: 0 | G54: 0 | H54: 0 | I54: 0 | J54: 0 | K54: 0 | L54: 0 | M54: 0 | N54: =SUM(B54:M54) -> 0
A55: Total | B55: =SUM(B52:B54) -> 2.936985e+08 | C55: =SUM(C52:C54) -> 1.9562172e+08 | D55: =SUM(D52:D54) -> 1.5021675e+08 | E55: =SUM(E52:E54) -> 1.772009e+08 | F55: =SUM(F52:F54) -> 23562710 | G55: =SUM(G52:G54) -> 0 | H55: =SUM(H52:H54) -> 0 | I55: =SUM(I52:I54) -> 0 | ... N55: =SUM(N52:N54) -> 8.4030058e+08
A57: Project | B57: January | C57: February | D57: March | E57: April | F57: May | G57: June | H57: July | I57: Aug | J57: Sep | K57: Oct | L57: Nov | M57: Dec | N57: Collected till date
A58: Greens-Phase I | B58: 51041 | C58: 0 | D58: 0 | E58: 500 | F58: 0 | G58: 0 | H58: 0 | I58: 0 | J58: 0 | K58: 0 | L58: 0 | M58: 0 | N58: =SUM(B58:M58) -> 51541
A59: Greens-Phase II | B59: 1625 | C59: 500 | D59: 0 | E59: 2225 | F59: 0 | G59: 0 | H59: 0 | I59: 0 | J59: 0 | K59: 0 | L59: 0 | M59: 0 | N59: =SUM(B59:M59) -> 4350
A60: Greens-Phase III | B60: 30365 | C60: 155500 | D60: 98050.76 | E60: 0 | F60: 0 | G60: 0 | H60: 0 | I60: 0 | J60: 0 | K60: 0 | L60: 0 | M60: 0 | N60: =SUM(B60:M60) -> 283915.76
A61: Creek Vistas | B61: 500 | C61: 7455 | D61: 258420 | E61: 61803 | F61: 0 | G61: 0 | H61: 0 | I61: 0 | J61: 0 | K61: 0 | L61: 0 | M61: 0 | N61: =SUM(B61:M61) -> 328178
A62: Creek Vistas Reserve | B62: 481802.23 | C62: 186348.38 | D62: 464449 | E62: 74345.66 | F62: 33532.57 | G62: 0 | H62: 0 | I62: 0 | J62: 0 | K62: 0 | L62: 0 | M62: 0 | N62: =SUM(B62:M62) -> 1240477.8
A63: Townhouses | B63: 0 | C63: 0 | D63: 1000 | E63: 0 | F63: 0 | G63: 0 | H63: 0 | I63: 0 | J63: 0 | K63: 0 | L63: 0 | M63: 0 | N63: =SUM(B63:M63) -> 1000
A64: Villas-Phase I | B64: 500 | C64: 500 | D64: 0 | E64: 0 | F64: 0 | G64: 0 | H64: 0 | I64: 0 | J64: 0 | K64: 0 | L64: 0 | M64: 0 | N64: =SUM(B64:M64) -> 1000
A65: Villas-Phase II | B65: 500 | C65: 0 | D65: 474250 | E65: 0 | F65: 0 | G65: 0 | H65: 0 | I65: 0 | J65: 0 | K65: 0 | L65: 0 | M65: 0 | N65: =SUM(B65:M65) -> 474750
A66: Villas - Phase III | B66: 0 | C66: 4500963 | D66: 4852837 | E66: 1522969 | F66: 1000000 | G66: 0 | H66: 0 | I66: 0 | J66: 0 | K66: 0 | L66: 0 | M66: 0 | N66: =SUM(B66:M66) -> 11876769
A67: Villas - Phase IV | B67: 0 | C67: 0 | D67: 0 | E67: 0 | F67: 0 | G67: 0 | H67: 0 | I67: 0 | J67: 0 | K67: 0 | L67: 0 | M67: 0 | N67: =SUM(B67:M67) -> 0
A68: Hartland II Villas | B68: 38055594 | C68: 35890764 | D68: 63628435 | E68: 34965104 | F68: 4573190 | G68: 0 | H68: 0 | I68: 0 | J68: 0 | K68: 0 | L68: 0 | M68: 0 | N68: =SUM(B68:M68) -> 1.7711309e+08
A69: 310 Riverside Crescent | B69: 44329051 | C69: 32200204 | D69: 23849939 | E69: 23153367 | F69: 2162157.5 | G69: 0 | H69: 0 | I69: 0 | J69: 0 | K69: 0 | L69: 0 | M69: 0 | N69: =SUM(B69:M69) -> 1.2569472e+08
...
