Workbook
Name Ak: #REF!
Name Ak: #REF!
Name Ak: #REF!
Name NOB: #REF!
Name NOB: #REF!
Name NOB: #REF!
Name Source: #REF!
Name Source: #REF!
Name Source: #REF!
Name SRCE: #REF!
Name SRCE: #REF!
Name SRCE: #REF!
Name Style: #REF!
Name Style: #REF!
Name Style: #REF!
Name TOS: #REF!
Name TOS: #REF!
Name TOS: #REF!
Name Type: #REF!
Name Type: #REF!
Name Type: #REF!
Name VLOOKUP: #REF!
Name VLOOKUP: #REF!
Name VLOOKUP: #REF!

Sheet MDO Dynamic
B2: MONTHLY COLLECTIONS SNAPSHOT 2026 - MDO Dynamic
S3: 46148
B4: Total Collections
B5: 2026 | C5: Jan | D5: Feb | E5: March | F5: Q1 | G5: Apr | H5: May | I5: Jun | J5: Q2 | K5: H1 | L5: July | M5: Aug | N5: Sept | O5: Q3 | P5: Oct | Q5: Nov | R5: Dec | S5: Total
B6: Dues Target | C6: 7.996295e+08 | D6: 6.8783216e+08 | E6: 6.2872517e+08 | F6: =SUM(C6:E6) -> 2.1161868e+09 | G6: 6.775692e+08 | H6: 6.3911674e+08 | I6: 7.439746e+08 | J6: =SUM(G6:I6) -> 2.0606605e+09 | K6: =F6+J6 -> 4.1768474e+09 | L6: 7.6329371e+08 | M6: 7.9616032e+08 | N6: 1.1671879e+09 | O6: =SUM(L6:N6) -> 2.726642e+09 | P6: 1.1515722e+09 | Q6: 1.1227199e+09 | R6: 1.1570794e+09 | S6: =SUM(K6,O6:R6) -> 1.0334861e+10 | W6: =S6-V6 -> 1.0334861e+10
B7: Dues | C7: ='Monthwise MDO'!C7 -> 7.996295e+08 | D7: ='Monthwise MDO'!D7 -> 6.8783216e+08 | E7: ='Monthwise MDO'!E7 -> 6.2872517e+08 | F7: =SUM(C7:E7) -> 2.1161868e+09 | G7: ='Monthwise MDO'!G7 -> 7.8388328e+08 | H7: ='Monthwise MDO'!H7 -> 1.7539732e+08 | I7: ='Monthwise MDO'!I7 -> 0 | J7: =SUM(G7:I7) -> 9.592806e+08 | K7: =F7+J7 -> 3.0754674e+09 | L7: ='Monthwise MDO'!L7 -> 0 | M7: ='Monthwise MDO'!M7 -> 0 | N7: ='Monthwise MDO'!N7 -> 0 | O7: =SUM(L7:N7) -> 0 | P7: ='Monthwise MDO'!P7 -> 0 | Q7: ='Monthwise MDO'!Q7 -> 0 | R7: ='Monthwise MDO'!R7 -> 0 | S7: =SUM(K7,O7:R7) -> 3.0754674e+09 | T7: ='Monthwise MDO'!S7 -> 3.0754674e+09 | U7: =S7-T7 -> 0
B8: Advance Target | C8: 3.0579842e+08 | D8: 3.1648332e+08 | E8: 1.9244555e+08 | F8: =SUM(C8:E8) -> 8.1472729e+08 | G8: 2.1627337e+08 | H8: 2.1627337e+08 | I8: 2.1627337e+08 | J8: =SUM(G8:I8) -> 6.488201e+08 | K8: =F8+J8 -> 1.4635474e+09 | L8: 2.1627337e+08 | M8: 2.1627337e+08 | N8: 2.1627337e+08 | O8: =SUM(L8:N8) -> 6.488201e+08 | P8: 2.1627337e+08 | Q8: 2.1627337e+08 | R8: 2.1627337e+08 | S8: =SUM(K8,O8:R8) -> 2.7611876e+09 | W8: =S8-V8 -> 2.7611876e+09
B9: Current Year Advance | C9: 2.2744602e+08 | D9: 2.3438347e+08 | E9: 1.4642373e+08 | F9: =SUM(C9:E9) -> 6.0825322e+08 | G9: 2.0231277e+08 | H9: 40997469 | I9: 0 | J9: =SUM(G9:I9) -> 2.4331024e+08 | K9: =F9+J9 -> 8.5156347e+08 | L9: 0 | M9: 0 | N9: 0 | O9: =SUM(L9:N9) -> 0 | P9: 0 | Q9: 0 | R9: 0 | S9: =SUM(K9,O9:R9) -> 8.5156347e+08 | T9: ='Monthwise MDO'!S9 -> 1.134076e+09 | U9: =S9+S10-T9 -> 22790730
B10: Future Year Advance | C10: 78352395 | D10: 82099852 | E10: 46021820 | F10: =SUM(C10:E10) -> 2.0647407e+08 | G10: 86537796 | H10: 12291351 | I10: 0 | J10: =SUM(G10:I10) -> 98829147 | K10: =F10+J10 -> 3.0530321e+08 | L10: 0 | M10: 0 | N10: 0 | O10: =SUM(L10:N10) -> 0 | P10: 0 | Q10: 0 | R10: 0 | S10: =SUM(K10,O10:R10) -> 3.0530321e+08
B11: Dues+ Advance Target | C11: =SUM(C6,C8) -> 1.1054279e+09 | D11: =SUM(D6,D8) -> 1.0043155e+09 | E11: =SUM(E6,E8) -> 821170721 | F11: =SUM(C11:E11) -> 2.9309141e+09 | G11: =SUM(G6,G8) -> 8.9384256e+08 | H11: =SUM(H6,H8) -> 8.553901e+08 | I11: =SUM(I6,I8) -> 9.6024796e+08 | J11: =SUM(G11:I11) -> 2.7094806e+09 | K11: =F11+J11 -> 5.6403948e+09 | L11: =SUM(L6,L8) -> 9.7956708e+08 | M11: =SUM(M6,M8) -> 1.0124337e+09 | N11: =SUM(N6,N8) -> 1.3834613e+09 | O11: =SUM(L11:N11) -> 3.3754621e+09 | P11: =SUM(P6,P8) -> 1.3678456e+09 | Q11: =SUM(Q6,Q8) -> 1.3389933e+09 | R11: =SUM(R6,R8) -> 1.3733528e+09 | S11: =SUM(K11,O11:R11) -> 1.3096048e+10 | W11: =S11-V11 -> 1.3096048e+10
B12: Dues+ Advance | C12: ='Monthwise MDO'!C11 -> 1.1054279e+09 | D12: ='Monthwise MDO'!D11 -> 1.0043155e+09 | E12: ='Monthwise MDO'!E11 -> 821170721 | F12: =SUM(C12:E12) -> 2.9309141e+09 | G12: ='Monthwise MDO'!G11 -> 1.0499431e+09 | H12: ='Monthwise MDO'!H11 -> 2.2868614e+08 | I12: ='Monthwise MDO'!I11 -> 0 | J12: =SUM(G12:I12) -> 1.2786293e+09 | K12: =F12+J12 -> 4.2095434e+09 | L12: ='Monthwise MDO'!L11 -> 0 | M12: ='Monthwise MDO'!M11 -> 0 | N12: ='Monthwise MDO'!N11 -> 0 | O12: =SUM(L12:N12) -> 0 | P12: ='Monthwise MDO'!P11 -> 0 | Q12: ='Monthwise MDO'!Q11 -> 0 | R12: ='Monthwise MDO'!R11 -> 0 | S12: =SUM(K12,O12:R12) -> 4.2095434e+09 | T12: ='Monthwise MDO'!S11 -> 4.2095434e+09 | U12: =S12-T12 -> 0
B13: New Sales Target | C13: 2.3312495e+08 | D13: 2.588536e+08 | E13: 82601425 | F13: =SUM(C13:E13) -> 5.7457997e+08 | G13: 150000000 | H13: 150000000 | I13: 150000000 | J13: =SUM(G13:I13) -> 450000000 | K13: =F13+J13 -> 1.02458e+09 | L13: 150000000 | M13: 150000000 | N13: 150000000 | O13: =SUM(L13:N13) -> 450000000 | P13: 1.65e+08 | Q13: 1.65e+08 | R13: 1.65e+08 | S13: =SUM(K13,O13:R13) -> 1.96958e+09 | W13: =S13-V13 -> 1.96958e+09
B14: New Sales | C14: ='Monthwise MDO'!C13 -> 2.3312495e+08 | D14: ='Monthwise MDO'!D13 -> 2.588536e+08 | E14: ='Monthwise MDO'!E13 -> 82601425 | F14: =SUM(C14:E14) -> 5.7457997e+08 | G14: ='Monthwise MDO'!G13 -> 1.4979889e+08 | H14: ='Monthwise MDO'!H13 -> 43613059 | I14: ='Monthwise MDO'!I13 -> 0 | J14: =SUM(G14:I14) -> 1.9341195e+08 | K14: =F14+J14 -> 7.6799192e+08 | L14: ='Monthwise MDO'!L13 -> 0 | M14: ='Monthwise MDO'!M13 -> 0 | N14: ='Monthwise MDO'!N13 -> 0 | O14: =SUM(L14:N14) -> 0 | P14: ='Monthwise MDO'!P13 -> 0 | Q14: ='Monthwise MDO'!Q13 -> 0 | R14: ='Monthwise MDO'!R13 -> 0 | S14: =SUM(K14,O14:R14) -> 7.6799192e+08 | T14: ='Monthwise MDO'!S13 -> 7.6799192e+08 | U14: =S14-T14 -> 0
B15: Total Collections Target | C15: =C13+C11 -> 1.3385529e+09 | D15: =D13+D11 -> 1.2631691e+09 | E15: =E13+E11 -> 903772146 | F15: =SUM(C15:E15) -> 3.5054941e+09 | G15: =G13+G11 -> 1.0438426e+09 | H15: =H13+H11 -> 1.0053901e+09 | I15: =I13+I11 -> 1.110248e+09 | J15: =SUM(G15:I15) -> 3.1594806e+09 | K15: =F15+J15 -> 6.6649747e+09 | L15: =L13+L11 -> 1.1295671e+09 | M15: =M13+M11 -> 1.1624337e+09 | N15: =N13+N11 -> 1.5334613e+09 | O15: =SUM(L15:N15) -> 3.8254621e+09 | P15: =P13+P11 -> 1.5328456e+09 | Q15: =Q13+Q11 -> 1.5039933e+09 | R15: =R13+R11 -> 1.5383528e+09 | S15: =SUM(K15,O15:R15) -> 1.5065628e+10 | W15: =S15-V15 -> 1.5065628e+10
B16: MTD Total Collections | C16: =C12+C14 -> 1.3385529e+09 | D16: =D12+D14 -> 1.2631691e+09 | E16: =E12+E14 -> 903772146 | F16: =SUM(C16:E16) -> 3.5054941e+09 | G16: =G12+G14 -> 1.199742e+09 | H16: =H12+H14 -> 2.722992e+08 | I16: =I12+I14 -> 0 | J16: =SUM(G16:I16) -> 1.4720412e+09 | K16: =F16+J16 -> 4.9775353e+09 | L16: =L12+L14 -> 0 | M16: =M12+M14 -> 0 | N16: =N12+N14 -> 0 | O16: =SUM(L16:N16) -> 0 | P16: =P12+P14 -> 0 | Q16: =Q12+Q14 -> 0 | R16: =R12+R14 -> 0 | S16: =SUM(K16,O16:R16) -> 4.9775353e+09 | T16: ='Monthwise MDO'!S15 -> 4.9775353e+09 | U16: =S16-T16 -> 0
B18: Siniya Total Collections
B19: 2026 | C19: Jan | D19: Feb | E19: March | F19: Q1 | G19: Apr | H19: May | I19: Jun | J19: Q2 | K19: H1 | L19: July | M19: Aug | N19: Sept | O19: Q3 | P19: Oct | Q19: Nov | R19: Dec | S19: Total
B20: Dues Target | C20: 1.3021322e+08 | D20: 1.266256e+08 | E20: 1.0498264e+08 | F20: =SUM(C20:E20) -> 3.6182146e+08 | G20: 1.2562074e+08 | H20: 1.1343168e+08 | I20: 1.4021636e+08 | J20: =SUM(G20:I20) -> 3.7926878e+08 | K20: =F20+J20 -> 7.4109024e+08 | L20: 1.7418391e+08 | M20: 1.4040037e+08 | N20: 1.5081996e+08 | O20: =SUM(L20:N20) -> 4.6540425e+08 | P20: 1.503269e+08 | Q20: 1.4081256e+08 | R20: 1.339562e+08 | S20: =SUM(K20,O20:R20) -> 1.6315901e+09 | W20: =S20-V20 -> 1.6315901e+09
B21: Dues | C21: ='Monthwise MDO'!C20 -> 1.3021322e+08 | D21: ='Monthwise MDO'!D20 -> 1.266256e+08 | E21: ='Monthwise MDO'!E20 -> 1.0498264e+08 | F21: =SUM(C21:E21) -> 3.6182146e+08 | G21: ='Monthwise MDO'!G20 -> 1.2284411e+08 | H21: ='Monthwise MDO'!H20 -> 30099656 | I21: ='Monthwise MDO'!I20 -> 0 | J21: =SUM(G21:I21) -> 1.5294377e+08 | K21: =F21+J21 -> 5.1476523e+08 | L21: ='Monthwise MDO'!L20 -> 0 | M21: ='Monthwise MDO'!M20 -> 0 | N21: ='Monthwise MDO'!N20 -> 0 | O21: =SUM(L21:N21) -> 0 | P21: ='Monthwise MDO'!P20 -> 0 | Q21: =Q26-Q23 -> 0 | R21: =R26-R23 -> 0 | S21: =SUM(K21,O21:R21) -> 5.1476523e+08 | T21: ='Monthwise MDO'!S20 -> 5.1476523e+08 | U21: =S21-T21 -> 0
B22: Advance Target | C22: 33012253 | D22: 39134249 | E22: 18539714 | F22: =SUM(C22:E22) -> 90686215 | G22: 31273365 | H22: 31273365 | I22: 31273365 | J22: =SUM(G22:I22) -> 93820095 | K22: =F22+J22 -> 1.8450631e+08 | L22: 31273365 | M22: 31273365 | N22: 31273365 | O22: =SUM(L22:N22) -> 93820095 | P22: 31273365 | Q22: 31273365 | R22: 31273365 | S22: =SUM(K22,O22:R22) -> 3.721465e+08 | W22: =S22-V22 -> 3.721465e+08
B23: Current Year Advance | C23: 24172123 | D23: 26102885 | E23: 12451065 | F23: =SUM(C23:E23) -> 62726072 | G23: 22073633 | H23: 3804997.4 | I23: 0 | J23: =SUM(G23:I23) -> 25878630 | K23: =F23+J23 -> 88604703 | L23: 0 | M23: 0 | N23: 0 | O23: =SUM(L23:N23) -> 0 | P23: 0 | Q23: 0 | R23: 0 | S23: =SUM(K23,O23:R23) -> 88604703 | T23: ='Monthwise MDO'!S22 -> 1.3500322e+08 | U23: =S23+S24-T23 -> 0
B24: Future Year Advance | C24: 8840129.8 | D24: 13031364 | E24: 6088649 | F24: =SUM(C24:E24) -> 27960143 | G24: 17525178 | H24: 913198.62 | I24: 0 | J24: =SUM(G24:I24) -> 18438376 | K24: =F24+J24 -> 46398519 | L24: 0 | M24: 0 | N24: 0 | O24: =SUM(L24:N24) -> 0 | P24: 0 | Q24: 0 | R24: 0 | S24: =SUM(K24,O24:R24) -> 46398519
B25: Dues+ Advance Target | C25: =C20+C22 -> 163225471 | D25: =D20+D22 -> 1.6575985e+08 | E25: =E20+E22 -> 1.2352235e+08 | F25: =SUM(C25:E25) -> 4.5250767e+08 | G25: =G20+G22 -> 1.568941e+08 | H25: =H20+H22 -> 1.4470505e+08 | I25: =I20+I22 -> 1.7148972e+08 | J25: =SUM(G25:I25) -> 4.7308887e+08 | K25: =F25+J25 -> 9.2559655e+08 | L25: =SUM(L20,L22) -> 2.0545728e+08 | M25: =SUM(M20,M22) -> 1.7167374e+08 | N25: =SUM(N20,N22) -> 1.8209333e+08 | O25: =SUM(L25:N25) -> 5.5922434e+08 | P25: =SUM(P20,P22) -> 1.8160027e+08 | Q25: =SUM(Q20,Q22) -> 1.7208592e+08 | R25: =SUM(R20,R22) -> 1.6522956e+08 | S25: =SUM(K25,O25:R25) -> 2.0037366e+09 | W25: =S25-V25 -> 2.0037366e+09
B26: Dues+ Advance | C26: ='Monthwise MDO'!C24 -> 163225471 | D26: ='Monthwise MDO'!D24 -> 1.6575985e+08 | E26: ='Monthwise MDO'!E24 -> 1.2352235e+08 | F26: =SUM(C26:E26) -> 4.5250767e+08 | G26: ='Monthwise MDO'!G24 -> 1.6244292e+08 | H26: ='Monthwise MDO'!H24 -> 34817852 | I26: ='Monthwise MDO'!I24 -> 0 | J26: =SUM(G26:I26) -> 1.9726077e+08 | K26: =F26+J26 -> 6.4976845e+08 | L26: ='Monthwise MDO'!L24 -> 0 | M26: ='Monthwise MDO'!M24 -> 0 | N26: ='Monthwise MDO'!N24 -> 0 | O26: =SUM(L26:N26) -> 0 | P26: ='Monthwise MDO'!P24 -> 0 | Q26: ='Monthwise MDO'!Q24 -> 0 | R26: ='Monthwise MDO'!R24 -> 0 | S26: =SUM(K26,O26:R26) -> 6.4976845e+08 | T26: ='Monthwise MDO'!S24 -> 6.4976845e+08 | U26: =S26-T26 -> 0
B27: New Sales Target | C27: 30463929 | D27: 29508594 | E27: 11304707 | F27: =SUM(C27:E27) -> 71277229 | G27: 12500000 | H27: 12500000 | I27: 12500000 | J27: =SUM(G27:I27) -> 37500000 | K27: =F27+J27 -> 1.0877723e+08 | L27: 12500000 | M27: 12500000 | N27: 12500000 | O27: =SUM(L27:N27) -> 37500000 | P27: 13750000 | Q27: 13750000 | R27: 13750000 | S27: =SUM(K27,O27:R27) -> 1.8752723e+08 | W27: =S27-V27 -> 1.8752723e+08
B28: New Sales | C28: ='Monthwise MDO'!C26 -> 30463929 | D28: ='Monthwise MDO'!D26 -> 29508594 | E28: ='Monthwise MDO'!E26 -> 11304707 | F28: =SUM(C28:E28) -> 71277229 | G28: ='Monthwise MDO'!G26 -> 318807.83 | H28: ='Monthwise MDO'!H26 -> 93 | I28: ='Monthwise MDO'!I26 -> 0 | J28: =SUM(G28:I28) -> 318900.83 | K28: =F28+J28 -> 71596130 | L28: ='Monthwise MDO'!L26 -> 0 | M28: ='Monthwise MDO'!M26 -> 0 | N28: ='Monthwise MDO'!N26 -> 0 | O28: =SUM(L28:N28) -> 0 | P28: ='Monthwise MDO'!P26 -> 0 | Q28: ='Monthwise MDO'!Q26 -> 0 | R28: ='Monthwise MDO'!R26 -> 0 | S28: =SUM(K28,O28:R28) -> 71596130 | T28: ='Monthwise MDO'!S26 -> 71596130 | U28: =S28-T28 -> 0
B29: Total Collections Target | C29: =C25+C27 -> 193689400 | D29: =D25+D27 -> 1.9526844e+08 | E29: =E25+E27 -> 1.3482706e+08 | F29: =SUM(C29:E29) -> 5.237849e+08 | G29: =G25+G27 -> 1.693941e+08 | H29: =H25+H27 -> 1.5720505e+08 | I29: =I25+I27 -> 1.8398972e+08 | J29: =SUM(G29:I29) -> 5.1058887e+08 | K29: =F29+J29 -> 1.0343738e+09 | L29: =L25+L27 -> 2.1795728e+08 | M29: =M25+M27 -> 1.8417374e+08 | N29: =N25+N27 -> 1.9459333e+08 | O29: =SUM(L29:N29) -> 5.9672434e+08 | P29: =P25+P27 -> 1.9535027e+08 | Q29: =Q25+Q27 -> 1.8583592e+08 | R29: =R25+R27 -> 1.7897956e+08 | S29: =SUM(K29,O29:R29) -> 2.1912639e+09 | W29: =S29-V29 -> 2.1912639e+09
B30: MTD Total Collections | C30: =C26+C28 -> 193689400 | D30: =D26+D28 -> 1.9526844e+08 | E30: =E26+E28 -> 1.3482706e+08 | F30: =SUM(C30:E30) -> 5.237849e+08 | G30: =G26+G28 -> 1.6276173e+08 | H30: =H26+H28 -> 34817945 | I30: =I26+I28 -> 0 | J30: =SUM(G30:I30) -> 1.9757967e+08 | K30: =F30+J30 -> 7.2136458e+08 | L30: =L26+L28 -> 0 | M30: =M26+M28 -> 0 | N30: =N26+N28 -> 0 | O30: =SUM(L30:N30) -> 0 | P30: =P26+P28 -> 0 | Q30: =Q26+Q28 -> 0 | R30: =R26+R28 -> 0 | S30: =SUM(K30,O30:R30) -> 7.2136458e+08 | T30: ='Monthwise MDO'!S28 -> 7.2136458e+08 | U30: =S30-T30 -> 0
B32: Sobha Total Collections
B33: 2026 | C33: Jan | D33: Feb | E33: March | F33: Q1 | G33: Apr | H33: May | I33: Jun | J33: Q2 | K33: H1 | L33: July | M33: Aug | N33: Sept | O33: Q3 | P33: Oct | Q33: Nov | R33: Dec | S33: Total
B34: Dues Target | C34: =C6-C20-C48 -> 6.5659947e+08 | D34: =D6-D20-D48 -> 5.5159569e+08 | E34: =E6-E20-E48 -> 5.171397e+08 | F34: =SUM(C34:E34) -> 1.7253349e+09 | G34: 5.4384264e+08 | H34: 5.1092451e+08 | I34: 585000000 | J34: =SUM(G34:I34) -> 1.6397671e+09 | K34: =F34+J34 -> 3.365102e+09 | L34: 5.7707746e+08 | M34: 6.4462724e+08 | N34: 1.0078082e+09 | O34: =SUM(L34:N34) -> 2.2295129e+09 | P34: 9.7517537e+08 | Q34: 9.6060312e+08 | R34: 1.0060398e+09 | S34: =SUM(K34,O34:R34) -> 8.5364332e+09 | W34: =S34-V34 -> 8.5364332e+09
B35: Dues | C35: ='Monthwise MDO'!C33 -> 6.5659947e+08 | D35: ='Monthwise MDO'!D33 -> 5.5159569e+08 | E35: ='Monthwise MDO'!E33 -> 5.171397e+08 | F35: =SUM(C35:E35) -> 1.7253349e+09 | G35: ='Monthwise MDO'!G33 -> 6.4402254e+08 | H35: ='Monthwise MDO'!H33 -> 1.3982628e+08 | I35: ='Monthwise MDO'!I33 -> 0 | J35: =SUM(G35:I35) -> 7.8384882e+08 | K35: =F35+J35 -> 2.5091837e+09 | L35: ='Monthwise MDO'!L33 -> 0 | M35: ='Monthwise MDO'!M33 -> 0 | N35: ='Monthwise MDO'!N33 -> 0 | O35: =SUM(L35:N35) -> 0 | P35: ='Monthwise MDO'!P33 -> 0 | Q35: ='Monthwise MDO'!Q33 -> 0 | R35: ='Monthwise MDO'!R33 -> 0 | S35: =SUM(K35,O35:R35) -> 2.5091837e+09 | T35: ='Monthwise MDO'!S33 -> 2.5091837e+09 | U35: =S35-T35 -> 0
B36: Advance Target | C36: =C8-C22-C50 -> 2.7030392e+08 | D36: =D8-D22-D50 -> 2.7013421e+08 | E36: =E8-E22-E50 -> 1.7047877e+08 | F36: =SUM(C36:E36) -> 7.1091689e+08 | G36: 180000000 | H36: 180000000 | I36: 180000000 | J36: =SUM(G36:I36) -> 540000000 | K36: =F36+J36 -> 1.2509169e+09 | L36: 180000000 | M36: 180000000 | N36: 180000000 | O36: =SUM(L36:N36) -> 540000000 | P36: 180000000 | Q36: 180000000 | R36: 180000000 | S36: =SUM(K36,O36:R36) -> 2.3309169e+09 | W36: =S36-V36 -> 2.3309169e+09
B37: Current Year Advance | C37: =C9-C23-C51 -> 2.0119061e+08 | D37: =D9-D23-D51 -> 2.0479201e+08 | E37: =E9-E23-E51 -> 1.3126328e+08 | F37: =SUM(C37:E37) -> 5.3724591e+08 | G37: =G9-G23-G51 -> 1.7766639e+08 | H37: =H9-H23-H51-H78 -> 35699157 | I37: =I9-I23-I51 -> 0 | J37: =SUM(G37:I37) -> 2.1434465e+08 | K37: =F37+J37 -> 7.5159056e+08 | L37: =L9-L23-L51 -> 0 | M37: =M9-M23-M51 -> 0 | N37: =N9-N23-N51 -> 0 | O37: =SUM(L37:N37) -> 0 | P37: =P9-P23-P51 -> 0 | Q37: =Q9-Q23-Q51 -> 0 | R37: =R9-R23-R51 -> 0 | S37: =SUM(K37,O37:R37) -> 7.5159056e+08 | T37: ='Monthwise MDO'!S35 -> 9.7939953e+08 | U37: =S37+S38-T37 -> 23800215
B38: Future Year Advance | C38: =C10-C24-C52 -> 69113304 | D38: =D10-D24-D52 -> 65342193 | E38: =E10-E24-E52 -> 39215486 | F38: =SUM(C38:E38) -> 1.7367098e+08 | G38: =G10-G24-G52 -> 66677091 | H38: =H10-H24-H52-H79 -> 11016331 | I38: =I10-I24-I52 -> 0 | J38: =SUM(G38:I38) -> 77938200 | K38: =F38+J38 -> 2.5160918e+08 | L38: =L10-L24-L52 -> 0 | M38: =M10-M24-M52 -> 0 | N38: =N10-N24-N52 -> 0 | O38: =SUM(L38:N38) -> 0 | P38: =P10-P24-P52 -> 0 | Q38: =Q10-Q24-Q52 -> 0 | R38: =R10-R24-R52 -> 0 | S38: =SUM(K38,O38:R38) -> 2.5160918e+08
B39: Dues+ Advance Target | C39: =C34+C36 -> 9.2690338e+08 | D39: =D34+D36 -> 8.2172989e+08 | E39: =E34+E36 -> 6.8761847e+08 | F39: =SUM(C39:E39) -> 2.4362517e+09 | G39: =G34+G36 -> 7.2384264e+08 | H39: =H34+H36 -> 6.9092451e+08 | I39: =I34+I36 -> 765000000 | J39: =SUM(G39:I39) -> 2.1797671e+09 | K39: =F39+J39 -> 4.6160189e+09 | L39: =SUM(L34,L36) -> 7.5707746e+08 | M39: =SUM(M34,M36) -> 8.2462724e+08 | N39: =SUM(N34,N36) -> 1.1878082e+09 | O39: =SUM(L39:N39) -> 2.7695129e+09 | P39: =SUM(P34,P36) -> 1.1551754e+09 | Q39: =SUM(Q34,Q36) -> 1.1406031e+09 | R39: =SUM(R34,R36) -> 1.1860398e+09 | S39: =SUM(K39,O39:R39) -> 1.086735e+10 | W39: =S39-V39 -> 1.086735e+10
B40: Dues+ Advance | C40: ='Monthwise MDO'!C37 -> 9.2690338e+08 | D40: ='Monthwise MDO'!D37 -> 8.2172989e+08 | E40: ='Monthwise MDO'!E37 -> 6.8761847e+08 | F40: =SUM(C40:E40) -> 2.4362517e+09 | G40: ='Monthwise MDO'!G37 -> 8.6578969e+08 | H40: ='Monthwise MDO'!H37 -> 1.8654177e+08 | I40: ='Monthwise MDO'!I37 -> 0 | J40: =SUM(G40:I40) -> 1.0523315e+09 | K40: =F40+J40 -> 3.4885832e+09 | L40: ='Monthwise MDO'!L37 -> 0 | M40: ='Monthwise MDO'!M37 -> 0 | N40: ='Monthwise MDO'!N37 -> 0 | O40: =SUM(L40:N40) -> 0 | P40: ='Monthwise MDO'!P37 -> 0 | Q40: ='Monthwise MDO'!Q37 -> 0 | R40: ='Monthwise MDO'!R37 -> 0 | S40: =SUM(K40,O40:R40) -> 3.4885832e+09 | T40: ='Monthwise MDO'!S37 -> 3.4885832e+09 | U40: =S40-T40 -> 0
B41: New Sales Target | C41: =C13-C27-C55 -> 1.9546922e+08 | D41: =D13-D27-D55 -> 2.2197776e+08 | E41: =E13-E27-E55 -> 68950536 | F41: =SUM(C41:E41) -> 4.8639752e+08 | G41: 125000000 | H41: 125000000 | I41: 125000000 | J41: =SUM(G41:I41) -> 375000000 | K41: =F41+J41 -> 8.6139752e+08 | L41: 125000000 | M41: 125000000 | N41: 125000000 | O41: =SUM(L41:N41) -> 375000000 | P41: 1.375e+08 | Q41: 1.375e+08 | R41: 1.375e+08 | S41: =SUM(K41,O41:R41) -> 1.6488975e+09 | W41: =S41-V41 -> 1.6488975e+09
B42: New Sales | C42: ='Monthwise MDO'!C39 -> 1.9546922e+08 | D42: ='Monthwise MDO'!D39 -> 2.2197776e+08 | E42: ='Monthwise MDO'!E39 -> 68950536 | F42: =SUM(C42:E42) -> 4.8639752e+08 | G42: ='Monthwise MDO'!G39 -> 96743360 | H42: ='Monthwise MDO'!H39 -> 26212146 | I42: ='Monthwise MDO'!I39 -> 0 | J42: =SUM(G42:I42) -> 1.2295551e+08 | K42: =F42+J42 -> 6.0935302e+08 | L42: ='Monthwise MDO'!L39 -> 0 | M42: ='Monthwise MDO'!M39 -> 0 | N42: ='Monthwise MDO'!N39 -> 0 | O42: =SUM(L42:N42) -> 0 | P42: ='Monthwise MDO'!P39 -> 0 | Q42: ='Monthwise MDO'!Q39 -> 0 | R42: ='Monthwise MDO'!R39 -> 0 | S42: =SUM(K42,O42:R42) -> 6.0935302e+08 | T42: ='Monthwise MDO'!S39 -> 6.0935302e+08 | U42: =S42-T42 -> 0
B43: Total Collections Target | C43: =C39+C41 -> 1.1223726e+09 | D43: =D39+D41 -> 1.0437077e+09 | E43: =E39+E41 -> 7.56569e+08 | F43: =SUM(C43:E43) -> 2.9226493e+09 | G43: =G39+G41 -> 8.4884264e+08 | H43: =H39+H41 -> 8.1592451e+08 | I43: =I39+I41 -> 890000000 | J43: =SUM(G43:I43) -> 2.5547671e+09 | K43: =F43+J43 -> 5.4774164e+09 | L43: =L39+L41 -> 8.8207746e+08 | M43: =M39+M41 -> 9.4962724e+08 | N43: =N39+N41 -> 1.3128082e+09 | O43: =SUM(L43:N43) -> 3.1445129e+09 | P43: =P39+P41 -> 1.2926754e+09 | Q43: =Q39+Q41 -> 1.2781031e+09 | R43: =R39+R41 -> 1.3235398e+09 | S43: =SUM(K43,O43:R43) -> 1.2516248e+10 | W43: =S43-V43 -> 1.2516248e+10
...

Sheet Monthwise MDO
B2: MONTHLY COLLECTIONS SNAPSHOT 2026
S3: 46148
B4: Total Collections
B5: 2026 | C5: Jan | D5: Feb | E5: March | F5: Q1 | G5: Apr | H5: May | I5: Jun | J5: Q2 | K5: H1 | L5: July | M5: Aug | N5: Sept | O5: Q3 | P5: Oct | Q5: Nov | R5: Dec | S5: Total
B6: Dues Target | C6: 7.996295e+08 | D6: 6.8783216e+08 | E6: 6.2872517e+08 | F6: =SUM(C6:E6) -> 2.1161868e+09 | G6: 6.775692e+08 | H6: 6.3911674e+08 | I6: 7.439746e+08 | J6: =SUM(G6:I6) -> 2.0606605e+09 | K6: =F6+J6 -> 4.1768474e+09 | L6: 7.6329371e+08 | M6: 7.9616032e+08 | N6: 1.1671879e+09 | O6: =SUM(L6:N6) -> 2.726642e+09 | P6: 1.1515722e+09 | Q6: 1.1227199e+09 | R6: 1.1570794e+09 | S6: =SUM(K6,O6:R6) -> 1.0334861e+10
B7: Dues | C7: =C11-C9 -> 7.996295e+08 | D7: =D11-D9 -> 6.8783216e+08 | E7: =E11-E9 -> 6.2872517e+08 | F7: =SUM(C7:E7) -> 2.1161868e+09 | G7: =G11-G9 -> 7.8388328e+08 | H7: =H11-H9 -> 1.7539732e+08 | I7: =I11-I9 -> 0 | J7: =SUM(G7:I7) -> 9.592806e+08 | K7: =F7+J7 -> 3.0754674e+09 | L7: =L11-L9 -> 0 | M7: =M11-M9 -> 0 | N7: =N11-N9 -> 0 | O7: =SUM(L7:N7) -> 0 | P7: =P11-P9 -> 0 | Q7: =Q11-Q9 -> 0 | R7: =R11-R9 -> 0 | S7: =SUM(K7,O7:R7) -> 3.0754674e+09
B8: Advance Target | C8: 3.2e+08 | D8: 3.2e+08 | E8: 1.9244555e+08 | F8: =SUM(C8:E8) -> 8.3244555e+08 | G8: 2.1627337e+08 | H8: 2.1627337e+08 | I8: 2.1627337e+08 | J8: =SUM(G8:I8) -> 6.488201e+08 | K8: =F8+J8 -> 1.4812656e+09 | L8: 2.1627337e+08 | M8: 2.1627337e+08 | N8: 2.1627337e+08 | O8: =SUM(L8:N8) -> 6.488201e+08 | P8: 2.1627337e+08 | Q8: 2.1627337e+08 | R8: 2.1627337e+08 | S8: =SUM(K8,O8:R8) -> 2.7789058e+09
B9: Advance | C9: 3.0579842e+08 | D9: 3.1648332e+08 | E9: 1.9244555e+08 | F9: =SUM(C9:E9) -> 8.1472729e+08 | G9: 2.6605984e+08 | H9: 53288820 | I9: 0 | J9: =SUM(G9:I9) -> 3.1934866e+08 | K9: =F9+J9 -> 1.134076e+09 | L9: 0 | M9: 0 | N9: 0 | O9: =SUM(L9:N9) -> 0 | P9: 0 | Q9: 0 | R9: 0 | S9: =SUM(K9,O9:R9) -> 1.134076e+09
B10: Dues+ Advance Target | C10: =C8+C6 -> 1.1196295e+09 | D10: =D8+D6 -> 1.0078322e+09 | E10: =E8+E6 -> 821170721 | F10: =SUM(C10:E10) -> 2.9486324e+09 | G10: =G8+G6 -> 8.9384256e+08 | H10: =H8+H6 -> 8.553901e+08 | I10: =I8+I6 -> 9.6024796e+08 | J10: =SUM(G10:I10) -> 2.7094806e+09 | K10: =F10+J10 -> 5.658113e+09 | L10: =L8+L6 -> 9.7956708e+08 | M10: =M8+M6 -> 1.0124337e+09 | N10: =N8+N6 -> 1.3834613e+09 | O10: =SUM(L10:N10) -> 3.3754621e+09 | P10: =P8+P6 -> 1.3678456e+09 | Q10: =Q8+Q6 -> 1.3389933e+09 | R10: =R8+R6 -> 1.3733528e+09 | S10: =SUM(K10,O10:R10) -> 1.3113767e+10
B11: Dues+ Advance | C11: 1.1054279e+09 | D11: 1.0043155e+09 | E11: 821170721 | F11: =SUM(C11:E11) -> 2.9309141e+09 | G11: 1.0499431e+09 | H11: 2.2868614e+08 | I11: 0 | J11: =SUM(G11:I11) -> 1.2786293e+09 | K11: =F11+J11 -> 4.2095434e+09 | L11: 0 | M11: 0 | N11: 0 | O11: =SUM(L11:N11) -> 0 | P11: 0 | Q11: 0 | R11: 0 | S11: =SUM(K11,O11:R11) -> 4.2095434e+09
B12: New Sales Target | C12: 507262500 | D12: 507262500 | E12: 82601425 | F12: =SUM(C12:E12) -> 1097126425 | G12: 150000000 | H12: 150000000 | I12: 150000000 | J12: =SUM(G12:I12) -> 450000000 | K12: =F12+J12 -> 1547126425 | L12: 150000000 | M12: 150000000 | N12: 150000000 | O12: =SUM(L12:N12) -> 450000000 | P12: 1.65e+08 | Q12: 1.65e+08 | R12: 1.65e+08 | S12: =SUM(K12,O12:R12) -> 2492126425
B13: New Sales | C13: 2.3312495e+08 | D13: 2.588536e+08 | E13: 82601425 | F13: =SUM(C13:E13) -> 5.7457997e+08 | G13: 1.4979889e+08 | H13: 43613059 | I13: 0 | J13: =SUM(G13:I13) -> 1.9341195e+08 | K13: =F13+J13 -> 7.6799192e+08 | L13: 0 | M13: 0 | N13: 0 | O13: =SUM(L13:N13) -> 0 | P13: 0 | Q13: 0 | R13: 0 | S13: =SUM(K13,O13:R13) -> 7.6799192e+08
B14: Total Collections Target | C14: =C12+C10 -> 1.626892e+09 | D14: =D12+D10 -> 1.5150947e+09 | E14: =E12+E10 -> 903772146 | F14: =SUM(C14:E14) -> 4.0457588e+09 | G14: =G12+G10 -> 1.0438426e+09 | H14: =H12+H10 -> 1.0053901e+09 | I14: =I12+I10 -> 1.110248e+09 | J14: =SUM(G14:I14) -> 3.1594806e+09 | K14: =F14+J14 -> 7.2052394e+09 | L14: =L12+L10 -> 1.1295671e+09 | M14: =M12+M10 -> 1.1624337e+09 | N14: =N12+N10 -> 1.5334613e+09 | O14: =SUM(L14:N14) -> 3.8254621e+09 | P14: =P12+P10 -> 1.5328456e+09 | Q14: =Q12+Q10 -> 1.5039933e+09 | R14: =R12+R10 -> 1.5383528e+09 | S14: =SUM(K14,O14:R14) -> 1.5605893e+10
B15: MTD Total Collections | C15: =C11+C13 -> 1.3385529e+09 | D15: =D11+D13 -> 1.2631691e+09 | E15: =E11+E13 -> 903772146 | F15: =SUM(C15:E15) -> 3.5054941e+09 | G15: =G11+G13 -> 1.199742e+09 | H15: =H11+H13 -> 2.722992e+08 | I15: =I11+I13 -> 0 | J15: =SUM(G15:I15) -> 1.4720412e+09 | K15: =F15+J15 -> 4.9775353e+09 | L15: =L11+L13 -> 0 | M15: =M11+M13 -> 0 | N15: =N11+N13 -> 0 | O15: =SUM(L15:N15) -> 0 | P15: =P11+P13 -> 0 | Q15: =Q11+Q13 -> 0 | R15: =R11+R13 -> 0 | S15: =SUM(K15,O15:R15) -> 4.9775353e+09
B17: Siniya Total Collections
B18: 2026 | C18: Jan | D18: Feb | E18: March | F18: Q1 | G18: Apr | H18: May | I18: Jun | J18: Q2 | K18: H1 | L18: July | M18: Aug | N18: Sept | O18: Q3 | P18: Oct | Q18: Nov | R18: Dec | S18: Total
B19: Dues Target | C19: 1.0484322e+08 | D19: 1.0849465e+08 | E19: 1.0498264e+08 | F19: =SUM(C19:E19) -> 3.1832051e+08 | G19: 1.2562074e+08 | H19: 1.1343168e+08 | I19: 1.4021636e+08 | J19: =SUM(G19:I19) -> 3.7926878e+08 | K19: =F19+J19 -> 6.9758929e+08 | L19: 1.7418391e+08 | M19: 1.4040037e+08 | N19: 1.5081996e+08 | O19: =SUM(L19:N19) -> 4.6540425e+08 | P19: 1.503269e+08 | Q19: 1.4081256e+08 | R19: 1.339562e+08 | S19: =SUM(K19,O19:R19) -> 1.5880892e+09
B20: Dues | C20: =C24-C22 -> 1.3021322e+08 | D20: =D24-D22 -> 1.266256e+08 | E20: =E24-E22 -> 1.0498264e+08 | F20: =SUM(C20:E20) -> 3.6182146e+08 | G20: =G24-G22 -> 1.2284411e+08 | H20: =H24-H22 -> 30099656 | I20: =I24-I22 -> 0 | J20: =SUM(G20:I20) -> 1.5294377e+08 | K20: =F20+J20 -> 5.1476523e+08 | L20: =L24-L22 -> 0 | M20: =M24-M22 -> 0 | N20: =N24-N22 -> 0 | O20: =SUM(L20:N20) -> 0 | P20: =P24-P22 -> 0 | Q20: =Q24-Q22 -> 0 | R20: =R24-R22 -> 0 | S20: =SUM(K20,O20:R20) -> 5.1476523e+08
B21: Advance Target | C21: 50000000 | D21: 50000000 | E21: 18539714 | F21: =SUM(C21:E21) -> 1.1853971e+08 | G21: 31273365 | H21: 31273365 | I21: 31273365 | J21: =SUM(G21:I21) -> 93820095 | K21: =F21+J21 -> 2.1235981e+08 | L21: 31273365 | M21: 31273365 | N21: 31273365 | O21: =SUM(L21:N21) -> 93820095 | P21: 31273365 | Q21: 31273365 | R21: 31273365 | S21: =SUM(K21,O21:R21) -> 4e+08
B22: Advance | C22: 33012253 | D22: 39134249 | E22: 18539714 | F22: =SUM(C22:E22) -> 90686215 | G22: 39598811 | H22: 4718196 | I22: 0 | J22: =SUM(G22:I22) -> 44317007 | K22: =F22+J22 -> 1.3500322e+08 | L22: 0 | M22: 0 | N22: 0 | O22: =SUM(L22:N22) -> 0 | P22: 0 | Q22: 0 | R22: 0 | S22: =SUM(K22,O22:R22) -> 1.3500322e+08
B23: Dues+ Advance Target | C23: =C19+C21 -> 1.5484322e+08 | D23: =D19+D21 -> 1.5849465e+08 | E23: =E19+E21 -> 1.2352235e+08 | F23: =SUM(C23:E23) -> 4.3686023e+08 | G23: =G19+G21 -> 1.568941e+08 | H23: =H19+H21 -> 1.4470505e+08 | I23: =I19+I21 -> 1.7148972e+08 | J23: =SUM(G23:I23) -> 4.7308887e+08 | K23: =F23+J23 -> 9.099491e+08 | L23: =L19+L21 -> 2.0545728e+08 | M23: =M19+M21 -> 1.7167374e+08 | N23: =N19+N21 -> 1.8209333e+08 | O23: =SUM(L23:N23) -> 5.5922434e+08 | P23: =P19+P21 -> 1.8160027e+08 | Q23: =Q19+Q21 -> 1.7208592e+08 | R23: =R19+R21 -> 1.6522956e+08 | S23: =SUM(K23,O23:R23) -> 1.9880892e+09
B24: Dues+ Advance | C24: 163225471 | D24: 1.6575985e+08 | E24: 1.2352235e+08 | F24: =SUM(C24:E24) -> 4.5250767e+08 | G24: 1.6244292e+08 | H24: 34817852 | I24: 0 | J24: =SUM(G24:I24) -> 1.9726077e+08 | K24: =F24+J24 -> 6.4976845e+08 | L24: 0 | M24: 0 | N24: 0 | O24: =SUM(L24:N24) -> 0 | P24: 0 | Q24: 0 | R24: 0 | S24: =SUM(K24,O24:R24) -> 6.4976845e+08
B25: New Sales Target | C25: 57262500 | D25: 57262500 | E25: 11304707 | F25: =SUM(C25:E25) -> 1.2582971e+08 | G25: 12500000 | H25: 12500000 | I25: 12500000 | J25: =SUM(G25:I25) -> 37500000 | K25: =F25+J25 -> 1.6332971e+08 | L25: 12500000 | M25: 12500000 | N25: 12500000 | O25: =SUM(L25:N25) -> 37500000 | P25: 13750000 | Q25: 13750000 | R25: 13750000 | S25: =SUM(K25,O25:R25) -> 2.4207971e+08
B26: New Sales | C26: 30463929 | D26: 29508594 | E26: 11304707 | F26: =SUM(C26:E26) -> 71277229 | G26: 318807.83 | H26: 93 | I26: 0 | J26: =SUM(G26:I26) -> 318900.83 | K26: =F26+J26 -> 71596130 | L26: 0 | M26: 0 | N26: 0 | O26: =SUM(L26:N26) -> 0 | P26: 0 | Q26: 0 | R26: 0 | S26: =SUM(K26,O26:R26) -> 71596130
B27: Total Collections Target | C27: =C23+C25 -> 2.1210572e+08 | D27: =D23+D25 -> 2.1575715e+08 | E27: =E23+E25 -> 1.3482706e+08 | F27: =SUM(C27:E27) -> 5.6268993e+08 | G27: =G23+G25 -> 1.693941e+08 | H27: =H23+H25 -> 1.5720505e+08 | I27: =I23+I25 -> 1.8398972e+08 | J27: =SUM(G27:I27) -> 5.1058887e+08 | K27: =F27+J27 -> 1.0732788e+09 | L27: =L23+L25 -> 2.1795728e+08 | M27: =M23+M25 -> 1.8417374e+08 | N27: =N23+N25 -> 1.9459333e+08 | O27: =SUM(L27:N27) -> 5.9672434e+08 | P27: =P23+P25 -> 1.9535027e+08 | Q27: =Q23+Q25 -> 1.8583592e+08 | R27: =R23+R25 -> 1.7897956e+08 | S27: =SUM(K27,O27:R27) -> 2.2301689e+09
B28: MTD Total Collections | C28: =C24+C26 -> 193689400 | D28: =D24+D26 -> 1.9526844e+08 | E28: =E24+E26 -> 1.3482706e+08 | F28: =SUM(C28:E28) -> 5.237849e+08 | G28: =G24+G26 -> 1.6276173e+08 | H28: =H24+H26 -> 34817945 | I28: =I24+I26 -> 0 | J28: =SUM(G28:I28) -> 1.9757967e+08 | K28: =F28+J28 -> 7.2136458e+08 | L28: =L24+L26 -> 0 | M28: =M24+M26 -> 0 | N28: =N24+N26 -> 0 | O28: =SUM(L28:N28) -> 0 | P28: =P24+P26 -> 0 | Q28: =Q24+Q26 -> 0 | R28: =R24+R26 -> 0 | S28: =SUM(K28,O28:R28) -> 7.2136458e+08
B30: Sobha Total Collections
B31: 2026 | C31: Jan | D31: Feb | E31: March | F31: Q1 | G31: Apr | H31: May | I31: Jun | J31: Q2 | K31: H1 | L31: July | M31: Aug | N31: Sept | O31: Q3 | P31: Oct | Q31: Nov | R31: Dec | S31: Total
B32: Dues Target | C32: =C6-C19-C45 -> 6.8792283e+08 | D32: =D6-D19-D45 -> 5.7362576e+08 | E32: =E6-E19-E45 -> 5.171397e+08 | F32: =SUM(C32:E32) -> 1.7786883e+09 | G32: =G6-G19-G45 -> 5.4384264e+08 | H32: =H6-H19-H45 -> 5.1092451e+08 | I32: =I6-I19-I45 -> 585000000 | J32: =SUM(G32:I32) -> 1.6397671e+09 | K32: =F32+J32 -> 3.4184554e+09 | L32: =L6-L19-L45 -> 5.7707746e+08 | M32: =M6-M19-M45 -> 6.4462724e+08 | N32: =N6-N19-N45 -> 1.0078082e+09 | O32: =SUM(L32:N32) -> 2.2295129e+09 | P32: =P6-P19-P45 -> 9.7517537e+08 | Q32: =Q6-Q19-Q45 -> 9.6060312e+08 | R32: =R6-R19-R45 -> 1.0060398e+09 | S32: =SUM(K32,O32:R32) -> 8.5897866e+09
B33: Dues | C33: =C7-C20-C46-C58 -> 6.5659947e+08 | D33: =D7-D20-D46-D58 -> 5.5159569e+08 | E33: =E7-E20-E46-E58 -> 5.171397e+08 | F33: =SUM(C33:E33) -> 1.7253349e+09 | G33: =G7-G20-G46-G58 -> 6.4402254e+08 | H33: =H7-H20-H46-H58 -> 1.3982628e+08 | I33: =I7-I20-I46-I58 -> 0 | J33: =SUM(G33:I33) -> 7.8384882e+08 | K33: =F33+J33 -> 2.5091837e+09 | L33: =L7-L20-L46-L58 -> 0 | M33: =M7-M20-M46-M58 -> 0 | N33: =N7-N20-N46-N58 -> 0 | O33: =SUM(L33:N33) -> 0 | P33: =P7-P20-P46-P58 -> 0 | Q33: =Q7-Q20-Q46-Q58 -> 0 | R33: =R7-R20-R46-R58 -> 0 | S33: =SUM(K33,O33:R33) -> 2.5091837e+09
B34: Advance Target | C34: =C8-C21-C47 -> 2.6666667e+08 | D34: =D8-D21-D47 -> 2.6666667e+08 | E34: =E8-E21-E47 -> 1.7047877e+08 | F34: =SUM(C34:E34) -> 7.038121e+08 | G34: =G8-G21-G47 -> 180000000 | H34: =H8-H21-H47 -> 180000000 | I34: =I8-I21-I47 -> 180000000 | J34: =SUM(G34:I34) -> 540000000 | K34: =F34+J34 -> 1.2438121e+09 | L34: =L8-L21-L47 -> 180000000 | M34: =M8-M21-M47 -> 180000000 | N34: =N8-N21-N47 -> 180000000 | O34: =SUM(L34:N34) -> 540000000 | P34: =P8-P21-P47 -> 180000000 | Q34: =Q8-Q21-Q47 -> 180000000 | R34: =R8-R21-R47 -> 180000000 | S34: =SUM(K34,O34:R34) -> 2.3238121e+09
B35: Advance | C35: =C9-C22-C48-C59 -> 2.7030392e+08 | D35: =D9-D22-D48-D59 -> 2.7013421e+08 | E35: =E9-E22-E48-E59 -> 1.7047877e+08 | F35: =SUM(C35:E35) -> 7.1091689e+08 | G35: =G9-G22-G48-G59 -> 2.2176715e+08 | H35: =H9-H22-H48-H59 -> 46715487 | I35: =I9-I22-I48-I59 -> 0 | J35: =SUM(G35:I35) -> 2.6848264e+08 | K35: =F35+J35 -> 9.7939953e+08 | L35: =L9-L22-L48-L59 -> 0 | M35: =M9-M22-M48-M59 -> 0 | N35: =N9-N22-N48-N59 -> 0 | O35: =SUM(L35:N35) -> 0 | P35: =P9-P22-P48-P59 -> 0 | Q35: =Q9-Q22-Q48-Q59 -> 0 | R35: =R9-R22-R48-R59 -> 0 | S35: =SUM(K35,O35:R35) -> 9.7939953e+08
B36: Dues+ Advance Target | C36: =C32+C34 -> 9.545895e+08 | D36: =D32+D34 -> 8.4029243e+08 | E36: =E32+E34 -> 6.8761847e+08 | F36: =SUM(C36:E36) -> 2.4825004e+09 | G36: =G32+G34 -> 7.2384264e+08 | H36: =H32+H34 -> 6.9092451e+08 | I36: =I32+I34 -> 765000000 | J36: =SUM(G36:I36) -> 2.1797671e+09 | K36: =F36+J36 -> 4.6622675e+09 | L36: =L32+L34 -> 7.5707746e+08 | M36: =M32+M34 -> 8.2462724e+08 | N36: =N32+N34 -> 1.1878082e+09 | O36: =SUM(L36:N36) -> 2.7695129e+09 | P36: =P32+P34 -> 1.1551754e+09 | Q36: =Q32+Q34 -> 1.1406031e+09 | R36: =R32+R34 -> 1.1860398e+09 | S36: =SUM(K36,O36:R36) -> 1.0913599e+10
B37: Dues+ Advance | C37: =C11-C24-C50-C60 -> 9.2690338e+08 | D37: =D11-D24-D50-D60 -> 8.2172989e+08 | E37: =E11-E24-E50-E60 -> 6.8761847e+08 | F37: =SUM(C37:E37) -> 2.4362517e+09 | G37: =G11-G24-G50-G60 -> 8.6578969e+08 | H37: =H11-H24-H50-H60 -> 1.8654177e+08 | I37: =I11-I24-I50-I60 -> 0 | J37: =SUM(G37:I37) -> 1.0523315e+09 | K37: =F37+J37 -> 3.4885832e+09 | L37: =L11-L24-L50-L60 -> 0 | M37: =M11-M24-M50-M60 -> 0 | N37: =N11-N24-N50-N60 -> 0 | O37: =SUM(L37:N37) -> 0 | P37: =P11-P24-P50-P60 -> 0 | Q37: =Q11-Q24-Q50-Q60 -> 0 | R37: =R11-R24-R50-R60 -> 0 | S37: =SUM(K37,O37:R37) -> 3.4885832e+09
B38: New Sales Target | C38: =C12-C25-C51 -> 393750000 | D38: =D12-D25-D51 -> 393750000 | E38: =E12-E25-E51 -> 68950536 | F38: =SUM(C38:E38) -> 8.5645054e+08 | G38: =G12-G25-G51 -> 125000000 | H38: =H12-H25-H51 -> 125000000 | I38: =I12-I25-I51 -> 125000000 | J38: =SUM(G38:I38) -> 375000000 | K38: =F38+J38 -> 1.2314505e+09 | L38: =L12-L25-L51 -> 125000000 | M38: =M12-M25-M51 -> 125000000 | N38: =N12-N25-N51 -> 125000000 | O38: =SUM(L38:N38) -> 375000000 | P38: =P12-P25-P51 -> 1.375e+08 | Q38: =Q12-Q25-Q51 -> 1.375e+08 | R38: =R12-R25-R51 -> 1.375e+08 | S38: =SUM(K38,O38:R38) -> 2.0189505e+09
B39: New Sales | C39: =C13-C26-C52-C61 -> 1.9546922e+08 | D39: =D13-D26-D52-D61 -> 2.2197776e+08 | E39: =E13-E26-E52-E61 -> 68950536 | F39: =SUM(C39:E39) -> 4.8639752e+08 | G39: =G13-G26-G52-G61 -> 96743360 | H39: =H13-H26-H52-H61 -> 26212146 | I39: =I13-I26-I52-I61 -> 0 | J39: =SUM(G39:I39) -> 1.2295551e+08 | K39: =F39+J39 -> 6.0935302e+08 | L39: =L13-L26-L52-L61 -> 0 | M39: =M13-M26-M52-M61 -> 0 | N39: =N13-N26-N52-N61 -> 0 | O39: =SUM(L39:N39) -> 0 | P39: =P13-P26-P52-P61 -> 0 | Q39: =Q13-Q26-Q52-Q61 -> 0 | R39: =R13-R26-R52-R61 -> 0 | S39: =SUM(K39,O39:R39) -> 6.0935302e+08
B40: Total Collections Target | C40: =C36+C38 -> 1.3483395e+09 | D40: =D36+D38 -> 1.2340424e+09 | E40: =E36+E38 -> 7.56569e+08 | F40: =SUM(C40:E40) -> 3.3389509e+09 | G40: =G36+G38 -> 8.4884264e+08 | H40: =H36+H38 -> 8.1592451e+08 | I40: =I36+I38 -> 890000000 | J40: =SUM(G40:I40) -> 2.5547671e+09 | K40: =F40+J40 -> 5.8937181e+09 | L40: =L36+L38 -> 8.8207746e+08 | M40: =M36+M38 -> 9.4962724e+08 | N40: =N36+N38 -> 1.3128082e+09 | O40: =SUM(L40:N40) -> 3.1445129e+09 | P40: =P36+P38 -> 1.2926754e+09 | Q40: =Q36+Q38 -> 1.2781031e+09 | R40: =R36+R38 -> 1.3235398e+09 | S40: =SUM(K40,O40:R40) -> 1.2932549e+10
B41: MTD Total Collections | C41: =C37+C39 -> 1.1223726e+09 | D41: =D37+D39 -> 1.0437077e+09 | E41: =E37+E39 -> 7.56569e+08 | F41: =SUM(C41:E41) -> 2.9226493e+09 | G41: =G37+G39 -> 9.6253305e+08 | H41: =H37+H39 -> 2.1275391e+08 | I41: =I37+I39 -> 0 | J41: =SUM(G41:I41) -> 1.175287e+09 | K41: =F41+J41 -> 4.0979362e+09 | L41: =L37+L39 -> 0 | M41: =M37+M39 -> 0 | N41: =N37+N39 -> 0 | O41: =SUM(L41:N41) -> 0 | P41: =P37+P39 -> 0 | Q41: =Q37+Q39 -> 0 | R41: =R37+R39 -> 0 | S41: =SUM(K41,O41:R41) -> 4.0979362e+09
B43: Downtown UAQ Total Collections
B44: 2026 | C44: Jan | D44: Feb | E44: March | F44: Q1 | G44: Apr | H44: May | I44: Jun | J44: Q2 | K44: H1 | L44: July | M44: Aug | N44: Sept | O44: Q3 | P44: Oct | Q44: Nov | R44: Dec | S44: Total
...

Sheet Siniya Units Sales
A2: 46148
A3: =EOMONTH(A2,-1)+1 -> 46143 | B3: ="As on "&TEXT(A2,"DD.MM.YY") -> As on 06.05.26
B4: Project | C4: Not qualified | D4: Sale Value (Unqualified) | E4: Qualified Units | F4: Sale Value (Qualified Units) | G4: Total units | H4: Sale value total
B5: Siniya Island-Villas & Mansion | C5: =SUM(C6:C9) -> 3 | D5: =SUM(D6:D9) -> 33025916 | E5: =SUM(E6:E9) -> 172 | F5: =SUM(F6:F9) -> 2.5435763e+09 | G5: =SUM(G6:G9) -> 175 | H5: =SUM(H6:H9) -> 2.5766022e+09
B6: Siniya Island | C6: 3 | D6: 33025916 | E6: 157 | F6: 2.2252357e+09 | G6: =SUM(C6,E6) -> 160 | H6: =SUM(D6,F6) -> 2.2582616e+09
B7: Siniya Island-Villas Phase II | C7: 0 | D7: 0 | E7: 15 | F7: 3.1834055e+08 | G7: =SUM(C7,E7) -> 15 | H7: =SUM(D7,F7) -> 3.1834055e+08
B8: Siniya Island-Villas Phase IV | C8: 0 | D8: 0 | E8: 0 | F8: 0 | G8: =SUM(C8,E8) -> 0 | H8: =SUM(D8,F8) -> 0
B9: Siniya Island Mansions | C9: 0 | D9: 0 | E9: 0 | F9: 0 | G9: =SUM(C9,E9) -> 0 | H9: =SUM(D9,F9) -> 0
B10: Siniya Beach Residences | C10: =SUM(C11:C19) -> 1 | D10: =SUM(D11:D19) -> 1113544.8 | E10: =SUM(E11:E19) -> 3651 | F10: =SUM(F11:F19) -> 6.5951995e+09 | G10: =SUM(G11:G19) -> 3652 | H10: =SUM(H11:H19) -> 6.596313e+09
B11: Selene Beach Residences | C11: 1 | D11: 1113544.8 | E11: 525 | F11: 8.4891778e+08 | G11: =SUM(C11,E11) -> 526 | H11: =SUM(D11,F11) -> 8.5003132e+08
B12: Delphine Beach Residences | C12: 0 | D12: 0 | E12: 569 | F12: 9.0410227e+08 | G12: =SUM(C12,E12) -> 569 | H12: =SUM(D12,F12) -> 9.0410227e+08
B13: Coraline Beach Residences | C13: 0 | D13: 0 | E13: 566 | F13: 9.6619053e+08 | G13: =SUM(C13,E13) -> 566 | H13: =SUM(D13,F13) -> 9.6619053e+08
B14: Aquamarine Beach Residences | C14: 0 | D14: 0 | E14: 557 | F14: 9.4313176e+08 | G14: =SUM(C14,E14) -> 557 | H14: =SUM(D14,F14) -> 9.4313176e+08
B15: Florine Beach Residences | C15: 0 | D15: 0 | E15: 337 | F15: 6.7403374e+08 | G15: =SUM(C15,E15) -> 337 | H15: =SUM(D15,F15) -> 6.7403374e+08
B16: Coastline Beach Residences | C16: 0 | D16: 0 | E16: 331 | F16: 6.6768686e+08 | G16: =SUM(C16,E16) -> 331 | H16: =SUM(D16,F16) -> 6.6768686e+08
B17: Starline Beach Residences | C17: 0 | D17: 0 | E17: 272 | F17: 5.6242169e+08 | G17: =SUM(C17,E17) -> 272 | H17: =SUM(D17,F17) -> 5.6242169e+08
B18: Pristine Beach Residences | C18: 0 | D18: 0 | E18: 222 | F18: 4.6629315e+08 | G18: =SUM(C18,E18) -> 222 | H18: =SUM(D18,F18) -> 4.6629315e+08
B19: Starline Beach Residences | C19: 0 | D19: 0 | E19: 272 | F19: 5.6242169e+08 | G19: =SUM(C19,E19) -> 272 | H19: =SUM(D19,F19) -> 5.6242169e+08
B20: Siniya Marina Residences | C20: =SUM(C21:C27) -> 4 | D20: =SUM(D21:D27) -> 5906301.6 | E20: =SUM(E21:E27) -> 1616 | F20: =SUM(F21:F27) -> 2.6241974e+09 | G20: =SUM(G21:G27) -> 1620 | H20: =SUM(H21:H27) -> 2.6301037e+09
B21: Bayside Marina Residences | C21: 0 | D21: 0 | E21: 322 | F21: 5.316334e+08 | G21: =SUM(C21,E21) -> 322 | H21: =SUM(D21,F21) -> 5.316334e+08
B22: Pierside Marina Residences | C22: 1 | D22: 1788098 | E22: 338 | F22: 5.510793e+08 | G22: =SUM(C22,E22) -> 339 | H22: =SUM(D22,F22) -> 5.528674e+08
B23: Yachtside Marina Residences | C23: 0 | D23: 0 | E23: 252 | F23: 4.2466127e+08 | G23: =SUM(C23,E23) -> 252 | H23: =SUM(D23,F23) -> 4.2466127e+08
B24: Bayfront Marina Residences | C24: 2 | D24: 2709503.8 | E24: 341 | F24: 5.3456059e+08 | G24: =SUM(C24,E24) -> 343 | H24: =SUM(D24,F24) -> 5.3727009e+08
B25: Canalside Marina Residences | C25: 0 | D25: 0 | E25: 268 | F25: 4.2889366e+08 | G25: =SUM(C25,E25) -> 268 | H25: =SUM(D25,F25) -> 4.2889366e+08
B26: Capeside Marina Residences | C26: 0 | D26: 0 | E26: 0 | F26: 0 | G26: =SUM(C26,E26) -> 0 | H26: =SUM(D26,F26) -> 0
B27: Pearlside Marina Residences | C27: 1 | D27: 1408699.8 | E27: 95 | F27: 1.5336921e+08 | G27: =SUM(C27,E27) -> 96 | H27: =SUM(D27,F27) -> 1.5477791e+08
B28: Total | C28: =SUM(C5,C10,C20) -> 8 | D28: =SUM(D5,D10,D20) -> 40045762 | E28: =SUM(E5,E10,E20) -> 5439 | F28: =SUM(F5,F10,F20) -> 1.1762973e+10 | G28: =SUM(G5,G10,G20) -> 5447 | H28: =SUM(H5,H10,H20) -> 1.1803019e+10
B30: ="MTD "&TEXT(A3,"mmm-YY") -> MTD May-26
B31: Project | C31: Not Qualified | D31: Sale Value (Unqualified) | E31: Qualified Units | F31: Sale Value (Qualified Units) | G31: Total Units | H31: Sale Value Total
B32: Siniya Island-Villas & Mansion | C32: =SUM(C33:C36) -> 0 | D32: =SUM(D33:D36) -> 0 | E32: =SUM(E33:E36) -> 0 | F32: =SUM(F33:F36) -> 0 | G32: =SUM(G33:G36) -> 0 | H32: =SUM(H33:H36) -> 0
B33: Siniya Island | C33: 0 | D33: 0 | E33: 0 | F33: 0 | G33: =SUM(C33,E33) -> 0 | H33: =SUM(D33,F33) -> 0
B34: Siniya Island-Villas Phase II | C34: 0 | D34: 0 | E34: 0 | F34: 0 | G34: =SUM(C34,E34) -> 0 | H34: =SUM(D34,F34) -> 0
B35: Siniya Island-Villas Phase IV | C35: 0 | D35: 0 | E35: 0 | F35: 0 | G35: =SUM(C35,E35) -> 0 | H35: =SUM(D35,F35) -> 0
B36: Siniya Island Mansions | C36: 0 | D36: 0 | E36: 0 | F36: 0 | G36: =SUM(C36,E36) -> 0 | H36: =SUM(D36,F36) -> 0
B37: Siniya Beach Residences | C37: =SUM(C38:C45) -> 0 | D37: =SUM(D38:D45) -> 0 | E37: =SUM(E38:E45) -> 0 | F37: =SUM(F38:F45) -> 0 | G37: =SUM(G38:G45) -> 0 | H37: =SUM(H38:H45) -> 0
B38: Selene Beach Residences | C38: 0 | D38: 0 | E38: 0 | F38: 0 | G38: =SUM(C38,E38) -> 0 | H38: =SUM(D38,F38) -> 0
B39: Delphine Beach Residences | C39: 0 | D39: 0 | E39: 0 | F39: 0 | G39: =SUM(C39,E39) -> 0 | H39: =SUM(D39,F39) -> 0
B40: Coraline Beach Residences | C40: 0 | D40: 0 | E40: 0 | F40: 0 | G40: =SUM(C40,E40) -> 0 | H40: =SUM(D40,F40) -> 0
B41: Aquamarine Beach Residences | C41: 0 | D41: 0 | E41: 0 | F41: 0 | G41: =SUM(C41,E41) -> 0 | H41: =SUM(D41,F41) -> 0
B42: Florine Beach Residences | C42: 0 | D42: 0 | E42: 0 | F42: 0 | G42: =SUM(C42,E42) -> 0 | H42: =SUM(D42,F42) -> 0
...

Sheet Dowtown Units Sales
A2: 46148
B3: ="As on "&TEXT(A2,"DD.MM.YY") -> As on 06.05.26
B4: Project | C4: Not qualified | D4: Sale Value (Unqualified) | E4: Qualified Units | F4: Sale Value (Qualified Units) | G4: Total units | H4: Sale value total
B5: Sobha Aquamont | C5: 2 | D5: 2724211.2 | E5: 705 | F5: 9.9602346e+08 | G5: =SUM(C5,E5) -> 707 | H5: =SUM(D5,F5) -> 9.9874767e+08
B6: Sobha Aquacrest | C6: 1 | D6: 1215914.4 | E6: 121 | F6: 1.6867798e+08 | G6: =SUM(C6,E6) -> 122 | H6: =SUM(D6,F6) -> 1.6989389e+08
B7: Total | C7: =SUM(C5:C6) -> 3 | D7: =SUM(D5:D6) -> 3940125.6 | E7: =SUM(E5:E6) -> 826 | F7: =SUM(F5:F6) -> 1.1647014e+09 | G7: =SUM(G5:G6) -> 829 | H7: =SUM(H5:H6) -> 1.1686416e+09
B9: ="MTD "&TEXT(A10,"mmm-YY") -> MTD May-26
A10: =EOMONTH(A2,-1)+1 -> 46143 | B10: Project | C10: Not Qualified | D10: Sale Value (Unqualified) | E10: Qualified Units | F10: Sale Value (Qualified Units) | G10: Total Units | H10: Sale Value Total
B11: Sobha Aquamont | C11: 0 | D11: 0 | E11: 0 | F11: 0 | G11: =SUM(C11,E11) -> 0 | H11: =SUM(D11,F11) -> 0
B12: Sobha Aquacrest | C12: 0 | D12: 0 | E12: 0 | F12: 0 | G12: =SUM(C12,E12) -> 0 | H12: =SUM(D12,F12) -> 0
B13: Total | C13: =SUM(C11:C12) -> 0 | D13: =SUM(D11:D12) -> 0 | E13: =SUM(E11:E12) -> 0 | F13: =SUM(F11:F12) -> 0 | G13: =SUM(G11:G12) -> 0 | H13: =SUM(H11:H12) -> 0
B15: ="As on "&TEXT(EOMONTH(A2,-1),"dd.mm.yy") -> As on 30.04.26
B16: Project | C16: Not qualified | D16: Sale Value (Unqualified) | E16: Qualified Units | F16: Sale Value (Qualified Units) | G16: Total units | H16: Sale value total
B17: Sobha Aquamont | C17: =SUM(C5-C11) -> 2 | D17: =SUM(D5-D11) -> 2724211.2 | E17: =SUM(E5-E11) -> 705 | F17: =SUM(F5-F11) -> 9.9602346e+08 | G17: =SUM(G5-G11) -> 707 | H17: =SUM(H5-H11) -> 9.9874767e+08
B18: Sobha Aquacrest | C18: =SUM(C6-C12) -> 1 | D18: =SUM(D6-D12) -> 1215914.4 | E18: =SUM(E6-E12) -> 121 | F18: =SUM(F6-F12) -> 1.6867798e+08 | G18: =SUM(G6-G12) -> 122 | H18: =SUM(H6-H12) -> 1.6989389e+08
B19: Total | C19: =SUM(C17:C18) -> 3 | D19: =SUM(D17:D18) -> 3940125.6 | E19: =SUM(E17:E18) -> 826 | F19: =SUM(F17:F18) -> 1.1647014e+09 | G19: =SUM(G17:G18) -> 829 | H19: =SUM(H17:H18) -> 1.1686416e+09
A21: 45658 | B21: ="YTD "&TEXT(A21,"YYYY") -> YTD 2025
A22: 46022 | B22: Project | C22: Not Qualified | D22: Sale Value (Unqualified) | E22: Qualified Units | F22: Sale Value (Qualified Units) | G22: Total Units | H22: Sale Value Total
B23: Sobha Aquamont | C23: 0 | D23: 0 | E23: 660 | F23: 9.3240252e+08 | G23: =SUM(C23,E23) -> 660 | H23: =SUM(D23,F23) -> 9.3240252e+08
B24: Sobha Aquacrest | C24: 0 | D24: 0 | E24: 74 | F24: 1.0570044e+08 | G24: =SUM(C24,E24) -> 74 | H24: =SUM(D24,F24) -> 1.0570044e+08
B25: Total | C25: =SUM(C23:C24) -> 0 | D25: =SUM(D23:D24) -> 0 | E25: =SUM(E23:E24) -> 734 | F25: =SUM(F23:F24) -> 1.038103e+09 | G25: =SUM(G23:G24) -> 734 | H25: =SUM(H23:H24) -> 1.038103e+09
A27: 46023 | B27: ="YTD "&TEXT(A27,"YYYY") -> YTD 2026
A28: 46387 | B28: Project | C28: Not Qualified | D28: Sale Value (Unqualified) | E28: Qualified Units | F28: Sale Value (Qualified Units) | G28: Total Units | H28: Sale Value Total
B29: Sobha Aquamont | C29: 2 | D29: 2724211.2 | E29: 45 | F29: 63620937 | G29: =SUM(C29,E29) -> 47 | H29: =SUM(D29,F29) -> 66345148
B30: Sobha Aquacrest | C30: 1 | D30: 1215914.4 | E30: 47 | F30: 62977534 | G30: =SUM(C30,E30) -> 48 | H30: =SUM(D30,F30) -> 64193448
B31: Total | C31: =SUM(C29:C30) -> 3 | D31: =SUM(D29:D30) -> 3940125.6 | E31: =SUM(E29:E30) -> 92 | F31: =SUM(F29:F30) -> 1.2659847e+08 | G31: =SUM(G29:G30) -> 95 | H31: =SUM(H29:H30) -> 1.305386e+08

Sheet daily
B2: =UPPER(_xlfn.CONCAT(TEXT(F3,"MMMM YYYY "),"COLLECTION SUMMARY")) -> MAY 2026 COLLECTION SUMMARY
E3: As on | F3: 46148 | G3: "=MAX(gcdump!X:X)"
C4: Collection Due | D4: New sales | E4: Total
A5: Target | C5: 8.6042919e+08 | D5: 563625000 | E5: =SUM(C5:D5) -> 1.4240542e+09
A6: MTD Pro-rata Target | C6: 2.0245393e+08 | D6: 1.3261765e+08 | E6: =SUM(C6:D6) -> 3.3507157e+08
A8: Sno. | B8: Day & Date | C8: Collection Due | D8: New sales | E8: Total | F8: DLD/Oqood | AE8: AR Tracker Rows -1873
A9: 1 | B9: 46143 | C9: 53938555 | D9: =E9-C9 -> 1465167.3 | E9: 55403722 | F9: 983015.41 | AF9: 518637.46 | AJ9: =C9-AH9 -> 53938555 | AK9: =D9-AI9 -> 1465167.3
A10: 2 | B10: 46144 | C10: 0 | D10: =E10-C10 -> 0 | E10: 0 | F10: 633865.91 | AE10: =_xlfn.XLOOKUP(daily!$F3,B:B,D:D)-AE11 -> 367114 | AF10: 303910.97 | AH10: 25259161 | AI10: 1183126 | AJ10: =C10-AH10 -> -25259161 | AK10: =D10-AI10 -> -1183126
A11: 3 | B11: 46145 | C11: 0 | D11: =E11-C11 -> 0 | E11: 0 | F11: 0 | AE11: 12125677 | AF11: 0 | AH11: 39474332 | AI11: 1778245 | AJ11: =C11-AH11 -> -39474332 | AK11: =D11-AI11 -> -1778245
A12: 4 | B12: 46146 | C12: 63640347 | D12: =E12-C12 -> 10452008 | E12: 74092355 | F12: 1301233.7 | AF12: 587342.5 | AH12: 41314431 | AI12: 1804177 | AJ12: =C12-AH12 -> 22325916 | AK12: =D12-AI12 -> 8647830.7
A13: 5 | B13: 46147 | C13: 56488256 | D13: =E13-C13 -> 19203093 | E13: 75691349 | F13: 416510 | AF13: 194042 | AJ13: =C13-AH13 -> 56488256 | AK13: =D13-AI13 -> 19203093
B14: 46148 | C14: 54618983 | D14: =E14-C14 -> 12492791 | E14: 67111774 | F14: 585037.23 | AF14: 350651 | AJ14: =C14-AH14 -> 54618983 | AK14: =D14-AI14 -> 12492791
B15: 46149 | C15: 0 | D15: =E15-C15 -> 0 | E15: 0 | F15: 0 | AF15: 0 | AJ15: =C15-AH15 -> 0 | AK15: =D15-AI15 -> 0
A16: 6 | B16: 46150 | C16: 0 | D16: =E16-C16 -> 0 | E16: 0 | F16: 0 | AF16: 0 | AJ16: =C16-AH16 -> 0 | AK16: =D16-AI16 -> 0
A17: 7 | B17: 46151 | C17: 0 | D17: =E17-C17 -> 0 | E17: 0 | F17: 0 | AF17: 0 | AJ17: =C17-AH17 -> 0 | AK17: =D17-AI17 -> 0
A18: 8 | B18: 46152 | C18: 0 | D18: =E18-C18 -> 0 | E18: 0 | F18: 0 | I18: 0 | J18: 0 | K18: =C18-I18 -> 0 | L18: =J18-D18 -> 0 | M18: 45056 | AF18: 0 | AJ18: =C18-AH18 -> 0 | AK18: =D18-AI18 -> 0
A19: 9 | B19: 46153 | C19: 0 | D19: =E19-C19 -> 0 | E19: 0 | F19: 0 | I19: 0 | J19: 0 | K19: =C19-I19 -> 0 | L19: =J19-D19 -> 0 | M19: 45057 | AF19: 0 | AJ19: =C19-AH19 -> 0 | AK19: =D19-AI19 -> 0
A20: 10 | B20: 46154 | C20: 0 | D20: =E20-C20 -> 0 | E20: 0 | F20: 0 | I20: 19090565 | J20: 26755176 | K20: =C20-I20 -> -19090565 | L20: =J20-D20 -> 26755176 | M20: 45058 | AF20: 0 | AJ20: =C20-AH20 -> 0 | AK20: =D20-AI20 -> 0
B21: 46155 | C21: 0 | D21: =E21-C21 -> 0 | E21: 0 | F21: 0 | G21: =C21+$AE$10 -> 367114 | I21: 0 | J21: 0 | K21: =C21-I21 -> 0 | L21: =J21-D21 -> 0 | M21: 45059 | AF21: 0 | AJ21: =C21-AH21 -> 0 | AK21: =D21-AI21 -> 0
B22: 46156 | C22: 0 | D22: =E22-C22 -> 0 | E22: 0 | F22: 0 | G22: =C22+$AE$10 -> 367114 | I22: 0 | J22: 0 | K22: =C22-I22 -> 0 | L22: =J22-D22 -> 0 | M22: 45060 | AF22: 0 | AJ22: =C22-AH22 -> 0 | AK22: =D22-AI22 -> 0
A23: 11 | B23: 46157 | C23: 0 | D23: =E23-C23 -> 0 | E23: 0 | F23: 0 | I23: 0 | J23: 0 | K23: =C23-I23 -> 0 | L23: =J23-D23 -> 0 | M23: 45061 | AF23: 0 | AJ23: =C23-AH23 -> 0 | AK23: =D23-AI23 -> 0
A24: 12 | B24: 46158 | C24: 0 | D24: =E24-C24 -> 0 | E24: 0 | F24: 0 | I24: 0 | J24: 0 | K24: =C24-I24 -> 0 | L24: =J24-D24 -> 0 | M24: 45062 | AF24: 0 | AJ24: =C24-AH24 -> 0 | AK24: =D24-AI24 -> 0
A25: 13 | B25: 46159 | C25: 0 | D25: =E25-C25 -> 0 | E25: 0 | F25: 0 | I25: 0 | J25: 0 | K25: =C25-I25 -> 0 | L25: =J25-D25 -> 0 | M25: 45063 | V25: =SUM(V23,V17) -> 0 | AF25: 0 | AJ25: =C25-AH25 -> 0 | AK25: =D25-AI25 -> 0
A26: 14 | B26: 46160 | C26: 0 | D26: =E26-C26 -> 0 | E26: 0 | F26: 0 | AF26: 0 | AJ26: =C26-AH26 -> 0 | AK26: =D26-AI26 -> 0
A27: 15 | B27: 46161 | C27: 0 | D27: =E27-C27 -> 0 | E27: 0 | F27: 0 | AF27: 0 | AJ27: =C27-AH27 -> 0 | AK27: =D27-AI27 -> 0
B28: 46162 | C28: 0 | D28: =E28-C28 -> 0 | E28: 0 | F28: 0 | I28: 0 | J28: 0 | K28: =C28-I28 -> 0 | L28: =J28-D28 -> 0 | M28: 45066 | AF28: 0 | AJ28: =C28-AH28 -> 0 | AK28: =D28-AI28 -> 0
B29: 46163 | C29: 0 | D29: =E29-C29 -> 0 | E29: 0 | F29: 0 | I29: 0 | J29: 0 | K29: =C29-I29 -> 0 | L29: =J29-D29 -> 0 | M29: 45067 | AF29: 0 | AJ29: =C29-AH29 -> 0 | AK29: =D29-AI29 -> 0
A30: 16 | B30: 46164 | C30: 0 | D30: =E30-C30 -> 0 | E30: 0 | F30: 0 | I30: 0 | J30: 0 | K30: =C30-I30 -> 0 | L30: =J30-D30 -> 0 | M30: 45068 | AF30: 0 | AJ30: =C30-AH30 -> 0 | AK30: =D30-AI30 -> 0
A31: 17 | B31: 46165 | C31: 0 | D31: =E31-C31 -> 0 | E31: 0 | F31: 0 | I31: 0 | J31: 0 | K31: =C31-I31 -> 0 | L31: =J31-D31 -> 0 | M31: 45069 | AF31: 0 | AJ31: =C31-AH31 -> 0 | AK31: =D31-AI31 -> 0
A32: 18 | B32: 46166 | C32: 0 | D32: =E32-C32 -> 0 | E32: 0 | F32: 0 | I32: 0 | J32: 0 | K32: =C32-I32 -> 0 | L32: =J32-D32 -> 0 | M32: 45070 | AF32: 0 | AJ32: =C32-AH32 -> 0 | AK32: =D32-AI32 -> 0
A33: 19 | B33: 46167 | C33: 0 | D33: =E33-C33 -> 0 | E33: 0 | F33: 0 | I33: 0 | J33: 0 | K33: =C33-I33 -> 0 | L33: =J33-D33 -> 0 | M33: 45071 | AF33: 0 | AJ33: =C33-AH33 -> 0 | AK33: =D33-AI33 -> 0
A34: 20 | B34: 46168 | C34: 0 | D34: =E34-C34 -> 0 | E34: 0 | F34: 0 | I34: 0 | J34: 0 | K34: =C34-I34 -> 0 | L34: =J34-D34 -> 0 | M34: 45072 | AF34: 0 | AJ34: =C34-AH34 -> 0 | AK34: =D34-AI34 -> 0
B35: 46169 | C35: 0 | D35: =E35-C35 -> 0 | E35: 0 | F35: 0 | I35: 0 | J35: 0 | K35: =C35-I35 -> 0 | L35: =J35-D35 -> 0 | M35: 45071 | AF35: 0 | AJ35: =C35-AH35 -> 0 | AK35: =D35-AI35 -> 0
B36: 46170 | C36: 0 | D36: =E36-C36 -> 0 | E36: 0 | F36: 0 | I36: 0 | J36: k | K36: =C36-I36 -> 0 | L36: =J36-D36 -> #VALUE! | M36: 45071 | AF36: 0 | AJ36: =C36-AH36 -> 0 | AK36: =D36-AI36 -> 0
A37: 21 | B37: 46171 | C37: 0 | D37: =E37-C37 -> 0 | E37: 0 | F37: 0 | I37: 18395701 | J37: 13990864 | K37: =C37-I37 -> -18395701 | L37: =J37-D37 -> 13990864 | M37: 45075 | AF37: 0 | AJ37: =C37-AH37 -> 0 | AK37: =D37-AI37 -> 0
A38: 22 | B38: 46172 | C38: 0 | D38: =E38-C38 -> 0 | E38: 0 | F38: 0 | I38: 17773941 | J38: 873706 | AF38: 0 | AJ38: =C38-AH38 -> 0 | AK38: =D38-AI38 -> 0
A39: 23 | B39: 46173 | C39: 0 | D39: =E39-C39 -> 0 | E39: 0 | F39: 0 | AF39: 0
A40: Total MTD | C40: =SUM(C9:C39) -> 2.2868614e+08 | D40: =SUM(D9:D39) -> 43613059 | E40: =SUM(E9:E39) -> 2.722992e+08 | F40: =SUM(F9:F39) -> 3919662.3 | AE40: =E40-G40 -> 2.722992e+08 | AF40: =SUM(AF9:AF39) -> 1954583.9
A42: YTD Collection
A43: Particulars | C43: Collection Due | D43: New sales | E43: Total
...

Sheet daily (2)
B2: =UPPER(_xlfn.CONCAT("SOBHA - ",TEXT(F3,"MMMM YYYY "),"COLLECTION SUMMARY")) -> SOBHA - MAY 2026 COLLECTION SUMMARY
E3: As on | F3: =daily!F3 -> 46148
C4: Collection Due | D4: New sales | E4: Total
A5: Target | C5: 7.0288312e+08 | D5: 437500000 | E5: =SUM(C5:D5) -> 1.1403831e+09
A6: MTD Pro-rata Target | C6: 1.6538426e+08 | D6: 1.0294118e+08 | E6: =SUM(C6:D6) -> 2.6832544e+08
A8: Sno. | B8: Day & Date | C8: Collection Due | D8: New sales | E8: Total | F8: DLD/Oqood | I8: dues | J8: NS
A9: 1 | B9: 46143 | C9: 43879648 | D9: =E9-C9 -> 1337231 | E9: 45216879 | F9: 667705.46 | I9: 16996665 | J9: 6000000 | K9: =C9-I9 -> 26882983 | L9: =J9-D9 -> 4662769 | M9: 45047 | AF9: 518637.46
A10: 2 | B10: 46144 | C10: 0 | D10: =E10-C10 -> 0 | E10: 0 | F10: 432771.19 | I10: 13412362 | J10: 9041583.2 | K10: =C10-I10 -> -13412362 | L10: =J10-D10 -> 9041583.2 | M10: 45048 | AF10: 303910.97
A11: 3 | B11: 46145 | C11: 0 | D11: =E11-C11 -> 0 | E11: 0 | F11: 0 | I11: 0 | J11: 0 | K11: =C11-I11 -> 0 | L11: =J11-D11 -> 0 | M11: 45049 | AF11: 0
A12: 4 | B12: 46146 | C12: 49885612 | D12: =E12-C12 -> 1300605 | E12: 51186217 | F12: 840023.88 | I12: 0 | J12: 0 | K12: =C12-I12 -> 49885612 | L12: =J12-D12 -> -1300605 | M12: 45050 | AF12: 587342.5
A13: 5 | B13: 46147 | C13: 46921430 | D13: =E13-C13 -> 14207289 | E13: 61128719 | F13: 261611 | I13: 15087167 | J13: 19237054 | K13: =C13-I13 -> 31834263 | L13: =J13-D13 -> 5029765.2 | M13: 45051 | AF13: 194042
B14: 46148 | C14: 45855078 | D14: =E14-C14 -> 9367021 | E14: 55222099 | F14: 459349.61 | I14: 13923731 | J14: 5403520.4 | K14: =C14-I14 -> 31931347 | L14: =J14-D14 -> -3963500.6 | M14: 45052 | AF14: 350651
B15: 46149 | C15: 0 | D15: =E15-C15 -> 0 | E15: 0 | F15: 0 | I15: 13995160 | J15: 11816134 | K15: =C15-I15 -> -13995160 | L15: =J15-D15 -> 11816134 | M15: 45053 | AF15: 0
A16: 6 | B16: 46150 | C16: 0 | D16: =E16-C16 -> 0 | E16: 0 | F16: 0 | I16: 15532677 | J16: 3059004 | K16: =C16-I16 -> -15532677 | L16: =J16-D16 -> 3059004 | M16: 45054 | AF16: 0
A17: 7 | B17: 46151 | C17: 0 | D17: =E17-C17 -> 0 | E17: 0 | F17: 0 | I17: 18589390 | J17: 6865999 | K17: =C17-I17 -> -18589390 | L17: =J17-D17 -> 6865999 | M17: 45055 | AF17: 0
A18: 8 | B18: 46152 | C18: 0 | D18: =E18-C18 -> 0 | E18: 0 | F18: 0 | I18: 0 | J18: 0 | K18: =C18-I18 -> 0 | L18: =J18-D18 -> 0 | M18: 45056 | AF18: 0
A19: 9 | B19: 46153 | C19: 0 | D19: =E19-C19 -> 0 | E19: 0 | F19: 0 | I19: 0 | J19: 0 | K19: =C19-I19 -> 0 | L19: =J19-D19 -> 0 | M19: 45057 | AF19: 0
A20: 10 | B20: 46154 | C20: 0 | D20: =E20-C20 -> 0 | E20: 0 | F20: 0 | I20: 19090565 | J20: 26755176 | K20: =C20-I20 -> -19090565 | L20: =J20-D20 -> 26755176 | M20: 45058 | AF20: 0
B21: 46155 | C21: 0 | D21: =E21-C21 -> 0 | E21: 0 | F21: 0 | I21: 0 | J21: 0 | K21: =C21-I21 -> 0 | L21: =J21-D21 -> 0 | M21: 45059 | AF21: 0
B22: 46156 | C22: 0 | D22: =E22-C22 -> 0 | E22: 0 | F22: 0 | I22: 0 | J22: 0 | K22: =C22-I22 -> 0 | L22: =J22-D22 -> 0 | M22: 45060 | AF22: 0
A23: 11 | B23: 46157 | C23: 0 | D23: =E23-C23 -> 0 | E23: 0 | F23: 0 | I23: 0 | J23: 0 | K23: =C23-I23 -> 0 | L23: =J23-D23 -> 0 | M23: 45061 | AF23: 0
A24: 12 | B24: 46158 | C24: 0 | D24: =E24-C24 -> 0 | E24: 0 | F24: 0 | I24: 0 | J24: 0 | K24: =C24-I24 -> 0 | L24: =J24-D24 -> 0 | M24: 45062 | AF24: 0
A25: 13 | B25: 46159 | C25: 0 | D25: =E25-C25 -> 0 | E25: 0 | F25: 0 | I25: 0 | J25: 0 | K25: =C25-I25 -> 0 | L25: =J25-D25 -> 0 | M25: 45063 | V25: =SUM(V23,V17) -> 0 | AF25: 0
A26: 14 | B26: 46160 | C26: 0 | D26: =E26-C26 -> 0 | E26: 0 | F26: 0 | I26: 0 | J26: 0 | K26: =C26-I26 -> 0 | L26: =J26-D26 -> 0 | M26: 45064 | AF26: 0
A27: 15 | B27: 46161 | C27: 0 | D27: =E27-C27 -> 0 | E27: 0 | F27: 0 | AF27: 0
B28: 46162 | C28: 0 | D28: =E28-C28 -> 0 | E28: 0 | F28: 0 | AF28: 0
B29: 46163 | C29: 0 | D29: =E29-C29 -> 0 | E29: 0 | F29: 0 | AF29: 0
A30: 16 | B30: 46164 | C30: 0 | D30: =E30-C30 -> 0 | E30: 0 | F30: 0 | AF30: 0
A31: 17 | B31: 46165 | C31: 0 | D31: =E31-C31 -> 0 | E31: 0 | F31: 0 | AF31: 0
A32: 18 | B32: 46166 | C32: 0 | D32: =E32-C32 -> 0 | E32: 0 | F32: 0 | AF32: 0
A33: 19 | B33: 46167 | C33: 0 | D33: =E33-C33 -> 0 | E33: 0 | F33: 0 | AF33: 0
A34: 20 | B34: 46168 | C34: 0 | D34: =E34-C34 -> 0 | E34: 0 | F34: 0 | AF34: 0
B35: 46169 | C35: 0 | D35: =E35-C35 -> 0 | E35: 0 | F35: 0 | AF35: 0
B36: 46170 | C36: 0 | D36: =E36-C36 -> 0 | E36: 0 | F36: 0 | AF36: 0
A37: 21 | B37: 46171 | C37: 0 | D37: =E37-C37 -> 0 | E37: 0 | F37: 0 | AF37: 0
A38: 22 | B38: 46172 | C38: 0 | D38: =E38-C38 -> 0 | E38: 0 | F38: 0 | AF38: 0
A39: 23 | B39: 46173 | C39: 0 | D39: =E39-C39 -> 0 | E39: 0 | F39: 0 | AF39: 0
A40: Total MTD | C40: =SUM(C9:C39) -> 1.8654177e+08 | D40: =SUM(D9:D39) -> 26212146 | E40: =SUM(E9:E39) -> 2.1275391e+08 | F40: =SUM(F9:F39) -> 2661461.1 | AF40: =SUM(AF9:AF39) -> 1954583.9
A42: YTD Collection
A43: Particulars | C43: Collection Due | D43: New sales | E43: Total
...

Sheet daily (3)
B2: =UPPER(_xlfn.CONCAT("SINIYA - ",TEXT(F3,"MMMM YYYY "),"COLLECTION SUMMARY")) -> SINIYA - MAY 2026 COLLECTION SUMMARY
E3: As on | F3: =daily!F3 -> 46148
C4: Collection Due | D4: New sales | E4: Total
A5: Target | C5: 1.4307909e+08 | D5: 63625000 | E5: =SUM(C5:D5) -> 2.0670409e+08
A6: MTD Pro-rata Target | C6: 33665668 | D6: 14970588 | E6: =SUM(C6:D6) -> 48636256
A8: Sno. | B8: Day & Date | C8: Collection Due | D8: New sales | E8: Total | F8: DLD/Oqood | I8: dues | J8: NS
A9: 1 | B9: 46143 | C9: 8297654.2 | D9: =E9-C9 -> 0 | E9: 8297654.2 | F9: 1000 | I9: 16996665 | J9: 6000000 | K9: =C9-I9 -> -8699010.8 | L9: =J9-D9 -> 6000000 | M9: 45047 | AF9: 518637.46
A10: 2 | B10: 46144 | C10: 0 | D10: =E10-C10 -> 0 | E10: 0 | F10: 0 | I10: 13412362 | J10: 9041583.2 | K10: =C10-I10 -> -13412362 | L10: =J10-D10 -> 9041583.2 | M10: 45048 | AF10: 303910.97
A11: 3 | B11: 46145 | C11: 0 | D11: =E11-C11 -> 0 | E11: 0 | F11: 0 | I11: 0 | J11: 0 | K11: =C11-I11 -> 0 | L11: =J11-D11 -> 0 | M11: 45049 | AF11: 0
A12: 4 | B12: 46146 | C12: 12370281 | D12: =E12-C12 -> 0 | E12: 12370281 | F12: 0 | I12: 0 | J12: 0 | K12: =C12-I12 -> 12370281 | L12: =J12-D12 -> 0 | M12: 45050 | AF12: 587342.5
A13: 5 | B13: 46147 | C13: 7062413 | D13: =E13-C13 -> 0 | E13: 7062413 | F13: 1000 | I13: 15087167 | J13: 19237054 | K13: =C13-I13 -> -8024754 | L13: =J13-D13 -> 19237054 | M13: 45051 | AF13: 194042
B14: 46148 | C14: 7087503.4 | D14: =E14-C14 -> 93 | E14: 7087596.4 | F14: 0 | I14: 13923731 | J14: 5403520.4 | K14: =C14-I14 -> -6836227.6 | L14: =J14-D14 -> 5403427.4 | M14: 45052 | AF14: 350651
B15: 46149 | C15: 0 | D15: =E15-C15 -> 0 | E15: 0 | F15: 0 | I15: 13995160 | J15: 11816134 | K15: =C15-I15 -> -13995160 | L15: =J15-D15 -> 11816134 | M15: 45053 | AF15: 0
A16: 6 | B16: 46150 | C16: 0 | D16: =E16-C16 -> 0 | E16: 0 | F16: 0 | I16: 15532677 | J16: 3059004 | K16: =C16-I16 -> -15532677 | L16: =J16-D16 -> 3059004 | M16: 45054 | AF16: 0
A17: 7 | B17: 46151 | C17: 0 | D17: =E17-C17 -> 0 | E17: 0 | F17: 0 | I17: 18589390 | J17: 6865999 | K17: =C17-I17 -> -18589390 | L17: =J17-D17 -> 6865999 | M17: 45055 | AF17: 0
A18: 8 | B18: 46152 | C18: 0 | D18: =E18-C18 -> 0 | E18: 0 | F18: 0 | I18: 0 | J18: 0 | K18: =C18-I18 -> 0 | L18: =J18-D18 -> 0 | M18: 45056 | AF18: 0
A19: 9 | B19: 46153 | C19: 0 | D19: =E19-C19 -> 0 | E19: 0 | F19: 0 | I19: 0 | J19: 0 | K19: =C19-I19 -> 0 | L19: =J19-D19 -> 0 | M19: 45057 | AF19: 0
A20: 10 | B20: 46154 | C20: 0 | D20: =E20-C20 -> 0 | E20: 0 | F20: 0 | I20: 19090565 | J20: 26755176 | K20: =C20-I20 -> -19090565 | L20: =J20-D20 -> 26755176 | M20: 45058 | AF20: 0
B21: 46155 | C21: 0 | D21: =E21-C21 -> 0 | E21: 0 | F21: 0 | I21: 0 | J21: 0 | K21: =C21-I21 -> 0 | L21: =J21-D21 -> 0 | M21: 45059 | AF21: 0
B22: 46156 | C22: 0 | D22: =E22-C22 -> 0 | E22: 0 | F22: 0 | I22: 0 | J22: 0 | K22: =C22-I22 -> 0 | L22: =J22-D22 -> 0 | M22: 45060 | AF22: 0
A23: 11 | B23: 46157 | C23: 0 | D23: =E23-C23 -> 0 | E23: 0 | F23: 0 | I23: 0 | J23: 0 | K23: =C23-I23 -> 0 | L23: =J23-D23 -> 0 | M23: 45061 | AF23: 0
A24: 12 | B24: 46158 | C24: 0 | D24: =E24-C24 -> 0 | E24: 0 | F24: 0 | I24: 0 | J24: 0 | K24: =C24-I24 -> 0 | L24: =J24-D24 -> 0 | M24: 45062 | AF24: 0
A25: 13 | B25: 46159 | C25: 0 | D25: =E25-C25 -> 0 | E25: 0 | F25: 0 | I25: 0 | J25: 0 | K25: =C25-I25 -> 0 | L25: =J25-D25 -> 0 | M25: 45063 | V25: =SUM(V23,V17) -> 0 | AF25: 0
A26: 14 | B26: 46160 | C26: 0 | D26: =E26-C26 -> 0 | E26: 0 | F26: 0 | I26: 0 | J26: 0 | K26: =C26-I26 -> 0 | L26: =J26-D26 -> 0 | M26: 45064 | AF26: 0
A27: 15 | B27: 46161 | C27: 0 | D27: =E27-C27 -> 0 | E27: 0 | F27: 0 | AF27: 0
B28: 46162 | C28: 0 | D28: =E28-C28 -> 0 | E28: 0 | F28: 0 | AF28: 0
B29: 46163 | C29: 0 | D29: =E29-C29 -> 0 | E29: 0 | F29: 0 | AF29: 0
A30: 16 | B30: 46164 | C30: 0 | D30: =E30-C30 -> 0 | E30: 0 | F30: 0 | AF30: 0
A31: 17 | B31: 46165 | C31: 0 | D31: =E31-C31 -> 0 | E31: 0 | F31: 0 | AF31: 0
A32: 18 | B32: 46166 | C32: 0 | D32: =E32-C32 -> 0 | E32: 0 | F32: 0 | AF32: 0
A33: 19 | B33: 46167 | C33: 0 | D33: =E33-C33 -> 0 | E33: 0 | F33: 0 | AF33: 0
A34: 20 | B34: 46168 | C34: 0 | D34: =E34-C34 -> 0 | E34: 0 | F34: 0 | AF34: 0
B35: 46169 | C35: 0 | D35: =E35-C35 -> 0 | E35: 0 | F35: 0 | I35: 0 | J35: 0 | K35: =C35-I35 -> 0 | L35: =J35-D35 -> 0 | M35: 45071 | AF35: 0
