Workbook
Name Ak: !#REF!
Name NOB: !#REF!
Name qwerty: #REF!
Name Source: !#REF!
Name SRCE: !#REF!
Name Style: !#REF!
Name TOS: !#REF!
Name Type: !#REF!
Name VLOOKUP: !#REF!

Sheet Summary
A1: Note: | B1: Month On month collections are shown
B2: Unidentified = Realised-Reg-Receipts | N2: 46148
B3: Receipts = New sale+Other charges+dues&adv
S4: Difference | AE4: Yesterday
B5: =_xlfn.CONCAT("Summary as on-",TEXT(N2,"DD/MM/YYYY")) -> Summary as on-06/05/2026 | S5: =B5 -> Summary as on-06/05/2026 | AE5: =CONCATENATE("Summary as on-",TEXT(TODAY()-3,"dd/mm/yyyy")) -> Summary as on-05/05/2026
B6: Year | C6: Total realised | D6: DLD | E6: Receipts total | F6: Dues + Advance collection | G6: New sale receipts | H6: Other charges | I6: Est. Unidentified | J6: Advance collection | K6: Dues collection | L6: Actual unidentifed | S6: Year | T6: Total realised | U6: DLD | V6: Receipts total | W6: Dues + Advance collection | X6: New sale receipts | Y6: Other charges | Z6: Est. Unidentified | AA6: Advance collection | AB6: Dues collection | AC6: Actual unidentifed | AE6: Year | AF6: Total realised | AG6: DLD | AH6: Receipts total | AI6: Dues + Advance collection | AJ6: New sale receipts | AK6: Other charges | AL6: Est. Unidentified | AM6: Advance collection | AN6: Dues collection | AO6: Actual unidentifed
A7: 44196 | B7: 2020 & Before | C7: =SUM(D7:E7) -> 1.7716423e+09 | D7: 64288549 | E7: 1.7073538e+09 | F7: 1274263635 | G7: 431100953 | H7: 1989377 | I7: =C7-E7-D7 -> 0 | J7: 3.3403115e+08 | K7: 9.4023249e+08 | L7: =C7-E7-D7 -> 0 | N7: =_xlfn.CONCAT("Values as on ",TEXT(N2,"dd-mm-yyyy")) -> Values as on 06-05-2026 | S7: 2020 & Before | T7: =C7-AF7 -> 0 | U7: =D7-AG7 -> 0 | V7: =E7-AH7 -> 0 | W7: =F7-AI7 -> -322590 | X7: =G7-AJ7 -> 322593 | Y7: =H7-AK7 -> 0 | Z7: =I7-AL7 -> 0 | AA7: =J7-AM7 -> -98.78 | ... AC7: =L7-AO7 -> 0 | AE7: 2020 & Before | AF7: 1.7716423e+09 | AG7: 64288549 | AH7: 1.7073538e+09 | AI7: 1274586225 | AJ7: 430778360 | AK7: 1989377 | AL7: 0 | AM7: 3.3403124e+08 | AN7: 9.4055498e+08 | AO7: 0
A8: 44561 | B8: 2021 Total | C8: 1698298327 | D8: 130078450 | E8: 1.5664545e+09 | F8: 866125495 | G8: 699134658 | H8: 1194387 | I8: =C8-E8-D8 -> 1765331.1 | J8: 2.1768337e+08 | K8: 6.4844212e+08 | L8: =C8-E8-D8 -> 1765331.1 | N8: Sobha | O8: 2.309767e+08 | P8: 1.1685699e+09 | Q8: =P8-O8 -> 9.3759316e+08 | S8: 2021 Total | T8: =C8-AF8 -> 0 | U8: =D8-AG8 -> 0 | V8: =E8-AH8 -> 0 | W8: =F8-AI8 -> -276 | X8: =G8-AJ8 -> 277 | Y8: =H8-AK8 -> 0 | Z8: =I8-AL8 -> 0 | AA8: =J8-AM8 -> 2559.66 | ... AC8: =L8-AO8 -> 0 | AE8: 2021 Total | AF8: 1698298327 | AG8: 130078450 | AH8: 1.5664545e+09 | AI8: 866125771 | AJ8: 699134381 | AK8: 1194387 | AL8: 1765331.1 | AM8: 2.1768081e+08 | AN8: 6.4844496e+08 | AO8: 1765331.1
A9: =EOMONTH(A8,12) -> 44926 | B9: 2022 Total | C9: 4272715411 | D9: 407978084 | E9: 3.8596445e+09 | F9: 2498323296 | G9: 1357599331 | H9: 3722293 | I9: =C9-E9-D9 -> 5092824.3 | J9: 8.1500144e+08 | K9: 1.6833219e+09 | L9: =C9-E9-D9 -> 5092824.3 | N9: Siniya | O9: 28868668 | P9: 1.7880593e+08 | Q9: =P9-O9 -> 1.4993727e+08 | S9: 2022 Total | T9: =C9-AF9 -> 0 | U9: =D9-AG9 -> 0 | V9: =E9-AH9 -> 0 | W9: =F9-AI9 -> -13731 | X9: =G9-AJ9 -> 13756 | Y9: =H9-AK9 -> 0 | Z9: =I9-AL9 -> 0 | AA9: =J9-AM9 -> -11567.82 | ... AC9: =L9-AO9 -> 0 | AE9: 2022 Total | AF9: 4272715411 | AG9: 407978084 | AH9: 3.8596445e+09 | AI9: 2498337027 | AJ9: 1357585575 | AK9: 3722293 | AL9: 5092824.3 | AM9: 8.1501301e+08 | AN9: 1.683324e+09 | AO9: 5092824.3
A10: =EOMONTH(A9,12) -> 45291 | B10: 2023 Total | C10: 7825770561 | D10: 637652517 | E10: 7.1731795e+09 | F10: 4692684807 | G10: 2467593381 | H10: 12901651 | I10: =C10-E10-D10 -> 14938503 | J10: 9.6426387e+08 | K10: 3.7284209e+09 | L10: =C10-E10-D10 -> 14938503 | N10: Downtown UAQ | O10: 5891204 | P10: 20322591 | Q10: =P10-O10 -> 14431387 | S10: 2023 Total | T10: =C10-AF10 -> 0 | U10: =D10-AG10 -> 0 | V10: =E10-AH10 -> 0 | W10: =F10-AI10 -> -338716 | X10: =G10-AJ10 -> 338717 | Y10: =H10-AK10 -> 0 | Z10: =I10-AL10 -> 0 | AA10: =J10-AM10 -> -15880.52 | ... AC10: =L10-AO10 -> 0 | AE10: 2023 Total | AF10: 7825770561 | AG10: 637652517 | AH10: 7.1731795e+09 | AI10: 4693023523 | AJ10: 2467254664 | AK10: 12901651 | AL10: 14938503 | AM10: 9.6427975e+08 | AN10: 3.7287438e+09 | AO10: 14938503
A11: 45291 | B11: 2024 Total | C11: =SUM(C12:C23) -> 1.0895088e+10 | D11: =SUM(D12:D23) -> 637969023 | E11: =SUM(E12:E23) -> 1.0211958e+10 | F11: =SUM(F12:F23) -> 6977755871 | G11: =SUM(G12:G23) -> 3215483679 | H11: =SUM(H12:H23) -> 18719302 | I11: =SUM(I12:I23) -> 45160940 | J11: =SUM(J12:J23) -> 1.4516105e+09 | K11: =SUM(K12:K23) -> 5.5261453e+09 | L11: =C11-E11-D11 -> 45160940 | N11: Abu Dhabi | O11: 18449471 | P11: =SUM(P8:P10) -> 1.3676984e+09 | S11: 2024 Total | T11: =C11-AF11 -> 0 | U11: =D11-AG11 -> 0 | V11: =E11-AH11 -> 73152.56 | W11: =F11-AI11 -> 467386 | X11: =G11-AJ11 -> -394228 | Y11: =H11-AK11 -> 0 | Z11: =I11-AL11 -> -73152.56 | AA11: =J11-AM11 -> 357154.53 | ... AC11: =L11-AO11 -> -73152.56 | AE11: 2024 Total | AF11: 1.0895088e+10 | AG11: 637969023 | AH11: 1.0211885e+10 | AI11: 6977288485 | AJ11: 3215877907 | AK11: 18719302 | AL11: 45234092 | AM11: 1.4512534e+09 | AN11: 5.5260351e+09 | AO11: 45234092
A12: 45322 | B12: Jan'24 | C12: 7.876635e+08 | D12: 51330740 | E12: 7.3222493e+08 | F12: 518398287 | G12: 212004087 | H12: 1822587 | I12: =C12-E12-D12 -> 4107824.9 | J12: 1.2490968e+08 | K12: 3.9348861e+08 | L12: =C12-E12-D12 -> 4107824.9 | N12: Total | O12: =SUM(O8:O11) -> 2.8418604e+08 | S12: Jan'24 | T12: =C12-AF12 -> 0 | U12: =D12-AG12 -> 0 | V12: =E12-AH12 -> 0 | W12: =F12-AI12 -> -5 | X12: =G12-AJ12 -> 2 | Y12: =H12-AK12 -> 0 | Z12: =I12-AL12 -> 0 | AA12: =J12-AM12 -> -1617.13 | ... AC12: =L12-AO12 -> 0 | AE12: Jan'24 | AF12: 7.876635e+08 | AG12: 51330740 | AH12: 7.3222493e+08 | AI12: 518398292 | AJ12: 212004085 | AK12: 1822587 | AL12: 4107824.9 | AM12: 1.249113e+08 | AN12: 3.9348699e+08 | AO12: 4107824.9
A13: =EOMONTH(A12+1,0) -> 45351 | B13: Feb'24 | C13: 8.4275091e+08 | D13: 62367891 | E13: 7.7412302e+08 | F13: 532780998 | G13: 238989502 | H13: 2352539 | I13: =C13-E13-D13 -> 6259995.4 | J13: 1.1004926e+08 | K13: 4.2273174e+08 | L13: =C13-E13-D13 -> 6259995.4 | S13: Feb'24 | T13: =C13-AF13 -> 0 | U13: =D13-AG13 -> 0 | V13: =E13-AH13 -> 0 | W13: =F13-AI13 -> 4 | X13: =G13-AJ13 -> 0 | Y13: =H13-AK13 -> 0 | Z13: =I13-AL13 -> 0 | AA13: =J13-AM13 -> -54997.29 | ... AC13: =L13-AO13 -> 0 | AE13: Feb'24 | AF13: 8.4275091e+08 | AG13: 62367891 | AH13: 7.7412302e+08 | AI13: 532780994 | AJ13: 238989502 | AK13: 2352539 | AL13: 6259995.4 | AM13: 1.1010426e+08 | AN13: 4.2267674e+08 | AO13: 6259995.4
A14: =EOMONTH(A13+1,0) -> 45382 | B14: Mar'24 | C14: 9.1567892e+08 | D14: 63072708 | E14: 8.4811473e+08 | F14: 520422396 | G14: 325507505 | H14: 2184784 | I14: =C14-E14-D14 -> 4491482 | J14: 1.2028879e+08 | K14: 4.0013361e+08 | L14: =C14-E14-D14 -> 4491482 | S14: Mar'24 | T14: =C14-AF14 -> 0 | U14: =D14-AG14 -> 0 | V14: =E14-AH14 -> 0 | W14: =F14-AI14 -> -3 | X14: =G14-AJ14 -> 1 | Y14: =H14-AK14 -> 0 | Z14: =I14-AL14 -> 0 | AA14: =J14-AM14 -> -9821.85 | ... AC14: =L14-AO14 -> 0 | AE14: Mar'24 | AF14: 9.1567892e+08 | AG14: 63072708 | AH14: 8.4811473e+08 | AI14: 520422399 | AJ14: 325507504 | AK14: 2184784 | AL14: 4491482 | AM14: 1.2029861e+08 | AN14: 4.0012379e+08 | AO14: 4491482
A15: =EOMONTH(A14+1,0) -> 45412 | B15: Apr'24 | C15: 7.9590015e+08 | D15: 55989228 | E15: 7.3625981e+08 | F15: 487717181 | G15: 247240968 | H15: 1301619 | I15: =C15-E15-D15 -> 3651108.2 | J15: 82130973 | K15: 4.0558621e+08 | L15: =C15-E15-D15 -> 3651108.2 | S15: Apr'24 | T15: =C15-AF15 -> 0 | U15: =D15-AG15 -> 0 | V15: =E15-AH15 -> 0 | W15: =F15-AI15 -> 420471 | X15: =G15-AJ15 -> -420468 | Y15: =H15-AK15 -> 0 | Z15: =I15-AL15 -> 0 | AA15: =J15-AM15 -> 419815.93 | ... AC15: =L15-AO15 -> 0 | AE15: Apr'24 | AF15: 7.9590015e+08 | AG15: 55989228 | AH15: 7.3625981e+08 | AI15: 487296710 | AJ15: 247661436 | AK15: 1301619 | AL15: 3651108.2 | AM15: 81711157 | AN15: 4.0558555e+08 | AO15: 3651108.2
A16: =EOMONTH(A15+1,0) -> 45443 | B16: May'24 | C16: 8.942952e+08 | D16: 66293170 | E16: 8.2675483e+08 | F16: 580599202 | G16: 243818421 | H16: 2337246 | I16: =C16-E16-D16 -> 1247194.7 | J16: 1.2056465e+08 | K16: 4.6003455e+08 | L16: =C16-E16-D16 -> 1247194.7 | S16: May'24 | T16: =C16-AF16 -> 0 | U16: =D16-AG16 -> 0 | V16: =E16-AH16 -> 0 | W16: =F16-AI16 -> 2 | X16: =G16-AJ16 -> 0 | Y16: =H16-AK16 -> 0 | Z16: =I16-AL16 -> 0 | AA16: =J16-AM16 -> 12688.09 | ... AC16: =L16-AO16 -> 0 | AE16: May'24 | AF16: 8.942952e+08 | AG16: 66293170 | AH16: 8.2675483e+08 | AI16: 580599200 | AJ16: 243818421 | AK16: 2337246 | AL16: 1247194.7 | AM16: 1.2055196e+08 | AN16: 4.6004724e+08 | AO16: 1247194.7
A17: =EOMONTH(A16+1,0) -> 45473 | B17: Jun'24 | C17: 7.4129294e+08 | D17: 43018017 | E17: 6.9636041e+08 | F17: 502657372 | G17: 192285683 | H17: 1417459 | I17: =C17-E17-D17 -> 1914511.4 | J17: 80140512 | K17: 4.2251686e+08 | L17: =C17-E17-D17 -> 1914511.4 | S17: Jun'24 | T17: =C17-AF17 -> 0 | U17: =D17-AG17 -> 0 | V17: =E17-AH17 -> 0 | W17: =F17-AI17 -> -6 | X17: =G17-AJ17 -> 2 | Y17: =H17-AK17 -> 0 | Z17: =I17-AL17 -> 0 | AA17: =J17-AM17 -> -12002.21 | ... AC17: =L17-AO17 -> 0 | AE17: Jun'24 | AF17: 7.4129294e+08 | AG17: 43018017 | AH17: 6.9636041e+08 | AI17: 502657378 | AJ17: 192285681 | AK17: 1417459 | AL17: 1914511.4 | AM17: 80152514 | AN17: 4.2250486e+08 | AO17: 1914511.4
A18: =EOMONTH(A17+1,0) -> 45504 | B18: Jul'24 | C18: 8.1709479e+08 | D18: 48059793 | E18: 7.6690817e+08 | F18: 571037984 | G18: 194700434 | H18: 1169899 | I18: =C18-E18-D18 -> 2126827 | J18: 1.0617752e+08 | K18: 4.6486046e+08 | L18: =C18-E18-D18 -> 2126827 | S18: Jul'24 | T18: =C18-AF18 -> 0 | U18: =D18-AG18 -> 0 | V18: =E18-AH18 -> 0.35000002 | W18: =F18-AI18 -> 7 | X18: =G18-AJ18 -> -3 | Y18: =H18-AK18 -> 0 | Z18: =I18-AL18 -> -0.35000002 | AA18: =J18-AM18 -> 6.22 | ... AC18: =L18-AO18 -> -0.35000002 | AE18: Jul'24 | AF18: 8.1709479e+08 | AG18: 48059793 | AH18: 7.6690817e+08 | AI18: 571037977 | AJ18: 194700437 | AK18: 1169899 | AL18: 2126827.3 | AM18: 1.0617752e+08 | AN18: 4.6486046e+08 | AO18: 2126827.3
A19: =EOMONTH(A18+1,0) -> 45535 | B19: Aug'24 | C19: 8.7325706e+08 | D19: 45030725 | E19: 8.2334793e+08 | F19: 574432824 | G19: 247529835 | H19: 1385453 | I19: =C19-E19-D19 -> 4878399.6 | J19: 1.3452376e+08 | K19: 4.3990906e+08 | L19: =C19-E19-D19 -> 4878399.6 | S19: Aug'24 | T19: =C19-AF19 -> 0 | U19: =D19-AG19 -> 0 | V19: =E19-AH19 -> -0.039999962 | W19: =F19-AI19 -> 9 | X19: =G19-AJ19 -> -3 | Y19: =H19-AK19 -> 0 | Z19: =I19-AL19 -> 0.039999962 | AA19: =J19-AM19 -> -14591.8 | ... AC19: =L19-AO19 -> 0.039999962 | AE19: Aug'24 | AF19: 8.7325706e+08 | AG19: 45030725 | AH19: 8.2334793e+08 | AI19: 574432815 | AJ19: 247529838 | AK19: 1385453 | AL19: 4878399.5 | AM19: 1.3453836e+08 | AN19: 4.3989446e+08 | AO19: 4878399.5
A20: =EOMONTH(A19+1,0) -> 45565 | B20: Sep'24 | C20: 8.971543e+08 | D20: 45977307 | E20: 8.4999415e+08 | F20: 583889163 | G20: 265105888 | H20: 999285 | I20: =C20-E20-D20 -> 1182838.8 | J20: 1.1611706e+08 | K20: 4.677721e+08 | L20: =C20-E20-D20 -> 1182838.8 | S20: Sep'24 | T20: =C20-AF20 -> 0 | U20: =D20-AG20 -> 0 | V20: =E20-AH20 -> 0.92000008 | W20: =F20-AI20 -> 402 | X20: =G20-AJ20 -> -402 | Y20: =H20-AK20 -> 0 | Z20: =I20-AL20 -> -0.92000008 | AA20: =J20-AM20 -> -4599.59 | ... AC20: =L20-AO20 -> -0.92000008 | AE20: Sep'24 | AF20: 8.971543e+08 | AG20: 45977307 | AH20: 8.4999415e+08 | AI20: 583888761 | AJ20: 265106290 | AK20: 999285 | AL20: 1182839.7 | AM20: 1.1612166e+08 | AN20: 4.677671e+08 | AO20: 1182839.7
A21: =EOMONTH(A20+1,0) -> 45596 | B21: Oct'24 | C21: 1.1078732e+09 | D21: 43325977 | E21: 1.0573714e+09 | F21: 732948378 | G21: 323373274 | H21: 1049902 | I21: =C21-E21-D21 -> 7175855.9 | J21: 1.6419767e+08 | K21: 5.6875071e+08 | L21: =C21-E21-D21 -> 7175855.9 | S21: Oct'24 | T21: =C21-AF21 -> 0 | U21: =D21-AG21 -> 0 | V21: =E21-AH21 -> 1454.43 | W21: =F21-AI21 -> 1438 | X21: =G21-AJ21 -> 12 | Y21: =H21-AK21 -> 0 | Z21: =I21-AL21 -> -1454.43 | AA21: =J21-AM21 -> -2747.79 | ... AC21: =L21-AO21 -> -1454.43 | AE21: Oct'24 | AF21: 1.1078732e+09 | AG21: 43325977 | AH21: 1.0573699e+09 | AI21: 732946940 | AJ21: 323373262 | AK21: 1049902 | AL21: 7177310.3 | AM21: 1.6420042e+08 | AN21: 5.6874652e+08 | AO21: 7177310.3
A22: =EOMONTH(A21+1,0) -> 45626 | B22: Nov'24 | C22: 1.1290055e+09 | D22: 56642195 | E22: 1.0685267e+09 | F22: 703279277 | G22: 363909082 | H22: 1338503 | I22: =C22-E22-D22 -> 3836633.5 | J22: 1.4794022e+08 | K22: 5.5533906e+08 | L22: =C22-E22-D22 -> 3836633.5 | S22: Nov'24 | T22: =C22-AF22 -> 0 | U22: =D22-AG22 -> 0 | V22: =E22-AH22 -> 64722.32 | W22: =F22-AI22 -> 38082 | X22: =G22-AJ22 -> 26637 | Y22: =H22-AK22 -> 0 | Z22: =I22-AL22 -> -64722.32 | AA22: =J22-AM22 -> -3766.1 | ... AC22: =L22-AO22 -> -64722.32 | AE22: Nov'24 | AF22: 1.1290055e+09 | AG22: 56642195 | AH22: 1.068462e+09 | AI22: 703241195 | AJ22: 363882445 | AK22: 1338503 | AL22: 3901355.9 | AM22: 1.4794398e+08 | AN22: 5.5529721e+08 | AO22: 3901355.9
A23: =EOMONTH(A22+1,0) -> 45657 | B23: Dec'24 | C23: 1.0931212e+09 | D23: 56861272 | E23: 1.0319716e+09 | F23: 669592809 | G23: 361019000 | H23: 1360026 | I23: =C23-E23-D23 -> 4288268.5 | J23: 1.4457046e+08 | K23: 5.2502235e+08 | L23: =C23-E23-D23 -> 4288268.5 | S23: Dec'24 | T23: =C23-AF23 -> 0 | U23: =D23-AG23 -> 0 | V23: =E23-AH23 -> 6974.58 | W23: =F23-AI23 -> 6985 | X23: =G23-AJ23 -> -6 | Y23: =H23-AK23 -> 0 | Z23: =I23-AL23 -> -6974.58 | AA23: =J23-AM23 -> 28788.05 | ... AC23: =L23-AO23 -> -6974.58 | AE23: Dec'24 | AF23: 1.0931212e+09 | AG23: 56861272 | AH23: 1.0319646e+09 | AI23: 669585824 | AJ23: 361019006 | AK23: 1360026 | AL23: 4295243.1 | AM23: 1.4454167e+08 | AN23: 5.2504415e+08 | AO23: 4295243.1
A24: =A23 -> 45657 | B24: 2025 Total | C24: =SUM(C25:C36) -> 1.7685139e+10 | D24: =SUM(D25:D36) -> 813260419 | E24: =SUM(E25:E36) -> 1.674614e+10 | F24: =SUM(F25:F36) -> 12876250831 | G24: =SUM(G25:G36) -> 3821295883 | H24: =SUM(H25:H36) -> 48597532 | I24: =SUM(I25:I36) -> 1.2573875e+08 | J24: =SUM(J25:J36) -> 3.2678293e+09 | K24: =SUM(K25:K36) -> 9.6084215e+09 | L24: =C24-E24-D24 -> 1.2573875e+08 | S24: 2025 Total | T24: =C24-AF24 -> 0 | U24: =D24-AG24 -> -1000775 | V24: =E24-AH24 -> 1733084.8 | W24: =F24-AI24 -> 1844233 | X24: =G24-AJ24 -> -126049 | Y24: =H24-AK24 -> 14799 | Z24: =I24-AL24 -> -732309.78 | AA24: =J24-AM24 -> 1552775.3 | ... AC24: =L24-AO24 -> -732309.78 | AE24: 2025 Total | AF24: 1.7685139e+10 | AG24: 814261194 | AH24: 1.6744407e+10 | AI24: 12874406598 | AJ24: 3821421932 | AK24: 48582733 | AL24: 1.2647106e+08 | AM24: 3.2662765e+09 | AN24: 9.6081301e+09 | AO24: 1.2647106e+08
A25: =EOMONTH(A23+1,0) -> 45688 | B25: Jan'25 | C25: 1.1804646e+09 | D25: 65721792 | E25: 1.109371e+09 | F25: 767307303 | G25: 338848056 | H25: 3215774 | I25: =C25-E25-D25 -> 5371812 | J25: 1.6547692e+08 | K25: 6.0183038e+08 | L25: =C25-E25-D25 -> 5371812 | S25: Jan'25 | T25: =C25-AF25 -> 0 | U25: =D25-AG25 -> 0 | V25: =E25-AH25 -> 1.47 | W25: =F25-AI25 -> -996 | X25: =G25-AJ25 -> 991 | Y25: =H25-AK25 -> 0 | Z25: =I25-AL25 -> -1.47 | AA25: =J25-AM25 -> 29439.62 | ... AC25: =L25-AO25 -> -1.47 | AE25: Jan'25 | AF25: 1.1804646e+09 | AG25: 65721792 | AH25: 1.109371e+09 | AI25: 767308299 | AJ25: 338847065 | AK25: 3215774 | AL25: 5371813.5 | AM25: 1.6544748e+08 | AN25: 6.0186081e+08 | AO25: 5371813.5
A26: =EOMONTH(A25+1,0) -> 45716 | B26: Feb'25 | C26: 1.25877e+09 | D26: 64905273 | E26: 1.1895738e+09 | F26: 808162069 | G26: 378552326 | H26: 2859574 | I26: =C26-E26-D26 -> 4291001.3 | J26: 1.6239916e+08 | K26: 6.4576291e+08 | L26: =C26-E26-D26 -> 4291001.3 | S26: Feb'25 | T26: =C26-AF26 -> 0 | U26: =D26-AG26 -> 0 | V26: =E26-AH26 -> 2.0900002 | W26: =F26-AI26 -> -9 | X26: =G26-AJ26 -> 0 | Y26: =H26-AK26 -> 0 | Z26: =I26-AL26 -> -2.0900002 | AA26: =J26-AM26 -> -39763.92 | ... AC26: =L26-AO26 -> -2.0900002 | AE26: Feb'25 | AF26: 1.25877e+09 | AG26: 64905273 | AH26: 1.1895738e+09 | AI26: 808162078 | AJ26: 378552326 | AK26: 2859574 | AL26: 4291003.4 | AM26: 1.6243892e+08 | AN26: 6.4572315e+08 | AO26: 4291003.4
A27: =EOMONTH(A26+1,0) -> 45747 | B27: Mar'25 | C27: =C68+C110 -> 1.3230797e+09 | D27: 69441622 | E27: 1.2424912e+09 | F27: 859123980 | G27: 380926920 | H27: 2440561 | I27: =C27-E27-D27 -> 11146795 | J27: 1.8601571e+08 | K27: 6.7310827e+08 | L27: =C27-E27-D27 -> 11146795 | S27: Mar'25 | T27: =C27-AF27 -> 0 | U27: =D27-AG27 -> 0 | V27: =E27-AH27 -> 1.22 | W27: =F27-AI27 -> -9795 | X27: =G27-AJ27 -> -7 | Y27: =H27-AK27 -> 9799 | Z27: =I27-AL27 -> -1.22 | AA27: =J27-AM27 -> -10802.19 | ... AC27: =L27-AO27 -> -1.22 | AE27: Mar'25 | AF27: 1.3230797e+09 | AG27: 69441622 | AH27: 1.2424912e+09 | AI27: 859133775 | AJ27: 380926927 | AK27: 2430762 | AL27: 11146796 | AM27: 1.8602652e+08 | AN27: 6.7310726e+08 | AO27: 11146796
A28: =EOMONTH(A27+1,0) -> 45777 | B28: Apr'25 | C28: =C69+C111+C152 -> 1.598189e+09 | D28: 79954589 | E28: 1.5102089e+09 | F28: 1140645654 | G28: 367121996 | H28: 2441637 | I28: =C28-E28-D28 -> 8025487.7 | J28: 2.6626716e+08 | K28: 8.7437849e+08 | L28: =C28-E28-D28 -> 8025487.7 | S28: Apr'25 | T28: =C28-AF28 -> 0 | U28: =D28-AG28 -> 0 | V28: =E28-AH28 -> 1.8500001 | W28: =F28-AI28 -> -5 | X28: =G28-AJ28 -> 0 | Y28: =H28-AK28 -> 0 | Z28: =I28-AL28 -> -1.8500001 | AA28: =J28-AM28 -> 38394.32 | ... AC28: =L28-AO28 -> -1.8500001 | AE28: Apr'25 | AF28: 1.598189e+09 | AG28: 79954589 | AH28: 1.5102089e+09 | AI28: 1140645659 | AJ28: 367121996 | AK28: 2441637 | AL28: 8025489.5 | AM28: 2.6622877e+08 | AN28: 8.7441689e+08 | AO28: 8025489.5
A29: =EOMONTH(A28+1,0) -> 45808 | B29: May'25 | C29: 1.9444494e+09 | D29: 79033925 | E29: 1.8609266e+09 | F29: 1370943432 | G29: 485635021 | H29: 4348425 | I29: =C29-E29-D29 -> 4488866.6 | J29: 3.3099024e+08 | K29: 1.0399532e+09 | L29: =C29-E29-D29 -> 4488866.6 | S29: May'25 | T29: =C29-AF29 -> 0 | U29: =D29-AG29 -> 0 | V29: =E29-AH29 -> 1003.25 | W29: =F29-AI29 -> 98994 | X29: =G29-AJ29 -> -99008 | Y29: =H29-AK29 -> 1000 | Z29: =I29-AL29 -> -1003.25 | AA29: =J29-AM29 -> 7938.8 | ... AC29: =L29-AO29 -> -1003.25 | AE29: May'25 | AF29: 1.9444494e+09 | AG29: 79033925 | AH29: 1.8609256e+09 | AI29: 1370844438 | AJ29: 485734029 | AK29: 4347425 | AL29: 4489869.8 | AM29: 3.3098231e+08 | AN29: 1.0398621e+09 | AO29: 4489869.8
A30: =EOMONTH(A29+1,0) -> 45838 | B30: Jun'25 | C30: 1.4722783e+09 | D30: 68830274 | E30: 1.400346e+09 | F30: 1099329815 | G30: 296353229 | H30: 4663369 | I30: =C30-E30-D30 -> 3102040.6 | J30: 2.6016832e+08 | K30: 8.391615e+08 | L30: =C30-E30-D30 -> 3102040.6 | S30: Jun'25 | T30: =C30-AF30 -> 0 | U30: =D30-AG30 -> 0 | V30: =E30-AH30 -> 3.0999997 | W30: =F30-AI30 -> -7 | X30: =G30-AJ30 -> 0 | Y30: =H30-AK30 -> 0 | Z30: =I30-AL30 -> -3.0999997 | AA30: =J30-AM30 -> 38481.14 | ... AC30: =L30-AO30 -> -3.0999997 | AE30: Jun'25 | AF30: 1.4722783e+09 | AG30: 68830274 | AH30: 1.400346e+09 | AI30: 1099329822 | AJ30: 296353229 | AK30: 4663369 | AL30: 3102043.7 | AM30: 2.6012984e+08 | AN30: 8.3919999e+08 | AO30: 3102043.7
A31: =EOMONTH(A30+1,0) -> 45869 | B31: Jul'25 | C31: 1.6257204e+09 | D31: 70900193 | E31: 1.5474905e+09 | F31: 1274543105 | G31: 262770133 | H31: 10177651 | I31: =C31-E31-D31 -> 7329688.9 | J31: 2.7430239e+08 | K31: 1.0002407e+09 | L31: =C31-E31-D31 -> 7329688.9 | S31: Jul'25 | T31: =C31-AF31 -> 0 | U31: =D31-AG31 -> 0 | V31: =E31-AH31 -> 1.9400001 | W31: =F31-AI31 -> -11 | X31: =G31-AJ31 -> 2 | Y31: =H31-AK31 -> 0 | Z31: =I31-AL31 -> -1.9400001 | AA31: =J31-AM31 -> 5055.33 | ... AC31: =L31-AO31 -> -1.9400001 | AE31: Jul'25 | AF31: 1.6257204e+09 | AG31: 70900193 | AH31: 1.5474905e+09 | AI31: 1274543116 | AJ31: 262770131 | AK31: 10177651 | AL31: 7329690.8 | AM31: 2.7429733e+08 | AN31: 1.0002458e+09 | AO31: 7329690.8
A32: =EOMONTH(A31+1,0) -> 45900 | B32: Aug'25 | C32: 1.4063328e+09 | D32: 61803640 | E32: 1.3332144e+09 | F32: 1102695131 | G32: 224969722 | H32: 5549969 | I32: =C32-E32-D32 -> 11314744 | J32: 3.1959171e+08 | K32: 7.8310343e+08 | L32: =C32-E32-D32 -> 11314744 | S32: Aug'25 | T32: =C32-AF32 -> 0 | U32: =D32-AG32 -> 0 | V32: =E32-AH32 -> 1.4799998 | W32: =F32-AI32 -> -2994 | X32: =G32-AJ32 -> -3 | Y32: =H32-AK32 -> 3000 | Z32: =I32-AL32 -> -1.4799998 | AA32: =J32-AM32 -> 32805.41 | ... AC32: =L32-AO32 -> -1.4799998 | AE32: Aug'25 | AF32: 1.4063328e+09 | AG32: 61803640 | AH32: 1.3332144e+09 | AI32: 1102698125 | AJ32: 224969725 | AK32: 5546969 | AL32: 11314746 | AM32: 3.195589e+08 | AN32: 7.8313922e+08 | AO32: 11314746
A33: =EOMONTH(A32+1,0) -> 45930 | B33: Sep'25 | C33: 1.4324796e+09 | D33: 67497164 | E33: 1.3531684e+09 | F33: 1061165347 | G33: 288019909 | H33: 3983562 | I33: =C33-E33-D33 -> 11814090 | J33: 2.6492628e+08 | K33: 7.9623907e+08 | L33: =C33-E33-D33 -> 11814090 | S33: Sep'25 | T33: =C33-AF33 -> 0 | U33: =D33-AG33 -> 0 | V33: =E33-AH33 -> 149973.68 | W33: =F33-AI33 -> 175258 | X33: =G33-AJ33 -> -25299 | Y33: =H33-AK33 -> 0 | Z33: =I33-AL33 -> -149973.68 | AA33: =J33-AM33 -> 41001.56 | ... AC33: =L33-AO33 -> -149973.68 | AE33: Sep'25 | AF33: 1.4324796e+09 | AG33: 67497164 | AH33: 1.3530184e+09 | AI33: 1060990089 | AJ33: 288045208 | AK33: 3983562 | AL33: 11964063 | AM33: 2.6488528e+08 | AN33: 7.9610481e+08 | AO33: 11964063
A34: =EOMONTH(A33+1,0) -> 45961 | B34: Oct'25 | C34: 1.5956937e+09 | D34: 67826211 | E34: 1.5148785e+09 | F34: 1230466877 | G34: 280841968 | H34: 3570199 | I34: =C34-E34-D34 -> 12988960 | J34: 3.3412961e+08 | K34: 8.9633726e+08 | L34: =C34-E34-D34 -> 12988960 | S34: Oct'25 | T34: =C34-AF34 -> 0 | U34: =D34-AG34 -> 0 | V34: =E34-AH34 -> 577315.9 | W34: =F34-AI34 -> 580017 | X34: =G34-AJ34 -> -2708 | Y34: =H34-AK34 -> 0 | Z34: =I34-AL34 -> -577315.9 | AA34: =J34-AM34 -> 451783.46 | ... AC34: =L34-AO34 -> -577315.9 | AE34: Oct'25 | AF34: 1.5956937e+09 | AG34: 67826211 | AH34: 1.5143012e+09 | AI34: 1229886860 | AJ34: 280844676 | AK34: 3570199 | AL34: 13566275 | AM34: 3.3367783e+08 | AN34: 8.9620903e+08 | AO34: 13566275
A35: =EOMONTH(A34+1,0) -> 45991 | B35: Nov'25 | C35: 1.3620788e+09 | D35: 52464720 | E35: 1.2916248e+09 | F35: 1053588885 | G35: 235254193 | H35: 2782147 | I35: =C35-E35-D35 -> 17989306 | J35: 2.9433599e+08 | K35: 7.5925289e+08 | L35: =C35-E35-D35 -> 17989306 | S35: Nov'25 | T35: =C35-AF35 -> 0 | U35: =D35-AG35 -> 0 | V35: =E35-AH35 -> 4001.1 | W35: =F35-AI35 -> 3004 | X35: =G35-AJ35 -> -12 | Y35: =H35-AK35 -> 1000 | Z35: =I35-AL35 -> -4001.1 | AA35: =J35-AM35 -> -97018.91 | ... AC35: =L35-AO35 -> -4001.1 | AE35: Nov'25 | AF35: 1.3620788e+09 | AG35: 52464720 | AH35: 1.2916208e+09 | AI35: 1053585881 | AJ35: 235254205 | AK35: 2781147 | AL35: 17993307 | AM35: 2.9443301e+08 | AN35: 7.5915287e+08 | AO35: 17993307
A36: =EOMONTH(A35+1,0) -> 46022 | B36: Dec'25 | C36: 1.4856029e+09 | D36: 64881016 | E36: 1.3928459e+09 | F36: 1108279233 | G36: 282002410 | H36: 2564664 | I36: =C36-E36-D36 -> 27875958 | J36: 4.0922581e+08 | K36: 6.9905342e+08 | L36: =C36-E36-D36 -> 27875958 | S36: Dec'25 | T36: =C36-AF36 -> 0 | U36: =D36-AG36 -> -1000775 | V36: =E36-AH36 -> 1000777.7 | W36: =F36-AI36 -> 1000777 | X36: =G36-AJ36 -> -5 | Y36: =H36-AK36 -> 0 | Z36: =I36-AL36 -> -2.7 | AA36: =J36-AM36 -> 1055460.6 | ... AC36: =L36-AO36 -> -2.7 | AE36: Dec'25 | AF36: 1.4856029e+09 | AG36: 65881791 | AH36: 1.3918451e+09 | AI36: 1107278456 | AJ36: 282002415 | AK36: 2564664 | AL36: 27875960 | AM36: 4.0817035e+08 | AN36: 6.9910811e+08 | AO36: 27875960
A37: =A36 -> 46022 | B37: 2026 Total | C37: =SUM(C38:C42) -> 5.1596519e+09 | D37: =SUM(D38:D42) -> 166812996 | E37: =SUM(E38:E42) -> 4.7048011e+09 | F37: =SUM(F38:F42) -> 3989466475 | G37: =SUM(G38:G42) -> 702267049 | H37: =SUM(H38:H42) -> 13069540 | I37: =SUM(I38:I42) -> 2.8803779e+08 | J37: =SUM(J38:J42) -> 1.1045567e+09 | ... L37: =SUM(L38:L42) -> 2.8803779e+08 | S37: 2026 Total | T37: =C37-AF37 -> 65971850 | U37: =D37-AG37 -> 1184486 | V37: =E37-AH37 -> 69233281 | W37: =F37-AI37 -> 63773400 | X37: =G37-AJ37 -> 5214699 | Y37: =H37-AK37 -> 245177 | Z37: =I37-AL37 -> -4445916.8 | AA37: =J37-AM37 -> 14611150 | ... AC37: =L37-AO37 -> -4445916.8 | AE37: 2026 Total | AF37: 5.09368e+09 | AG37: 165628510 | AH37: 4.6355678e+09 | AI37: 3925693075 | AJ37: 697052350 | AK37: 12824363 | AL37: 2.924837e+08 | AM37: 1.0899456e+09 | AN37: 2.8357475e+09 | AO37: 2.924837e+08
A38: =EOMONTH(A36+1,0) -> 46053 | B38: Jan'26 | C38: 1.4004564e+09 | D38: 60584218 | E38: 1.3173643e+09 | F38: 1083565209 | G38: 231454801 | H38: 2344798 | I38: =C38-E38-D38 -> 22507886 | J38: 3.0048129e+08 | K38: 7.8308392e+08 | L38: =C38-E38-D38 -> 22507886 | S38: Jan'26 | T38: =C38-AF38 -> 0 | U38: =D38-AG38 -> 0 | V38: =E38-AH38 -> 14000.96 | W38: =F38-AI38 -> 11990 | X38: =G38-AJ38 -> -3 | Y38: =H38-AK38 -> 2000 | Z38: =I38-AL38 -> -14000.96 | AA38: =J38-AM38 -> 32506.33 | ... AC38: =L38-AO38 -> -14000.96 | AE38: Jan'26 | AF38: 1.4004564e+09 | AG38: 60584218 | AH38: 1.3173503e+09 | AI38: 1083553219 | AJ38: 231454804 | AK38: 2342798 | AL38: 22521887 | AM38: 3.0044879e+08 | AN38: 7.8310443e+08 | AO38: 22521887
A39: =EOMONTH(A38+1,0) -> 46081 | B39: Feb'26 | C39: 1322812098 | D39: 58065532 | E39: 1.2443408e+09 | F39: 990560081 | G39: 251180015 | H39: 2601244 | I39: =C39-E39-D39 -> 20405766 | J39: 3.1116158e+08 | K39: 6.793985e+08 | L39: =C39-E39-D39 -> 20405766 | S39: Feb'26 | T39: =C39-AF39 -> 0 | U39: =D39-AG39 -> 0 | V39: =E39-AH39 -> 744666.87 | W39: =F39-AI39 -> 746632 | X39: =G39-AJ39 -> -1969 | Y39: =H39-AK39 -> 0 | Z39: =I39-AL39 -> -744666.87 | AA39: =J39-AM39 -> 346078.32 | ... AC39: =L39-AO39 -> -744666.87 | AE39: Feb'26 | AF39: 1322812098 | AG39: 58065532 | AH39: 1.2435961e+09 | AI39: 989813449 | AJ39: 251181984 | AK39: 2601244 | AL39: 21150433 | AM39: 3.108155e+08 | AN39: 6.7899795e+08 | AO39: 21150433
A40: =EOMONTH(A39+1,0) -> 46112 | B40: Mar'26 | C40: 9.2781305e+08 | D40: 25635088 | E40: 8.6900522e+08 | F40: 794213519 | G40: 73284054 | H40: 1508149 | I40: =C40-E40-D40 -> 33172743 | J40: 1.9859364e+08 | K40: 5.9561987e+08 | L40: =C40-E40-D40 -> 33172743 | S40: Mar'26 | T40: =C40-AF40 -> 0 | U40: =D40-AG40 -> 351 | V40: =E40-AH40 -> 195085.05 | W40: =F40-AI40 -> 172040 | X40: =G40-AJ40 -> -4 | Y40: =H40-AK40 -> 23045 | Z40: =I40-AL40 -> -195436.05 | AA40: =J40-AM40 -> 214903.6 | ... AC40: =L40-AO40 -> -195436.05 | AE40: Mar'26 | AF40: 9.2781305e+08 | AG40: 25634737 | AH40: 8.6881013e+08 | AI40: 794041479 | AJ40: 73284058 | AK40: 1485104 | AL40: 33368179 | AM40: 1.9837874e+08 | AN40: 5.9566274e+08 | AO40: 33368179
...

Sheet Dues Qrtwise
A2: Note | C2: Quarter and Monthwise dues Projectwise for last 3 quarters | U2: =IF(AND(ABS(F205-F231)<10,ABS(P205-P231)<10,ABS(K205-K231)<10,ABS(U205-U231)<10,ABS(Z205-Z231)<10,ABS(AE205-AE231)<10),"Ok") -> Ok
C4: 2025 | H4: 2025 | M4: 2025 | R4: 2025 | W4: 2026 | AB4: 2026
C5: =_xlfn.CONCAT("Dues-",C4,"'","Q1") -> Dues-2025'Q1 | H5: =_xlfn.CONCAT("Dues-",H4,"'","Q2") -> Dues-2025'Q2 | M5: =_xlfn.CONCAT("Dues-",M4,"'","Q3") -> Dues-2025'Q3 | R5: =_xlfn.CONCAT("Dues-",R4,"'","Q4") -> Dues-2025'Q4 | W5: =_xlfn.CONCAT("Dues-",W4,"'","Q1") -> Dues-2026'Q1 | AB5: =_xlfn.CONCAT("Dues-",AB4,"'","Q2") -> Dues-2026'Q2
A6: Project | C6: Jan | D6: Feb | E6: Mar | F6: Grand Total | H6: Apr | I6: May | J6: Jun | K6: Grand Total | M6: Jul | N6: Aug | O6: Sep | P6: Grand Total | R6: Oct | S6: Nov | T6: Dec | U6: Grand Total | W6: Jan | X6: Feb | Y6: Mar | Z6: Grand Total | AB6: Apr | AC6: May | AD6: Jun | AE6: Grand Total
A7: Greens | C7: =SUM(C8:C13) -> 0 | D7: =SUM(D8:D13) -> 4240 | E7: =SUM(E8:E13) -> 256042.16 | F7: =SUM(F8:F13) -> 260282.16 | H7: =SUM(H8:H13) -> 115199 | I7: =SUM(I8:I13) -> 667064.16 | J7: =SUM(J8:J13) -> 0 | K7: =SUM(K8:K13) -> 782263.16 | M7: =SUM(M8:M13) -> 0 | N7: =SUM(N8:N13) -> 96671 | O7: =SUM(O8:O13) -> 579436 | P7: =SUM(M7:O7) -> 676107 | R7: =SUM(R8:R13) -> 0 | S7: =SUM(S8:S13) -> 1206413 | T7: =SUM(T8:T13) -> 0 | U7: =SUM(R7:T7) -> 1206413 | W7: =SUM(W8:W13) -> 54196 | X7: =SUM(X8:X13) -> 155000 | Y7: =SUM(Y8:Y13) -> 98050.2 | Z7: =SUM(W7:Y7) -> 307246.2 | AB7: =SUM(AB8:AB13) -> 225 | AC7: =SUM(AC8:AC13) -> 0 | AD7: =SUM(AD8:AD13) -> 0 | AE7: =SUM(AB7:AD7) -> 225
A8: Phase I - Building 1 | C8: 0 | D8: 0 | E8: 0 | F8: =SUM(C8:E8) -> 0 | H8: 0 | I8: 0 | J8: 0 | K8: =SUM(H8:J8) -> 0 | M8: 0 | N8: 0 | O8: 0 | P8: =SUM(M8:O8) -> 0 | R8: 0 | S8: 0 | T8: 0 | U8: =SUM(R8:T8) -> 0 | W8: 50541 | X8: 0 | Y8: 0 | Z8: =SUM(W8:Y8) -> 50541 | AB8: 0 | AC8: 0 | AD8: 0 | AE8: =SUM(AB8:AD8) -> 0
A9: Phase I - Building 4 | C9: 0 | D9: 0 | E9: 0 | F9: =SUM(C9:E9) -> 0 | H9: 0 | I9: 0 | J9: 0 | K9: =SUM(H9:J9) -> 0 | M9: 0 | N9: 0 | O9: 0 | P9: =SUM(M9:O9) -> 0 | R9: 0 | S9: 0 | T9: 0 | U9: =SUM(R9:T9) -> 0 | W9: 0 | X9: 0 | Y9: 0 | Z9: =SUM(W9:Y9) -> 0 | AB9: 0 | AC9: 0 | AD9: 0 | AE9: =SUM(AB9:AD9) -> 0
A10: Phase II - Building 2 | C10: 0 | D10: 0 | E10: 0 | F10: =SUM(C10:E10) -> 0 | H10: 0 | I10: 119412.6 | J10: 0 | K10: =SUM(H10:J10) -> 119412.6 | M10: 0 | N10: 0 | O10: 0 | P10: =SUM(M10:O10) -> 0 | R10: 0 | S10: 119413 | T10: 0 | U10: =SUM(R10:T10) -> 119413 | W10: 0 | X10: 0 | Y10: 0 | Z10: =SUM(W10:Y10) -> 0 | AB10: 225 | AC10: 0 | AD10: 0 | AE10: =SUM(AB10:AD10) -> 225
A11: Phase II - Building 3 | C11: 0 | D11: 0 | E11: 0 | F11: =SUM(C11:E11) -> 0 | H11: 0 | I11: 0 | J11: 0 | K11: =SUM(H11:J11) -> 0 | M11: 0 | N11: 0 | O11: 0 | P11: =SUM(M11:O11) -> 0 | R11: 0 | S11: 1032000 | T11: 0 | U11: =SUM(R11:T11) -> 1032000 | W11: 125 | X11: 0 | Y11: 0 | Z11: =SUM(W11:Y11) -> 125 | AB11: 0 | AC11: 0 | AD11: 0 | AE11: =SUM(AB11:AD11) -> 0
A12: Phase III - Building 5 | C12: 0 | D12: 0 | E12: 75000 | F12: =SUM(C12:E12) -> 75000 | H12: 115199 | I12: 437651.56 | J12: 0 | K12: =SUM(H12:J12) -> 552850.56 | M12: 0 | N12: 41671 | O12: 579436 | P12: =SUM(M12:O12) -> 621107 | R12: 0 | S12: 0 | T12: 0 | U12: =SUM(R12:T12) -> 0 | W12: 3530 | X12: 0 | Y12: 2000 | Z12: =SUM(W12:Y12) -> 5530 | AB12: 0 | AC12: 0 | AD12: 0 | AE12: =SUM(AB12:AD12) -> 0
A13: Phase III - Building 6 | C13: 0 | D13: 4240 | E13: 181042.16 | F13: =SUM(C13:E13) -> 185282.16 | H13: 0 | I13: 110000 | J13: 0 | K13: =SUM(H13:J13) -> 110000 | M13: 0 | N13: 55000 | O13: 0 | P13: =SUM(M13:O13) -> 55000 | R13: 0 | S13: 55000 | T13: 0 | U13: =SUM(R13:T13) -> 55000 | W13: 0 | X13: 155000 | Y13: 96050.2 | Z13: =SUM(W13:Y13) -> 251050.2 | AB13: 0 | AC13: 0 | AD13: 0 | AE13: =SUM(AB13:AD13) -> 0
A14: One Park Avenue Tower | C14: 9281154.6 | D14: 3158465.3 | E14: 1068335.8 | F14: =SUM(C14:E14) -> 13507956 | H14: 356106 | I14: 28134 | J14: 0 | K14: =SUM(H14:J14) -> 384240 | M14: 195267 | N14: 189896.99 | O14: 18410 | P14: =SUM(M14:O14) -> 403573.99 | R14: 82858 | S14: 1194907.9 | T14: 855 | U14: =SUM(R14:T14) -> 1278620.9 | W14: 100000 | X14: 292553.54 | Y14: 44823.98 | Z14: =SUM(W14:Y14) -> 437377.52 | AB14: 29476.96 | AC14: 0 | AD14: 0 | AE14: =SUM(AB14:AD14) -> 29476.96
A15: Hartland 1 villas & townhouses | C15: =SUM(C16:C20) -> 5763438.7 | D15: =SUM(D16:D20) -> 11936678 | E15: =SUM(E16:E20) -> 6872161.9 | F15: =SUM(F16:F20) -> 24572278 | H15: =SUM(H16:H20) -> 8062315.9 | I15: =SUM(I16:I20) -> 13519210 | J15: =SUM(J16:J20) -> 12338230 | K15: =SUM(K16:K20) -> 33919757 | M15: =SUM(M16:M20) -> 5627191.1 | N15: =SUM(N16:N20) -> 78128.98 | O15: =SUM(O16:O20) -> 2473212 | P15: =SUM(M15:O15) -> 8178532.1 | R15: =SUM(R16:R20) -> 6649502.6 | S15: =SUM(S16:S20) -> 4956761 | T15: =SUM(T16:T20) -> 7676132 | U15: =SUM(R15:T15) -> 19282396 | W15: =SUM(W16:W20) -> 0 | X15: =SUM(X16:X20) -> 4500463 | Y15: =SUM(Y16:Y20) -> 5324087 | Z15: =SUM(W15:Y15) -> 9824550 | AB15: =SUM(AB16:AB20) -> 1500000 | AC15: =SUM(AC16:AC20) -> 1000000 | AD15: =SUM(AD16:AD20) -> 0 | AE15: =SUM(AB15:AD15) -> 2500000
A16: Townhouse | C16: 0 | D16: 0 | E16: 26864.98 | F16: =SUM(C16:E16) -> 26864.98 | H16: 3907.96 | I16: 0 | J16: 0 | K16: =SUM(H16:J16) -> 3907.96 | M16: 0 | N16: 3.98 | O16: 0 | P16: =SUM(M16:O16) -> 3.98 | R16: 0 | S16: 2668974 | T16: 0 | U16: =SUM(R16:T16) -> 2668974 | W16: 0 | X16: 0 | Y16: 0 | Z16: =SUM(W16:Y16) -> 0 | AB16: 0 | AC16: 0 | AD16: 0 | AE16: =SUM(AB16:AD16) -> 0
A17: Villas Phase I | C17: 250145 | D17: 196901 | E17: 156250 | F17: =SUM(C17:E17) -> 603296 | H17: 78125 | I17: 1242015 | J17: 153075 | K17: =SUM(H17:J17) -> 1473215 | M17: 78125 | N17: 78125 | O17: 78125 | P17: =SUM(M17:O17) -> 234375 | R17: 4409613 | S17: 0 | T17: 196357 | U17: =SUM(R17:T17) -> 4605970 | W17: 0 | X17: 0 | Y17: 0 | Z17: =SUM(W17:Y17) -> 0 | AB17: 0 | AC17: 0 | AD17: 0 | AE17: =SUM(AB17:AD17) -> 0
A18: Villas Phase II | C18: 179207 | D18: 0 | E18: 179207 | F18: =SUM(C18:E18) -> 358414 | H18: 0 | I18: 179207 | J18: 0 | K18: =SUM(H18:J18) -> 179207 | M18: 179207 | N18: 0 | O18: 179207 | P18: =SUM(M18:O18) -> 358414 | R18: 0 | S18: 179207 | T18: 0 | U18: =SUM(R18:T18) -> 179207 | W18: 0 | X18: 0 | Y18: 472250 | Z18: =SUM(W18:Y18) -> 472250 | AB18: 0 | AC18: 0 | AD18: 0 | AE18: =SUM(AB18:AD18) -> 0
A19: Villas Phase III | C19: 5334086.7 | D19: 11739777 | E19: 6509839.9 | F19: =SUM(C19:E19) -> 23583703 | H19: 5763397.7 | I19: 3455852.1 | J19: 12185155 | K19: =SUM(H19:J19) -> 21404405 | M19: 826159.71 | N19: 0 | O19: 2215880 | P19: =SUM(M19:O19) -> 3042039.7 | R19: 2239889 | S19: 2108580 | T19: 7479775 | U19: =SUM(R19:T19) -> 11828244 | W19: 0 | X19: 0 | Y19: 4851837 | Z19: =SUM(W19:Y19) -> 4851837 | AB19: 1500000 | AC19: 1000000 | AD19: 0 | AE19: =SUM(AB19:AD19) -> 2500000
A20: Villas Phase IV | C20: 0 | D20: 0 | E20: 0 | F20: =SUM(C20:E20) -> 0 | H20: 2216885.3 | I20: 8642136.4 | J20: 0 | K20: =SUM(H20:J20) -> 10859022 | M20: 4543699.4 | N20: 0 | O20: 0 | P20: =SUM(M20:O20) -> 4543699.4 | R20: 0.63 | S20: 0 | T20: 0 | U20: =SUM(R20:T20) -> 0.63 | W20: 0 | X20: 4500463 | Y20: 0 | Z20: =SUM(W20:Y20) -> 4500463 | AB20: 0 | AC20: 0 | AD20: 0 | AE20: =SUM(AB20:AD20) -> 0
A21: CV & CVR | C21: =SUM(C22:C25) -> 3328548.2 | D21: =SUM(D22:D25) -> 530578 | E21: =SUM(E22:E25) -> 3247305 | F21: =SUM(F22:F25) -> 7106431.3 | H21: =SUM(H22:H25) -> 6986459 | I21: =SUM(I22:I25) -> 1875044 | J21: =SUM(J22:J25) -> 2415929 | K21: =SUM(K22:K25) -> 11277432 | M21: =SUM(M22:M25) -> 771780 | N21: =SUM(N22:N25) -> 937739.2 | O21: =SUM(O22:O25) -> 1864847.6 | P21: =SUM(M21:O21) -> 3574366.8 | R21: =SUM(R22:R25) -> 414823.91 | S21: =SUM(S22:S25) -> 87394 | T21: =SUM(T22:T25) -> 50001 | U21: =SUM(R21:T21) -> 552218.91 | W21: =SUM(W22:W25) -> 362650 | X21: =SUM(X22:X25) -> 185239.11 | Y21: =SUM(Y22:Y25) -> 669604.79 | Z21: =SUM(W21:Y21) -> 1217493.9 | AB21: =SUM(AB22:AB25) -> 65369.73 | AC21: =SUM(AC22:AC25) -> 0 | AD21: =SUM(AD22:AD25) -> 0 | AE21: =SUM(AB21:AD21) -> 65369.73
A22: Creek vista reserve Tower A | C22: 1298479.2 | D22: 263505 | E22: 1425627.6 | F22: =SUM(C22:E22) -> 2987611.8 | H22: 3639254 | I22: 1014940 | J22: 1158951 | K22: =SUM(H22:J22) -> 5813145 | M22: 296020 | N22: 535412.2 | O22: 1043076.6 | P22: =SUM(M22:O22) -> 1874508.8 | R22: 105887.93 | S22: 37489 | T22: 0 | U22: =SUM(R22:T22) -> 143376.93 | W22: 341182 | X22: 173669.12 | Y22: 89444.94 | Z22: =SUM(W22:Y22) -> 604296.06 | AB22: 7086.75 | AC22: 0 | AD22: 0 | AE22: =SUM(AB22:AD22) -> 7086.75
A23: Creek vista reserve Tower B | C23: 930439.03 | D23: 37443 | E23: 516526.54 | F23: =SUM(C23:E23) -> 1484408.6 | H23: 3206426 | I23: 320000 | J23: 465878 | K23: =SUM(H23:J23) -> 3992304 | M23: 309110 | N23: 291273 | O23: 395432 | P23: =SUM(M23:O23) -> 995815 | R23: 94763.98 | S23: 49905 | T23: 50000 | U23: =SUM(R23:T23) -> 194668.98 | W23: 21468 | X23: 11564.99 | Y23: 322239.85 | Z23: =SUM(W23:Y23) -> 355272.84 | AB23: 43281.98 | AC23: 0 | AD23: 0 | AE23: =SUM(AB23:AD23) -> 43281.98
A24: Creek Vista Tower A | C24: 5680 | D24: 218630 | E24: 734354.95 | F24: =SUM(C24:E24) -> 958664.95 | H24: 0 | I24: 163905 | J24: 150000 | K24: =SUM(H24:J24) -> 313905 | M24: 450 | N24: 13904 | O24: 0 | P24: =SUM(M24:O24) -> 14354 | R24: 0 | S24: 0 | T24: 0 | U24: =SUM(R24:T24) -> 0 | W24: 0 | X24: 0 | Y24: 0 | Z24: =SUM(W24:Y24) -> 0 | AB24: 0 | AC24: 0 | AD24: 0 | AE24: =SUM(AB24:AD24) -> 0
A25: Creek vista Tower B | C25: 1093950 | D25: 11000 | E25: 570796 | F25: =SUM(C25:E25) -> 1675746 | H25: 140779 | I25: 376199 | J25: 641100 | K25: =SUM(H25:J25) -> 1158078 | M25: 166200 | N25: 97150 | O25: 426339 | P25: =SUM(M25:O25) -> 689689 | R25: 214172 | S25: 0 | T25: 1 | U25: =SUM(R25:T25) -> 214173 | W25: 0 | X25: 5 | Y25: 257920 | Z25: =SUM(W25:Y25) -> 257925 | AB25: 15001 | AC25: 0 | AD25: 0 | AE25: =SUM(AB25:AD25) -> 15001
A26: Waves | C26: 8886089.2 | D26: 16986582 | E26: 4108353 | F26: =SUM(C26:E26) -> 29981024 | H26: 2648499.3 | I26: 1448327 | J26: 678473 | K26: =SUM(H26:J26) -> 4775299.3 | M26: 1775897 | N26: 972249 | O26: 2802965 | P26: =SUM(M26:O26) -> 5551111 | R26: 895199 | S26: 247584 | T26: 1739713 | U26: =SUM(R26:T26) -> 2882496 | W26: 650565 | X26: 410458 | Y26: 63337 | Z26: =SUM(W26:Y26) -> 1124360 | AB26: 10000 | AC26: 0 | AD26: 0 | AE26: =SUM(AB26:AD26) -> 10000
A27: Waves Grande | C27: 1192929 | D27: 3128426.6 | E27: 9364394.7 | F27: =SUM(C27:E27) -> 13685750 | H27: 3641761.9 | I27: 1149443.1 | J27: 2447894.3 | K27: =SUM(H27:J27) -> 7239099.2 | M27: 1214693.8 | N27: 3756521.8 | O27: 7336471 | P27: =SUM(M27:O27) -> 12307687 | R27: 3231039 | S27: 911920 | T27: 1598750 | U27: =SUM(R27:T27) -> 5741709 | W27: 689374 | X27: 437290 | Y27: 132745 | Z27: =SUM(W27:Y27) -> 1259409 | AB27: 0 | AC27: 0 | AD27: 0 | AE27: =SUM(AB27:AD27) -> 0
A28: Hartland 1 plots | C28: =SUM(C29:C31) -> 416412 | D28: =SUM(D29:D31) -> 848945 | E28: =SUM(E29:E31) -> 2166186 | F28: =SUM(F29:F31) -> 3431543 | H28: =SUM(H29:H31) -> 3102819 | I28: =SUM(I29:I31) -> 1643912 | J28: =SUM(J29:J31) -> 338376 | K28: =SUM(K29:K31) -> 5085107 | M28: =SUM(M29:M31) -> 130000 | N28: =SUM(N29:N31) -> 413442 | O28: =SUM(O29:O31) -> 480024 | P28: =SUM(M28:O28) -> 1023466 | R28: =SUM(R29:R31) -> 2588008 | S28: =SUM(S29:S31) -> 361010 | T28: =SUM(T29:T31) -> 0 | U28: =SUM(R28:T28) -> 2949018 | W28: =SUM(W29:W31) -> 320704 | X28: =SUM(X29:X31) -> 66210 | Y28: =SUM(Y29:Y31) -> 215000 | Z28: =SUM(W28:Y28) -> 601914 | AB28: =SUM(AB29:AB31) -> 284195 | AC28: =SUM(AC29:AC31) -> 286551 | AD28: =SUM(AD29:AD31) -> 0 | AE28: =SUM(AB28:AD28) -> 570746
A29: Hartland Extension | C29: 351412 | D29: 362003 | E29: 215000 | F29: =SUM(C29:E29) -> 928415 | H29: 244007 | I29: 314548 | J29: 55008 | K29: =SUM(H29:J29) -> 613563 | M29: 130000 | N29: 331010 | O29: 330024 | P29: =SUM(M29:O29) -> 791034 | R29: 87008 | S29: 71010 | T29: 0 | U29: =SUM(R29:T29) -> 158018 | W29: 320704 | X29: 65000 | Y29: 75000 | Z29: =SUM(W29:Y29) -> 460704 | AB29: 114715 | AC29: 0 | AD29: 0 | AE29: =SUM(AB29:AD29) -> 114715
A30: Sobha Tranquility | C30: 0 | D30: 377202 | E30: 1816880 | F30: =SUM(C30:E30) -> 2194082 | H30: 292812 | I30: 1264364 | J30: 283368 | K30: =SUM(H30:J30) -> 1840544 | M30: 0 | N30: 67606 | O30: 150000 | P30: =SUM(M30:O30) -> 217606 | R30: 0 | S30: 290000 | T30: 0 | U30: =SUM(R30:T30) -> 290000 | W30: 0 | X30: 0 | Y30: 140000 | Z30: =SUM(W30:Y30) -> 140000 | AB30: 169480 | AC30: 286551 | AD30: 0 | AE30: =SUM(AB30:AD30) -> 456031
A31: Waterside Plots | C31: 65000 | D31: 109740 | E31: 134306 | F31: =SUM(C31:E31) -> 309046 | H31: 2566000 | I31: 65000 | J31: 0 | K31: =SUM(H31:J31) -> 2631000 | M31: 0 | N31: 14826 | O31: 0 | P31: =SUM(M31:O31) -> 14826 | R31: 2501000 | S31: 0 | T31: 0 | U31: =SUM(R31:T31) -> 2501000 | W31: 0 | X31: 1210 | Y31: 0 | Z31: =SUM(W31:Y31) -> 1210 | AB31: 0 | AC31: 0 | AD31: 0 | AE31: =SUM(AB31:AD31) -> 0
A32: Creek Vistas Grande | C32: 14209313 | D32: 14010321 | E32: 14236704 | F32: =SUM(C32:E32) -> 42456338 | H32: 17240377 | I32: 35783550 | J32: 9702908.1 | K32: =SUM(H32:J32) -> 62726835 | M32: 6592382.1 | N32: 4947511.2 | O32: 1746971.4 | P32: =SUM(M32:O32) -> 13286865 | R32: 7997354 | S32: 24172282 | T32: 5692035.5 | U32: =SUM(R32:T32) -> 37861672 | W32: 3658635.8 | X32: 953549.83 | Y32: 75955.36 | Z32: =SUM(W32:Y32) -> 4688141 | AB32: 5490419.4 | AC32: 11668189 | AD32: 0 | AE32: =SUM(AB32:AD32) -> 17158609
A33: Crest | C33: =SUM(C34:C38) -> 9562978.3 | D33: =SUM(D34:D38) -> 7781042.4 | E33: =SUM(E34:E38) -> 19120769 | F33: =SUM(F34:F38) -> 36464790 | H33: =SUM(H34:H38) -> 28466749 | I33: =SUM(I34:I38) -> 92873801 | J33: =SUM(J34:J38) -> 49919206 | K33: =SUM(K34:K38) -> 1.7125976e+08 | M33: =SUM(M34:M38) -> 31381060 | N33: =SUM(N34:N38) -> 29252315 | O33: =SUM(O34:O38) -> 6495020.9 | P33: =SUM(M33:O33) -> 67128396 | R33: =SUM(R34:R38) -> 54329700 | S33: =SUM(S34:S38) -> 91477179 | T33: =SUM(T34:T38) -> 19916384 | U33: =SUM(R33:T33) -> 1.6572326e+08 | W33: =SUM(W34:W38) -> 10908968 | X33: =SUM(X34:X38) -> 2985971.3 | Y33: =SUM(Y34:Y38) -> 1150887.3 | Z33: =SUM(W33:Y33) -> 15045826 | AB33: =SUM(AB34:AB38) -> 36019998 | AC33: =SUM(AC34:AC38) -> 33839599 | AD33: =SUM(AD34:AD38) -> 0 | AE33: =SUM(AB33:AD33) -> 69859597
A34: The Crest - A | C34: 4323807.9 | D34: 2709302.1 | E34: 4868389.1 | F34: =SUM(C34:E34) -> 11901499 | H34: 7350312.3 | I34: 56404639 | J34: 28019487 | K34: =SUM(H34:J34) -> 91774438 | M34: 13348727 | N34: 17213609 | O34: 2527214.7 | P34: =SUM(M34:O34) -> 33089551 | R34: 23860780 | S34: 25980037 | T34: 7842093 | U34: =SUM(R34:T34) -> 57682910 | W34: 4782294.3 | X34: 872566.95 | Y34: 635245.68 | Z34: =SUM(W34:Y34) -> 6290106.9 | AB34: 10720140 | AC34: 8870279.5 | AD34: 0 | AE34: =SUM(AB34:AD34) -> 19590420
A35: The crest - B | C35: 2338250 | D35: 2489376.7 | E35: 7861727.6 | F35: =SUM(C35:E35) -> 12689354 | H35: 11159000 | I35: 12586023 | J35: 5147249 | K35: =SUM(H35:J35) -> 28892272 | M35: 6962643.3 | N35: 6401496.5 | O35: 1270418.1 | P35: =SUM(M35:O35) -> 14634558 | R35: 15124507 | S35: 30471122 | T35: 5475210.8 | U35: =SUM(R35:T35) -> 51070839 | W35: 2720058.9 | X35: 1005460.5 | Y35: 150469.24 | Z35: =SUM(W35:Y35) -> 3875988.7 | AB35: 13260029 | AC35: 11798775 | AD35: 0 | AE35: =SUM(AB35:AD35) -> 25058804
A36: The crest - C | C36: 2025091.4 | D36: 2276487.4 | E36: 5999835.3 | F36: =SUM(C36:E36) -> 10301414 | H36: 9319221 | I36: 8320167.4 | J36: 9162466.9 | K36: =SUM(H36:J36) -> 26801855 | M36: 5778952.9 | N36: 1310199.1 | O36: 944568.21 | P36: =SUM(M36:O36) -> 8033720.1 | R36: 12342241 | S36: 24749075 | T36: 5535668 | U36: =SUM(R36:T36) -> 42626983 | W36: 3406614.5 | X36: 823830.63 | Y36: 337292.31 | Z36: =SUM(W36:Y36) -> 4567737.5 | AB36: 9024370.4 | AC36: 9426155.1 | AD36: 0 | AE36: =SUM(AB36:AD36) -> 18450526
A37: The crest - D | C37: 845828.88 | D37: 285876.22 | E37: 333128.92 | F37: =SUM(C37:E37) -> 1464834 | H37: 638215.94 | I37: 6871374.7 | J37: 5745240.5 | K37: =SUM(H37:J37) -> 13254831 | M37: 1599292 | N37: 2605509.2 | O37: 1752819.9 | P37: =SUM(M37:O37) -> 5957621.1 | R37: 3002172.2 | S37: 9996068.3 | T37: 1063412.5 | U37: =SUM(R37:T37) -> 14061653 | W37: 0 | X37: 275080.13 | Y37: 0.06 | Z37: =SUM(W37:Y37) -> 275080.19 | AB37: 3008755.2 | AC37: 3595500.7 | AD37: 0 | AE37: =SUM(AB37:AD37) -> 6604256
A38: The Crest - Retail | C38: 30000 | D38: 20000 | E38: 57687.98 | F38: =SUM(C38:E38) -> 107687.98 | H38: 0 | I38: 8691597 | J38: 1844762 | K38: =SUM(H38:J38) -> 10536359 | M38: 3691445 | N38: 1721501 | O38: 0 | P38: =SUM(M38:O38) -> 5412946 | R38: 0 | S38: 280877.1 | T38: 0 | U38: =SUM(R38:T38) -> 280877.1 | W38: 0 | X38: 9033 | Y38: 27880 | Z38: =SUM(W38:Y38) -> 36913 | AB38: 6703 | AC38: 148888.63 | AD38: 0 | AE38: =SUM(AB38:AD38) -> 155591.63
A39: The S | C39: 3690184 | D39: 91582.41 | E39: 2724317 | F39: =SUM(C39:E39) -> 6506083.4 | H39: 1.2551534e+08 | I39: 1.2857713e+08 | J39: 68467070 | K39: =SUM(H39:J39) -> 3.2255953e+08 | M39: 1.8595834e+08 | N39: 41539967 | O39: 34806321 | P39: =SUM(M39:O39) -> 2.6230463e+08 | R39: 3747817 | S39: 18561623 | T39: 7487138 | U39: =SUM(R39:T39) -> 29796578 | W39: 10796000 | X39: 23134624 | Y39: 52443.98 | Z39: =SUM(W39:Y39) -> 33983068 | AB39: 1478310 | AC39: 0 | AD39: 0 | AE39: =SUM(AB39:AD39) -> 1478310
A40: Sub Total (A) | C40: =SUM(C7,C14,C15,C21,C26,C27,C28,C32,C33,C39) -> 56331047 | D40: =SUM(D7,D14,D15,D21,D26,D27,D28,D32,D33,D39) -> 58476860 | E40: =SUM(E7,E14,E15,E21,E26,E27,E28,E32,E33,E39) -> 63164569 | F40: =SUM(F7,F14,F15,F21,F26,F27,F28,F32,F33,F39) -> 1.7797248e+08 | H40: =SUM(H7,H14,H15,H21,H26,H27,H28,H32,H33,H39) -> 1.9613562e+08 | I40: =SUM(I7,I14,I15,I21,I26,I27,I28,I32,I33,I39) -> 2.7756561e+08 | J40: =SUM(J7,J14,J15,J21,J26,J27,J28,J32,J33,J39) -> 1.4630809e+08 | K40: =SUM(K7,K14,K15,K21,K26,K27,K28,K32,K33,K39) -> 6.2000932e+08 | M40: =SUM(M7,M14,M15,M21,M26,M27,M28,M32,M33,M39) -> 2.3364661e+08 | N40: =SUM(N7,N14,N15,N21,N26,N27,N28,N32,N33,N39) -> 82184443 | O40: =SUM(O7,O14,O15,O21,O26,O27,O28,O32,O33,O39) -> 58603679 | P40: =SUM(P7,P14,P15,P21,P26,P27,P28,P32,P33,P39) -> 3.7443473e+08 | R40: =SUM(R7,R14,R15,R21,R26,R27,R28,R32,R33,R39) -> 79936301 | S40: =SUM(S7,S14,S15,S21,S26,S27,S28,S32,S33,S39) -> 1.4317707e+08 | T40: =SUM(T7,T14,T15,T21,T26,T27,T28,T32,T33,T39) -> 44161009 | U40: =SUM(U7,U14,U15,U21,U26,U27,U28,U32,U33,U39) -> 2.6727438e+08 | W40: =SUM(W7,W14,W15,W21,W26,W27,W28,W32,W33,W39) -> 27541093 | X40: =SUM(X7,X14,X15,X21,X26,X27,X28,X32,X33,X39) -> 33121359 | Y40: =SUM(Y7,Y14,Y15,Y21,Y26,Y27,Y28,Y32,Y33,Y39) -> 7826934.6 | Z40: =SUM(Z7,Z14,Z15,Z21,Z26,Z27,Z28,Z32,Z33,Z39) -> 68489386 | AB40: =SUM(AB7,AB14,AB15,AB21,AB26,AB27,AB28,AB32,AB33,AB39) -> 44877994 | AC40: =SUM(AC7,AC14,AC15,AC21,AC26,AC27,AC28,AC32,AC33,AC39) -> 46794339 | AD40: =SUM(AD7,AD14,AD15,AD21,AD26,AD27,AD28,AD32,AD33,AD39) -> 0 | AE40: =SUM(AE7,AE14,AE15,AE21,AE26,AE27,AE28,AE32,AE33,AE39) -> 91672333
A41: Crest Grande | C41: =SUM(C42:C45) -> 26770025 | D41: =SUM(D42:D45) -> 42707735 | E41: =SUM(E42:E45) -> 45780001 | F41: =SUM(F42:F45) -> 1.1525776e+08 | H41: =SUM(H42:H45) -> 34807965 | I41: =SUM(I42:I45) -> 22822336 | J41: =SUM(J42:J45) -> 11149288 | K41: =SUM(K42:K45) -> 68779589 | M41: =SUM(M42:M45) -> 12899007 | N41: =SUM(N42:N45) -> 13296760 | O41: =SUM(O42:O45) -> 9529948.7 | P41: =SUM(M41:O41) -> 35725716 | R41: =SUM(R42:R45) -> 3864275.2 | S41: =SUM(S42:S45) -> 2849679.6 | T41: =SUM(T42:T45) -> 2141580.3 | U41: =SUM(R41:T41) -> 8855535.2 | W41: =SUM(W42:W45) -> 1030572.8 | X41: =SUM(X42:X45) -> 4371303 | Y41: =SUM(Y42:Y45) -> 11759223 | Z41: =SUM(W41:Y41) -> 17161098 | AB41: =SUM(AB42:AB45) -> 42086358 | AC41: =SUM(AC42:AC45) -> 4704980.1 | AD41: =SUM(AD42:AD45) -> 0 | AE41: =SUM(AB41:AD41) -> 46791338
A42: Crest Grande - Tower A | C42: 12572236 | D42: 15630560 | E42: 14250615 | F42: =SUM(C42:E42) -> 42453411 | H42: 9036470 | I42: 6631803.8 | J42: 4584544.4 | K42: =SUM(H42:J42) -> 20252818 | M42: 4363670.2 | N42: 3404625.1 | O42: 3130581.9 | P42: =SUM(M42:O42) -> 10898877 | R42: 1652364.1 | S42: 1231493.1 | T42: 1133022.3 | U42: =SUM(R42:T42) -> 4016879.4 | W42: 86133.15 | X42: 3013134.9 | Y42: 2906105.2 | Z42: =SUM(W42:Y42) -> 6005373.3 | AB42: 12944028 | AC42: 1574652.6 | AD42: 0 | AE42: =SUM(AB42:AD42) -> 14518680
...

Sheet Dues summary
C1: Note | K1: =IF(AND(D40=D41,D75=D40,D110=D111,F40=D146),"Ok") -> Ok
C2: Overall dues collected, and categorization of the same in Booking amount dues( BA collected beyond 10% and after 30days) and non-Booking amount dues
C3: Dues collection from MS overdue aging (+/-)30 days, 30-60 days, 60-90 days and 90+ days
C4: New sales collection from aging 30 days, 30-60 days, 60-90 days and 90+ days from booking
C5: Booking amount (BA collected beyond 10% and after 30days) collection from aging 30-60 days, 60-90 days and 90+ days from booking
C7: =_xlfn.CONCAT("Dues collected - booking amount vs non booking amount") -> Dues collected - booking amount vs non booking amount
C8: Month | D8: Dues collected | E8: Non-BA dues | F8: BA dues(BA collected beyond 10% & after 30days) | G8: %non BA dues | H8: %BA dues
A9: 2024 | B9: Jan | C9: Jan'24 | D9: 3.9348861e+08 | E9: =D9-F9 -> 3.4560637e+08 | F9: 47882239 | G9: ='Dues summary'!$E9/'Dues summary'!$D9 -> 0.87831353 | H9: =F9/'Dues summary'!$D9 -> 0.12168647
A10: 2024 | B10: Feb | C10: Feb'24 | D10: 4.2273174e+08 | E10: =D10-F10 -> 3.8280434e+08 | F10: 39927400 | G10: ='Dues summary'!$E10/'Dues summary'!$D10 -> 0.90554908 | H10: =F10/'Dues summary'!$D10 -> 0.094450916
A11: 2024 | B11: Mar | C11: Mar'24 | D11: 4.0013361e+08 | E11: =D11-F11 -> 3.6206899e+08 | F11: 38064619 | G11: ='Dues summary'!$E11/'Dues summary'!$D11 -> 0.90487023 | H11: =F11/'Dues summary'!$D11 -> 0.095129772
A12: 2024 | B12: Apr | C12: Apr'24 | D12: 4.0558621e+08 | E12: =D12-F12 -> 3.5592049e+08 | F12: 49665719 | G12: ='Dues summary'!$E12/'Dues summary'!$D12 -> 0.87754584 | H12: =F12/'Dues summary'!$D12 -> 0.12245416
A13: 2024 | B13: May | C13: May'24 | D13: 4.6003455e+08 | E13: =D13-F13 -> 3.8867134e+08 | F13: 71363217 | G13: ='Dues summary'!$E13/'Dues summary'!$D13 -> 0.84487422 | H13: =F13/'Dues summary'!$D13 -> 0.15512578
A14: 2024 | B14: Jun | C14: Jun'24 | D14: 4.2251686e+08 | E14: =D14-F14 -> 3.8127393e+08 | F14: 41242932 | G14: ='Dues summary'!$E14/'Dues summary'!$D14 -> 0.90238749 | H14: =F14/'Dues summary'!$D14 -> 0.097612512
A15: 2024 | B15: Jul | C15: Jul'24 | D15: 4.6486046e+08 | E15: =D15-F15 -> 4.1675675e+08 | F15: 48103709 | G15: ='Dues summary'!$E15/'Dues summary'!$D15 -> 0.89652011 | H15: =F15/'Dues summary'!$D15 -> 0.10347989
A16: 2024 | B16: Aug | C16: Aug'24 | D16: 4.3990906e+08 | E16: =D16-F16 -> 4.0283924e+08 | F16: 37069818 | G16: ='Dues summary'!$E16/'Dues summary'!$D16 -> 0.915733 | H16: =F16/'Dues summary'!$D16 -> 0.084267003
A17: 2024 | B17: Sep | C17: Sep'24 | D17: 4.677721e+08 | E17: =D17-F17 -> 4.2843223e+08 | F17: 39339875 | G17: ='Dues summary'!$E17/'Dues summary'!$D17 -> 0.91589948 | H17: =F17/'Dues summary'!$D17 -> 0.084100515
A18: 2024 | B18: Oct | C18: Oct'24 | D18: 5.6875071e+08 | E18: =D18-F18 -> 5.3310419e+08 | F18: 35646524 | G18: ='Dues summary'!$E18/'Dues summary'!$D18 -> 0.93732487 | H18: =F18/'Dues summary'!$D18 -> 0.062675129
A19: 2024 | B19: Nov | C19: Nov'24 | D19: 5.5533906e+08 | E19: =D19-F19 -> 5.2646565e+08 | F19: 28873416 | G19: ='Dues summary'!$E19/'Dues summary'!$D19 -> 0.94800759 | H19: =F19/'Dues summary'!$D19 -> 0.05199241
A20: 2024 | B20: Dec | C20: Dec'24 | D20: 5.2502235e+08 | E20: =D20-F20 -> 4.9886535e+08 | F20: 26156998 | G20: ='Dues summary'!$E20/'Dues summary'!$D20 -> 0.95017927 | H20: =F20/'Dues summary'!$D20 -> 0.049820732
C21: 2024 Total | D21: =SUM(D9:D20) -> 5.5261453e+09 | E21: =SUM(E9:E20) -> 5.0228089e+09 | F21: =SUM(F9:F20) -> 503336466 | G21: ='Dues summary'!$E21/'Dues summary'!$D21 -> 0.90891726 | H21: =F21/'Dues summary'!$D21 -> 0.091082741
A22: 2025 | B22: Jan | C22: Jan'25 | D22: 6.0183038e+08 | E22: =D22-F22 -> 5.6516752e+08 | F22: 36662862 | G22: ='Dues summary'!$E22/'Dues summary'!$D22 -> 0.93908107 | H22: =F22/'Dues summary'!$D22 -> 0.060918929
A23: 2025 | B23: Feb | C23: Feb'25 | D23: 6.4576291e+08 | E23: =D23-F23 -> 6.2054103e+08 | F23: 25221879 | G23: ='Dues summary'!$E23/'Dues summary'!$D23 -> 0.96094251 | H23: =F23/'Dues summary'!$D23 -> 0.039057491
A24: 2025 | B24: Mar | C24: Mar'25 | D24: 6.7310827e+08 | E24: =D24-F24 -> 6.5117195e+08 | F24: 21936319 | G24: ='Dues summary'!$E24/'Dues summary'!$D24 -> 0.96741042 | H24: =F24/'Dues summary'!$D24 -> 0.032589585
A25: 2025 | B25: Apr | C25: Apr'25 | D25: 8.7437849e+08 | E25: =D25-F25 -> 8.4906462e+08 | F25: 25313867 | G25: ='Dues summary'!$E25/'Dues summary'!$D25 -> 0.9710493 | H25: =F25/'Dues summary'!$D25 -> 0.028950697
A26: 2025 | B26: May | C26: May'25 | D26: 1.0399532e+09 | E26: =D26-F26 -> 1.0169147e+09 | F26: 23038526 | G26: ='Dues summary'!$E26/'Dues summary'!$D26 -> 0.97784657 | H26: =F26/'Dues summary'!$D26 -> 0.022153426
A27: 2025 | B27: Jun | C27: Jun'25 | D27: 8.391615e+08 | E27: =D27-F27 -> 8.1670234e+08 | F27: 22459156 | G27: ='Dues summary'!$E27/'Dues summary'!$D27 -> 0.97323619 | H27: =F27/'Dues summary'!$D27 -> 0.026763807
A28: 2025 | B28: Jul | C28: Jul'25 | D28: 1.0002407e+09 | E28: =D28-F28 -> 9.8258962e+08 | F28: 17651093 | G28: ='Dues summary'!$E28/'Dues summary'!$D28 -> 0.98235315 | H28: =F28/'Dues summary'!$D28 -> 0.017646845
A29: 2025 | B29: Aug | C29: Aug'25 | D29: 7.8310343e+08 | E29: =D29-F29 -> 7.693344e+08 | F29: 13769028 | G29: ='Dues summary'!$E29/'Dues summary'!$D29 -> 0.98241736 | H29: =F29/'Dues summary'!$D29 -> 0.017582643
A30: 2025 | B30: Sep | C30: Sep'25 | D30: 7.9623907e+08 | E30: =D30-F30 -> 7.8331561e+08 | F30: 12923458 | G30: ='Dues summary'!$E30/'Dues summary'!$D30 -> 0.98376937 | H30: =F30/'Dues summary'!$D30 -> 0.016230625
A31: 2025 | B31: Oct | C31: Oct'25 | D31: 8.9633726e+08 | E31: =D31-F31 -> 8.8223345e+08 | F31: 14103811 | G31: ='Dues summary'!$E31/'Dues summary'!$D31 -> 0.98426506 | H31: =F31/'Dues summary'!$D31 -> 0.015734938
A32: 2025 | B32: Nov | C32: Nov'25 | D32: 7.5925289e+08 | E32: =D32-F32 -> 7.2587289e+08 | F32: 33380004 | G32: ='Dues summary'!$E32/'Dues summary'!$D32 -> 0.95603572 | H32: =F32/'Dues summary'!$D32 -> 0.043964276
A33: 2025 | B33: Dec | C33: Dec'25 | D33: 6.9905342e+08 | E33: =D33-F33 -> 6.8331663e+08 | F33: 15736798 | G33: ='Dues summary'!$E33/'Dues summary'!$D33 -> 0.97748842 | H33: =F33/'Dues summary'!$D33 -> 0.022511581
C34: 2025 Total | D34: =SUM(D22:D33) -> 9.6084215e+09 | E34: =SUM(E22:E33) -> 9.3462247e+09 | F34: =SUM(F22:F33) -> 262196801 | G34: ='Dues summary'!$E34/'Dues summary'!$D34 -> 0.97271177 | H34: =F34/'Dues summary'!$D34 -> 0.027288228
A35: 2026 | B35: Jan | C35: Jan'26 | D35: 7.8308392e+08 | E35: =D35-F35 -> 7.7429344e+08 | F35: 8790475 | G35: ='Dues summary'!$E35/'Dues summary'!$D35 -> 0.98877454 | H35: =F35/'Dues summary'!$D35 -> 0.011225457
A36: 2026 | B36: Feb | C36: Feb'26 | D36: 6.793985e+08 | E36: =D36-F36 -> 6.7009173e+08 | F36: 9306776 | G36: ='Dues summary'!$E36/'Dues summary'!$D36 -> 0.98630145 | H36: =F36/'Dues summary'!$D36 -> 0.013698552
A37: 2026 | B37: Mar | C37: Mar'26 | D37: 5.9561987e+08 | E37: =D37-F37 -> 5.887993e+08 | F37: 6820576 | G37: ='Dues summary'!$E37/'Dues summary'!$D37 -> 0.98854878 | H37: =F37/'Dues summary'!$D37 -> 0.011451223
A38: 2026 | B38: Apr | C38: Apr'26 | D38: 6.9987301e+08 | E38: =D38-F38 -> 6.9574525e+08 | F38: 4127760 | G38: ='Dues summary'!$E38/'Dues summary'!$D38 -> 0.99410213 | H38: =F38/'Dues summary'!$D38 -> 0.00589787
A39: 2026 | B39: May | C39: May'26 | D39: 1.2693444e+08 | E39: =D39-F39 -> 1.2662698e+08 | F39: 307454 | G39: ='Dues summary'!$E39/'Dues summary'!$D39 -> 0.99757785 | H39: =F39/'Dues summary'!$D39 -> 0.002422148
C40: Grand Total | D40: =D21+D34+D35+D36+D37+D38+D39 -> 1.8019477e+10 | E40: =E21+E34+E35+E36+E37+E38+E39 -> 1.722459e+10 | F40: =F21+F34+F35+F36+F37+F38+F39 -> 794886308 | G40: ='Dues summary'!$E40/'Dues summary'!$D40 -> 0.95588738 | H40: =F40/'Dues summary'!$D40 -> 0.044112619
D41: =SUM(Summary!K11,Summary!K24,Summary!K37) -> 1.8019477e+10
...

Sheet Dues summary SOBHA
C1: Note | K1: =IF(AND(D40=D41,D75=D40,D110=D111,F40=D146),"Ok") -> Ok
C2: Overall dues collected, and categorization of the same in Booking amount dues( BA collected beyond 10% and after 30days) and non-Booking amount dues
C3: Dues collection from MS overdue aging (+/-)30 days, 30-60 days, 60-90 days and 90+ days
C4: New sales collection from aging 30 days, 30-60 days, 60-90 days and 90+ days from booking
C5: Booking amount (BA collected beyond 10% and after 30days) collection from aging 30-60 days, 60-90 days and 90+ days from booking
C7: =_xlfn.CONCAT("Dues collected - booking amount vs non booking amount") -> Dues collected - booking amount vs non booking amount
C8: Month | D8: Dues collected | E8: Non-BA dues | F8: BA dues(BA collected beyond 10% & after 30days) | G8: %non BA dues | H8: %BA dues
A9: 2024 | B9: Jan | C9: Jan'24 | D9: 3.9348861e+08 | E9: =D9-F9 -> 3.4560637e+08 | F9: 47882239 | G9: ='Dues summary SOBHA'!$E9/'Dues summary SOBHA'!$D9 -> 0.87831353 | H9: =F9/'Dues summary SOBHA'!$D9 -> 0.12168647
A10: 2024 | B10: Feb | C10: Feb'24 | D10: 4.2273174e+08 | E10: =D10-F10 -> 3.8280434e+08 | F10: 39927400 | G10: ='Dues summary SOBHA'!$E10/'Dues summary SOBHA'!$D10 -> 0.90554908 | H10: =F10/'Dues summary SOBHA'!$D10 -> 0.094450916
A11: 2024 | B11: Mar | C11: Mar'24 | D11: 4.0013361e+08 | E11: =D11-F11 -> 3.6206899e+08 | F11: 38064619 | G11: ='Dues summary SOBHA'!$E11/'Dues summary SOBHA'!$D11 -> 0.90487023 | H11: =F11/'Dues summary SOBHA'!$D11 -> 0.095129772
A12: 2024 | B12: Apr | C12: Apr'24 | D12: 4.0558621e+08 | E12: =D12-F12 -> 3.5592049e+08 | F12: 49665719 | G12: ='Dues summary SOBHA'!$E12/'Dues summary SOBHA'!$D12 -> 0.87754584 | H12: =F12/'Dues summary SOBHA'!$D12 -> 0.12245416
A13: 2024 | B13: May | C13: May'24 | D13: 4.6003455e+08 | E13: =D13-F13 -> 3.8867134e+08 | F13: 71363217 | G13: ='Dues summary SOBHA'!$E13/'Dues summary SOBHA'!$D13 -> 0.84487422 | H13: =F13/'Dues summary SOBHA'!$D13 -> 0.15512578
A14: 2024 | B14: Jun | C14: Jun'24 | D14: 4.2251686e+08 | E14: =D14-F14 -> 3.8127393e+08 | F14: 41242932 | G14: ='Dues summary SOBHA'!$E14/'Dues summary SOBHA'!$D14 -> 0.90238749 | H14: =F14/'Dues summary SOBHA'!$D14 -> 0.097612512
A15: 2024 | B15: Jul | C15: Jul'24 | D15: 4.6486046e+08 | E15: =D15-F15 -> 4.1675675e+08 | F15: 48103709 | G15: ='Dues summary SOBHA'!$E15/'Dues summary SOBHA'!$D15 -> 0.89652011 | H15: =F15/'Dues summary SOBHA'!$D15 -> 0.10347989
A16: 2024 | B16: Aug | C16: Aug'24 | D16: 4.3947488e+08 | E16: =D16-F16 -> 4.0240507e+08 | F16: 37069818 | G16: ='Dues summary SOBHA'!$E16/'Dues summary SOBHA'!$D16 -> 0.91564975 | H16: =F16/'Dues summary SOBHA'!$D16 -> 0.084350254
A17: 2024 | B17: Sep | C17: Sep'24 | D17: 4.6490624e+08 | E17: =D17-F17 -> 4.2766058e+08 | F17: 37245660 | G17: ='Dues summary SOBHA'!$E17/'Dues summary SOBHA'!$D17 -> 0.91988565 | H17: =F17/'Dues summary SOBHA'!$D17 -> 0.080114348
A18: 2024 | B18: Oct | C18: Oct'24 | D18: 5.4281485e+08 | E18: =D18-F18 -> 5.1256981e+08 | F18: 30245036 | G18: ='Dues summary SOBHA'!$E18/'Dues summary SOBHA'!$D18 -> 0.94428112 | H18: =F18/'Dues summary SOBHA'!$D18 -> 0.055718881
A19: 2024 | B19: Nov | C19: Nov'24 | D19: 5.2030255e+08 | E19: =D19-F19 -> 5.0035727e+08 | F19: 19945278 | G19: ='Dues summary SOBHA'!$E19/'Dues summary SOBHA'!$D19 -> 0.961666 | H19: =F19/'Dues summary SOBHA'!$D19 -> 0.038334
A20: 2024 | B20: Dec | C20: Dec'24 | D20: 4.9950127e+08 | E20: =D20-F20 -> 4.822365e+08 | F20: 17264767 | G20: ='Dues summary SOBHA'!$E20/'Dues summary SOBHA'!$D20 -> 0.96543599 | H20: =F20/'Dues summary SOBHA'!$D20 -> 0.03456401
C21: 2024 Total | D21: =SUM(D9:D20) -> 5.4363518e+09 | E21: =SUM(E9:E20) -> 4.9583314e+09 | F21: =SUM(F9:F20) -> 478020394 | G21: ='Dues summary SOBHA'!$E21/'Dues summary SOBHA'!$D21 -> 0.91206964 | H21: =F21/'Dues summary SOBHA'!$D21 -> 0.087930364
A22: 2025 | B22: Jan | C22: Jan'25 | D22: 5.4009127e+08 | E22: =D22-F22 -> 5.1846846e+08 | F22: 21622813 | G22: ='Dues summary SOBHA'!$E22/'Dues summary SOBHA'!$D22 -> 0.95996452 | H22: =F22/'Dues summary SOBHA'!$D22 -> 0.040035479
A23: 2025 | B23: Feb | C23: Feb'25 | D23: 5.7927494e+08 | E23: =D23-F23 -> 5.6286271e+08 | F23: 16412221 | G23: ='Dues summary SOBHA'!$E23/'Dues summary SOBHA'!$D23 -> 0.97166765 | H23: =F23/'Dues summary SOBHA'!$D23 -> 0.028332351
A24: 2025 | B24: Mar | C24: Mar'25 | D24: 6.0232232e+08 | E24: =D24-F24 -> 5.8782693e+08 | F24: 14495391 | G24: ='Dues summary SOBHA'!$E24/'Dues summary SOBHA'!$D24 -> 0.97593416 | H24: =F24/'Dues summary SOBHA'!$D24 -> 0.024065837
A25: 2025 | B25: Apr | C25: Apr'25 | D25: 7.8262117e+08 | E25: =D25-F25 -> 7.6274809e+08 | F25: 19873077 | G25: ='Dues summary SOBHA'!$E25/'Dues summary SOBHA'!$D25 -> 0.97460703 | H25: =F25/'Dues summary SOBHA'!$D25 -> 0.025392971
A26: 2025 | B26: May | C26: May'25 | D26: 9.4735467e+08 | E26: =D26-F26 -> 9.3030237e+08 | F26: 17052300 | G26: ='Dues summary SOBHA'!$E26/'Dues summary SOBHA'!$D26 -> 0.98200009 | H26: =F26/'Dues summary SOBHA'!$D26 -> 0.017999911
A27: 2025 | B27: Jun | C27: Jun'25 | D27: 7.5397875e+08 | E27: =D27-F27 -> 7.3717363e+08 | F27: 16805118 | G27: ='Dues summary SOBHA'!$E27/'Dues summary SOBHA'!$D27 -> 0.97771142 | H27: =F27/'Dues summary SOBHA'!$D27 -> 0.022288583
A28: 2025 | B28: Jul | C28: Jul'25 | D28: 8.683614e+08 | E28: =D28-F28 -> 8.5499713e+08 | F28: 13364269 | G28: ='Dues summary SOBHA'!$E28/'Dues summary SOBHA'!$D28 -> 0.98460978 | H28: =F28/'Dues summary SOBHA'!$D28 -> 0.015390215
