Workbook
Name Ak: !#REF!
Name NOB: !#REF!
Name qwerty: #REF!
Name Source: !#REF!
Name SRCE: !#REF!
Name Style: !#REF!
Name TOS: !#REF!
Name Type: !#REF!
Name VLOOKUP: !#REF!

Sheet Summary
A1: Note: | B1: Month On month collections are shown
B2: Unidentified = Realised-Reg-Receipts | N2: 46148
B3: Receipts = New sale+Other charges+dues&adv
S4: Difference | AE4: Yesterday
B5: =_xlfn.CONCAT("Summary as on-",TEXT(N2,"DD/MM/YYYY")) -> Summary as on-06/05/2026 | S5: =B5 -> Summary as on-06/05/2026 | AE5: =CONCATENATE("Summary as on-",TEXT(TODAY()-3,"dd/mm/yyyy")) -> Summary as on-05/05/2026
B6: Year | C6: Total realised | D6: DLD | E6: Receipts total | F6: Dues + Advance collection | G6: New sale receipts | H6: Other charges | I6: Est. Unidentified | J6: Advance collection | K6: Dues collection | L6: Actual unidentifed | S6: Year | T6: Total realised | U6: DLD | V6: Receipts total | W6: Dues + Advance collection | X6: New sale receipts | Y6: Other charges | Z6: Est. Unidentified | AA6: Advance collection | AB6: Dues collection | AC6: Actual unidentifed | AE6: Year | AF6: Total realised | AG6: DLD | AH6: Receipts total | AI6: Dues + Advance collection | AJ6: New sale receipts | AK6: Other charges | AL6: Est. Unidentified | AM6: Advance collection | AN6: Dues collection | AO6: Actual unidentifed
A7: 44196 | B7: 2020 & Before | C7: =SUM(D7:E7) -> 1.7716423e+09 | D7: 64288549 | E7: 1.7073538e+09 | F7: 1274263635 | G7: 431100953 | H7: 1989377 | I7: =C7-E7-D7 -> 0 | J7: 3.3403115e+08 | K7: 9.4023249e+08 | L7: =C7-E7-D7 -> 0 | N7: =_xlfn.CONCAT("Values as on ",TEXT(N2,"dd-mm-yyyy")) -> Values as on 06-05-2026 | S7: 2020 & Before | T7: =C7-AF7 -> 0 | U7: =D7-AG7 -> 0 | V7: =E7-AH7 -> 0 | W7: =F7-AI7 -> -322590 | X7: =G7-AJ7 -> 322593 | Y7: =H7-AK7 -> 0 | Z7: =I7-AL7 -> 0 | AA7: =J7-AM7 -> -98.78 | ... AC7: =L7-AO7 -> 0 | AE7: 2020 & Before | AF7: 1.7716423e+09 | AG7: 64288549 | AH7: 1.7073538e+09 | AI7: 1274586225 | AJ7: 430778360 | AK7: 1989377 | AL7: 0 | AM7: 3.3403124e+08 | AN7: 9.4055498e+08 | AO7: 0
A8: 44561 | B8: 2021 Total | C8: 1698298327 | D8: 130078450 | E8: 1.5664545e+09 | F8: 866125495 | G8: 699134658 | H8: 1194387 | I8: =C8-E8-D8 -> 1765331.1 | J8: 2.1768337e+08 | K8: 6.4844212e+08 | L8: =C8-E8-D8 -> 1765331.1 | N8: Sobha | O8: 2.309767e+08 | P8: 1.1685699e+09 | Q8: =P8-O8 -> 9.3759316e+08 | S8: 2021 Total | T8: =C8-AF8 -> 0 | U8: =D8-AG8 -> 0 | V8: =E8-AH8 -> 0 | W8: =F8-AI8 -> -276 | X8: =G8-AJ8 -> 277 | Y8: =H8-AK8 -> 0 | Z8: =I8-AL8 -> 0 | AA8: =J8-AM8 -> 2559.66 | ... AC8: =L8-AO8 -> 0 | AE8: 2021 Total | AF8: 1698298327 | AG8: 130078450 | AH8: 1.5664545e+09 | AI8: 866125771 | AJ8: 699134381 | AK8: 1194387 | AL8: 1765331.1 | AM8: 2.1768081e+08 | AN8: 6.4844496e+08 | AO8: 1765331.1
A9: =EOMONTH(A8,12) -> 44926 | B9: 2022 Total | C9: 4272715411 | D9: 407978084 | E9: 3.8596445e+09 | F9: 2498323296 | G9: 1357599331 | H9: 3722293 | I9: =C9-E9-D9 -> 5092824.3 | J9: 8.1500144e+08 | K9: 1.6833219e+09 | L9: =C9-E9-D9 -> 5092824.3 | N9: Siniya | O9: 28868668 | P9: 1.7880593e+08 | Q9: =P9-O9 -> 1.4993727e+08 | S9: 2022 Total | T9: =C9-AF9 -> 0 | U9: =D9-AG9 -> 0 | V9: =E9-AH9 -> 0 | W9: =F9-AI9 -> -13731 | X9: =G9-AJ9 -> 13756 | Y9: =H9-AK9 -> 0 | Z9: =I9-AL9 -> 0 | AA9: =J9-AM9 -> -11567.82 | ... AC9: =L9-AO9 -> 0 | AE9: 2022 Total | AF9: 4272715411 | AG9: 407978084 | AH9: 3.8596445e+09 | AI9: 2498337027 | AJ9: 1357585575 | AK9: 3722293 | AL9: 5092824.3 | AM9: 8.1501301e+08 | AN9: 1.683324e+09 | AO9: 5092824.3
A10: =EOMONTH(A9,12) -> 45291 | B10: 2023 Total | C10: 7825770561 | D10: 637652517 | E10: 7.1731795e+09 | F10: 4692684807 | G10: 2467593381 | H10: 12901651 | I10: =C10-E10-D10 -> 14938503 | J10: 9.6426387e+08 | K10: 3.7284209e+09 | L10: =C10-E10-D10 -> 14938503 | N10: Downtown UAQ | O10: 5891204 | P10: 20322591 | Q10: =P10-O10 -> 14431387 | S10: 2023 Total | T10: =C10-AF10 -> 0 | U10: =D10-AG10 -> 0 | V10: =E10-AH10 -> 0 | W10: =F10-AI10 -> -338716 | X10: =G10-AJ10 -> 338717 | Y10: =H10-AK10 -> 0 | Z10: =I10-AL10 -> 0 | AA10: =J10-AM10 -> -15880.52 | ... AC10: =L10-AO10 -> 0 | AE10: 2023 Total | AF10: 7825770561 | AG10: 637652517 | AH10: 7.1731795e+09 | AI10: 4693023523 | AJ10: 2467254664 | AK10: 12901651 | AL10: 14938503 | AM10: 9.6427975e+08 | AN10: 3.7287438e+09 | AO10: 14938503
A11: 45291 | B11: 2024 Total | C11: =SUM(C12:C23) -> 1.0895088e+10 | D11: =SUM(D12:D23) -> 637969023 | E11: =SUM(E12:E23) -> 1.0211958e+10 | F11: =SUM(F12:F23) -> 6977755871 | G11: =SUM(G12:G23) -> 3215483679 | H11: =SUM(H12:H23) -> 18719302 | I11: =SUM(I12:I23) -> 45160940 | J11: =SUM(J12:J23) -> 1.4516105e+09 | K11: =SUM(K12:K23) -> 5.5261453e+09 | L11: =C11-E11-D11 -> 45160940 | N11: Abu Dhabi | O11: 18449471 | P11: =SUM(P8:P10) -> 1.3676984e+09 | S11: 2024 Total | T11: =C11-AF11 -> 0 | U11: =D11-AG11 -> 0 | V11: =E11-AH11 -> 73152.56 | W11: =F11-AI11 -> 467386 | X11: =G11-AJ11 -> -394228 | Y11: =H11-AK11 -> 0 | Z11: =I11-AL11 -> -73152.56 | AA11: =J11-AM11 -> 357154.53 | ... AC11: =L11-AO11 -> -73152.56 | AE11: 2024 Total | AF11: 1.0895088e+10 | AG11: 637969023 | AH11: 1.0211885e+10 | AI11: 6977288485 | AJ11: 3215877907 | AK11: 18719302 | AL11: 45234092 | AM11: 1.4512534e+09 | AN11: 5.5260351e+09 | AO11: 45234092
A12: 45322 | B12: Jan'24 | C12: 7.876635e+08 | D12: 51330740 | E12: 7.3222493e+08 | F12: 518398287 | G12: 212004087 | H12: 1822587 | I12: =C12-E12-D12 -> 4107824.9 | J12: 1.2490968e+08 | K12: 3.9348861e+08 | L12: =C12-E12-D12 -> 4107824.9 | N12: Total | O12: =SUM(O8:O11) -> 2.8418604e+08 | S12: Jan'24 | T12: =C12-AF12 -> 0 | U12: =D12-AG12 -> 0 | V12: =E12-AH12 -> 0 | W12: =F12-AI12 -> -5 | X12: =G12-AJ12 -> 2 | Y12: =H12-AK12 -> 0 | Z12: =I12-AL12 -> 0 | AA12: =J12-AM12 -> -1617.13 | ... AC12: =L12-AO12 -> 0 | AE12: Jan'24 | AF12: 7.876635e+08 | AG12: 51330740 | AH12: 7.3222493e+08 | AI12: 518398292 | AJ12: 212004085 | AK12: 1822587 | AL12: 4107824.9 | AM12: 1.249113e+08 | AN12: 3.9348699e+08 | AO12: 4107824.9
A13: =EOMONTH(A12+1,0) -> 45351 | B13: Feb'24 | C13: 8.4275091e+08 | D13: 62367891 | E13: 7.7412302e+08 | F13: 532780998 | G13: 238989502 | H13: 2352539 | I13: =C13-E13-D13 -> 6259995.4 | J13: 1.1004926e+08 | K13: 4.2273174e+08 | L13: =C13-E13-D13 -> 6259995.4 | S13: Feb'24 | T13: =C13-AF13 -> 0 | U13: =D13-AG13 -> 0 | V13: =E13-AH13 -> 0 | W13: =F13-AI13 -> 4 | X13: =G13-AJ13 -> 0 | Y13: =H13-AK13 -> 0 | Z13: =I13-AL13 -> 0 | AA13: =J13-AM13 -> -54997.29 | ... AC13: =L13-AO13 -> 0 | AE13: Feb'24 | AF13: 8.4275091e+08 | AG13: 62367891 | AH13: 7.7412302e+08 | AI13: 532780994 | AJ13: 238989502 | AK13: 2352539 | AL13: 6259995.4 | AM13: 1.1010426e+08 | AN13: 4.2267674e+08 | AO13: 6259995.4
A14: =EOMONTH(A13+1,0) -> 45382 | B14: Mar'24 | C14: 9.1567892e+08 | D14: 63072708 | E14: 8.4811473e+08 | F14: 520422396 | G14: 325507505 | H14: 2184784 | I14: =C14-E14-D14 -> 4491482 | J14: 1.2028879e+08 | K14: 4.0013361e+08 | L14: =C14-E14-D14 -> 4491482 | S14: Mar'24 | T14: =C14-AF14 -> 0 | U14: =D14-AG14 -> 0 | V14: =E14-AH14 -> 0 | W14: =F14-AI14 -> -3 | X14: =G14-AJ14 -> 1 | Y14: =H14-AK14 -> 0 | Z14: =I14-AL14 -> 0 | AA14: =J14-AM14 -> -9821.85 | ... AC14: =L14-AO14 -> 0 | AE14: Mar'24 | AF14: 9.1567892e+08 | AG14: 63072708 | AH14: 8.4811473e+08 | AI14: 520422399 | AJ14: 325507504 | AK14: 2184784 | AL14: 4491482 | AM14: 1.2029861e+08 | AN14: 4.0012379e+08 | AO14: 4491482
A15: =EOMONTH(A14+1,0) -> 45412 | B15: Apr'24 | C15: 7.9590015e+08 | D15: 55989228 | E15: 7.3625981e+08 | F15: 487717181 | G15: 247240968 | H15: 1301619 | I15: =C15-E15-D15 -> 3651108.2 | J15: 82130973 | K15: 4.0558621e+08 | L15: =C15-E15-D15 -> 3651108.2 | S15: Apr'24 | T15: =C15-AF15 -> 0 | U15: =D15-AG15 -> 0 | V15: =E15-AH15 -> 0 | W15: =F15-AI15 -> 420471 | X15: =G15-AJ15 -> -420468 | Y15: =H15-AK15 -> 0 | Z15: =I15-AL15 -> 0 | AA15: =J15-AM15 -> 419815.93 | ... AC15: =L15-AO15 -> 0 | AE15: Apr'24 | AF15: 7.9590015e+08 | AG15: 55989228 | AH15: 7.3625981e+08 | AI15: 487296710 | AJ15: 247661436 | AK15: 1301619 | AL15: 3651108.2 | AM15: 81711157 | AN15: 4.0558555e+08 | AO15: 3651108.2
A16: =EOMONTH(A15+1,0) -> 45443 | B16: May'24 | C16: 8.942952e+08 | D16: 66293170 | E16: 8.2675483e+08 | F16: 580599202 | G16: 243818421 | H16: 2337246 | I16: =C16-E16-D16 -> 1247194.7 | J16: 1.2056465e+08 | K16: 4.6003455e+08 | L16: =C16-E16-D16 -> 1247194.7 | S16: May'24 | T16: =C16-AF16 -> 0 | U16: =D16-AG16 -> 0 | V16: =E16-AH16 -> 0 | W16: =F16-AI16 -> 2 | X16: =G16-AJ16 -> 0 | Y16: =H16-AK16 -> 0 | Z16: =I16-AL16 -> 0 | AA16: =J16-AM16 -> 12688.09 | ... AC16: =L16-AO16 -> 0 | AE16: May'24 | AF16: 8.942952e+08 | AG16: 66293170 | AH16: 8.2675483e+08 | AI16: 580599200 | AJ16: 243818421 | AK16: 2337246 | AL16: 1247194.7 | AM16: 1.2055196e+08 | AN16: 4.6004724e+08 | AO16: 1247194.7
A17: =EOMONTH(A16+1,0) -> 45473 | B17: Jun'24 | C17: 7.4129294e+08 | D17: 43018017 | E17: 6.9636041e+08 | F17: 502657372 | G17: 192285683 | H17: 1417459 | I17: =C17-E17-D17 -> 1914511.4 | J17: 80140512 | K17: 4.2251686e+08 | L17: =C17-E17-D17 -> 1914511.4 | S17: Jun'24 | T17: =C17-AF17 -> 0 | U17: =D17-AG17 -> 0 | V17: =E17-AH17 -> 0 | W17: =F17-AI17 -> -6 | X17: =G17-AJ17 -> 2 | Y17: =H17-AK17 -> 0 | Z17: =I17-AL17 -> 0 | AA17: =J17-AM17 -> -12002.21 | ... AC17: =L17-AO17 -> 0 | AE17: Jun'24 | AF17: 7.4129294e+08 | AG17: 43018017 | AH17: 6.9636041e+08 | AI17: 502657378 | AJ17: 192285681 | AK17: 1417459 | AL17: 1914511.4 | AM17: 80152514 | AN17: 4.2250486e+08 | AO17: 1914511.4
A18: =EOMONTH(A17+1,0) -> 45504 | B18: Jul'24 | C18: 8.1709479e+08 | D18: 48059793 | E18: 7.6690817e+08 | F18: 571037984 | G18: 194700434 | H18: 1169899 | I18: =C18-E18-D18 -> 2126827 | J18: 1.0617752e+08 | K18: 4.6486046e+08 | L18: =C18-E18-D18 -> 2126827 | S18: Jul'24 | T18: =C18-AF18 -> 0 | U18: =D18-AG18 -> 0 | V18: =E18-AH18 -> 0.35000002 | W18: =F18-AI18 -> 7 | X18: =G18-AJ18 -> -3 | Y18: =H18-AK18 -> 0 | Z18: =I18-AL18 -> -0.35000002 | AA18: =J18-AM18 -> 6.22 | ... AC18: =L18-AO18 -> -0.35000002 | AE18: Jul'24 | AF18: 8.1709479e+08 | AG18: 48059793 | AH18: 7.6690817e+08 | AI18: 571037977 | AJ18: 194700437 | AK18: 1169899 | AL18: 2126827.3 | AM18: 1.0617752e+08 | AN18: 4.6486046e+08 | AO18: 2126827.3
A19: =EOMONTH(A18+1,0) -> 45535 | B19: Aug'24 | C19: 8.7325706e+08 | D19: 45030725 | E19: 8.2334793e+08 | F19: 574432824 | G19: 247529835 | H19: 1385453 | I19: =C19-E19-D19 -> 4878399.6 | J19: 1.3452376e+08 | K19: 4.3990906e+08 | L19: =C19-E19-D19 -> 4878399.6 | S19: Aug'24 | T19: =C19-AF19 -> 0 | U19: =D19-AG19 -> 0 | V19: =E19-AH19 -> -0.039999962 | W19: =F19-AI19 -> 9 | X19: =G19-AJ19 -> -3 | Y19: =H19-AK19 -> 0 | Z19: =I19-AL19 -> 0.039999962 | AA19: =J19-AM19 -> -14591.8 | ... AC19: =L19-AO19 -> 0.039999962 | AE19: Aug'24 | AF19: 8.7325706e+08 | AG19: 45030725 | AH19: 8.2334793e+08 | AI19: 574432815 | AJ19: 247529838 | AK19: 1385453 | AL19: 4878399.5 | AM19: 1.3453836e+08 | AN19: 4.3989446e+08 | AO19: 4878399.5
A20: =EOMONTH(A19+1,0) -> 45565 | B20: Sep'24 | C20: 8.971543e+08 | D20: 45977307 | E20: 8.4999415e+08 | F20: 583889163 | G20: 265105888 | H20: 999285 | I20: =C20-E20-D20 -> 1182838.8 | J20: 1.1611706e+08 | K20: 4.677721e+08 | L20: =C20-E20-D20 -> 1182838.8 | S20: Sep'24 | T20: =C20-AF20 -> 0 | U20: =D20-AG20 -> 0 | V20: =E20-AH20 -> 0.92000008 | W20: =F20-AI20 -> 402 | X20: =G20-AJ20 -> -402 | Y20: =H20-AK20 -> 0 | Z20: =I20-AL20 -> -0.92000008 | AA20: =J20-AM20 -> -4599.59 | ... AC20: =L20-AO20 -> -0.92000008 | AE20: Sep'24 | AF20: 8.971543e+08 | AG20: 45977307 | AH20: 8.4999415e+08 | AI20: 583888761 | AJ20: 265106290 | AK20: 999285 | AL20: 1182839.7 | AM20: 1.1612166e+08 | AN20: 4.677671e+08 | AO20: 1182839.7
A21: =EOMONTH(A20+1,0) -> 45596 | B21: Oct'24 | C21: 1.1078732e+09 | D21: 43325977 | E21: 1.0573714e+09 | F21: 732948378 | G21: 323373274 | H21: 1049902 | I21: =C21-E21-D21 -> 7175855.9 | J21: 1.6419767e+08 | K21: 5.6875071e+08 | L21: =C21-E21-D21 -> 7175855.9 | S21: Oct'24 | T21: =C21-AF21 -> 0 | U21: =D21-AG21 -> 0 | V21: =E21-AH21 -> 1454.43 | W21: =F21-AI21 -> 1438 | X21: =G21-AJ21 -> 12 | Y21: =H21-AK21 -> 0 | Z21: =I21-AL21 -> -1454.43 | AA21: =J21-AM21 -> -2747.79 | ... AC21: =L21-AO21 -> -1454.43 | AE21: Oct'24 | AF21: 1.1078732e+09 | AG21: 43325977 | AH21: 1.0573699e+09 | AI21: 732946940 | AJ21: 323373262 | AK21: 1049902 | AL21: 7177310.3 | AM21: 1.6420042e+08 | AN21: 5.6874652e+08 | AO21: 7177310.3
A22: =EOMONTH(A21+1,0) -> 45626 | B22: Nov'24 | C22: 1.1290055e+09 | D22: 56642195 | E22: 1.0685267e+09 | F22: 703279277 | G22: 363909082 | H22: 1338503 | I22: =C22-E22-D22 -> 3836633.5 | J22: 1.4794022e+08 | K22: 5.5533906e+08 | L22: =C22-E22-D22 -> 3836633.5 | S22: Nov'24 | T22: =C22-AF22 -> 0 | U22: =D22-AG22 -> 0 | V22: =E22-AH22 -> 64722.32 | W22: =F22-AI22 -> 38082 | X22: =G22-AJ22 -> 26637 | Y22: =H22-AK22 -> 0 | Z22: =I22-AL22 -> -64722.32 | AA22: =J22-AM22 -> -3766.1 | ... AC22: =L22-AO22 -> -64722.32 | AE22: Nov'24 | AF22: 1.1290055e+09 | AG22: 56642195 | AH22: 1.068462e+09 | AI22: 703241195 | AJ22: 363882445 | AK22: 1338503 | AL22: 3901355.9 | AM22: 1.4794398e+08 | AN22: 5.5529721e+08 | AO22: 3901355.9
A23: =EOMONTH(A22+1,0) -> 45657 | B23: Dec'24 | C23: 1.0931212e+09 | D23: 56861272 | E23: 1.0319716e+09 | F23: 669592809 | G23: 361019000 | H23: 1360026 | I23: =C23-E23-D23 -> 4288268.5 | J23: 1.4457046e+08 | K23: 5.2502235e+08 | L23: =C23-E23-D23 -> 4288268.5 | S23: Dec'24 | T23: =C23-AF23 -> 0 | U23: =D23-AG23 -> 0 | V23: =E23-AH23 -> 6974.58 | W23: =F23-AI23 -> 6985 | X23: =G23-AJ23 -> -6 | Y23: =H23-AK23 -> 0 | Z23: =I23-AL23 -> -6974.58 | AA23: =J23-AM23 -> 28788.05 | ... AC23: =L23-AO23 -> -6974.58 | AE23: Dec'24 | AF23: 1.0931212e+09 | AG23: 56861272 | AH23: 1.0319646e+09 | AI23: 669585824 | AJ23: 361019006 | AK23: 1360026 | AL23: 4295243.1 | AM23: 1.4454167e+08 | AN23: 5.2504415e+08 | AO23: 4295243.1
A24: =A23 -> 45657 | B24: 2025 Total | C24: =SUM(C25:C36) -> 1.7685139e+10 | D24: =SUM(D25:D36) -> 813260419 | E24: =SUM(E25:E36) -> 1.674614e+10 | F24: =SUM(F25:F36) -> 12876250831 | G24: =SUM(G25:G36) -> 3821295883 | H24: =SUM(H25:H36) -> 48597532 | I24: =SUM(I25:I36) -> 1.2573875e+08 | J24: =SUM(J25:J36) -> 3.2678293e+09 | K24: =SUM(K25:K36) -> 9.6084215e+09 | L24: =C24-E24-D24 -> 1.2573875e+08 | S24: 2025 Total | T24: =C24-AF24 -> 0 | U24: =D24-AG24 -> -1000775 | V24: =E24-AH24 -> 1733084.8 | W24: =F24-AI24 -> 1844233 | X24: =G24-AJ24 -> -126049 | Y24: =H24-AK24 -> 14799 | Z24: =I24-AL24 -> -732309.78 | AA24: =J24-AM24 -> 1552775.3 | ... AC24: =L24-AO24 -> -732309.78 | AE24: 2025 Total | AF24: 1.7685139e+10 | AG24: 814261194 | AH24: 1.6744407e+10 | AI24: 12874406598 | AJ24: 3821421932 | AK24: 48582733 | AL24: 1.2647106e+08 | AM24: 3.2662765e+09 | AN24: 9.6081301e+09 | AO24: 1.2647106e+08
A25: =EOMONTH(A23+1,0) -> 45688 | B25: Jan'25 | C25: 1.1804646e+09 | D25: 65721792 | E25: 1.109371e+09 | F25: 767307303 | G25: 338848056 | H25: 3215774 | I25: =C25-E25-D25 -> 5371812 | J25: 1.6547692e+08 | K25: 6.0183038e+08 | L25: =C25-E25-D25 -> 5371812 | S25: Jan'25 | T25: =C25-AF25 -> 0 | U25: =D25-AG25 -> 0 | V25: =E25-AH25 -> 1.47 | W25: =F25-AI25 -> -996 | X25: =G25-AJ25 -> 991 | Y25: =H25-AK25 -> 0 | Z25: =I25-AL25 -> -1.47 | AA25: =J25-AM25 -> 29439.62 | ... AC25: =L25-AO25 -> -1.47 | AE25: Jan'25 | AF25: 1.1804646e+09 | AG25: 65721792 | AH25: 1.109371e+09 | AI25: 767308299 | AJ25: 338847065 | AK25: 3215774 | AL25: 5371813.5 | AM25: 1.6544748e+08 | AN25: 6.0186081e+08 | AO25: 5371813.5
A26: =EOMONTH(A25+1,0) -> 45716 | B26: Feb'25 | C26: 1.25877e+09 | D26: 64905273 | E26: 1.1895738e+09 | F26: 808162069 | G26: 378552326 | H26: 2859574 | I26: =C26-E26-D26 -> 4291001.3 | J26: 1.6239916e+08 | K26: 6.4576291e+08 | L26: =C26-E26-D26 -> 4291001.3 | S26: Feb'25 | T26: =C26-AF26 -> 0 | U26: =D26-AG26 -> 0 | V26: =E26-AH26 -> 2.0900002 | W26: =F26-AI26 -> -9 | X26: =G26-AJ26 -> 0 | Y26: =H26-AK26 -> 0 | Z26: =I26-AL26 -> -2.0900002 | AA26: =J26-AM26 -> -39763.92 | ... AC26: =L26-AO26 -> -2.0900002 | AE26: Feb'25 | AF26: 1.25877e+09 | AG26: 64905273 | AH26: 1.1895738e+09 | AI26: 808162078 | AJ26: 378552326 | AK26: 2859574 | AL26: 4291003.4 | AM26: 1.6243892e+08 | AN26: 6.4572315e+08 | AO26: 4291003.4
A27: =EOMONTH(A26+1,0) -> 45747 | B27: Mar'25 | C27: =C68+C110 -> 1.3230797e+09 | D27: 69441622 | E27: 1.2424912e+09 | F27: 859123980 | G27: 380926920 | H27: 2440561 | I27: =C27-E27-D27 -> 11146795 | J27: 1.8601571e+08 | K27: 6.7310827e+08 | L27: =C27-E27-D27 -> 11146795 | S27: Mar'25 | T27: =C27-AF27 -> 0 | U27: =D27-AG27 -> 0 | V27: =E27-AH27 -> 1.22 | W27: =F27-AI27 -> -9795 | X27: =G27-AJ27 -> -7 | Y27: =H27-AK27 -> 9799 | Z27: =I27-AL27 -> -1.22 | AA27: =J27-AM27 -> -10802.19 | ... AC27: =L27-AO27 -> -1.22 | AE27: Mar'25 | AF27: 1.3230797e+09 | AG27: 69441622 | AH27: 1.2424912e+09 | AI27: 859133775 | AJ27: 380926927 | AK27: 2430762 | AL27: 11146796 | AM27: 1.8602652e+08 | AN27: 6.7310726e+08 | AO27: 11146796
A28: =EOMONTH(A27+1,0) -> 45777 | B28: Apr'25 | C28: =C69+C111+C152 -> 1.598189e+09 | D28: 79954589 | E28: 1.5102089e+09 | F28: 1140645654 | G28: 367121996 | H28: 2441637 | I28: =C28-E28-D28 -> 8025487.7 | J28: 2.6626716e+08 | K28: 8.7437849e+08 | L28: =C28-E28-D28 -> 8025487.7 | S28: Apr'25 | T28: =C28-AF28 -> 0 | U28: =D28-AG28 -> 0 | V28: =E28-AH28 -> 1.8500001 | W28: =F28-AI28 -> -5 | X28: =G28-AJ28 -> 0 | Y28: =H28-AK28 -> 0 | Z28: =I28-AL28 -> -1.8500001 | AA28: =J28-AM28 -> 38394.32 | ... AC28: =L28-AO28 -> -1.8500001 | AE28: Apr'25 | AF28: 1.598189e+09 | AG28: 79954589 | AH28: 1.5102089e+09 | AI28: 1140645659 | AJ28: 367121996 | AK28: 2441637 | AL28: 8025489.5 | AM28: 2.6622877e+08 | AN28: 8.7441689e+08 | AO28: 8025489.5
A29: =EOMONTH(A28+1,0) -> 45808 | B29: May'25 | C29: 1.9444494e+09 | D29: 79033925 | E29: 1.8609266e+09 | F29: 1370943432 | G29: 485635021 | H29: 4348425 | I29: =C29-E29-D29 -> 4488866.6 | J29: 3.3099024e+08 | K29: 1.0399532e+09 | L29: =C29-E29-D29 -> 4488866.6 | S29: May'25 | T29: =C29-AF29 -> 0 | U29: =D29-AG29 -> 0 | V29: =E29-AH29 -> 1003.25 | W29: =F29-AI29 -> 98994 | X29: =G29-AJ29 -> -99008 | Y29: =H29-AK29 -> 1000 | Z29: =I29-AL29 -> -1003.25 | AA29: =J29-AM29 -> 7938.8 | ... AC29: =L29-AO29 -> -1003.25 | AE29: May'25 | AF29: 1.9444494e+09 | AG29: 79033925 | AH29: 1.8609256e+09 | AI29: 1370844438 | AJ29: 485734029 | AK29: 4347425 | AL29: 4489869.8 | AM29: 3.3098231e+08 | AN29: 1.0398621e+09 | AO29: 4489869.8
A30: =EOMONTH(A29+1,0) -> 45838 | B30: Jun'25 | C30: 1.4722783e+09 | D30: 68830274 | E30: 1.400346e+09 | F30: 1099329815 | G30: 296353229 | H30: 4663369 | I30: =C30-E30-D30 -> 3102040.6 | J30: 2.6016832e+08 | K30: 8.391615e+08 | L30: =C30-E30-D30 -> 3102040.6 | S30: Jun'25 | T30: =C30-AF30 -> 0 | U30: =D30-AG30 -> 0 | V30: =E30-AH30 -> 3.0999997 | W30: =F30-AI30 -> -7 | X30: =G30-AJ30 -> 0 | Y30: =H30-AK30 -> 0 | Z30: =I30-AL30 -> -3.0999997 | AA30: =J30-AM30 -> 38481.14 | ... AC30: =L30-AO30 -> -3.0999997 | AE30: Jun'25 | AF30: 1.4722783e+09 | AG30: 68830274 | AH30: 1.400346e+09 | AI30: 1099329822 | AJ30: 296353229 | AK30: 4663369 | AL30: 3102043.7 | AM30: 2.6012984e+08 | AN30: 8.3919999e+08 | AO30: 3102043.7
A31: =EOMONTH(A30+1,0) -> 45869 | B31: Jul'25 | C31: 1.6257204e+09 | D31: 70900193 | E31: 1.5474905e+09 | F31: 1274543105 | G31: 262770133 | H31: 10177651 | I31: =C31-E31-D31 -> 7329688.9 | J31: 2.7430239e+08 | K31: 1.0002407e+09 | L31: =C31-E31-D31 -> 7329688.9 | S31: Jul'25 | T31: =C31-AF31 -> 0 | U31: =D31-AG31 -> 0 | V31: =E31-AH31 -> 1.9400001 | W31: =F31-AI31 -> -11 | X31: =G31-AJ31 -> 2 | Y31: =H31-AK31 -> 0 | Z31: =I31-AL31 -> -1.9400001 | AA31: =J31-AM31 -> 5055.33 | ... AC31: =L31-AO31 -> -1.9400001 | AE31: Jul'25 | AF31: 1.6257204e+09 | AG31: 70900193 | AH31: 1.5474905e+09 | AI31: 1274543116 | AJ31: 262770131 | AK31: 10177651 | AL31: 7329690.8 | AM31: 2.7429733e+08 | AN31: 1.0002458e+09 | AO31: 7329690.8
A32: =EOMONTH(A31+1,0) -> 45900 | B32: Aug'25 | C32: 1.4063328e+09 | D32: 61803640 | E32: 1.3332144e+09 | F32: 1102695131 | G32: 224969722 | H32: 5549969 | I32: =C32-E32-D32 -> 11314744 | J32: 3.1959171e+08 | K32: 7.8310343e+08 | L32: =C32-E32-D32 -> 11314744 | S32: Aug'25 | T32: =C32-AF32 -> 0 | U32: =D32-AG32 -> 0 | V32: =E32-AH32 -> 1.4799998 | W32: =F32-AI32 -> -2994 | X32: =G32-AJ32 -> -3 | Y32: =H32-AK32 -> 3000 | Z32: =I32-AL32 -> -1.4799998 | AA32: =J32-AM32 -> 32805.41 | ... AC32: =L32-AO32 -> -1.4799998 | AE32: Aug'25 | AF32: 1.4063328e+09 | AG32: 61803640 | AH32: 1.3332144e+09 | AI32: 1102698125 | AJ32: 224969725 | AK32: 5546969 | AL32: 11314746 | AM32: 3.195589e+08 | AN32: 7.8313922e+08 | AO32: 11314746
A33: =EOMONTH(A32+1,0) -> 45930 | B33: Sep'25 | C33: 1.4324796e+09 | D33: 67497164 | E33: 1.3531684e+09 | F33: 1061165347 | G33: 288019909 | H33: 3983562 | I33: =C33-E33-D33 -> 11814090 | J33: 2.6492628e+08 | K33: 7.9623907e+08 | L33: =C33-E33-D33 -> 11814090 | S33: Sep'25 | T33: =C33-AF33 -> 0 | U33: =D33-AG33 -> 0 | V33: =E33-AH33 -> 149973.68 | W33: =F33-AI33 -> 175258 | X33: =G33-AJ33 -> -25299 | Y33: =H33-AK33 -> 0 | Z33: =I33-AL33 -> -149973.68 | AA33: =J33-AM33 -> 41001.56 | ... AC33: =L33-AO33 -> -149973.68 | AE33: Sep'25 | AF33: 1.4324796e+09 | AG33: 67497164 | AH33: 1.3530184e+09 | AI33: 1060990089 | AJ33: 288045208 | AK33: 3983562 | AL33: 11964063 | AM33: 2.6488528e+08 | AN33: 7.9610481e+08 | AO33: 11964063
A34: =EOMONTH(A33+1,0) -> 45961 | B34: Oct'25 | C34: 1.5956937e+09 | D34: 67826211 | E34: 1.5148785e+09 | F34: 1230466877 | G34: 280841968 | H34: 3570199 | I34: =C34-E34-D34 -> 12988960 | J34: 3.3412961e+08 | K34: 8.9633726e+08 | L34: =C34-E34-D34 -> 12988960 | S34: Oct'25 | T34: =C34-AF34 -> 0 | U34: =D34-AG34 -> 0 | V34: =E34-AH34 -> 577315.9 | W34: =F34-AI34 -> 580017 | X34: =G34-AJ34 -> -2708 | Y34: =H34-AK34 -> 0 | Z34: =I34-AL34 -> -577315.9 | AA34: =J34-AM34 -> 451783.46 | ... AC34: =L34-AO34 -> -577315.9 | AE34: Oct'25 | AF34: 1.5956937e+09 | AG34: 67826211 | AH34: 1.5143012e+09 | AI34: 1229886860 | AJ34: 280844676 | AK34: 3570199 | AL34: 13566275 | AM34: 3.3367783e+08 | AN34: 8.9620903e+08 | AO34: 13566275
A35: =EOMONTH(A34+1,0) -> 45991 | B35: Nov'25 | C35: 1.3620788e+09 | D35: 52464720 | E35: 1.2916248e+09 | F35: 1053588885 | G35: 235254193 | H35: 2782147 | I35: =C35-E35-D35 -> 17989306 | J35: 2.9433599e+08 | K35: 7.5925289e+08 | L35: =C35-E35-D35 -> 17989306 | S35: Nov'25 | T35: =C35-AF35 -> 0 | U35: =D35-AG35 -> 0 | V35: =E35-AH35 -> 4001.1 | W35: =F35-AI35 -> 3004 | X35: =G35-AJ35 -> -12 | Y35: =H35-AK35 -> 1000 | Z35: =I35-AL35 -> -4001.1 | AA35: =J35-AM35 -> -97018.91 | ... AC35: =L35-AO35 -> -4001.1 | AE35: Nov'25 | AF35: 1.3620788e+09 | AG35: 52464720 | AH35: 1.2916208e+09 | AI35: 1053585881 | AJ35: 235254205 | AK35: 2781147 | AL35: 17993307 | AM35: 2.9443301e+08 | AN35: 7.5915287e+08 | AO35: 17993307
A36: =EOMONTH(A35+1,0) -> 46022 | B36: Dec'25 | C36: 1.4856029e+09 | D36: 64881016 | E36: 1.3928459e+09 | F36: 1108279233 | G36: 282002410 | H36: 2564664 | I36: =C36-E36-D36 -> 27875958 | J36: 4.0922581e+08 | K36: 6.9905342e+08 | L36: =C36-E36-D36 -> 27875958 | S36: Dec'25 | T36: =C36-AF36 -> 0 | U36: =D36-AG36 -> -1000775 | V36: =E36-AH36 -> 1000777.7 | W36: =F36-AI36 -> 1000777 | X36: =G36-AJ36 -> -5 | Y36: =H36-AK36 -> 0 | Z36: =I36-AL36 -> -2.7 | AA36: =J36-AM36 -> 1055460.6 | ... AC36: =L36-AO36 -> -2.7 | AE36: Dec'25 | AF36: 1.4856029e+09 | AG36: 65881791 | AH36: 1.3918451e+09 | AI36: 1107278456 | AJ36: 282002415 | AK36: 2564664 | AL36: 27875960 | AM36: 4.0817035e+08 | AN36: 6.9910811e+08 | AO36: 27875960
A37: =A36 -> 46022 | B37: 2026 Total | C37: =SUM(C38:C42) -> 5.1596519e+09 | D37: =SUM(D38:D42) -> 166812996 | E37: =SUM(E38:E42) -> 4.7048011e+09 | F37: =SUM(F38:F42) -> 3989466475 | G37: =SUM(G38:G42) -> 702267049 | H37: =SUM(H38:H42) -> 13069540 | I37: =SUM(I38:I42) -> 2.8803779e+08 | J37: =SUM(J38:J42) -> 1.1045567e+09 | ... L37: =SUM(L38:L42) -> 2.8803779e+08 | S37: 2026 Total | T37: =C37-AF37 -> 65971850 | U37: =D37-AG37 -> 1184486 | V37: =E37-AH37 -> 69233281 | W37: =F37-AI37 -> 63773400 | X37: =G37-AJ37 -> 5214699 | Y37: =H37-AK37 -> 245177 | Z37: =I37-AL37 -> -4445916.8 | AA37: =J37-AM37 -> 14611150 | ... AC37: =L37-AO37 -> -4445916.8 | AE37: 2026 Total | AF37: 5.09368e+09 | AG37: 165628510 | AH37: 4.6355678e+09 | AI37: 3925693075 | AJ37: 697052350 | AK37: 12824363 | AL37: 2.924837e+08 | AM37: 1.0899456e+09 | AN37: 2.8357475e+09 | AO37: 2.924837e+08
A38: =EOMONTH(A36+1,0) -> 46053 | B38: Jan'26 | C38: 1.4004564e+09 | D38: 60584218 | E38: 1.3173643e+09 | F38: 1083565209 | G38: 231454801 | H38: 2344798 | I38: =C38-E38-D38 -> 22507886 | J38: 3.0048129e+08 | K38: 7.8308392e+08 | L38: =C38-E38-D38 -> 22507886 | S38: Jan'26 | T38: =C38-AF38 -> 0 | U38: =D38-AG38 -> 0 | V38: =E38-AH38 -> 14000.96 | W38: =F38-AI38 -> 11990 | X38: =G38-AJ38 -> -3 | Y38: =H38-AK38 -> 2000 | Z38: =I38-AL38 -> -14000.96 | AA38: =J38-AM38 -> 32506.33 | ... AC38: =L38-AO38 -> -14000.96 | AE38: Jan'26 | AF38: 1.4004564e+09 | AG38: 60584218 | AH38: 1.3173503e+09 | AI38: 1083553219 | AJ38: 231454804 | AK38: 2342798 | AL38: 22521887 | AM38: 3.0044879e+08 | AN38: 7.8310443e+08 | AO38: 22521887
A39: =EOMONTH(A38+1,0) -> 46081 | B39: Feb'26 | C39: 1322812098 | D39: 58065532 | E39: 1.2443408e+09 | F39: 990560081 | G39: 251180015 | H39: 2601244 | I39: =C39-E39-D39 -> 20405766 | J39: 3.1116158e+08 | K39: 6.793985e+08 | L39: =C39-E39-D39 -> 20405766 | S39: Feb'26 | T39: =C39-AF39 -> 0 | U39: =D39-AG39 -> 0 | V39: =E39-AH39 -> 744666.87 | W39: =F39-AI39 -> 746632 | X39: =G39-AJ39 -> -1969 | Y39: =H39-AK39 -> 0 | Z39: =I39-AL39 -> -744666.87 | AA39: =J39-AM39 -> 346078.32 | ... AC39: =L39-AO39 -> -744666.87 | AE39: Feb'26 | AF39: 1322812098 | AG39: 58065532 | AH39: 1.2435961e+09 | AI39: 989813449 | AJ39: 251181984 | AK39: 2601244 | AL39: 21150433 | AM39: 3.108155e+08 | AN39: 6.7899795e+08 | AO39: 21150433
A40: =EOMONTH(A39+1,0) -> 46112 | B40: Mar'26 | C40: 9.2781305e+08 | D40: 25635088 | E40: 8.6900522e+08 | F40: 794213519 | G40: 73284054 | H40: 1508149 | I40: =C40-E40-D40 -> 33172743 | J40: 1.9859364e+08 | K40: 5.9561987e+08 | L40: =C40-E40-D40 -> 33172743 | S40: Mar'26 | T40: =C40-AF40 -> 0 | U40: =D40-AG40 -> 351 | V40: =E40-AH40 -> 195085.05 | W40: =F40-AI40 -> 172040 | X40: =G40-AJ40 -> -4 | Y40: =H40-AK40 -> 23045 | Z40: =I40-AL40 -> -195436.05 | AA40: =J40-AM40 -> 214903.6 | ... AC40: =L40-AO40 -> -195436.05 | AE40: Mar'26 | AF40: 9.2781305e+08 | AG40: 25634737 | AH40: 8.6881013e+08 | AI40: 794041479 | AJ40: 73284058 | AK40: 1485104 | AL40: 33368179 | AM40: 1.9837874e+08 | AN40: 5.9566274e+08 | AO40: 33368179
...

Sheet Trend (3)
M1: 0.55
B2: Overall | N2: Overall | AE2: Overall
A3: 2025 | B3: Collection OD | N3: Booksize and collections | AE3: NET OF BCC booksize and collections
A4: Month | B4: 0-30 | C4: 31-60 | D4: 61-90 | E4: 91-120 | F4: 121-180 | G4: 180+ | H4: Total Collection OD | I4: Upcoming MS till EOM | J4: EOM OD | K4: EOM Unidentified(Estimation) | L4: BOM Unidentified | M4: estimate dues unidentified(BOM) | N4: Total duebook (BOM) | O4: Estimated duebook net of unidentified(BOM) | P4: Booksize less than 30 days | Q4: Booksize 30+ days | R4: Booksize 60+ days | S4: Dues collected from 30 days | T4: Dues collected from 30+ days | U4: Dues collected from 60+ days | V4: % Dues collected from 30 days book | W4: % Dues collected from 30+days book | X4: % Dues collected from 60+days book | Y4: Due receipts | Z4: Due receipts+Dues unidentified | AA4: dues collected / book size | AB4: estimated dues collected / booksize estimated | AC4: Total duebook (S and Crest grande) | AD4: Total duebook (Crest ) | AE4: Total duebook (Net of BCC) | AF4: Estimated duebook net of bcc& net of unidentified(BOM) | AG4: Booksize less than 30 days(Crest+s) | AH4: Booksize 30+ days(Crest+S) | AI4: Booksize 60+ days(Crest+S) | AJ4: Net BCC Booksize less than 30 days | AK4: Net BCC Booksize 30+ days | AL4: Net BCC Booksize 60+ days | AM4: Dues collected from 30 days | AN4: Dues collected from 30+ days | AO4: Dues collected from 60+ days | AP4: % Dues collected from 30 days book | AQ4: % Dues collected from 30+days book | AR4: % Dues collected from 60+days book | AS4: Due receipts | AT4: Due receipts+Dues unidentified | AU4: dues collected / book size | AV4: estimated dues collected / booksize estimated | AX4: Current UIF
A5: Jan | B5: 1.9750269e+08 | C5: 1.8813813e+08 | D5: 66983201 | E5: 43572121 | F5: 89598233 | G5: 4.8953772e+08 | H5: 1.0753321e+09 | I5: 4.7192414e+08 | J5: =SUM(H5:I5)-SUM(S5:T5) -> 9.4542586e+08 | K5: =H6-J5 -> 1.8232154e+08 | L5: 2.9919289e+08 | M5: =L5*$M$1 -> 1.6455609e+08 | N5: =SUM(H5:I5) -> 1.5472562e+09 | O5: =$N5-$M5 -> 1.3827002e+09 | P5: =SUM($I5,$B5) -> 6.6942683e+08 | Q5: =SUM($C5:$G5) -> 8.7782941e+08 | R5: =SUM($D5:$G5) -> 6.8969128e+08 | S5: 4.2718535e+08 | T5: 1.7464503e+08 | U5: 92402395 | V5: =S5/P5 -> 0.63813598 | W5: =T5/Q5 -> 0.19895099 | X5: =U5/R5 -> 0.13397646 | Y5: =SUM(S5:T5) -> 6.0183038e+08 | Z5: =SUM(S5:T5)+MAX(0,$M$1*$AX5) -> 6.0478488e+08 | AA5: =Y5/N5 -> 0.3889662 | AB5: =Z5/O5 -> 0.43739409 | AE5: =N5-SUM(AC5:AD5) -> 1.5472562e+09 | AF5: =AE5-M5 -> 1.3827002e+09 | AJ5: =P5-AG5 -> 6.6942683e+08 | AK5: =Q5-AH5 -> 8.7782941e+08 | AL5: =R5-AI5 -> 6.8969128e+08 | AM5: 4.2718535e+08 | AN5: 1.7464503e+08 | AO5: 92402395 | AP5: =AM5/AJ5 -> 0.63813598 | AQ5: =AN5/AK5 -> 0.19895099 | AR5: =AO5/AL5 -> 0.13397646 | AS5: =SUM(AM5:AN5) -> 6.0183038e+08 | AT5: =SUM(AM5:AN5)+MAX(0,$M$1*$AX5) -> 6.0478488e+08 | AU5: =AS5/AE5 -> 0.3889662 | AV5: =AT5/AF5 -> 0.43739409 | AX5: =Summary!I25 -> 5371812
A6: Feb | B6: 2.2014518e+08 | C6: 1.3290834e+08 | D6: 1.2663043e+08 | E6: 50311983 | F6: 75956632 | G6: 5.2179484e+08 | H6: 1.1277474e+09 | I6: 6.1315333e+08 | J6: =SUM(H6:I6)-SUM(S6:T6) -> 1.0951378e+09 | K6: =H7-J6 -> 66217054 | L6: 3.4901138e+08 | M6: =L6*$M$1 -> 1.9195626e+08 | N6: =SUM(H6:I6) -> 1.7409007e+09 | O6: =$N6-$M6 -> 1.5489445e+09 | P6: =SUM($I6,$B6) -> 8.3329851e+08 | Q6: =SUM($C6:$G6) -> 9.0760222e+08 | R6: =SUM($D6:$G6) -> 7.7469389e+08 | S6: 4.9158957e+08 | T6: 1.5417334e+08 | U6: 1.0123325e+08 | V6: =S6/P6 -> 0.58993213 | W6: =T6/Q6 -> 0.16986884 | X6: =U6/R6 -> 0.13067517 | Y6: =SUM(S6:T6) -> 6.4576291e+08 | Z6: =SUM(S6:T6)+MAX(0,$M$1*$AX6) -> 6.4812296e+08 | AA6: =Y6/N6 -> 0.37093609 | AB6: =Z6/O6 -> 0.41842879 | AE6: =N6-SUM(AC6:AD6) -> 1.7409007e+09 | AF6: =AE6-M6 -> 1.5489445e+09 | AJ6: =P6-AG6 -> 8.3329851e+08 | AK6: =Q6-AH6 -> 9.0760222e+08 | AL6: =R6-AI6 -> 7.7469389e+08 | AM6: 4.9158957e+08 | AN6: 1.5417334e+08 | AO6: 1.0123325e+08 | AP6: =AM6/AJ6 -> 0.58993213 | AQ6: =AN6/AK6 -> 0.16986884 | AR6: =AO6/AL6 -> 0.13067517 | AS6: =SUM(AM6:AN6) -> 6.4576291e+08 | AT6: =SUM(AM6:AN6)+MAX(0,$M$1*$AX6) -> 6.4812296e+08 | AU6: =AS6/AE6 -> 0.37093609 | AV6: =AT6/AF6 -> 0.41842879 | AX6: =Summary!I26 -> 4291001.3
A7: Mar | B7: 3.6461216e+08 | C7: 1.5582921e+08 | D7: 1.0528535e+08 | E7: 1.36686e+08 | F7: 1.0255328e+08 | G7: 2.9638888e+08 | H7: 1.1613549e+09 | I7: 6.9006056e+08 | J7: =SUM(H7:I7)-SUM(S7:T7) -> 1.1783072e+09 | K7: =H8-J7 -> 1.03979e+08 | L7: 3.6585552e+08 | M7: =L7*$M$1 -> 2.0122054e+08 | N7: =SUM(H7:I7) -> 1.8514154e+09 | O7: =$N7-$M7 -> 1.6501949e+09 | P7: =SUM($I7,$B7) -> 1.0546727e+09 | Q7: =SUM($C7:$G7) -> 7.9674272e+08 | R7: =SUM($D7:$G7) -> 6.4091351e+08 | S7: 5.311499e+08 | T7: 1.4195837e+08 | U7: 81586111 | V7: =S7/P7 -> 0.50361585 | W7: =T7/Q7 -> 0.17817341 | X7: =U7/R7 -> 0.1272966 | Y7: =SUM(S7:T7) -> 6.7310827e+08 | Z7: =SUM(S7:T7)+MAX(0,$M$1*$AX7) -> 6.79239e+08 | AA7: =Y7/N7 -> 0.36356414 | AB7: =Z7/O7 -> 0.41161138 | AE7: =N7-SUM(AC7:AD7) -> 1.8514154e+09 | AF7: =AE7-M7 -> 1.6501949e+09 | AJ7: =P7-AG7 -> 1.0546727e+09 | AK7: =Q7-AH7 -> 7.9674272e+08 | AL7: =R7-AI7 -> 6.4091351e+08 | AM7: 5.311499e+08 | AN7: 1.4195837e+08 | AO7: 81586111 | AP7: =AM7/AJ7 -> 0.50361585 | AQ7: =AN7/AK7 -> 0.17817341 | AR7: =AO7/AL7 -> 0.1272966 | AS7: =SUM(AM7:AN7) -> 6.7310827e+08 | AT7: =SUM(AM7:AN7)+MAX(0,$M$1*$AX7) -> 6.79239e+08 | AU7: =AS7/AE7 -> 0.36356414 | AV7: =AT7/AF7 -> 0.41161138 | AX7: =Summary!I27 -> 11146795
A8: Apr | B8: 4.080878e+08 | C8: 2.2188921e+08 | D8: 99350205 | E8: 81719241 | F8: 1.5902441e+08 | G8: 3.1221532e+08 | H8: 1.2822862e+09 | I8: 1.3694941e+09 | J8: =SUM(H8:I8)-SUM(S8:T8) -> 1.7774017e+09 | K8: =H9-J8 -> 47742600 | L8: 4.8170444e+08 | M8: =L8*$M$1 -> 2.6493744e+08 | N8: =SUM(H8:I8) -> 2.6517802e+09 | O8: =$N8-$M8 -> 2.3868428e+09 | P8: =SUM($I8,$B8) -> 1.7775819e+09 | Q8: =SUM($C8:$G8) -> 8.7419838e+08 | R8: =SUM($D8:$G8) -> 6.5230917e+08 | S8: 7.1363222e+08 | T8: 1.6074627e+08 | U8: 84031968 | V8: =S8/P8 -> 0.40146237 | W8: =T8/Q8 -> 0.18387848 | X8: =U8/R8 -> 0.1288223 | Y8: =SUM(S8:T8) -> 8.7437849e+08 | Z8: =SUM(S8:T8)+MAX(0,$M$1*$AX8) -> 8.7879251e+08 | AA8: =Y8/N8 -> 0.32973264 | AB8: =Z8/O8 -> 0.36818198 | AC8: 6.1449621e+08 | AE8: =N8-SUM(AC8:AD8) -> 2.037284e+09 | AF8: =AE8-M8 -> 1.7723466e+09 | AG8: 6.1449621e+08 | AH8: 0 | AI8: 0 | AJ8: =P8-AG8 -> 1.1630857e+09 | AK8: =Q8-AH8 -> 8.7419838e+08 | AL8: =R8-AI8 -> 6.5230917e+08 | AM8: 5.8817858e+08 | AN8: 1.6068457e+08 | AO8: 83970273 | AP8: =AM8/AJ8 -> 0.5057053 | AQ8: =AN8/AK8 -> 0.1838079 | AR8: =AO8/AL8 -> 0.12872772 | AS8: =SUM(AM8:AN8) -> 7.4886315e+08 | AT8: =SUM(AM8:AN8)+MAX(0,$M$1*$AX8) -> 7.5327717e+08 | AU8: =AS8/AE8 -> 0.36757916 | AV8: =AT8/AF8 -> 0.42501685 | AX8: =Summary!I28 -> 8025487.7
A9: May | B9: 3.7205862e+08 | C9: 7.4225562e+08 | D9: 1.4569246e+08 | E9: 88755040 | F9: 1.3173374e+08 | G9: 3.4464886e+08 | H9: 1.8251443e+09 | I9: 8.537568e+08 | J9: =SUM(H9:I9)-SUM(S9:T9) -> 1.638948e+09 | K9: =H10-J9 -> 1.0970667e+08 | L9: 3.8001783e+08 | M9: =L9*$M$1 -> 2.0900981e+08 | N9: =SUM(H9:I9) -> 2.6789011e+09 | O9: =$N9-$M9 -> 2.4698913e+09 | P9: =SUM($I9,$B9) -> 1.2258154e+09 | Q9: =SUM($C9:$G9) -> 1.4530857e+09 | R9: =SUM($D9:$G9) -> 7.1083011e+08 | S9: 7.470931e+08 | T9: 2.9286009e+08 | U9: 1.1294309e+08 | V9: =S9/P9 -> 0.60946623 | W9: =T9/Q9 -> 0.20154357 | X9: =U9/R9 -> 0.15888901 | Y9: =SUM(S9:T9) -> 1.0399532e+09 | Z9: =SUM(S9:T9)+MAX(0,$M$1*$AX9) -> 1.0424221e+09 | AA9: =Y9/N9 -> 0.3882014 | AB9: =Z9/O9 -> 0.42205179 | AC9: 4.9731121e+08 | AD9: 2.499336e+08 | AE9: =N9-SUM(AC9:AD9) -> 1.9316563e+09 | AF9: =AE9-M9 -> 1.7226465e+09 | AG9: =3021.78000000026+216961946.79 -> 2.1696497e+08 | AH9: =495145716.35+9088610.67 -> 5.0423433e+08 | AI9: =2162467.08+23883041.33 -> 26045508 | AJ9: =P9-AG9 -> 1.0088504e+09 | AK9: =Q9-AH9 -> 9.488514e+08 | AL9: =R9-AI9 -> 6.847846e+08 | AM9: 6.3134968e+08 | AN9: 1.8715258e+08 | AO9: 1.0955097e+08 | AP9: =AM9/AJ9 -> 0.62581097 | AQ9: =AN9/AK9 -> 0.19724119 | AR9: =AO9/AL9 -> 0.15997873 | AS9: =SUM(AM9:AN9) -> 8.1850226e+08 | AT9: =SUM(AM9:AN9)+MAX(0,$M$1*$AX9) -> 8.2097114e+08 | AU9: =AS9/AE9 -> 0.42373079 | AV9: =AT9/AF9 -> 0.4765755 | AX9: =Summary!I29 -> 4488866.6
A10: Jun | B10: 4.5938398e+08 | C10: 5.5152926e+08 | D10: 1.4425143e+08 | E10: 1.023342e+08 | F10: 1.1722103e+08 | G10: 3.7393473e+08 | H10: 1.7486546e+09 | I10: 7.9927376e+08 | J10: =SUM(H10:I10)-SUM(S10:T10) -> 1.7087669e+09 | K10: =H11-J10 -> -8609025 | L10: 4.0788608e+08 | M10: =L10*$M$1 -> 2.2433734e+08 | N10: =SUM(H10:I10) -> 2.5479284e+09 | O10: =$N10-$M10 -> 2.3235911e+09 | P10: =SUM($I10,$B10) -> 1.2586577e+09 | Q10: =SUM($C10:$G10) -> 1.2892707e+09 | R10: =SUM($D10:$G10) -> 7.3774139e+08 | S10: 5.8301736e+08 | T10: 2.5614414e+08 | U10: 1.6057063e+08 | V10: =S10/P10 -> 0.46320564 | W10: =T10/Q10 -> 0.19867367 | X10: =U10/R10 -> 0.21765165 | Y10: =SUM(S10:T10) -> 8.391615e+08 | Z10: =SUM(S10:T10)+MAX(0,$M$1*$AX10) -> 8.4086762e+08 | AA10: =Y10/N10 -> 0.3293505 | AB10: =Z10/O10 -> 0.36188279 | AC10: 3.721904e+08 | AD10: 1.648869e+08 | AE10: =N10-SUM(AC10:AD10) -> 2.0108511e+09 | AF10: =AE10-M10 -> 1.7865138e+09 | AG10: =21003407.51+129637510.72 -> 1.5064092e+08 | AH10: =349060664.78+10237800.22 -> 359298465 | AI10: =2126331.54+25011584.94 -> 27137916 | AJ10: =P10-AG10 -> 1.1080168e+09 | AK10: =Q10-AH10 -> 9.2997219e+08 | AL10: =R10-AI10 -> 7.1060348e+08 | AM10: 5.7603104e+08 | AN10: 1.4474418e+08 | AO10: 87691786 | AP10: =AM10/AJ10 -> 0.51987571 | AQ10: =AN10/AK10 -> 0.15564356 | AR10: =AO10/AL10 -> 0.12340467 | AS10: =SUM(AM10:AN10) -> 7.2077522e+08 | AT10: =SUM(AM10:AN10)+MAX(0,$M$1*$AX10) -> 7.2248134e+08 | AU10: =AS10/AE10 -> 0.35844286 | AV10: =AT10/AF10 -> 0.4044085 | AX10: =Summary!I30 -> 3102040.6
A11: Jul | B11: 3.5226713e+08 | C11: 2.9009539e+08 | D11: 1.2335639e+08 | E11: 4.0705855e+08 | F11: 1.3785186e+08 | G11: 3.8952856e+08 | H11: 1.7001579e+09 | I11: 6.1122133e+08 | J11: =SUM(H11:I11)-SUM(S11:T11) -> 1.3111075e+09 | K11: =H12-J11 -> 2.0792059e+08 | L11: 4.0896562e+08 | M11: =L11*$M$1 -> 2.2493109e+08 | N11: =SUM(H11:I11) -> 2.3113792e+09 | O11: =$N11-$M11 -> 2.0864481e+09 | P11: =SUM($I11,$B11) -> 9.6348846e+08 | Q11: =SUM($C11:$G11) -> 1.3478907e+09 | R11: =SUM($D11:$G11) -> 1.0577954e+09 | S11: 6.3103822e+08 | T11: 3.6923349e+08 | U11: 3.0411035e+08 | V11: =S11/P11 -> 0.65495151 | W11: =T11/Q11 -> 0.27393429 | X11: =U11/R11 -> 0.2874945 | Y11: =SUM(S11:T11) -> 1.0002717e+09 | Z11: =SUM(S11:T11)+MAX(0,$M$1*$AX11) -> 1.004303e+09 | AA11: =Y11/N11 -> 0.43275968 | AB11: =Z11/O11 -> 0.4813458 | AC11: 2.93221e+08 | AD11: 1.0673233e+08 | AE11: =N11-SUM(AC11:AD11) -> 1.9114259e+09 | AF11: =AE11-M11 -> 1.6864948e+09 | AG11: =994+324445.18 -> 325439.18 | AH11: =10000000+77990412.19 -> 87990412 | AI11: =283220007.52+28417474.48 -> 311637482 | AJ11: =P11-AG11 -> 9.6316302e+08 | AK11: =Q11-AH11 -> 1.2599003e+09 | AL11: =R11-AI11 -> 7.4615787e+08 | AM11: 6.2695381e+08 | AN11: 1.5597851e+08 | AO11: 96075221 | AP11: =AM11/AJ11 -> 0.65093218 | AQ11: =AN11/AK11 -> 0.12380226 | AR11: =AO11/AL11 -> 0.12875991 | AS11: =SUM(AM11:AN11) -> 7.8293232e+08 | AT11: =SUM(AM11:AN11)+MAX(0,$M$1*$AX11) -> 7.8696365e+08 | AU11: =AS11/AE11 -> 0.40960642 | AV11: =AT11/AF11 -> 0.46662679 | AX11: =Summary!I31 -> 7329688.9
A12: Aug | B12: 3.2693599e+08 | C12: 2.0737839e+08 | D12: 1.9908244e+08 | E12: 98889819 | F12: 2.73483e+08 | G12: 4.1325844e+08 | H12: 1.5190281e+09 | I12: 6.9763963e+08 | J12: =SUM(H12:I12)-SUM(S12:T12) -> 1.4335643e+09 | K12: =H13-J12 -> 47468203 | L12: 3.3847418e+08 | M12: =L12*$M$1 -> 1.861608e+08 | N12: =SUM(H12:I12) -> 2.2166677e+09 | O12: =$N12-$M12 -> 2.0305069e+09 | P12: =SUM($I12,$B12) -> 1.0245756e+09 | Q12: =SUM($C12:$G12) -> 1.1920921e+09 | R12: =SUM($D12:$G12) -> 9.847137e+08 | S12: 5.7849042e+08 | T12: 2.04613e+08 | U12: 1.5585021e+08 | V12: =S12/P12 -> 0.56461467 | W12: =T12/Q12 -> 0.17164194 | X12: =U12/R12 -> 0.15826956 | Y12: =SUM(S12:T12) -> 7.8310343e+08 | Z12: =SUM(S12:T12)+MAX(0,$M$1*$AX12) -> 7.8932653e+08 | AA12: =Y12/N12 -> 0.35327957 | AB12: =Z12/O12 -> 0.38873373 | AD12: 77530380 | AE12: =N12-SUM(AC12:AD12) -> 2.1391373e+09 | AF12: =AE12-M12 -> 1.9529765e+09 | AG12: 12648.05 | AH12: 297360.53 | AI12: 77220371 | AJ12: =P12-AG12 -> 1.024563e+09 | AK12: =Q12-AH12 -> 1.1917947e+09 | AL12: =R12-AI12 -> 9.0749333e+08 | AM12: 5.7780063e+08 | AN12: 1.7605048e+08 | AO12: 1.2728768e+08 | AP12: =AM12/AJ12 -> 0.56394838 | AQ12: =AN12/AK12 -> 0.14771879 | AR12: =AO12/AL12 -> 0.14026294 | AS12: =SUM(AM12:AN12) -> 7.5385111e+08 | AT12: =SUM(AM12:AN12)+MAX(0,$M$1*$AX12) -> 7.6007422e+08 | AU12: =AS12/AE12 -> 0.35240894 | AV12: =AT12/AF12 -> 0.38918759 | AX12: =Summary!I32 -> 11314744
A13: Sep | B13: 3.3652354e+08 | C13: 1.7715028e+08 | D13: 1.5907112e+08 | E13: 1.3174042e+08 | F13: 2.3845331e+08 | G13: 4.3809382e+08 | H13: 1.4810325e+09 | I13: 8.0393985e+08 | J13: =SUM(H13:I13)-SUM(S13:T13) -> 1.4891241e+09 | K13: =H14-J13 -> -29010527 | L13: 3.5183468e+08 | M13: =L13*$M$1 -> 1.9350908e+08 | N13: =SUM(H13:I13) -> 2.2849723e+09 | O13: =$N13-$M13 -> 2.0914633e+09 | P13: =SUM($I13,$B13) -> 1.1404634e+09 | Q13: =SUM($C13:$G13) -> 1.1445089e+09 | R13: =SUM($D13:$G13) -> 9.6735867e+08 | S13: 6.3291246e+08 | T13: 1.6293578e+08 | U13: 1.0446746e+08 | V13: =S13/P13 -> 0.55496078 | W13: =T13/Q13 -> 0.14236305 | X13: =U13/R13 -> 0.10799248 | Y13: =SUM(S13:T13) -> 7.9584824e+08 | Z13: =SUM(S13:T13)+MAX(0,$M$1*$AX13) -> 8.0234599e+08 | AA13: =Y13/N13 -> 0.34829666 | AB13: =Z13/O13 -> 0.38362901 | AE13: =N13-SUM(AC13:AD13) -> 2.2849723e+09 | AF13: =AE13-M13 -> 2.0914633e+09 | AJ13: =P13-AG13 -> 1.1404634e+09 | AK13: =Q13-AH13 -> 1.1445089e+09 | AL13: =R13-AI13 -> 9.6735867e+08 | AM13: 6.3291246e+08 | AN13: 1.6293578e+08 | AO13: 1.0446746e+08 | AP13: =AM13/AJ13 -> 0.55496078 | AQ13: =AN13/AK13 -> 0.14236305 | AR13: =AO13/AL13 -> 0.10799248 | AS13: =SUM(AM13:AN13) -> 7.9584824e+08 | AT13: =SUM(AM13:AN13)+MAX(0,$M$1*$AX13) -> 8.0234599e+08 | AU13: =AS13/AE13 -> 0.34829666 | AV13: =AT13/AF13 -> 0.38362901 | AX13: =Summary!I33 -> 11814090
A14: Oct | B14: 3.3968387e+08 | C14: 1.7066968e+08 | D14: 1.3185689e+08 | E14: 1.1101921e+08 | F14: 2.0532186e+08 | G14: 5.0156207e+08 | H14: =SUM(B14:G14) -> 1.4601136e+09 | I14: 7.9287402e+08 | J14: =SUM(H14:I14)-SUM(S14:T14) -> 1.3567112e+09 | K14: =H15-J14 -> 1.2910854e+08 | L14: 3.5816486e+08 | M14: =L14*$M$1 -> 1.9699068e+08 | N14: =SUM(H14:I14) -> 2.2529876e+09 | O14: =$N14-$M14 -> 2.0559969e+09 | P14: =SUM($I14,$B14) -> 1.1325579e+09 | Q14: =SUM($C14:$G14) -> 1.1204297e+09 | R14: =SUM($D14:$G14) -> 9.4976002e+08 | S14: 6.8341737e+08 | T14: 2.1285906e+08 | U14: 1.4523326e+08 | V14: =S14/P14 -> 0.6034282 | W14: =T14/Q14 -> 0.18997985 | X14: =U14/R14 -> 0.15291574 | Y14: =SUM(S14:T14) -> 8.9627643e+08 | Z14: =SUM(S14:T14)+MAX(0,$M$1*$AX14) -> 9.0342036e+08 | AA14: =Y14/N14 -> 0.39781685 | AB14: =Z14/O14 -> 0.43940745 | AE14: =N14-SUM(AC14:AD14) -> 2.2529876e+09 | AF14: =AE14-M14 -> 2.0559969e+09 | AJ14: =P14-AG14 -> 1.1325579e+09 | AK14: =Q14-AH14 -> 1.1204297e+09 | AL14: =R14-AI14 -> 9.4976002e+08 | AM14: 6.8341737e+08 | AN14: 2.1285906e+08 | AO14: 1.4523326e+08 | AP14: =AM14/AJ14 -> 0.6034282 | AQ14: =AN14/AK14 -> 0.18997985 | AR14: =AO14/AL14 -> 0.15291574 | AS14: =SUM(AM14:AN14) -> 8.9627643e+08 | AT14: =SUM(AM14:AN14)+MAX(0,$M$1*$AX14) -> 9.0342036e+08 | AU14: =AS14/AE14 -> 0.39781685 | AV14: =AT14/AF14 -> 0.43940745 | AX14: =Summary!I34 -> 12988960
A15: Nov | B15: 2.6970305e+08 | C15: 2.6707562e+08 | D15: 1.223251e+08 | E15: 98442363 | F15: 1.808962e+08 | G15: 5.4737735e+08 | H15: =SUM(B15:G15) -> 1.4858197e+09 | I15: 7.7891503e+08 | J15: =SUM(H15:I15)-SUM(S15:T15) -> 1.505425e+09 | K15: =H16-J15 -> -5698218.2 | L15: 4.0606213e+08 | M15: =L15*$M$1 -> 2.2333417e+08 | N15: =SUM(H15:I15) -> 2.2647347e+09 | O15: =$N15-$M15 -> 2.0414006e+09 | P15: =SUM($I15,$B15) -> 1.0486181e+09 | Q15: =SUM($C15:$G15) -> 1.2161166e+09 | R15: =SUM($D15:$G15) -> 9.4904102e+08 | S15: 5.8594136e+08 | T15: 1.7336835e+08 | U15: 83873481 | V15: =S15/P15 -> 0.5587748 | W15: =T15/Q15 -> 0.14255898 | X15: =U15/R15 -> 0.088377087 | Y15: =SUM(S15:T15) -> 7.5930971e+08 | Z15: =SUM(S15:T15)+MAX(0,$M$1*$AX15) -> 7.6920383e+08 | AA15: =Y15/N15 -> 0.33527534 | AB15: =Z15/O15 -> 0.37680201 | AE15: =N15-SUM(AC15:AD15) -> 2.2647347e+09 | AF15: =AE15-M15 -> 2.0414006e+09 | AJ15: =P15-AG15 -> 1.0486181e+09 | AK15: =Q15-AH15 -> 1.2161166e+09 | AL15: =R15-AI15 -> 9.4904102e+08 | AM15: 5.8594136e+08 | AN15: 1.7336835e+08 | AO15: 83873481 | AP15: =AM15/AJ15 -> 0.5587748 | AQ15: =AN15/AK15 -> 0.14255898 | AR15: =AO15/AL15 -> 0.088377087 | AS15: =SUM(AM15:AN15) -> 7.5930971e+08 | AT15: =SUM(AM15:AN15)+MAX(0,$M$1*$AX15) -> 7.6920383e+08 | AU15: =AS15/AE15 -> 0.33527534 | AV15: =AT15/AF15 -> 0.37680201 | AX15: =Summary!I35 -> 17989306
A16: Dec | B16: 3.1053608e+08 | C16: 1.7412908e+08 | D16: 1.8232458e+08 | E16: 1.0594791e+08 | F16: 1.5193203e+08 | G16: 5.7485712e+08 | H16: =SUM(B16:G16) -> 1.4997268e+09 | I16: 7.372739e+08 | J16: =SUM(H16:I16)-SUM(S16:T16) -> 1.5379557e+09 | K16: =H17-J16 -> -1.5379557e+09 | L16: 4.6199005e+08 | M16: =L16*$M$1 -> 2.5409453e+08 | N16: =SUM(H16:I16) -> 2.2370007e+09 | O16: =$N16-$M16 -> 1.9829062e+09 | P16: =SUM($I16,$B16) -> 1.04781e+09 | Q16: =SUM($C16:$G16) -> 1.1891907e+09 | R16: =SUM($D16:$G16) -> 1.0150616e+09 | S16: 5.3503107e+08 | T16: 1.6401389e+08 | U16: 1.0377167e+08 | V16: =S16/P16 -> 0.51061842 | W16: =T16/Q16 -> 0.1379206 | X16: =U16/R16 -> 0.10223189 | Y16: =SUM(S16:T16) -> 6.9904497e+08 | Z16: =SUM(S16:T16)+MAX(0,$M$1*$AX16) -> 7.1437674e+08 | AA16: =Y16/N16 -> 0.31249207 | AB16: =Z16/O16 -> 0.36026755 | AE16: =N16-SUM(AC16:AD16) -> 2.2370007e+09 | AF16: =AE16-M16 -> 1.9829062e+09 | AG16: =AC16+AD16 -> 0 | AH16: 0 | AI16: 0 | AJ16: =P16-AG16 -> 1.04781e+09 | AK16: =Q16-AH16 -> 1.1891907e+09 | AL16: =R16-AI16 -> 1.0150616e+09 | AM16: 5.3503107e+08 | AN16: 1.6401389e+08 | AO16: 1.0377167e+08 | AP16: =AM16/AJ16 -> 0.51061842 | AQ16: =AN16/AK16 -> 0.1379206 | AR16: =AO16/AL16 -> 0.10223189 | AS16: =SUM(AM16:AN16) -> 6.9904497e+08 | AT16: =SUM(AM16:AN16)+MAX(0,$M$1*$AX16) -> 7.1437674e+08 | AU16: =AS16/AE16 -> 0.31249207 | AV16: =AT16/AF16 -> 0.36026755 | AX16: =Summary!I36 -> 27875958
B18: Overall | N18: Overall | AE18: Overall
A19: 2026 | B19: Collection OD | N19: Booksize and collections | AE19: NET OF BCC booksize and collections
A20: Month | B20: 0-30 | C20: 31-60 | D20: 61-90 | E20: 91-120 | F20: 121-180 | G20: 180+ | H20: Total Collection OD | I20: Upcoming MS till EOM | J20: EOM OD | K20: EOM Unidentified(Estimation) | L20: BOM Unidentified | M20: estimate dues unidentified(BOM) | N20: Total duebook (BOM) | O20: Estimated duebook net of unidentified(BOM) | P20: Booksize less than 30 days | Q20: Booksize 30+ days | R20: Booksize 60+ days | S20: Dues collected from 30 days | T20: Dues collected from 30+ days | U20: Dues collected from 60+ days | V20: % Dues collected from 30 days book | W20: % Dues collected from 30+days book | X20: % Dues collected from 60+days book | Y20: Due receipts | Z20: Due receipts+Dues unidentified | AA20: dues collected / book size | AB20: estimated dues collected / booksize estimated | AC20: Total duebook (S and Crest grande) | AD20: Total duebook (Crest ) | AE20: Total duebook (Net of BCC) | AF20: Estimated duebook net of bcc& net of unidentified(BOM) | AG20: Booksize less than 30 days(Crest+s) | AH20: Booksize 30+ days(Crest+S) | AI20: Booksize 60+ days(Crest+S) | AJ20: Net BCC Booksize less than 30 days | AK20: Net BCC Booksize 30+ days | AL20: Net BCC Booksize 60+ days | AM20: Dues collected from 30 days | AN20: Dues collected from 30+ days | AO20: Dues collected from 60+ days | AP20: % Dues collected from 30 days book | AQ20: % Dues collected from 30+days book | AR20: % Dues collected from 60+days book | AS20: Due receipts | AT20: Due receipts+Dues unidentified | AU20: dues collected / book size | AV20: estimated dues collected / booksize estimated | AX20: Current UIF
A21: Jan | B21: 3.0562124e+08 | C21: =135583166.97-8225540 -> 1.2735763e+08 | D21: 1.4589042e+08 | E21: =160971832.04-25351475 -> 1.3562036e+08 | F21: 1.569749e+08 | G21: =577975134.52-75281821 -> 5.0269331e+08 | H21: =SUM(B21:G21) -> 1.3741579e+09 | I21: 9.2200347e+08 | J21: =SUM(H21:I21)-SUM(S21:T21) -> 1.5130859e+09 | K21: =H22-J21 -> -90618907 | L21: 5.0823231e+08 | M21: =L21*$M$1 -> 2.7952777e+08 | N21: =SUM(H21:I21) -> 2.2961613e+09 | O21: =$N21-$M21 -> 2.0166336e+09 | P21: =SUM($I21,$B21) -> 1.2276247e+09 | Q21: =SUM($C21:$G21) -> 1.0685366e+09 | R21: =SUM($D21:$G21) -> 9.4117899e+08 | S21: 6.2975819e+08 | T21: 1.5331726e+08 | U21: 1.1259468e+08 | V21: =S21/P21 -> 0.51298918 | W21: =T21/Q21 -> 0.1434834 | X21: =U21/R21 -> 0.11963153 | Y21: =SUM(S21:T21) -> 7.8307546e+08 | Z21: =SUM(S21:T21)+MAX(0,$M$1*$AX21) -> 7.9545479e+08 | AA21: =Y21/N21 -> 0.34103678 | AB21: =Z21/O21 -> 0.39444687 | AE21: =N21-SUM(AC21:AD21) -> 2.2961613e+09 | AF21: =AE21-M21 -> 2.0166336e+09 | AJ21: =P21-AG21 -> 1.2276247e+09 | AK21: =Q21-AH21 -> 1.0685366e+09 | AL21: =R21-AI21 -> 9.4117899e+08 | AM21: 6.2975819e+08 | AN21: 1.5331726e+08 | AO21: 1.1259468e+08 | AP21: =AM21/AJ21 -> 0.51298918 | AQ21: =AN21/AK21 -> 0.1434834 | AR21: =AO21/AL21 -> 0.11963153 | AS21: =SUM(AM21:AN21) -> 7.8307546e+08 | AT21: =SUM(AM21:AN21)+MAX(0,$M$1*$AX21) -> 7.9545479e+08 | AU21: =AS21/AE21 -> 0.34103678 | AV21: =AT21/AF21 -> 0.39444687 | AX21: =Summary!I38 -> 22507886
A22: Feb | B22: =511219008.49-185965093.28 -> 3.2525392e+08 | C22: 1.4625806e+08 | D22: 97293659 | E22: 1.2027542e+08 | F22: 2.0985585e+08 | G22: 5.2353006e+08 | H22: =SUM(B22:G22) -> 1.422467e+09 | I22: 6.3732692e+08 | L22: 520039534 | M22: =L22*$M$1 -> 2.8602174e+08 | N22: =SUM(H22:I22) -> 2.0597939e+09 | O22: =$N22-$M22 -> 1.7737721e+09 | P22: =SUM($I22,$B22) -> 9.6258084e+08 | Q22: =SUM($C22:$G22) -> 1.0972131e+09 | R22: =SUM($D22:$G22) -> 9.5095499e+08 | S22: 5.2377073e+08 | T22: 1.5562335e+08 | U22: 1.0722327e+08 | V22: =S22/P22 -> 0.54413168 | W22: =T22/Q22 -> 0.14183513 | X22: =U22/R22 -> 0.11275326 | Y22: =SUM(S22:T22) -> 6.7939409e+08 | Z22: =SUM(S22:T22)+MAX(0,$M$1*$AX22) -> 6.9061726e+08 | AA22: =Y22/N22 -> 0.32983596 | AB22: =Z22/O22 -> 0.38934948 | AE22: =N22-SUM(AC22:AD22) -> 2.0597939e+09 | AF22: =AE22-M22 -> 1.7737721e+09 | AJ22: =P22-AG22 -> 9.6258084e+08 | AK22: =Q22-AH22 -> 1.0972131e+09 | AL22: =R22-AI22 -> 9.5095499e+08 | AM22: 5.2377073e+08 | AN22: 1.5562335e+08 | AO22: 1.0722327e+08 | AP22: =AM22/AJ22 -> 0.54413168 | AQ22: =AN22/AK22 -> 0.14183513 | AR22: =AO22/AL22 -> 0.11275326 | AS22: =SUM(AM22:AN22) -> 6.7939409e+08 | AT22: =SUM(AM22:AN22)+MAX(0,$M$1*$AX22) -> 6.9061726e+08 | AU22: =AS22/AE22 -> 0.32983596 | AV22: =AT22/AF22 -> 0.38934948 | AX22: =Summary!I39 -> 20405766
A23: Mar | B23: 2.858824e+08 | C23: 1.7243416e+08 | D23: 1.136733e+08 | E23: 73246334 | F23: 1.851748e+08 | G23: 4.8480515e+08 | H23: =SUM(B23:G23) -> 1.3152161e+09 | I23: 9.0341664e+08 | L23: 4.4440254e+08 | M23: =L23*$M$1 -> 2.444214e+08 | N23: =SUM(H23:I23) -> 2.2186328e+09 | O23: =$N23-$M23 -> 1.9742114e+09 | P23: =SUM($I23,$B23) -> 1.189299e+09 | Q23: =SUM($C23:$G23) -> 1.0293337e+09 | R23: =SUM($D23:$G23) -> 8.5689958e+08 | S23: 5.0040412e+08 | T23: 95151359 | U23: 51861785 | V23: =S23/P23 -> 0.4207555 | W23: =T23/Q23 -> 0.092439755 | X23: =U23/R23 -> 0.060522593 | Y23: =SUM(S23:T23) -> 5.9555548e+08 | Z23: =SUM(S23:T23)+MAX(0,$M$1*$AX23) -> 6.1380049e+08 | AA23: =Y23/N23 -> 0.26843355 | AB23: =Z23/O23 -> 0.3109092 | AE23: =N23-SUM(AC23:AD23) -> 2.2186328e+09 | AF23: =AE23-M23 -> 1.9742114e+09 | AJ23: =P23-AG23 -> 1.189299e+09 | AK23: =Q23-AH23 -> 1.0293337e+09 | AL23: =R23-AI23 -> 8.5689958e+08 | AM23: 5.0040412e+08 | AN23: 95151359 | AO23: 51861785 | AP23: =AM23/AJ23 -> 0.4207555 | AQ23: =AN23/AK23 -> 0.092439755 | AR23: =AO23/AL23 -> 0.060522593 | AS23: =SUM(AM23:AN23) -> 5.9555548e+08 | AT23: =SUM(AM23:AN23)+MAX(0,$M$1*$AX23) -> 6.1380049e+08 | AU23: =AS23/AE23 -> 0.26843355 | AV23: =AT23/AF23 -> 0.3109092 | AX23: =Summary!I40 -> 33172743
A24: Apr | B24: 6.4378793e+08 | C24: 1.9841471e+08 | D24: 1.2633111e+08 | E24: 95688954 | F24: 1.6924863e+08 | G24: 4.8841206e+08 | H24: =SUM(B24:G24) -> 1.7218834e+09 | I24: 8.5092313e+08 | L24: 3.7961814e+08 | M24: =L24*$M$1 -> 2.0878998e+08 | N24: =SUM(H24:I24) -> 2.5728065e+09 | O24: =$N24-$M24 -> 2.3640166e+09 | P24: =SUM($I24,$B24) -> 1.4947111e+09 | Q24: =SUM($C24:$G24) -> 1.0780955e+09 | R24: =SUM($D24:$G24) -> 8.7968076e+08 | S24: 5.6749335e+08 | T24: 1.3083579e+08 | U24: 60539093 | V24: =S24/P24 -> 0.37966759 | W24: =T24/Q24 -> 0.12135826 | X24: =U24/R24 -> 0.06881939 | Y24: =SUM(S24:T24) -> 6.9832913e+08 | Z24: =SUM(S24:T24)+MAX(0,$M$1*$AX24) -> 7.6601043e+08 | AA24: =Y24/N24 -> 0.27142699 | AB24: =Z24/O24 -> 0.32402922 | AE24: =N24-SUM(AC24:AD24) -> 2.5728065e+09 | AF24: =AE24-M24 -> 2.3640166e+09 | AJ24: =P24-AG24 -> 1.4947111e+09 | AK24: =Q24-AH24 -> 1.0780955e+09 | AL24: =R24-AI24 -> 8.7968076e+08 | AM24: 5.6749335e+08 | AN24: 1.3083579e+08 | AO24: 60539093 | AP24: =AM24/AJ24 -> 0.37966759 | AQ24: =AN24/AK24 -> 0.12135826 | AR24: =AO24/AL24 -> 0.06881939 | AS24: =SUM(AM24:AN24) -> 6.9832913e+08 | AT24: =SUM(AM24:AN24)+MAX(0,$M$1*$AX24) -> 7.6601043e+08 | AU24: =AS24/AE24 -> 0.27142699 | AV24: =AT24/AF24 -> 0.32402922 | AX24: =Summary!I41 -> 1.2305691e+08
A25: May | B25: 4.2789748e+08 | C25: 4.2597666e+08 | D25: 1.532086e+08 | E25: 1.2103344e+08 | F25: 1.2602837e+08 | G25: 5.6603841e+08 | H25: 1.820183e+09 | I25: 9.0471134e+08 | L25: 4.8879564e+08 | M25: =L25*$M$1 -> 2.688376e+08 | N25: =SUM(H25:I25) -> 2.7248943e+09 | O25: =$N25-$M25 -> 2.4560567e+09 | P25: =SUM($I25,$B25) -> 1.3326088e+09 | Q25: =SUM($C25:$G25) -> 1.3922855e+09 | R25: =SUM($D25:$G25) -> 9.6630882e+08 | S25: 1.0044078e+08 | T25: 26493658 | U25: 15295863 | V25: =S25/P25 -> 0.075371541 | W25: =T25/Q25 -> 0.019028898 | X25: =U25/R25 -> 0.015829166 | Y25: =SUM(S25:T25) -> 1.2693444e+08 | Z25: =SUM(S25:T25)+MAX(0,$M$1*$AX25) -> 1.758264e+08 | AA25: =Y25/N25 -> 0.046583252 | AB25: =Z25/O25 -> 0.071588903 | AE25: =N25-SUM(AC25:AD25) -> 2.7248943e+09 | AF25: =AE25-M25 -> 2.4560567e+09 | AJ25: =P25-AG25 -> 1.3326088e+09 | AK25: =Q25-AH25 -> 1.3922855e+09 | AL25: =R25-AI25 -> 9.6630882e+08 | AM25: 1.0044078e+08 | AN25: 26493658 | AO25: 15295863 | AP25: =AM25/AJ25 -> 0.075371541 | AQ25: =AN25/AK25 -> 0.019028898 | AR25: =AO25/AL25 -> 0.015829166 | AS25: =SUM(AM25:AN25) -> 1.2693444e+08 | AT25: =SUM(AM25:AN25)+MAX(0,$M$1*$AX25) -> 1.758264e+08 | AU25: =AS25/AE25 -> 0.046583252 | AV25: =AT25/AF25 -> 0.071588903 | AX25: =Summary!I42 -> 88894482
A26: Jun
A27: Jul
A28: Aug
A29: Sep
A30: Oct
A31: Nov
A32: Dec
B34: Sobha | N34: Sobha | AE34: Sobha
A35: 2025 | B35: Collection OD
A36: Month | B36: 0-30 | C36: 31-60 | D36: 61-90 | E36: 91-120 | F36: 121-180 | G36: 180+ | H36: Total Collection OD | I36: Upcoming MS till EOM | J36: EOM OD | K36: EOM Unidentified(Estimation) | L36: BOM Unidentified | M36: estimate dues unidentified(BOM) | N36: Total duebook (BOM) | O36: Estimated duebook net of unidentified(BOM) | P36: Booksize less than 30 days | Q36: Booksize 30+ days | R36: Booksize 60+ days | S36: Dues collected from 30 days | T36: Dues collected from 30+ days | U36: Dues collected from 60+ days | V36: % Dues collected from 30 days book | W36: % Dues collected from 30+days book | X36: % Dues collected from 60+days book | Y36: Due receipts | Z36: Due receipts+Dues unidentified | AA36: dues collected / book size | AB36: estimated dues collected / booksize estimated | AC36: Total duebook (S and Crest grande) | AD36: Total duebook (Crest) | AE36: Total duebook (Net of BCC) | AF36: Estimated duebook net of bcc& net of unidentified(BOM) | AG36: Booksize less than 30 days(Crest+s) | AH36: Booksize 30+ days(Crest+S) | AI36: Booksize 60+ days(Crest+S) | AJ36: Net BCC Booksize less than 30 days | AK36: Net BCC Booksize 30+ days | AL36: Net BCC Booksize 60+ days | AM36: Dues collected from 30 days | AN36: Dues collected from 30+ days | AO36: Dues collected from 60+ days | AP36: % Dues collected from 30 days book | AQ36: % Dues collected from 30+days book | AR36: % Dues collected from 60+days book | AS36: Due receipts | AT36: Due receipts+Dues unidentified | AU36: dues collected / book size | AV36: estimated dues collected / booksize estimated | AX36: Current UIF
A37: Jan | B37: 1.8070273e+08 | C37: 1.6914379e+08 | D37: 57914728 | E37: 42080669 | F37: 86697495 | G37: 4.8953772e+08 | H37: =SUM(B37:G37) -> 1.0260771e+09 | I37: 4.3680499e+08 | J37: =SUM(H37:I37)-SUM(S37:T37) -> 9.2279085e+08 | K37: =H38-J37 -> 1.4571618e+08 | L37: 2.9919289e+08 | M37: =L37*$M$1 -> 1.6455609e+08 | N37: =SUM(H37:I37) -> 1.4628821e+09 | O37: =$N37-$M37 -> 1.298326e+09 | P37: =SUM($I37,$B37) -> 6.1750771e+08 | Q37: =SUM($C37:$G37) -> 8.4537441e+08 | R37: =SUM($D37:$G37) -> 6.7623061e+08 | S37: 3.8486003e+08 | T37: 1.5523124e+08 | U37: 88285951 | V37: =S37/P37 -> 0.62324733 | W37: =T37/Q37 -> 0.18362425 | X37: =U37/R37 -> 0.13055598 | Y37: =SUM(S37:T37) -> 5.4009127e+08 | Z37: =SUM(S37:T37)+MAX(0,$M$1*$AX37) -> 5.4304577e+08 | AA37: =Y37/N37 -> 0.36919672 | AB37: =Z37/O37 -> 0.4182661 | AE37: =N37-SUM(AC37:AD37) -> 1.4628821e+09 | AF37: =AE37-M37 -> 1.298326e+09 | AJ37: =P37-AG37 -> 6.1750771e+08 | AK37: =Q37-AH37 -> 8.4537441e+08 | AL37: =R37-AI37 -> 6.7623061e+08 | AM37: 3.8486003e+08 | AN37: 1.5523124e+08 | AO37: 88285951 | AP37: =AM37/AJ37 -> 0.62324733 | AQ37: =AN37/AK37 -> 0.18362425 | AR37: =AO37/AL37 -> 0.13055598 | AS37: =SUM(AM37:AN37) -> 5.4009127e+08 | AT37: =SUM(AM37:AN37)+MAX(0,$M$1*$AX37) -> 5.4304577e+08 | AU37: =AS37/AE37 -> 0.36919672 | AV37: =AT37/AF37 -> 0.4182661 | AX37: =Summary!I66 -> 5371812
A38: Feb | B38: 1.9949853e+08 | C38: 1.1417763e+08 | D38: 1.1739654e+08 | E38: 43320225 | F38: 74056882 | G38: 5.2005723e+08 | H38: =SUM(B38:G38) -> 1.068507e+09 | I38: 5.4510399e+08 | J38: =SUM(H38:I38)-SUM(S38:T38) -> 1.0343361e+09 | K38: =H39-J38 -> 56653983 | L38: 3.4901138e+08 | M38: =L38*$M$1 -> 1.9195626e+08 | N38: =SUM(H38:I38) -> 1.613611e+09 | O38: =$N38-$M38 -> 1.4216548e+09 | P38: =SUM($I38,$B38) -> 7.4460251e+08 | Q38: =SUM($C38:$G38) -> 8.690085e+08 | R38: =SUM($D38:$G38) -> 7.5483088e+08 | S38: 4.386853e+08 | T38: 1.4058964e+08 | U38: 93074320 | V38: =S38/P38 -> 0.58915366 | W38: =T38/Q38 -> 0.16178166 | X38: =U38/R38 -> 0.12330487 | Y38: =SUM(S38:T38) -> 5.7927494e+08 | Z38: =SUM(S38:T38)+MAX(0,$M$1*$AX38) -> 5.8163499e+08 | AA38: =Y38/N38 -> 0.35899292 | AB38: =Z38/O38 -> 0.40912534 | AE38: =N38-SUM(AC38:AD38) -> 1.613611e+09 | AF38: =AE38-M38 -> 1.4216548e+09 | AJ38: =P38-AG38 -> 7.4460251e+08 | AK38: =Q38-AH38 -> 8.690085e+08 | AL38: =R38-AI38 -> 7.5483088e+08 | AM38: 4.386853e+08 | AN38: 1.4058964e+08 | AO38: 93074320 | AP38: =AM38/AJ38 -> 0.58915366 | AQ38: =AN38/AK38 -> 0.16178166 | AR38: =AO38/AL38 -> 0.12330487 | AS38: =SUM(AM38:AN38) -> 5.7927494e+08 | AT38: =SUM(AM38:AN38)+MAX(0,$M$1*$AX38) -> 5.8163499e+08 | AU38: =AS38/AE38 -> 0.35899292 | AV38: =AT38/AF38 -> 0.40912534 | AX38: =Summary!I67 -> 4291001.3
A39: Mar | B39: 3.2465788e+08 | C39: 1.4572485e+08 | D39: 97499362 | E39: 1.3144445e+08 | F39: 95980994 | G39: 2.9568252e+08 | H39: =SUM(B39:G39) -> 1.0909901e+09 | I39: 6.1656286e+08 | J39: =SUM(H39:I39)-SUM(S39:T39) -> 1.1052306e+09 | K39: =H40-J39 -> 86256939 | L39: 3.442558e+08 | M39: =L39*$M$1 -> 1.8934069e+08 | N39: =SUM(H39:I39) -> 1.7075529e+09 | O39: =$N39-$M39 -> 1.5182122e+09 | P39: =SUM($I39,$B39) -> 9.4122074e+08 | Q39: =SUM($C39:$G39) -> 7.6633218e+08 | R39: =SUM($D39:$G39) -> 6.2060733e+08 | S39: 4.7432722e+08 | T39: 1.279951e+08 | U39: 77234948 | V39: =S39/P39 -> 0.50394896 | W39: =T39/Q39 -> 0.167023 | X39: =U39/R39 -> 0.12445059 | Y39: =SUM(S39:T39) -> 6.0232232e+08 | Z39: =SUM(S39:T39)+MAX(0,$M$1*$AX39) -> 6.0804004e+08 | AA39: =Y39/N39 -> 0.35274006 | AB39: =Z39/O39 -> 0.40049739 | AE39: =N39-SUM(AC39:AD39) -> 1.7075529e+09 | AF39: =AE39-M39 -> 1.5182122e+09 | AJ39: =P39-AG39 -> 9.4122074e+08 | AK39: =Q39-AH39 -> 7.6633218e+08 | AL39: =R39-AI39 -> 6.2060733e+08 | AM39: 4.7432722e+08 | AN39: 1.279951e+08 | AO39: 77234948 | AP39: =AM39/AJ39 -> 0.50394896 | AQ39: =AN39/AK39 -> 0.167023 | AR39: =AO39/AL39 -> 0.12445059 | AS39: =SUM(AM39:AN39) -> 6.0232232e+08 | AT39: =SUM(AM39:AN39)+MAX(0,$M$1*$AX39) -> 6.0804004e+08 | AU39: =AS39/AE39 -> 0.35274006 | AV39: =AT39/AF39 -> 0.40049739 | AX39: =Summary!I68 -> 10395855
