Workbook
Name Ak: #REF!
Name l: 'consolidated - Offplan'!#REF!
Name l: 'consolidated tracker'!#REF!
Name NOB: #REF!
Name Source: #REF!
Name SRCE: #REF!
Name Style: #REF!
Name TOS: #REF!
Name Type: #REF!
Name VLOOKUP: #REF!

Sheet consolidated tracker
A1: 46143
J2: Consolidated collections tracker | N2: As on | O2: 46143
C3: S.No. | D3: Project details | E3: Project registration status | F3: Unit Count | G3: Sale value | H3: Milestone due | I3: Collected against due | J3: Collected against Advance | K3: % Collected vs Milestone | L3: Due to be collected | M3: Future collectibles | N3: 2026 | O3: 2027 | P3: 2028 | Q3: 2029 | R3: 2030 | S3: 2031 | T3: =+S3+1 -> 2032 | U3: =T3+1 -> 2033 | V3: =U3+1 -> 2034 | W3: =V3+1 -> 2035
C4: 1 | D4: Greens | E4: RERA | F4: =SUM(F5:F10) -> 1026 | G4: =SUM(G5:G10) -> 1.5600085e+09 | H4: =SUM(H5:H10) -> 1.5605552e+09 | I4: =SUM(I5:I10) -> 1.557024e+09 | J4: =SUM(J5:J10) -> 610608.84 | K4: =I4/H4 -> 0.99773718 | L4: =SUM(L5:L10) -> 3531253.2 | M4: =SUM(M5:M10) -> 2069265.9 | N4: =M4-SUM(O4:W4) -> 772553.76 | O4: =SUM(O5:O10) -> 558962.14 | P4: =SUM(P5:P10) -> 368875 | Q4: =SUM(Q5:Q10) -> 368875 | R4: =SUM(R5:R10) -> 0 | S4: =SUM(S5:S10) -> 0 | T4: =SUM(T5:T10) -> 0 | U4: =SUM(U5:U10) -> 0 | V4: =SUM(V5:V10) -> 0 | W4: =SUM(W5:W10) -> 0 | X4: =_xlfn.XLOOKUP(D4,'Overdue-1'!D:D,'Overdue-1'!E:E,0)-G4 -> 0 | Y4: =_xlfn.FORMULATEXT(H4) -> =SUM(H5:H10)
D5: Phase I - Building 1 | E5: RERA | F5: 90 | G5: 1.5765538e+08 | H5: 1.5832814e+08 | I5: 1.5742695e+08 | J5: 0 | K5: 1 | L5: 901192.1 | M5: =MAX(G5-(H5+J5),0) -> 0 | N5: 0 | O5: 0 | P5: 0 | Q5: 0 | R5: 0 | S5: 0 | T5: 0 | U5: 0 | V5: 0 | W5: 0 | X5: =_xlfn.XLOOKUP(D5,'Overdue-1'!D:D,'Overdue-1'!E:E,0)-G5 -> 0 | Y5: =_xlfn.FORMULATEXT(H5) -> #N/A | Z5: 0
D6: Phase I - Building 4 | E6: RERA | F6: 78 | G6: 1.9920509e+08 | H6: 1.992051e+08 | I6: 1.9920509e+08 | J6: 3.02 | K6: =I6/H6 -> 0.99999997 | L6: 6.38 | M6: =MAX(G6-(H6+J6),0) -> 0 | N6: 0 | O6: 0 | P6: 0 | Q6: 0 | R6: 0 | S6: 0 | T6: 0 | U6: 0 | V6: 0 | W6: 0 | X6: =_xlfn.XLOOKUP(D6,'Overdue-1'!D:D,'Overdue-1'!E:E,0)-G6 -> 0 | Y6: =_xlfn.FORMULATEXT(H6) -> #N/A | Z6: 0
D7: Phase II - Building 2 | E7: RERA | F7: 257 | G7: 3.9253397e+08 | H7: 3.9404335e+08 | I7: 3.9377025e+08 | J7: 1.15 | K7: =I7/H7 -> 0.99930694 | L7: 273096.54 | M7: =MAX(G7-(H7+J7),0) -> 0 | N7: 0 | O7: 0 | P7: 0 | Q7: 0 | R7: 0 | S7: 0 | T7: 0 | U7: 0 | V7: 0 | W7: 0 | X7: =_xlfn.XLOOKUP(D7,'Overdue-1'!D:D,'Overdue-1'!E:E,0)-G7 -> 0 | Y7: =_xlfn.FORMULATEXT(H7) -> #N/A | Z7: 0
D8: Phase II - Building 3 | E8: RERA | F8: 96 | G8: 1.6107603e+08 | H8: 1.6107103e+08 | I8: 1.6097633e+08 | J8: 5004.64 | K8: =I8/H8 -> 0.99941205 | L8: 94701.56 | M8: =MAX(G8-(H8+J8),0) -> 0.53999999 | N8: =M8-SUM(O8:W8) -> 0.53999999 | O8: 0 | P8: 0 | Q8: 0 | R8: 0 | S8: 0 | T8: 0 | U8: 0 | V8: 0 | W8: 0 | X8: =_xlfn.XLOOKUP(D8,'Overdue-1'!D:D,'Overdue-1'!E:E,0)-G8 -> 0 | Y8: =_xlfn.FORMULATEXT(H8) -> #N/A | Z8: 0
D9: Phase III - Building 5 | E9: RERA | F9: 198 | G9: 3.5831243e+08 | H9: 3.5687859e+08 | I9: 3.5528974e+08 | J9: 468638.21 | K9: =I9/H9 -> 0.99554793 | L9: 1588849.6 | M9: =SUM(N9:W9) -> 1786525.1 | N9: 489813 | O9: 558962.14 | P9: 368875 | Q9: 368875 | R9: 0 | S9: 0 | T9: 0 | U9: 0 | V9: 0 | W9: 0 | X9: =_xlfn.XLOOKUP(D9,'Overdue-1'!D:D,'Overdue-1'!E:E,0)-G9 -> 0 | Y9: =_xlfn.FORMULATEXT(H9) -> #N/A | Z9: 0
D10: Phase III - Building 6 | E10: RERA | F10: 307 | G10: 2.9122561e+08 | H10: 2.9102902e+08 | I10: 2.9035561e+08 | J10: 136961.82 | K10: =I10/H10 -> 0.99768612 | L10: 673406.98 | M10: =SUM(N10:W10) -> 282740.22 | N10: 282740.22 | O10: 0 | P10: 0 | Q10: 0 | R10: 0 | S10: 0 | T10: 0 | U10: 0 | V10: 0 | W10: 0 | X10: =_xlfn.XLOOKUP(D10,'Overdue-1'!D:D,'Overdue-1'!E:E,0)-G10 -> 0 | Y10: =_xlfn.FORMULATEXT(H10) -> #N/A | Z10: 0
C11: 2 | D11: Hartland 1 villas & townhouses | E11: RERA | F11: =SUM(F12:F16) -> 154 | G11: =SUM(G12:G16) -> 1.8752878e+09 | H11: =SUM(H12:H16) -> 1.8682947e+09 | I11: =SUM(I12:I16) -> 1.8637744e+09 | J11: =SUM(J12:J16) -> 837382.12 | K11: =I11/H11 -> 0.99758052 | L11: =SUM(L12:L16) -> 4520296.8 | M11: =SUM(M12:M16) -> 6155754.6 | N11: =SUM(N12:N16) -> 6155754.6 | O11: =SUM(O12:O16) -> 0 | P11: =SUM(P12:P16) -> 0 | Q11: =SUM(Q12:Q16) -> 0 | R11: =SUM(R12:R16) -> 0 | S11: =SUM(S12:S16) -> 0 | ... W11: =SUM(W12:W16) -> 0 | X11: =_xlfn.XLOOKUP(D11,'Overdue-1'!D:D,'Overdue-1'!E:E,0)-G11 -> 0 | Y11: =_xlfn.FORMULATEXT(H11) -> =SUM(H12:H16)
D12: Villas Phase I | E12: RERA | F12: 48 | G12: 6.3438082e+08 | H12: 6.3281446e+08 | I12: 6.3278905e+08 | J12: 6.66 | K12: =I12/H12 -> 0.99995984 | L12: 25411.39 | M12: =MAX(G12-(H12+J12),0) -> 1566348.5 | N12: =M12 -> 1566348.5 | O12: 0 | P12: 0 | Q12: 0 | R12: 0 | S12: 0 | T12: 0 | U12: 0 | V12: 0 | W12: 0 | X12: =_xlfn.XLOOKUP(D12,'Overdue-1'!D:D,'Overdue-1'!E:E,0)-G12 -> 0 | Y12: =_xlfn.FORMULATEXT(H12) -> #N/A | Z12: 0
D13: Villas Phase II | E13: RERA | F13: 24 | G13: 1.8368157e+08 | H13: 1.828444e+08 | I13: 1.827949e+08 | J13: 837172.01 | K13: =I13/H13 -> 0.99972926 | L13: 49503.62 | M13: =MAX(G13-(H13+J13),0) -> 0 | N13: 0 | O13: 0 | P13: 0 | Q13: 0 | R13: 0 | S13: 0 | T13: 0 | U13: 0 | V13: 0 | W13: 0 | X13: =_xlfn.XLOOKUP(D13,'Overdue-1'!D:D,'Overdue-1'!E:E,0)-G13 -> 0 | Y13: =_xlfn.FORMULATEXT(H13) -> #N/A | Z13: 0
D14: Villas Phase III | E14: RERA | F14: 55 | G14: 9.1301278e+08 | H14: 9.0842317e+08 | I14: 9.0397779e+08 | J14: 203.17 | K14: =I14/H14 -> 0.99510649 | L14: 4445375.3 | M14: =MAX(G14-(H14+J14),0) -> 4589406.1 | N14: =M14 -> 4589406.1 | O14: 0 | P14: 0 | Q14: 0 | R14: 0 | S14: 0 | T14: 0 | U14: 0 | V14: 0 | W14: 0 | X14: =_xlfn.XLOOKUP(D14,'Overdue-1'!D:D,'Overdue-1'!E:E,0)-G14 -> 0 | Y14: =_xlfn.FORMULATEXT(H14) -> #N/A | Z14: 0
D15: Villas Phase IV | E15: RERA | F15: 0 | G15: 0 | H15: 0 | I15: 0 | J15: 0 | K15: =IFERROR(I15/H15,"-") -> - | L15: 0 | M15: =MAX(G15-(H15+J15),0) -> 0 | N15: 0 | O15: 0 | P15: 0 | Q15: 0 | R15: 0 | S15: 0 | T15: 0 | U15: 0 | V15: 0 | W15: 0 | X15: =_xlfn.XLOOKUP(D15,'Overdue-1'!D:D,'Overdue-1'!E:E,0)-G15 -> 0 | Y15: =_xlfn.FORMULATEXT(H15) -> #N/A | Z15: 0
D16: Townhouse | E16: RERA | F16: 27 | G16: 1.4421265e+08 | H16: 1.4421265e+08 | I16: 1.4421264e+08 | J16: 0.28 | K16: =I16/H16 -> 0.99999995 | L16: 6.43 | M16: =MAX(G16-(H16+J16),0) -> 0 | N16: 0 | O16: 0 | P16: 0 | Q16: 0 | R16: 0 | S16: 0 | T16: 0 | U16: 0 | V16: 0 | W16: 0 | X16: =_xlfn.XLOOKUP(D16,'Overdue-1'!D:D,'Overdue-1'!E:E,0)-G16 -> 0 | Y16: =_xlfn.FORMULATEXT(H16) -> #N/A | Z16: 0
C17: 3 | D17: CV & CVR | E17: RERA | F17: =SUM(F18:F21) -> 1562 | G17: =SUM(G18:G21) -> 1.6376391e+09 | H17: =SUM(H18:H21) -> 1.6349928e+09 | I17: =SUM(I18:I21) -> 1.6324027e+09 | J17: =SUM(J18:J21) -> 373043.07 | K17: =I17/H17 -> 0.99841581 | L17: =SUM(L18:L21) -> 2590134.1 | M17: =SUM(M18:M21) -> 2427182.3 | N17: =M17-SUM(O17:W17) -> 1036547.5 | O17: =SUM(O18:O21) -> 1025238.8 | P17: =SUM(P18:P21) -> 365396 | Q17: =SUM(Q18:Q21) -> 0 | R17: =SUM(R18:R21) -> 0 | S17: =SUM(S18:S21) -> 0 | T17: =SUM(T18:T21) -> 0 | U17: =SUM(U18:U21) -> 0 | V17: =SUM(V18:V21) -> 0 | W17: =SUM(W18:W21) -> 0 | X17: =_xlfn.XLOOKUP(D17,'Overdue-1'!D:D,'Overdue-1'!E:E,0)-G17 -> 0 | Y17: =_xlfn.FORMULATEXT(H17) -> =SUM(H18:H21)
D18: Creek vista reserve Tower A | E18: RERA | F18: 452 | G18: 4.6795197e+08 | H18: 4.6658041e+08 | I18: 4.6506066e+08 | J18: 349884.97 | K18: =I18/H18 -> 0.9967428 | L18: 1519743.6 | M18: =MAX(G18-(H18+J18),0) -> 1021675.2 | N18: =M18-SUM(O18:W18) -> 315299.56 | O18: 340979.6 | P18: 365396 | Q18: 0 | R18: 0 | S18: 0 | T18: 0 | U18: 0 | V18: 0 | W18: 0 | X18: =_xlfn.XLOOKUP(D18,'Overdue-1'!D:D,'Overdue-1'!E:E,0)-G18 -> 0 | Y18: =_xlfn.FORMULATEXT(H18) -> #N/A | Z18: -8.9406967e-07
D19: Creek vista reserve Tower B | E19: RERA | F19: 330 | G19: 3.3507329e+08 | H19: 3.3462999e+08 | I19: 3.3427189e+08 | J19: 20608.7 | K19: =I19/H19 -> 0.99892986 | L19: 358102.37 | M19: =MAX(G19-(H19+J19),0) -> 422684.77 | N19: =M19-SUM(O19:W19) -> 422684.77 | O19: 0 | P19: 0 | Q19: 0 | R19: 0 | S19: 0 | T19: 0 | U19: 0 | V19: 0 | W19: 0 | X19: =_xlfn.XLOOKUP(D19,'Overdue-1'!D:D,'Overdue-1'!E:E,0)-G19 -> 0 | Y19: =_xlfn.FORMULATEXT(H19) -> #N/A | Z19: 0
D20: Creek Vista Tower A | E20: RERA | F20: 389 | G20: 4.0749757e+08 | H20: 4.0765148e+08 | I20: 4.0700525e+08 | J20: 3.22 | K20: =I20/H20 -> 0.99841476 | L20: 646226.25 | M20: =MAX(G20-(H20+J20),0) -> 0 | N20: =M20-SUM(O20:W20) -> 0 | O20: 0 | P20: 0 | Q20: 0 | R20: 0 | S20: 0 | T20: 0 | U20: 0 | V20: 0 | W20: 0 | X20: =_xlfn.XLOOKUP(D20,'Overdue-1'!D:D,'Overdue-1'!E:E,0)-G20 -> 0 | Y20: =_xlfn.FORMULATEXT(H20) -> #N/A | Z20: -8.9406967e-07
D21: Creek vista Tower B | E21: RERA | F21: 391 | G21: 4.271163e+08 | H21: 4.2613093e+08 | I21: 4.2606487e+08 | J21: 2546.18 | K21: =I21/H21 -> 0.99984497 | L21: 66061.92 | M21: =MAX(G21-(H21+J21),0) -> 982822.42 | N21: =M21-SUM(O21:W21) -> 298563.22 | O21: 684259.2 | P21: 0 | Q21: 0 | R21: 0 | S21: 0 | T21: 0 | U21: 0 | V21: 0 | W21: 0 | X21: =_xlfn.XLOOKUP(D21,'Overdue-1'!D:D,'Overdue-1'!E:E,0)-G21 -> 0 | Y21: =_xlfn.FORMULATEXT(H21) -> #N/A | Z21: 0
C22: 4 | D22: One Park Avenue Tower | E22: RERA | F22: 415 | G22: 7.7670286e+08 | H22: 7.7835533e+08 | I22: 7.7655347e+08 | J22: 401335.66 | K22: =I22/H22 -> 0.99768505 | L22: 1801856.4 | M22: =SUM(N22:W22) -> 260280.26 | N22: 84418.14 | O22: 175862.12 | P22: 0 | Q22: 0 | R22: 0 | S22: 0 | T22: 0 | U22: 0 | V22: 0 | W22: 0 | X22: =_xlfn.XLOOKUP(D22,'Overdue-1'!D:D,'Overdue-1'!E:E,0)-G22 -> 0 | Y22: =_xlfn.FORMULATEXT(H22) -> #N/A | Z22: 3.2186508e-06
C23: 5 | D23: Waves | E23: RERA | F23: =F229 -> 600 | G23: =G229 -> 7.9367352e+08 | H23: =H229 -> 7.9492305e+08 | I23: =I229 -> 7.9396492e+08 | J23: =J229 -> 0.22 | K23: =I23/H23 -> 0.99879469 | L23: 958128.31 | M23: =SUM(N23:W23) -> 0 | N23: 0 | O23: 0 | P23: 0 | Q23: 0 | R23: 0 | S23: 0 | T23: 0 | U23: 0 | V23: 0 | W23: 0 | X23: =_xlfn.XLOOKUP(D23,'Overdue-1'!D:D,'Overdue-1'!E:E,0)-G23 -> 0 | Y23: =_xlfn.FORMULATEXT(H23) -> =H229
C24: 6 | D24: Waves Grande | E24: RERA | F24: 438 | G24: 7.9798872e+08 | H24: 7.9874645e+08 | I24: 7.9769453e+08 | J24: 0.19 | K24: =IFERROR(I24/H24,0) -> 0.99868304 | L24: 1051915.9 | M24: =SUM(N24:W24) -> 1102958 | N24: 940818.9 | O24: 162139.07 | P24: 0 | Q24: 0 | R24: 0 | S24: 0 | T24: 0 | U24: 0 | V24: 0 | W24: 0 | X24: =_xlfn.XLOOKUP(D24,'Overdue-1'!D:D,'Overdue-1'!E:E,0)-G24 -> 0 | Y24: =_xlfn.FORMULATEXT(H24) -> #N/A | Z24: -1.1920929e-06
C25: 7 | D25: Creek Vistas Grande | E25: RERA | F25: 399 | G25: 8.0263509e+08 | H25: 6.7796074e+08 | I25: 6.667116e+08 | J25: 57228841 | K25: =IFERROR(I25/H25,0) -> 0.98340739 | L25: 11249139 | M25: =MAX(G25-(H25+J25),0) -> 67445510 | N25: =M25-SUM(O25:W25) -> 66338413 | O25: 1107096.9 | P25: 0 | Q25: 0 | R25: 0 | S25: 0 | T25: 0 | U25: 0 | V25: 0 | W25: 0 | X25: =_xlfn.XLOOKUP(D25,'Overdue-1'!D:D,'Overdue-1'!E:E,0)-G25 -> 0 | Y25: =_xlfn.FORMULATEXT(H25) -> #N/A | Z25: 3.2186508e-06
C26: 8 | D26: Crest Grande | E26: RERA | F26: =SUM(F27:F30) -> 976 | G26: =SUM(G27:G30) -> 2.5487419e+09 | H26: =SUM(H27:H30) -> 1.8604904e+09 | I26: =SUM(I27:I30) -> 1.7495576e+09 | J26: =SUM(J27:J30) -> 88303513 | K26: =I26/H26 -> 0.94037441 | L26: =SUM(L27:L30) -> 1.1093283e+08 | M26: =SUM(M27:M30) -> 6.0233064e+08 | N26: =M26-SUM(O26:W26) -> 1.3660304e+08 | O26: =SUM(O27:O30) -> 3.0805485e+08 | P26: =SUM(P27:P30) -> 1.5767275e+08 | Q26: =SUM(Q27:Q30) -> 0 | R26: =SUM(R27:R30) -> 0 | S26: =SUM(S27:S30) -> 0 | T26: =SUM(T27:T30) -> 0 | U26: =SUM(U27:U30) -> 0 | V26: =SUM(V27:V30) -> 0 | W26: =SUM(W27:W30) -> 0 | X26: =_xlfn.XLOOKUP(D26,'Overdue-1'!D:D,'Overdue-1'!E:E,0)-G26 -> 0 | Y26: =_xlfn.FORMULATEXT(H26) -> =SUM(H27:H30)
D27: Crest Grande - Tower A | E27: RERA | F27: 317 | G27: 8.6294444e+08 | H27: 6.3575967e+08 | I27: 5.9104664e+08 | J27: 23092172 | K27: =I27/H27 -> 0.92966992 | L27: 44713031 | M27: =MAX(G27-(H27+J27),0) -> 2.040926e+08 | N27: =M27-SUM(O27:W27) -> 47056546 | O27: 1.0387168e+08 | P27: 53164374 | Q27: 0 | R27: 0 | S27: 0 | T27: 0 | U27: 0 | V27: 0 | W27: 0 | X27: =_xlfn.XLOOKUP(D27,'Overdue-1'!D:D,'Overdue-1'!E:E,0)-G27 -> 0 | Y27: =_xlfn.FORMULATEXT(H27) -> #N/A | Z27: 2.1457672e-06
D28: Crest Grande - Tower B | E28: RERA | F28: 353 | G28: 7.6960777e+08 | H28: 5.1935997e+08 | I28: 4.9814988e+08 | J28: 47316206 | K28: =I28/H28 -> 0.95916111 | L28: 21210086 | M28: =MAX(G28-(H28+J28),0) -> 2.0293159e+08 | N28: =M28-SUM(O28:W28) -> 45806588 | O28: 1.0380475e+08 | P28: 53320250 | Q28: 0 | R28: 0 | S28: 0 | T28: 0 | U28: 0 | V28: 0 | W28: 0 | X28: =_xlfn.XLOOKUP(D28,'Overdue-1'!D:D,'Overdue-1'!E:E,0)-G28 -> 0 | Y28: =_xlfn.FORMULATEXT(H28) -> #N/A | Z28: 3.2186508e-06
D29: Crest Grande - Tower C | E29: RERA | F29: 286 | G29: 8.68536e+08 | H29: 6.5830706e+08 | I29: 6.142898e+08 | J29: 17875390 | K29: =I29/H29 -> 0.93313566 | L29: 44017265 | M29: =MAX(G29-(H29+J29),0) -> 1.9235354e+08 | N29: =M29-SUM(O29:W29) -> 43016489 | O29: 98892087 | P29: 50444968 | Q29: 0 | R29: 0 | S29: 0 | T29: 0 | U29: 0 | V29: 0 | W29: 0 | X29: =_xlfn.XLOOKUP(D29,'Overdue-1'!D:D,'Overdue-1'!E:E,0)-G29 -> 0 | Y29: =_xlfn.FORMULATEXT(H29) -> #N/A | Z29: -2177912.5
D30: Crest Grande - Retail | E30: RERA | F30: 20 | G30: 47653647 | H30: 47063681 | I30: 46071235 | J30: 19745.29 | K30: =I30/H30 -> 0.97891271 | L30: 992445.62 | M30: =MAX(1.05*G30-(H30+J30),0) -> 2952902.8 | N30: =M30-SUM(O30:W30) -> 723416.73 | O30: 1486324.1 | P30: 743162.04 | Q30: 0 | R30: 0 | S30: 0 | T30: 0 | U30: 0 | V30: 0 | W30: 0 | X30: =_xlfn.XLOOKUP(D30,'Overdue-1'!D:D,'Overdue-1'!E:E,0)-G30 -> 0 | Y30: =_xlfn.FORMULATEXT(H30) -> #N/A | Z30: 0
C31: 9 | D31: Waves Opulence | E31: RERA | F31: 357 | G31: 1.0073601e+09 | H31: 5.9813452e+08 | I31: 5.8810201e+08 | J31: 1.0176234e+08 | K31: =I31/H31 -> 0.983227 | L31: 10032511 | M31: =MAX(G31-(H31+J31),0) -> 3.0746324e+08 | N31: =M31 -> 3.0746324e+08 | O31: 0 | P31: 0 | Q31: 0 | R31: 0 | S31: 0 | T31: 0 | U31: 0 | V31: 0 | W31: 0 | X31: =_xlfn.XLOOKUP(D31,'Overdue-1'!D:D,'Overdue-1'!E:E,0)-G31 -> 0 | Y31: =_xlfn.FORMULATEXT(H31) -> #N/A | Z31: 0
C32: 10 | D32: Creek Vista Heights | E32: RERA | F32: =SUM(F33:F35) -> 1324 | G32: =SUM(G33:G35) -> 2.5411988e+09 | H32: =SUM(H33:H35) -> 1.5483509e+09 | I32: =SUM(I33:I35) -> 1.5273238e+09 | J32: =SUM(J33:J35) -> 1.8429219e+08 | K32: =I32/H32 -> 0.98641966 | L32: =SUM(L33:L35) -> 20972071 | M32: =MAX(G32-(H32+J32),0) -> 8.0855569e+08 | N32: =M32 -> 8.0855569e+08 | O32: 0 | P32: 0 | Q32: 0 | R32: 0 | S32: 0 | T32: 0 | U32: 0 | V32: 0 | W32: 0 | X32: =_xlfn.XLOOKUP(D32,'Overdue-1'!D:D,'Overdue-1'!E:E,0)-G32 -> 0 | Y32: =_xlfn.FORMULATEXT(H32) -> =SUM(H33:H35)
D33: Creek vista heights tower A | E33: RERA | F33: 631 | G33: 1.01787e+09 | H33: 6.2624529e+08 | I33: 6.1799097e+08 | J33: 67154177 | K33: =I33/H33 -> 0.98681936 | L33: 8254316.5 | M33: =MAX(G33-(H33+J33),0) -> 3.2447049e+08 | N33: =M33-SUM(O33:W33) -> 3.2406294e+08 | O33: 407554.18 | P33: 0 | Q33: 0 | R33: 0 | S33: 0 | T33: 0 | U33: 0 | V33: 0 | W33: 0 | X33: =_xlfn.XLOOKUP(D33,'Overdue-1'!D:D,'Overdue-1'!E:E,0)-G33 -> 0 | Y33: =_xlfn.FORMULATEXT(H33) -> #N/A | Z33: 2.1457672e-06
D34: Creek vista heights tower B | E34: RERA | F34: 681 | G34: 1.4709835e+09 | H34: 8.8972357e+08 | I34: 8.7732214e+08 | J34: 1.0895002e+08 | K34: =I34/H34 -> 0.98606149 | L34: 12401425 | M34: =MAX(G34-(H34+J34),0) -> 4.723099e+08 | N34: =M34 -> 4.723099e+08 | O34: 0 | P34: 0 | Q34: 0 | R34: 0 | S34: 0 | T34: 0 | U34: 0 | V34: 0 | W34: 0 | X34: =_xlfn.XLOOKUP(D34,'Overdue-1'!D:D,'Overdue-1'!E:E,0)-G34 -> 0 | Y34: =_xlfn.FORMULATEXT(H34) -> #N/A | Z34: 1.0371208e-05
D35: Creek vista heights retail | E35: RERA | F35: 12 | G35: 52345357 | H35: 32382061 | I35: 32010669 | J35: 8187994 | K35: =I35/H35 -> 0.98853095 | L35: 316330 | M35: =MAX(G35-(H35+J35),0) -> 11775303 | N35: =M35 -> 11775303 | O35: 0 | P35: 0 | Q35: 0 | R35: 0 | S35: 0 | T35: 0 | U35: 0 | V35: 0 | W35: 0 | X35: =_xlfn.XLOOKUP(D35,'Overdue-1'!D:D,'Overdue-1'!E:E,0)-G35 -> 0 | Y35: =_xlfn.FORMULATEXT(H35) -> #N/A | Z35: 0
C36: 11 | D36: Sea Haven | E36: RERA | F36: =SUM(F37:F39) -> 680 | G36: =SUM(G37:G39) -> 5.3019632e+09 | H36: =SUM(H37:H39) -> 3.0618523e+09 | I36: =SUM(I37:I39) -> 2.8612734e+09 | J36: =SUM(J37:J39) -> 2.5897524e+08 | K36: =I36/H36 -> 0.93449097 | L36: =SUM(L37:L39) -> 2.0057897e+08 | M36: =MAX(G36-(H36+J36),0) -> 1.9811356e+09 | N36: =M36-SUM(O36:W36) -> 9.6545294e+08 | O36: =SUM(O37:O39) -> 1.0156827e+09 | P36: =SUM(P37:P39) -> 0 | Q36: =SUM(Q37:Q39) -> 0 | R36: =SUM(R37:R39) -> 0 | S36: =SUM(S37:S39) -> 0 | T36: =SUM(T37:T39) -> 0 | U36: =SUM(U37:U39) -> 0 | V36: =SUM(V37:V39) -> 0 | W36: =SUM(W37:W39) -> 0 | X36: =_xlfn.XLOOKUP(D36,'Overdue-1'!D:D,'Overdue-1'!E:E,0)-G36 -> -5.3019632e+09 | Y36: =_xlfn.FORMULATEXT(H36) -> =SUM(H37:H39)
D37: Sea Haven Tower A | E37: RERA | F37: 315 | G37: 2.6154909e+09 | H37: 1.736494e+09 | I37: 1.6042163e+09 | J37: 1.4571977e+08 | K37: =I37/H37 -> 0.92382487 | L37: 1.3227765e+08 | M37: =MAX(G37-(H37+J37),0) -> 7.3327714e+08 | N37: =M37 -> 7.3327714e+08 | O37: 0 | P37: 0 | Q37: 0 | R37: 0 | S37: 0 | T37: 0 | U37: 0 | V37: 0 | W37: 0 | X37: =_xlfn.XLOOKUP(D37,'Overdue-1'!D:D,'Overdue-1'!E:E,0)-G37 -> 0 | Y37: =_xlfn.FORMULATEXT(H37) -> #N/A | Z37: 1592974.8
D38: Sea Haven Tower B | E38: RERA | F38: 223 | G38: 1.5122856e+09 | H38: 7.9933232e+08 | I38: 7.6172395e+08 | J38: 33855061 | K38: =I38/H38 -> 0.95295027 | L38: 37608372 | M38: =MAX(G38-(H38+J38),0) -> 6.7909826e+08 | N38: =M38-SUM(O38:W38) -> 1.3857051e+08 | O38: 5.4052775e+08 | P38: 0 | Q38: 0 | R38: 0 | S38: 0 | T38: 0 | U38: 0 | V38: 0 | W38: 0 | X38: =_xlfn.XLOOKUP(D38,'Overdue-1'!D:D,'Overdue-1'!E:E,0)-G38 -> 0 | Y38: =_xlfn.FORMULATEXT(H38) -> #N/A | Z38: 1527856.8
D39: Sea Haven Tower C | E39: RERA | F39: 142 | G39: 1.1741867e+09 | H39: 5.2602603e+08 | I39: 4.9533309e+08 | J39: 79400407 | K39: =I39/H39 -> 0.94165128 | L39: 30692945 | M39: =MAX(G39-(H39+J39),0) -> 5.6876024e+08 | N39: =M39-SUM(O39:W39) -> 93605285 | O39: 4.7515495e+08 | P39: 0 | Q39: 0 | R39: 0 | S39: 0 | T39: 0 | U39: 0 | V39: 0 | W39: 0 | X39: =_xlfn.XLOOKUP(D39,'Overdue-1'!D:D,'Overdue-1'!E:E,0)-G39 -> 0 | Y39: =_xlfn.FORMULATEXT(H39) -> #N/A | Z39: 0
C40: 12 | D40: Verde | E40: RERA | F40: 606 | G40: 1.5355297e+09 | H40: 8.9106197e+08 | I40: 8.6332707e+08 | J40: 62673788 | K40: =I40/H40 -> 0.96887433 | L40: 27734901 | M40: =MAX(G40-(H40+J40),0) -> 5.8179392e+08 | N40: =M40-SUM(O40:W40) -> 5.8179392e+08 | O40: 0 | P40: 0 | Q40: 0 | R40: 0 | S40: 0 | T40: 0 | U40: 0 | V40: 0 | W40: 0 | X40: =_xlfn.XLOOKUP(D40,'Overdue-1'!D:D,'Overdue-1'!E:E,0)-G40 -> 0 | Y40: =_xlfn.FORMULATEXT(H40) -> #N/A | Z40: 376077.2
...

Sheet consolidated - Offplan
A1: 46143
K2: Consolidated collections tracker - Offplan projects | O2: As on | P2: 46143
C3: S.No. | D3: Project details | E3: Project registration status | F3: ACD (Anticipated Completion Date) | G3: Unit Count | H3: Sale value | I3: Milestone due | J3: Collected against due | K3: Collected against Advance | L3: % Collected vs Milestone | M3: Due to be collected | N3: Future collectibles | O3: 2026 | P3: 2027 | Q3: 2028 | R3: 2029 | S3: 2030 | T3: =S3+1 -> 2031 | U3: =T3+1 -> 2032 | V3: =U3+1 -> 2033 | W3: =V3+1 -> 2034 | X3: =W3+1 -> 2035
C4: 1 | D4: Waves Opulence | E4: =_xlfn.XLOOKUP(D4,'consolidated tracker'!D:D,'consolidated tracker'!E:E) -> RERA | F4: 46203 | G4: =_xlfn.XLOOKUP(D4,'consolidated tracker'!D:D,'consolidated tracker'!F:F) -> 357 | H4: =_xlfn.XLOOKUP(D4,'consolidated tracker'!D:D,'consolidated tracker'!G:G) -> 1.0073601e+09 | I4: =_xlfn.XLOOKUP(D4,'consolidated tracker'!D:D,'consolidated tracker'!H:H) -> 5.9813452e+08 | J4: =_xlfn.XLOOKUP(D4,'consolidated tracker'!D:D,'consolidated tracker'!I:I) -> 5.8810201e+08 | K4: =_xlfn.XLOOKUP(D4,'consolidated tracker'!D:D,'consolidated tracker'!J:J) -> 1.0176234e+08 | L4: =_xlfn.XLOOKUP(D4,'consolidated tracker'!D:D,'consolidated tracker'!K:K) -> 0.983227 | M4: =_xlfn.XLOOKUP('consolidated - Offplan'!D4,'consolidated tracker'!D:D,'consolidated tracker'!L:L) -> 10032511 | N4: =_xlfn.XLOOKUP($D4,'consolidated tracker'!$D:$D,'consolidated tracker'!M:M) -> 3.0746324e+08 | O4: =_xlfn.XLOOKUP($D4,'consolidated tracker'!$D:$D,'consolidated tracker'!N:N) -> 3.0746324e+08 | P4: =_xlfn.XLOOKUP($D4,'consolidated tracker'!$D:$D,'consolidated tracker'!O:O) -> 0 | Q4: =_xlfn.XLOOKUP($D4,'consolidated tracker'!$D:$D,'consolidated tracker'!P:P) -> 0 | R4: =_xlfn.XLOOKUP($D4,'consolidated tracker'!$D:$D,'consolidated tracker'!Q:Q) -> 0 | S4: =_xlfn.XLOOKUP($D4,'consolidated tracker'!$D:$D,'consolidated tracker'!R:R) -> 0 | T4: =_xlfn.XLOOKUP($D4,'consolidated tracker'!$D:$D,'consolidated tracker'!S:S) -> 0 | U4: =_xlfn.XLOOKUP($D4,'consolidated tracker'!$D:$D,'consolidated tracker'!T:T) -> 0 | V4: =_xlfn.XLOOKUP($D4,'consolidated tracker'!$D:$D,'consolidated tracker'!U:U) -> 0 | W4: =_xlfn.XLOOKUP($D4,'consolidated tracker'!$D:$D,'consolidated tracker'!V:V) -> 0 | X4: =_xlfn.XLOOKUP($D4,'consolidated tracker'!$D:$D,'consolidated tracker'!W:W) -> 0
C5: =+C4+1 -> 2 | D5: Creek Vista Heights | E5: =_xlfn.XLOOKUP(D5,'consolidated tracker'!D:D,'consolidated tracker'!E:E) -> RERA | F5: - | G5: =_xlfn.XLOOKUP(D5,'consolidated tracker'!D:D,'consolidated tracker'!F:F) -> 1324 | H5: =_xlfn.XLOOKUP(D5,'consolidated tracker'!D:D,'consolidated tracker'!G:G) -> 2.5411988e+09 | I5: =_xlfn.XLOOKUP(D5,'consolidated tracker'!D:D,'consolidated tracker'!H:H) -> 1.5483509e+09 | J5: =_xlfn.XLOOKUP(D5,'consolidated tracker'!D:D,'consolidated tracker'!I:I) -> 1.5273238e+09 | K5: =_xlfn.XLOOKUP(D5,'consolidated tracker'!D:D,'consolidated tracker'!J:J) -> 1.8429219e+08 | L5: =_xlfn.XLOOKUP(D5,'consolidated tracker'!D:D,'consolidated tracker'!K:K) -> 0.98641966 | M5: =_xlfn.XLOOKUP('consolidated - Offplan'!D5,'consolidated tracker'!D:D,'consolidated tracker'!L:L) -> 20972071 | N5: =_xlfn.XLOOKUP($D5,'consolidated tracker'!$D:$D,'consolidated tracker'!M:M) -> 8.0855569e+08 | O5: =_xlfn.XLOOKUP($D5,'consolidated tracker'!$D:$D,'consolidated tracker'!N:N) -> 8.0855569e+08 | P5: =_xlfn.XLOOKUP($D5,'consolidated tracker'!$D:$D,'consolidated tracker'!O:O) -> 0 | Q5: =_xlfn.XLOOKUP($D5,'consolidated tracker'!$D:$D,'consolidated tracker'!P:P) -> 0 | R5: =_xlfn.XLOOKUP($D5,'consolidated tracker'!$D:$D,'consolidated tracker'!Q:Q) -> 0 | S5: =_xlfn.XLOOKUP($D5,'consolidated tracker'!$D:$D,'consolidated tracker'!R:R) -> 0 | T5: =_xlfn.XLOOKUP($D5,'consolidated tracker'!$D:$D,'consolidated tracker'!S:S) -> 0 | U5: =_xlfn.XLOOKUP($D5,'consolidated tracker'!$D:$D,'consolidated tracker'!T:T) -> 0 | V5: =_xlfn.XLOOKUP($D5,'consolidated tracker'!$D:$D,'consolidated tracker'!U:U) -> 0 | W5: =_xlfn.XLOOKUP($D5,'consolidated tracker'!$D:$D,'consolidated tracker'!V:V) -> 0 | X5: =_xlfn.XLOOKUP($D5,'consolidated tracker'!$D:$D,'consolidated tracker'!W:W) -> 0
D6: Creek vista heights tower A | E6: =_xlfn.XLOOKUP(D6,'consolidated tracker'!D:D,'consolidated tracker'!E:E) -> RERA | F6: 46265 | G6: =_xlfn.XLOOKUP(D6,'consolidated tracker'!D:D,'consolidated tracker'!F:F) -> 631 | H6: =_xlfn.XLOOKUP(D6,'consolidated tracker'!D:D,'consolidated tracker'!G:G) -> 1.01787e+09 | I6: =_xlfn.XLOOKUP(D6,'consolidated tracker'!D:D,'consolidated tracker'!H:H) -> 6.2624529e+08 | J6: =_xlfn.XLOOKUP(D6,'consolidated tracker'!D:D,'consolidated tracker'!I:I) -> 6.1799097e+08 | K6: =_xlfn.XLOOKUP(D6,'consolidated tracker'!D:D,'consolidated tracker'!J:J) -> 67154177 | L6: =_xlfn.XLOOKUP(D6,'consolidated tracker'!D:D,'consolidated tracker'!K:K) -> 0.98681936 | M6: =_xlfn.XLOOKUP('consolidated - Offplan'!D6,'consolidated tracker'!D:D,'consolidated tracker'!L:L) -> 8254316.5 | N6: =_xlfn.XLOOKUP($D6,'consolidated tracker'!$D:$D,'consolidated tracker'!M:M) -> 3.2447049e+08 | O6: =_xlfn.XLOOKUP($D6,'consolidated tracker'!$D:$D,'consolidated tracker'!N:N) -> 3.2406294e+08 | P6: =_xlfn.XLOOKUP($D6,'consolidated tracker'!$D:$D,'consolidated tracker'!O:O) -> 407554.18 | Q6: =_xlfn.XLOOKUP($D6,'consolidated tracker'!$D:$D,'consolidated tracker'!P:P) -> 0 | R6: =_xlfn.XLOOKUP($D6,'consolidated tracker'!$D:$D,'consolidated tracker'!Q:Q) -> 0 | S6: =_xlfn.XLOOKUP($D6,'consolidated tracker'!$D:$D,'consolidated tracker'!R:R) -> 0 | T6: =_xlfn.XLOOKUP($D6,'consolidated tracker'!$D:$D,'consolidated tracker'!S:S) -> 0 | U6: =_xlfn.XLOOKUP($D6,'consolidated tracker'!$D:$D,'consolidated tracker'!T:T) -> 0 | V6: =_xlfn.XLOOKUP($D6,'consolidated tracker'!$D:$D,'consolidated tracker'!U:U) -> 0 | W6: =_xlfn.XLOOKUP($D6,'consolidated tracker'!$D:$D,'consolidated tracker'!V:V) -> 0 | X6: =_xlfn.XLOOKUP($D6,'consolidated tracker'!$D:$D,'consolidated tracker'!W:W) -> 0
D7: Creek vista heights tower B | E7: =_xlfn.XLOOKUP(D7,'consolidated tracker'!D:D,'consolidated tracker'!E:E) -> RERA | F7: 46265 | G7: =_xlfn.XLOOKUP(D7,'consolidated tracker'!D:D,'consolidated tracker'!F:F) -> 681 | H7: =_xlfn.XLOOKUP(D7,'consolidated tracker'!D:D,'consolidated tracker'!G:G) -> 1.4709835e+09 | I7: =_xlfn.XLOOKUP(D7,'consolidated tracker'!D:D,'consolidated tracker'!H:H) -> 8.8972357e+08 | J7: =_xlfn.XLOOKUP(D7,'consolidated tracker'!D:D,'consolidated tracker'!I:I) -> 8.7732214e+08 | K7: =_xlfn.XLOOKUP(D7,'consolidated tracker'!D:D,'consolidated tracker'!J:J) -> 1.0895002e+08 | L7: =_xlfn.XLOOKUP(D7,'consolidated tracker'!D:D,'consolidated tracker'!K:K) -> 0.98606149 | M7: =_xlfn.XLOOKUP('consolidated - Offplan'!D7,'consolidated tracker'!D:D,'consolidated tracker'!L:L) -> 12401425 | N7: =_xlfn.XLOOKUP($D7,'consolidated tracker'!$D:$D,'consolidated tracker'!M:M) -> 4.723099e+08 | O7: =_xlfn.XLOOKUP($D7,'consolidated tracker'!$D:$D,'consolidated tracker'!N:N) -> 4.723099e+08 | P7: =_xlfn.XLOOKUP($D7,'consolidated tracker'!$D:$D,'consolidated tracker'!O:O) -> 0 | Q7: =_xlfn.XLOOKUP($D7,'consolidated tracker'!$D:$D,'consolidated tracker'!P:P) -> 0 | R7: =_xlfn.XLOOKUP($D7,'consolidated tracker'!$D:$D,'consolidated tracker'!Q:Q) -> 0 | S7: =_xlfn.XLOOKUP($D7,'consolidated tracker'!$D:$D,'consolidated tracker'!R:R) -> 0 | T7: =_xlfn.XLOOKUP($D7,'consolidated tracker'!$D:$D,'consolidated tracker'!S:S) -> 0 | U7: =_xlfn.XLOOKUP($D7,'consolidated tracker'!$D:$D,'consolidated tracker'!T:T) -> 0 | V7: =_xlfn.XLOOKUP($D7,'consolidated tracker'!$D:$D,'consolidated tracker'!U:U) -> 0 | W7: =_xlfn.XLOOKUP($D7,'consolidated tracker'!$D:$D,'consolidated tracker'!V:V) -> 0 | X7: =_xlfn.XLOOKUP($D7,'consolidated tracker'!$D:$D,'consolidated tracker'!W:W) -> 0
D8: Creek vista heights retail | E8: =_xlfn.XLOOKUP(D8,'consolidated tracker'!D:D,'consolidated tracker'!E:E) -> RERA | F8: 46203 | G8: =_xlfn.XLOOKUP(D8,'consolidated tracker'!D:D,'consolidated tracker'!F:F) -> 12 | H8: =_xlfn.XLOOKUP(D8,'consolidated tracker'!D:D,'consolidated tracker'!G:G) -> 52345357 | I8: =_xlfn.XLOOKUP(D8,'consolidated tracker'!D:D,'consolidated tracker'!H:H) -> 32382061 | J8: =_xlfn.XLOOKUP(D8,'consolidated tracker'!D:D,'consolidated tracker'!I:I) -> 32010669 | K8: =_xlfn.XLOOKUP(D8,'consolidated tracker'!D:D,'consolidated tracker'!J:J) -> 8187994 | L8: =_xlfn.XLOOKUP(D8,'consolidated tracker'!D:D,'consolidated tracker'!K:K) -> 0.98853095 | M8: =_xlfn.XLOOKUP('consolidated - Offplan'!D8,'consolidated tracker'!D:D,'consolidated tracker'!L:L) -> 316330 | N8: =_xlfn.XLOOKUP($D8,'consolidated tracker'!$D:$D,'consolidated tracker'!M:M) -> 11775303 | O8: =_xlfn.XLOOKUP($D8,'consolidated tracker'!$D:$D,'consolidated tracker'!N:N) -> 11775303 | P8: =_xlfn.XLOOKUP($D8,'consolidated tracker'!$D:$D,'consolidated tracker'!O:O) -> 0 | Q8: =_xlfn.XLOOKUP($D8,'consolidated tracker'!$D:$D,'consolidated tracker'!P:P) -> 0 | R8: =_xlfn.XLOOKUP($D8,'consolidated tracker'!$D:$D,'consolidated tracker'!Q:Q) -> 0 | S8: =_xlfn.XLOOKUP($D8,'consolidated tracker'!$D:$D,'consolidated tracker'!R:R) -> 0 | T8: =_xlfn.XLOOKUP($D8,'consolidated tracker'!$D:$D,'consolidated tracker'!S:S) -> 0 | U8: =_xlfn.XLOOKUP($D8,'consolidated tracker'!$D:$D,'consolidated tracker'!T:T) -> 0 | V8: =_xlfn.XLOOKUP($D8,'consolidated tracker'!$D:$D,'consolidated tracker'!U:U) -> 0 | W8: =_xlfn.XLOOKUP($D8,'consolidated tracker'!$D:$D,'consolidated tracker'!V:V) -> 0 | X8: =_xlfn.XLOOKUP($D8,'consolidated tracker'!$D:$D,'consolidated tracker'!W:W) -> 0
C9: =+C5+1 -> 3 | D9: Sea Haven | E9: =_xlfn.XLOOKUP(D9,'consolidated tracker'!D:D,'consolidated tracker'!E:E) -> RERA | F9: - | G9: =_xlfn.XLOOKUP(D9,'consolidated tracker'!D:D,'consolidated tracker'!F:F) -> 680 | H9: =_xlfn.XLOOKUP(D9,'consolidated tracker'!D:D,'consolidated tracker'!G:G) -> 5.3019632e+09 | I9: =_xlfn.XLOOKUP(D9,'consolidated tracker'!D:D,'consolidated tracker'!H:H) -> 3.0618523e+09 | J9: =_xlfn.XLOOKUP(D9,'consolidated tracker'!D:D,'consolidated tracker'!I:I) -> 2.8612734e+09 | K9: =_xlfn.XLOOKUP(D9,'consolidated tracker'!D:D,'consolidated tracker'!J:J) -> 2.5897524e+08 | L9: =_xlfn.XLOOKUP(D9,'consolidated tracker'!D:D,'consolidated tracker'!K:K) -> 0.93449097 | M9: =_xlfn.XLOOKUP('consolidated - Offplan'!D9,'consolidated tracker'!D:D,'consolidated tracker'!L:L) -> 2.0057897e+08 | N9: =_xlfn.XLOOKUP($D9,'consolidated tracker'!$D:$D,'consolidated tracker'!M:M) -> 1.9811356e+09 | O9: =_xlfn.XLOOKUP($D9,'consolidated tracker'!$D:$D,'consolidated tracker'!N:N) -> 9.6545294e+08 | P9: =_xlfn.XLOOKUP($D9,'consolidated tracker'!$D:$D,'consolidated tracker'!O:O) -> 1.0156827e+09 | Q9: =_xlfn.XLOOKUP($D9,'consolidated tracker'!$D:$D,'consolidated tracker'!P:P) -> 0 | R9: =_xlfn.XLOOKUP($D9,'consolidated tracker'!$D:$D,'consolidated tracker'!Q:Q) -> 0 | S9: =_xlfn.XLOOKUP($D9,'consolidated tracker'!$D:$D,'consolidated tracker'!R:R) -> 0 | T9: =_xlfn.XLOOKUP($D9,'consolidated tracker'!$D:$D,'consolidated tracker'!S:S) -> 0 | U9: =_xlfn.XLOOKUP($D9,'consolidated tracker'!$D:$D,'consolidated tracker'!T:T) -> 0 | V9: =_xlfn.XLOOKUP($D9,'consolidated tracker'!$D:$D,'consolidated tracker'!U:U) -> 0 | W9: =_xlfn.XLOOKUP($D9,'consolidated tracker'!$D:$D,'consolidated tracker'!V:V) -> 0 | X9: =_xlfn.XLOOKUP($D9,'consolidated tracker'!$D:$D,'consolidated tracker'!W:W) -> 0
D10: Sea Haven Tower A | E10: =_xlfn.XLOOKUP(D10,'consolidated tracker'!D:D,'consolidated tracker'!E:E) -> RERA | F10: 46387 | G10: =_xlfn.XLOOKUP(D10,'consolidated tracker'!D:D,'consolidated tracker'!F:F) -> 315 | H10: =_xlfn.XLOOKUP(D10,'consolidated tracker'!D:D,'consolidated tracker'!G:G) -> 2.6154909e+09 | I10: =_xlfn.XLOOKUP(D10,'consolidated tracker'!D:D,'consolidated tracker'!H:H) -> 1.736494e+09 | J10: =_xlfn.XLOOKUP(D10,'consolidated tracker'!D:D,'consolidated tracker'!I:I) -> 1.6042163e+09 | K10: =_xlfn.XLOOKUP(D10,'consolidated tracker'!D:D,'consolidated tracker'!J:J) -> 1.4571977e+08 | L10: =_xlfn.XLOOKUP(D10,'consolidated tracker'!D:D,'consolidated tracker'!K:K) -> 0.92382487 | M10: =_xlfn.XLOOKUP('consolidated - Offplan'!D10,'consolidated tracker'!D:D,'consolidated tracker'!L:L) -> 1.3227765e+08 | N10: =_xlfn.XLOOKUP($D10,'consolidated tracker'!$D:$D,'consolidated tracker'!M:M) -> 7.3327714e+08 | O10: =_xlfn.XLOOKUP($D10,'consolidated tracker'!$D:$D,'consolidated tracker'!N:N) -> 7.3327714e+08 | P10: =_xlfn.XLOOKUP($D10,'consolidated tracker'!$D:$D,'consolidated tracker'!O:O) -> 0 | Q10: =_xlfn.XLOOKUP($D10,'consolidated tracker'!$D:$D,'consolidated tracker'!P:P) -> 0 | R10: =_xlfn.XLOOKUP($D10,'consolidated tracker'!$D:$D,'consolidated tracker'!Q:Q) -> 0 | S10: =_xlfn.XLOOKUP($D10,'consolidated tracker'!$D:$D,'consolidated tracker'!R:R) -> 0 | T10: =_xlfn.XLOOKUP($D10,'consolidated tracker'!$D:$D,'consolidated tracker'!S:S) -> 0 | U10: =_xlfn.XLOOKUP($D10,'consolidated tracker'!$D:$D,'consolidated tracker'!T:T) -> 0 | V10: =_xlfn.XLOOKUP($D10,'consolidated tracker'!$D:$D,'consolidated tracker'!U:U) -> 0 | W10: =_xlfn.XLOOKUP($D10,'consolidated tracker'!$D:$D,'consolidated tracker'!V:V) -> 0 | X10: =_xlfn.XLOOKUP($D10,'consolidated tracker'!$D:$D,'consolidated tracker'!W:W) -> 0
D11: Sea Haven Tower B | E11: =_xlfn.XLOOKUP(D11,'consolidated tracker'!D:D,'consolidated tracker'!E:E) -> RERA | F11: 46630 | G11: =_xlfn.XLOOKUP(D11,'consolidated tracker'!D:D,'consolidated tracker'!F:F) -> 223 | H11: =_xlfn.XLOOKUP(D11,'consolidated tracker'!D:D,'consolidated tracker'!G:G) -> 1.5122856e+09 | I11: =_xlfn.XLOOKUP(D11,'consolidated tracker'!D:D,'consolidated tracker'!H:H) -> 7.9933232e+08 | J11: =_xlfn.XLOOKUP(D11,'consolidated tracker'!D:D,'consolidated tracker'!I:I) -> 7.6172395e+08 | K11: =_xlfn.XLOOKUP(D11,'consolidated tracker'!D:D,'consolidated tracker'!J:J) -> 33855061 | L11: =_xlfn.XLOOKUP(D11,'consolidated tracker'!D:D,'consolidated tracker'!K:K) -> 0.95295027 | M11: =_xlfn.XLOOKUP('consolidated - Offplan'!D11,'consolidated tracker'!D:D,'consolidated tracker'!L:L) -> 37608372 | N11: =_xlfn.XLOOKUP($D11,'consolidated tracker'!$D:$D,'consolidated tracker'!M:M) -> 6.7909826e+08 | O11: =_xlfn.XLOOKUP($D11,'consolidated tracker'!$D:$D,'consolidated tracker'!N:N) -> 1.3857051e+08 | P11: =_xlfn.XLOOKUP($D11,'consolidated tracker'!$D:$D,'consolidated tracker'!O:O) -> 5.4052775e+08 | Q11: =_xlfn.XLOOKUP($D11,'consolidated tracker'!$D:$D,'consolidated tracker'!P:P) -> 0 | R11: =_xlfn.XLOOKUP($D11,'consolidated tracker'!$D:$D,'consolidated tracker'!Q:Q) -> 0 | S11: =_xlfn.XLOOKUP($D11,'consolidated tracker'!$D:$D,'consolidated tracker'!R:R) -> 0 | T11: =_xlfn.XLOOKUP($D11,'consolidated tracker'!$D:$D,'consolidated tracker'!S:S) -> 0 | U11: =_xlfn.XLOOKUP($D11,'consolidated tracker'!$D:$D,'consolidated tracker'!T:T) -> 0 | V11: =_xlfn.XLOOKUP($D11,'consolidated tracker'!$D:$D,'consolidated tracker'!U:U) -> 0 | W11: =_xlfn.XLOOKUP($D11,'consolidated tracker'!$D:$D,'consolidated tracker'!V:V) -> 0 | X11: =_xlfn.XLOOKUP($D11,'consolidated tracker'!$D:$D,'consolidated tracker'!W:W) -> 0
D12: Sea Haven Tower C | E12: =_xlfn.XLOOKUP(D12,'consolidated tracker'!D:D,'consolidated tracker'!E:E) -> RERA | F12: 46630 | G12: =_xlfn.XLOOKUP(D12,'consolidated tracker'!D:D,'consolidated tracker'!F:F) -> 142 | H12: =_xlfn.XLOOKUP(D12,'consolidated tracker'!D:D,'consolidated tracker'!G:G) -> 1.1741867e+09 | I12: =_xlfn.XLOOKUP(D12,'consolidated tracker'!D:D,'consolidated tracker'!H:H) -> 5.2602603e+08 | J12: =_xlfn.XLOOKUP(D12,'consolidated tracker'!D:D,'consolidated tracker'!I:I) -> 4.9533309e+08 | K12: =_xlfn.XLOOKUP(D12,'consolidated tracker'!D:D,'consolidated tracker'!J:J) -> 79400407 | L12: =_xlfn.XLOOKUP(D12,'consolidated tracker'!D:D,'consolidated tracker'!K:K) -> 0.94165128 | M12: =_xlfn.XLOOKUP('consolidated - Offplan'!D12,'consolidated tracker'!D:D,'consolidated tracker'!L:L) -> 30692945 | N12: =_xlfn.XLOOKUP($D12,'consolidated tracker'!$D:$D,'consolidated tracker'!M:M) -> 5.6876024e+08 | O12: =_xlfn.XLOOKUP($D12,'consolidated tracker'!$D:$D,'consolidated tracker'!N:N) -> 93605285 | P12: =_xlfn.XLOOKUP($D12,'consolidated tracker'!$D:$D,'consolidated tracker'!O:O) -> 4.7515495e+08 | Q12: =_xlfn.XLOOKUP($D12,'consolidated tracker'!$D:$D,'consolidated tracker'!P:P) -> 0 | R12: =_xlfn.XLOOKUP($D12,'consolidated tracker'!$D:$D,'consolidated tracker'!Q:Q) -> 0 | S12: =_xlfn.XLOOKUP($D12,'consolidated tracker'!$D:$D,'consolidated tracker'!R:R) -> 0 | T12: =_xlfn.XLOOKUP($D12,'consolidated tracker'!$D:$D,'consolidated tracker'!S:S) -> 0 | U12: =_xlfn.XLOOKUP($D12,'consolidated tracker'!$D:$D,'consolidated tracker'!T:T) -> 0 | V12: =_xlfn.XLOOKUP($D12,'consolidated tracker'!$D:$D,'consolidated tracker'!U:U) -> 0 | W12: =_xlfn.XLOOKUP($D12,'consolidated tracker'!$D:$D,'consolidated tracker'!V:V) -> 0 | X12: =_xlfn.XLOOKUP($D12,'consolidated tracker'!$D:$D,'consolidated tracker'!W:W) -> 0
C13: 4 | D13: Verde | E13: =_xlfn.XLOOKUP(D13,'consolidated tracker'!D:D,'consolidated tracker'!E:E) -> RERA | F13: 46326 | G13: =_xlfn.XLOOKUP(D13,'consolidated tracker'!D:D,'consolidated tracker'!F:F) -> 606 | H13: =_xlfn.XLOOKUP(D13,'consolidated tracker'!D:D,'consolidated tracker'!G:G) -> 1.5355297e+09 | I13: =_xlfn.XLOOKUP(D13,'consolidated tracker'!D:D,'consolidated tracker'!H:H) -> 8.9106197e+08 | J13: =_xlfn.XLOOKUP(D13,'consolidated tracker'!D:D,'consolidated tracker'!I:I) -> 8.6332707e+08 | K13: =_xlfn.XLOOKUP(D13,'consolidated tracker'!D:D,'consolidated tracker'!J:J) -> 62673788 | L13: =_xlfn.XLOOKUP(D13,'consolidated tracker'!D:D,'consolidated tracker'!K:K) -> 0.96887433 | M13: =_xlfn.XLOOKUP('consolidated - Offplan'!D13,'consolidated tracker'!D:D,'consolidated tracker'!L:L) -> 27734901 | N13: =_xlfn.XLOOKUP($D13,'consolidated tracker'!$D:$D,'consolidated tracker'!M:M) -> 5.8179392e+08 | O13: =_xlfn.XLOOKUP($D13,'consolidated tracker'!$D:$D,'consolidated tracker'!N:N) -> 5.8179392e+08 | P13: =_xlfn.XLOOKUP($D13,'consolidated tracker'!$D:$D,'consolidated tracker'!O:O) -> 0 | Q13: =_xlfn.XLOOKUP($D13,'consolidated tracker'!$D:$D,'consolidated tracker'!P:P) -> 0 | R13: =_xlfn.XLOOKUP($D13,'consolidated tracker'!$D:$D,'consolidated tracker'!Q:Q) -> 0 | S13: =_xlfn.XLOOKUP($D13,'consolidated tracker'!$D:$D,'consolidated tracker'!R:R) -> 0 | T13: =_xlfn.XLOOKUP($D13,'consolidated tracker'!$D:$D,'consolidated tracker'!S:S) -> 0 | U13: =_xlfn.XLOOKUP($D13,'consolidated tracker'!$D:$D,'consolidated tracker'!T:T) -> 0 | V13: =_xlfn.XLOOKUP($D13,'consolidated tracker'!$D:$D,'consolidated tracker'!U:U) -> 0 | W13: =_xlfn.XLOOKUP($D13,'consolidated tracker'!$D:$D,'consolidated tracker'!V:V) -> 0 | X13: =_xlfn.XLOOKUP($D13,'consolidated tracker'!$D:$D,'consolidated tracker'!W:W) -> 0
C14: 5 | D14: Hartland II Villas & Mansion | E14: =_xlfn.XLOOKUP(D14,'consolidated tracker'!D:D,'consolidated tracker'!E:E) -> RERA | F14: 46387 | G14: =_xlfn.XLOOKUP(D14,'consolidated tracker'!D:D,'consolidated tracker'!F:F) -> 104 | H14: =_xlfn.XLOOKUP(D14,'consolidated tracker'!D:D,'consolidated tracker'!G:G) -> 2.9660575e+09 | I14: =_xlfn.XLOOKUP(D14,'consolidated tracker'!D:D,'consolidated tracker'!H:H) -> 1.6191306e+09 | J14: =_xlfn.XLOOKUP(D14,'consolidated tracker'!D:D,'consolidated tracker'!I:I) -> 1.5053489e+09 | K14: =_xlfn.XLOOKUP(D14,'consolidated tracker'!D:D,'consolidated tracker'!J:J) -> 2.1435543e+08 | L14: =_xlfn.XLOOKUP(D14,'consolidated tracker'!D:D,'consolidated tracker'!K:K) -> 0.92972664 | M14: =_xlfn.XLOOKUP('consolidated - Offplan'!D14,'consolidated tracker'!D:D,'consolidated tracker'!L:L) -> 1.1378175e+08 | N14: =_xlfn.XLOOKUP($D14,'consolidated tracker'!$D:$D,'consolidated tracker'!M:M) -> 1.1325715e+09 | O14: =_xlfn.XLOOKUP($D14,'consolidated tracker'!$D:$D,'consolidated tracker'!N:N) -> 6.1935862e+08 | P14: =_xlfn.XLOOKUP($D14,'consolidated tracker'!$D:$D,'consolidated tracker'!O:O) -> 5.1321284e+08 | Q14: =_xlfn.XLOOKUP($D14,'consolidated tracker'!$D:$D,'consolidated tracker'!P:P) -> 0 | R14: =_xlfn.XLOOKUP($D14,'consolidated tracker'!$D:$D,'consolidated tracker'!Q:Q) -> 0 | S14: =_xlfn.XLOOKUP($D14,'consolidated tracker'!$D:$D,'consolidated tracker'!R:R) -> 0 | T14: =_xlfn.XLOOKUP($D14,'consolidated tracker'!$D:$D,'consolidated tracker'!S:S) -> 0 | U14: =_xlfn.XLOOKUP($D14,'consolidated tracker'!$D:$D,'consolidated tracker'!T:T) -> 0 | V14: =_xlfn.XLOOKUP($D14,'consolidated tracker'!$D:$D,'consolidated tracker'!U:U) -> 0 | W14: =_xlfn.XLOOKUP($D14,'consolidated tracker'!$D:$D,'consolidated tracker'!V:V) -> 0 | X14: =_xlfn.XLOOKUP($D14,'consolidated tracker'!$D:$D,'consolidated tracker'!W:W) -> 0
D15: Hartland II Villas | E15: =_xlfn.XLOOKUP(D15,'consolidated tracker'!D:D,'consolidated tracker'!E:E) -> RERA | F15: 46203 | G15: =_xlfn.XLOOKUP(D15,'consolidated tracker'!D:D,'consolidated tracker'!F:F) -> 54 | H15: =_xlfn.XLOOKUP(D15,'consolidated tracker'!D:D,'consolidated tracker'!G:G) -> 1.5048054e+09 | I15: =_xlfn.XLOOKUP(D15,'consolidated tracker'!D:D,'consolidated tracker'!H:H) -> 1.063549e+09 | J15: =_xlfn.XLOOKUP(D15,'consolidated tracker'!D:D,'consolidated tracker'!I:I) -> 1.0353335e+09 | K15: =_xlfn.XLOOKUP(D15,'consolidated tracker'!D:D,'consolidated tracker'!J:J) -> 73147087 | L15: =_xlfn.XLOOKUP(D15,'consolidated tracker'!D:D,'consolidated tracker'!K:K) -> 0.97347042 | M15: =_xlfn.XLOOKUP('consolidated - Offplan'!D15,'consolidated tracker'!D:D,'consolidated tracker'!L:L) -> 28215504 | N15: =_xlfn.XLOOKUP($D15,'consolidated tracker'!$D:$D,'consolidated tracker'!M:M) -> 3.681093e+08 | O15: =_xlfn.XLOOKUP($D15,'consolidated tracker'!$D:$D,'consolidated tracker'!N:N) -> 3.681093e+08 | P15: =_xlfn.XLOOKUP($D15,'consolidated tracker'!$D:$D,'consolidated tracker'!O:O) -> 0 | Q15: =_xlfn.XLOOKUP($D15,'consolidated tracker'!$D:$D,'consolidated tracker'!P:P) -> 0 | R15: =_xlfn.XLOOKUP($D15,'consolidated tracker'!$D:$D,'consolidated tracker'!Q:Q) -> 0 | S15: =_xlfn.XLOOKUP($D15,'consolidated tracker'!$D:$D,'consolidated tracker'!R:R) -> 0 | T15: =_xlfn.XLOOKUP($D15,'consolidated tracker'!$D:$D,'consolidated tracker'!S:S) -> 0 | U15: =_xlfn.XLOOKUP($D15,'consolidated tracker'!$D:$D,'consolidated tracker'!T:T) -> 0 | V15: =_xlfn.XLOOKUP($D15,'consolidated tracker'!$D:$D,'consolidated tracker'!U:U) -> 0 | W15: =_xlfn.XLOOKUP($D15,'consolidated tracker'!$D:$D,'consolidated tracker'!V:V) -> 0 | X15: =_xlfn.XLOOKUP($D15,'consolidated tracker'!$D:$D,'consolidated tracker'!W:W) -> 0
D16: Hartland II Mansion | E16: =_xlfn.XLOOKUP(D16,'consolidated tracker'!D:D,'consolidated tracker'!E:E) -> RERA | F16: 46387 | G16: =_xlfn.XLOOKUP(D16,'consolidated tracker'!D:D,'consolidated tracker'!F:F) -> 1 | H16: =_xlfn.XLOOKUP(D16,'consolidated tracker'!D:D,'consolidated tracker'!G:G) -> 130000000 | I16: =_xlfn.XLOOKUP(D16,'consolidated tracker'!D:D,'consolidated tracker'!H:H) -> 78000000 | J16: =_xlfn.XLOOKUP(D16,'consolidated tracker'!D:D,'consolidated tracker'!I:I) -> 78000000 | K16: =_xlfn.XLOOKUP(D16,'consolidated tracker'!D:D,'consolidated tracker'!J:J) -> 0 | L16: =_xlfn.XLOOKUP(D16,'consolidated tracker'!D:D,'consolidated tracker'!K:K) -> 1 | M16: =_xlfn.XLOOKUP('consolidated - Offplan'!D16,'consolidated tracker'!D:D,'consolidated tracker'!L:L) -> 0 | N16: =_xlfn.XLOOKUP($D16,'consolidated tracker'!$D:$D,'consolidated tracker'!M:M) -> 52000000 | O16: =_xlfn.XLOOKUP($D16,'consolidated tracker'!$D:$D,'consolidated tracker'!N:N) -> 52000000 | P16: =_xlfn.XLOOKUP($D16,'consolidated tracker'!$D:$D,'consolidated tracker'!O:O) -> 0 | Q16: =_xlfn.XLOOKUP($D16,'consolidated tracker'!$D:$D,'consolidated tracker'!P:P) -> 0 | R16: =_xlfn.XLOOKUP($D16,'consolidated tracker'!$D:$D,'consolidated tracker'!Q:Q) -> 0 | S16: =_xlfn.XLOOKUP($D16,'consolidated tracker'!$D:$D,'consolidated tracker'!R:R) -> 0 | T16: =_xlfn.XLOOKUP($D16,'consolidated tracker'!$D:$D,'consolidated tracker'!S:S) -> 0 | U16: =_xlfn.XLOOKUP($D16,'consolidated tracker'!$D:$D,'consolidated tracker'!T:T) -> 0 | V16: =_xlfn.XLOOKUP($D16,'consolidated tracker'!$D:$D,'consolidated tracker'!U:U) -> 0 | W16: =_xlfn.XLOOKUP($D16,'consolidated tracker'!$D:$D,'consolidated tracker'!V:V) -> 0 | X16: =_xlfn.XLOOKUP($D16,'consolidated tracker'!$D:$D,'consolidated tracker'!W:W) -> 0
D17: Hartland II Villas-Phase II | E17: =_xlfn.XLOOKUP(D17,'consolidated tracker'!D:D,'consolidated tracker'!E:E) -> RERA | F17: 46387 | G17: =_xlfn.XLOOKUP(D17,'consolidated tracker'!D:D,'consolidated tracker'!F:F) -> 48 | H17: =_xlfn.XLOOKUP(D17,'consolidated tracker'!D:D,'consolidated tracker'!G:G) -> 1266411551 | I17: =_xlfn.XLOOKUP(D17,'consolidated tracker'!D:D,'consolidated tracker'!H:H) -> 4.7109756e+08 | J17: =_xlfn.XLOOKUP(D17,'consolidated tracker'!D:D,'consolidated tracker'!I:I) -> 3.8553132e+08 | K17: =_xlfn.XLOOKUP(D17,'consolidated tracker'!D:D,'consolidated tracker'!J:J) -> 85186086 | L17: =_xlfn.XLOOKUP(D17,'consolidated tracker'!D:D,'consolidated tracker'!K:K) -> 0.81836831 | M17: =_xlfn.XLOOKUP('consolidated - Offplan'!D17,'consolidated tracker'!D:D,'consolidated tracker'!L:L) -> 85566244 | N17: =_xlfn.XLOOKUP($D17,'consolidated tracker'!$D:$D,'consolidated tracker'!M:M) -> 7.1012791e+08 | O17: =_xlfn.XLOOKUP($D17,'consolidated tracker'!$D:$D,'consolidated tracker'!N:N) -> 1.9691507e+08 | P17: =_xlfn.XLOOKUP($D17,'consolidated tracker'!$D:$D,'consolidated tracker'!O:O) -> 5.1321284e+08 | Q17: =_xlfn.XLOOKUP($D17,'consolidated tracker'!$D:$D,'consolidated tracker'!P:P) -> 0 | R17: =_xlfn.XLOOKUP($D17,'consolidated tracker'!$D:$D,'consolidated tracker'!Q:Q) -> 0 | S17: =_xlfn.XLOOKUP($D17,'consolidated tracker'!$D:$D,'consolidated tracker'!R:R) -> 0 | T17: =_xlfn.XLOOKUP($D17,'consolidated tracker'!$D:$D,'consolidated tracker'!S:S) -> 0 | U17: =_xlfn.XLOOKUP($D17,'consolidated tracker'!$D:$D,'consolidated tracker'!T:T) -> 0 | V17: =_xlfn.XLOOKUP($D17,'consolidated tracker'!$D:$D,'consolidated tracker'!U:U) -> 0 | W17: =_xlfn.XLOOKUP($D17,'consolidated tracker'!$D:$D,'consolidated tracker'!V:V) -> 0 | X17: =_xlfn.XLOOKUP($D17,'consolidated tracker'!$D:$D,'consolidated tracker'!W:W) -> 0
D18: Hartland II Villas 6BR | E18: =_xlfn.XLOOKUP(D18,'consolidated tracker'!D:D,'consolidated tracker'!E:E) -> RERA | F18: - | G18: =_xlfn.XLOOKUP(D18,'consolidated tracker'!D:D,'consolidated tracker'!F:F) -> 1 | H18: =_xlfn.XLOOKUP(D18,'consolidated tracker'!D:D,'consolidated tracker'!G:G) -> 64840575 | I18: =_xlfn.XLOOKUP(D18,'consolidated tracker'!D:D,'consolidated tracker'!H:H) -> 6484057.5 | J18: =_xlfn.XLOOKUP(D18,'consolidated tracker'!D:D,'consolidated tracker'!I:I) -> 6484057.5 | K18: =_xlfn.XLOOKUP(D18,'consolidated tracker'!D:D,'consolidated tracker'!J:J) -> 56022258 | L18: =_xlfn.XLOOKUP(D18,'consolidated tracker'!D:D,'consolidated tracker'!K:K) -> 1 | M18: =_xlfn.XLOOKUP('consolidated - Offplan'!D18,'consolidated tracker'!D:D,'consolidated tracker'!L:L) -> 0 | N18: =_xlfn.XLOOKUP($D18,'consolidated tracker'!$D:$D,'consolidated tracker'!M:M) -> 2334260 | O18: =_xlfn.XLOOKUP($D18,'consolidated tracker'!$D:$D,'consolidated tracker'!N:N) -> 2334260 | P18: =_xlfn.XLOOKUP($D18,'consolidated tracker'!$D:$D,'consolidated tracker'!O:O) -> 0 | Q18: =_xlfn.XLOOKUP($D18,'consolidated tracker'!$D:$D,'consolidated tracker'!P:P) -> 0 | R18: =_xlfn.XLOOKUP($D18,'consolidated tracker'!$D:$D,'consolidated tracker'!Q:Q) -> 0 | S18: =_xlfn.XLOOKUP($D18,'consolidated tracker'!$D:$D,'consolidated tracker'!R:R) -> 0 | T18: =_xlfn.XLOOKUP($D18,'consolidated tracker'!$D:$D,'consolidated tracker'!S:S) -> 0 | U18: =_xlfn.XLOOKUP($D18,'consolidated tracker'!$D:$D,'consolidated tracker'!T:T) -> 0 | V18: =_xlfn.XLOOKUP($D18,'consolidated tracker'!$D:$D,'consolidated tracker'!U:U) -> 0 | W18: =_xlfn.XLOOKUP($D18,'consolidated tracker'!$D:$D,'consolidated tracker'!V:V) -> 0 | X18: =_xlfn.XLOOKUP($D18,'consolidated tracker'!$D:$D,'consolidated tracker'!W:W) -> 0
C19: 6 | D19: Sobha Reserve Villas | E19: =_xlfn.XLOOKUP(D19,'consolidated tracker'!D:D,'consolidated tracker'!E:E) -> RERA | F19: 46203 | G19: =_xlfn.XLOOKUP(D19,'consolidated tracker'!D:D,'consolidated tracker'!F:F) -> 345 | H19: =_xlfn.XLOOKUP(D19,'consolidated tracker'!D:D,'consolidated tracker'!G:G) -> 3.1842319e+09 | I19: =_xlfn.XLOOKUP(D19,'consolidated tracker'!D:D,'consolidated tracker'!H:H) -> 2.1189632e+09 | J19: =_xlfn.XLOOKUP(D19,'consolidated tracker'!D:D,'consolidated tracker'!I:I) -> 2.004563e+09 | K19: =_xlfn.XLOOKUP(D19,'consolidated tracker'!D:D,'consolidated tracker'!J:J) -> 1.12388e+08 | L19: =_xlfn.XLOOKUP(D19,'consolidated tracker'!D:D,'consolidated tracker'!K:K) -> 0.94601126 | M19: =_xlfn.XLOOKUP('consolidated - Offplan'!D19,'consolidated tracker'!D:D,'consolidated tracker'!L:L) -> 1.1440014e+08 | N19: =_xlfn.XLOOKUP($D19,'consolidated tracker'!$D:$D,'consolidated tracker'!M:M) -> 9.528807e+08 | O19: =_xlfn.XLOOKUP($D19,'consolidated tracker'!$D:$D,'consolidated tracker'!N:N) -> 5.2005271e+08 | P19: =_xlfn.XLOOKUP($D19,'consolidated tracker'!$D:$D,'consolidated tracker'!O:O) -> 4.2889717e+08 | Q19: =_xlfn.XLOOKUP($D19,'consolidated tracker'!$D:$D,'consolidated tracker'!P:P) -> 750000 | R19: =_xlfn.XLOOKUP($D19,'consolidated tracker'!$D:$D,'consolidated tracker'!Q:Q) -> 750000 | S19: =_xlfn.XLOOKUP($D19,'consolidated tracker'!$D:$D,'consolidated tracker'!R:R) -> 1000000 | T19: =_xlfn.XLOOKUP($D19,'consolidated tracker'!$D:$D,'consolidated tracker'!S:S) -> 1430823 | U19: =_xlfn.XLOOKUP($D19,'consolidated tracker'!$D:$D,'consolidated tracker'!T:T) -> 0 | V19: =_xlfn.XLOOKUP($D19,'consolidated tracker'!$D:$D,'consolidated tracker'!U:U) -> 0 | W19: =_xlfn.XLOOKUP($D19,'consolidated tracker'!$D:$D,'consolidated tracker'!V:V) -> 0 | X19: =_xlfn.XLOOKUP($D19,'consolidated tracker'!$D:$D,'consolidated tracker'!W:W) -> 0
C20: 7 | D20: Sobha One | E20: =_xlfn.XLOOKUP(D20,'consolidated tracker'!D:D,'consolidated tracker'!E:E) -> RERA | F20: - | G20: =_xlfn.XLOOKUP(D20,'consolidated tracker'!D:D,'consolidated tracker'!F:F) -> 2957 | H20: =_xlfn.XLOOKUP(D20,'consolidated tracker'!D:D,'consolidated tracker'!G:G) -> 6.9877767e+09 | I20: =_xlfn.XLOOKUP(D20,'consolidated tracker'!D:D,'consolidated tracker'!H:H) -> 3.7360142e+09 | J20: =_xlfn.XLOOKUP(D20,'consolidated tracker'!D:D,'consolidated tracker'!I:I) -> 3.5900023e+09 | K20: =_xlfn.XLOOKUP(D20,'consolidated tracker'!D:D,'consolidated tracker'!J:J) -> 3.1317277e+08 | L20: =_xlfn.XLOOKUP(D20,'consolidated tracker'!D:D,'consolidated tracker'!K:K) -> 0.96091772 | M20: =_xlfn.XLOOKUP('consolidated - Offplan'!D20,'consolidated tracker'!D:D,'consolidated tracker'!L:L) -> 1.4601195e+08 | N20: =_xlfn.XLOOKUP($D20,'consolidated tracker'!$D:$D,'consolidated tracker'!M:M) -> 2.9385897e+09 | O20: =_xlfn.XLOOKUP($D20,'consolidated tracker'!$D:$D,'consolidated tracker'!N:N) -> 2.9364198e+09 | P20: =_xlfn.XLOOKUP($D20,'consolidated tracker'!$D:$D,'consolidated tracker'!O:O) -> 2169916.8 | Q20: =_xlfn.XLOOKUP($D20,'consolidated tracker'!$D:$D,'consolidated tracker'!P:P) -> 0 | R20: =_xlfn.XLOOKUP($D20,'consolidated tracker'!$D:$D,'consolidated tracker'!Q:Q) -> 0 | S20: =_xlfn.XLOOKUP($D20,'consolidated tracker'!$D:$D,'consolidated tracker'!R:R) -> 0 | T20: =_xlfn.XLOOKUP($D20,'consolidated tracker'!$D:$D,'consolidated tracker'!S:S) -> 0 | U20: =_xlfn.XLOOKUP($D20,'consolidated tracker'!$D:$D,'consolidated tracker'!T:T) -> 0 | V20: =_xlfn.XLOOKUP($D20,'consolidated tracker'!$D:$D,'consolidated tracker'!U:U) -> 0 | W20: =_xlfn.XLOOKUP($D20,'consolidated tracker'!$D:$D,'consolidated tracker'!V:V) -> 0 | X20: =_xlfn.XLOOKUP($D20,'consolidated tracker'!$D:$D,'consolidated tracker'!W:W) -> 0
D21: Sobha One Tower A | E21: =_xlfn.XLOOKUP(D21,'consolidated tracker'!D:D,'consolidated tracker'!E:E) -> RERA | F21: 46387 | G21: =_xlfn.XLOOKUP(D21,'consolidated tracker'!D:D,'consolidated tracker'!F:F) -> 596 | H21: =_xlfn.XLOOKUP(D21,'consolidated tracker'!D:D,'consolidated tracker'!G:G) -> 1.437789e+09 | I21: =_xlfn.XLOOKUP(D21,'consolidated tracker'!D:D,'consolidated tracker'!H:H) -> 7.9624029e+08 | J21: =_xlfn.XLOOKUP(D21,'consolidated tracker'!D:D,'consolidated tracker'!I:I) -> 7.6298001e+08 | K21: =_xlfn.XLOOKUP(D21,'consolidated tracker'!D:D,'consolidated tracker'!J:J) -> 58937694 | L21: =_xlfn.XLOOKUP(D21,'consolidated tracker'!D:D,'consolidated tracker'!K:K) -> 0.95822833 | M21: =_xlfn.XLOOKUP('consolidated - Offplan'!D21,'consolidated tracker'!D:D,'consolidated tracker'!L:L) -> 33260288 | N21: =_xlfn.XLOOKUP($D21,'consolidated tracker'!$D:$D,'consolidated tracker'!M:M) -> 5.8261102e+08 | O21: =_xlfn.XLOOKUP($D21,'consolidated tracker'!$D:$D,'consolidated tracker'!N:N) -> 5.8261102e+08 | P21: =_xlfn.XLOOKUP($D21,'consolidated tracker'!$D:$D,'consolidated tracker'!O:O) -> 0 | Q21: =_xlfn.XLOOKUP($D21,'consolidated tracker'!$D:$D,'consolidated tracker'!P:P) -> 0 | R21: =_xlfn.XLOOKUP($D21,'consolidated tracker'!$D:$D,'consolidated tracker'!Q:Q) -> 0 | S21: =_xlfn.XLOOKUP($D21,'consolidated tracker'!$D:$D,'consolidated tracker'!R:R) -> 0 | T21: =_xlfn.XLOOKUP($D21,'consolidated tracker'!$D:$D,'consolidated tracker'!S:S) -> 0 | U21: =_xlfn.XLOOKUP($D21,'consolidated tracker'!$D:$D,'consolidated tracker'!T:T) -> 0 | V21: =_xlfn.XLOOKUP($D21,'consolidated tracker'!$D:$D,'consolidated tracker'!U:U) -> 0 | W21: =_xlfn.XLOOKUP($D21,'consolidated tracker'!$D:$D,'consolidated tracker'!V:V) -> 0 | X21: =_xlfn.XLOOKUP($D21,'consolidated tracker'!$D:$D,'consolidated tracker'!W:W) -> 0
D22: Sobha One Tower B | E22: =_xlfn.XLOOKUP(D22,'consolidated tracker'!D:D,'consolidated tracker'!E:E) -> RERA | F22: 46387 | G22: =_xlfn.XLOOKUP(D22,'consolidated tracker'!D:D,'consolidated tracker'!F:F) -> 860 | H22: =_xlfn.XLOOKUP(D22,'consolidated tracker'!D:D,'consolidated tracker'!G:G) -> 1.6496439e+09 | I22: =_xlfn.XLOOKUP(D22,'consolidated tracker'!D:D,'consolidated tracker'!H:H) -> 8.9362671e+08 | J22: =_xlfn.XLOOKUP(D22,'consolidated tracker'!D:D,'consolidated tracker'!I:I) -> 8.7130182e+08 | K22: =_xlfn.XLOOKUP(D22,'consolidated tracker'!D:D,'consolidated tracker'!J:J) -> 71956849 | L22: =_xlfn.XLOOKUP(D22,'consolidated tracker'!D:D,'consolidated tracker'!K:K) -> 0.97501765 | M22: =_xlfn.XLOOKUP('consolidated - Offplan'!D22,'consolidated tracker'!D:D,'consolidated tracker'!L:L) -> 22324893 | N22: =_xlfn.XLOOKUP($D22,'consolidated tracker'!$D:$D,'consolidated tracker'!M:M) -> 6.8406031e+08 | O22: =_xlfn.XLOOKUP($D22,'consolidated tracker'!$D:$D,'consolidated tracker'!N:N) -> 6.8406031e+08 | P22: =_xlfn.XLOOKUP($D22,'consolidated tracker'!$D:$D,'consolidated tracker'!O:O) -> 0 | Q22: =_xlfn.XLOOKUP($D22,'consolidated tracker'!$D:$D,'consolidated tracker'!P:P) -> 0 | R22: =_xlfn.XLOOKUP($D22,'consolidated tracker'!$D:$D,'consolidated tracker'!Q:Q) -> 0 | S22: =_xlfn.XLOOKUP($D22,'consolidated tracker'!$D:$D,'consolidated tracker'!R:R) -> 0 | T22: =_xlfn.XLOOKUP($D22,'consolidated tracker'!$D:$D,'consolidated tracker'!S:S) -> 0 | U22: =_xlfn.XLOOKUP($D22,'consolidated tracker'!$D:$D,'consolidated tracker'!T:T) -> 0 | V22: =_xlfn.XLOOKUP($D22,'consolidated tracker'!$D:$D,'consolidated tracker'!U:U) -> 0 | W22: =_xlfn.XLOOKUP($D22,'consolidated tracker'!$D:$D,'consolidated tracker'!V:V) -> 0 | X22: =_xlfn.XLOOKUP($D22,'consolidated tracker'!$D:$D,'consolidated tracker'!W:W) -> 0
D23: Sobha One Tower C | E23: =_xlfn.XLOOKUP(D23,'consolidated tracker'!D:D,'consolidated tracker'!E:E) -> RERA | F23: 46387 | G23: =_xlfn.XLOOKUP(D23,'consolidated tracker'!D:D,'consolidated tracker'!F:F) -> 390 | H23: =_xlfn.XLOOKUP(D23,'consolidated tracker'!D:D,'consolidated tracker'!G:G) -> 1.0204753e+09 | I23: =_xlfn.XLOOKUP(D23,'consolidated tracker'!D:D,'consolidated tracker'!H:H) -> 5.4504497e+08 | J23: =_xlfn.XLOOKUP(D23,'consolidated tracker'!D:D,'consolidated tracker'!I:I) -> 5.1869173e+08 | K23: =_xlfn.XLOOKUP(D23,'consolidated tracker'!D:D,'consolidated tracker'!J:J) -> 47445506 | L23: =_xlfn.XLOOKUP(D23,'consolidated tracker'!D:D,'consolidated tracker'!K:K) -> 0.95164942 | M23: =_xlfn.XLOOKUP('consolidated - Offplan'!D23,'consolidated tracker'!D:D,'consolidated tracker'!L:L) -> 26353241 | N23: =_xlfn.XLOOKUP($D23,'consolidated tracker'!$D:$D,'consolidated tracker'!M:M) -> 4.279848e+08 | O23: =_xlfn.XLOOKUP($D23,'consolidated tracker'!$D:$D,'consolidated tracker'!N:N) -> 4.262339e+08 | P23: =_xlfn.XLOOKUP($D23,'consolidated tracker'!$D:$D,'consolidated tracker'!O:O) -> 1750901.8 | Q23: =_xlfn.XLOOKUP($D23,'consolidated tracker'!$D:$D,'consolidated tracker'!P:P) -> 0 | R23: =_xlfn.XLOOKUP($D23,'consolidated tracker'!$D:$D,'consolidated tracker'!Q:Q) -> 0 | S23: =_xlfn.XLOOKUP($D23,'consolidated tracker'!$D:$D,'consolidated tracker'!R:R) -> 0 | T23: =_xlfn.XLOOKUP($D23,'consolidated tracker'!$D:$D,'consolidated tracker'!S:S) -> 0 | U23: =_xlfn.XLOOKUP($D23,'consolidated tracker'!$D:$D,'consolidated tracker'!T:T) -> 0 | V23: =_xlfn.XLOOKUP($D23,'consolidated tracker'!$D:$D,'consolidated tracker'!U:U) -> 0 | W23: =_xlfn.XLOOKUP($D23,'consolidated tracker'!$D:$D,'consolidated tracker'!V:V) -> 0 | X23: =_xlfn.XLOOKUP($D23,'consolidated tracker'!$D:$D,'consolidated tracker'!W:W) -> 0
D24: Sobha One Tower D | E24: =_xlfn.XLOOKUP(D24,'consolidated tracker'!D:D,'consolidated tracker'!E:E) -> RERA | F24: 46387 | G24: =_xlfn.XLOOKUP(D24,'consolidated tracker'!D:D,'consolidated tracker'!F:F) -> 519 | H24: =_xlfn.XLOOKUP(D24,'consolidated tracker'!D:D,'consolidated tracker'!G:G) -> 1.0662871e+09 | I24: =_xlfn.XLOOKUP(D24,'consolidated tracker'!D:D,'consolidated tracker'!H:H) -> 5.8050427e+08 | J24: =_xlfn.XLOOKUP(D24,'consolidated tracker'!D:D,'consolidated tracker'!I:I) -> 5.6311206e+08 | K24: =_xlfn.XLOOKUP(D24,'consolidated tracker'!D:D,'consolidated tracker'!J:J) -> 40491993 | L24: =_xlfn.XLOOKUP(D24,'consolidated tracker'!D:D,'consolidated tracker'!K:K) -> 0.97003948 | M24: =_xlfn.XLOOKUP('consolidated - Offplan'!D24,'consolidated tracker'!D:D,'consolidated tracker'!L:L) -> 17392210 | N24: =_xlfn.XLOOKUP($D24,'consolidated tracker'!$D:$D,'consolidated tracker'!M:M) -> 4.4529083e+08 | O24: =_xlfn.XLOOKUP($D24,'consolidated tracker'!$D:$D,'consolidated tracker'!N:N) -> 4.4529083e+08 | P24: =_xlfn.XLOOKUP($D24,'consolidated tracker'!$D:$D,'consolidated tracker'!O:O) -> 0 | Q24: =_xlfn.XLOOKUP($D24,'consolidated tracker'!$D:$D,'consolidated tracker'!P:P) -> 0 | R24: =_xlfn.XLOOKUP($D24,'consolidated tracker'!$D:$D,'consolidated tracker'!Q:Q) -> 0 | S24: =_xlfn.XLOOKUP($D24,'consolidated tracker'!$D:$D,'consolidated tracker'!R:R) -> 0 | T24: =_xlfn.XLOOKUP($D24,'consolidated tracker'!$D:$D,'consolidated tracker'!S:S) -> 0 | U24: =_xlfn.XLOOKUP($D24,'consolidated tracker'!$D:$D,'consolidated tracker'!T:T) -> 0 | V24: =_xlfn.XLOOKUP($D24,'consolidated tracker'!$D:$D,'consolidated tracker'!U:U) -> 0 | W24: =_xlfn.XLOOKUP($D24,'consolidated tracker'!$D:$D,'consolidated tracker'!V:V) -> 0 | X24: =_xlfn.XLOOKUP($D24,'consolidated tracker'!$D:$D,'consolidated tracker'!W:W) -> 0
D25: Sobha One Tower E | E25: =_xlfn.XLOOKUP(D25,'consolidated tracker'!D:D,'consolidated tracker'!E:E) -> RERA | F25: 46387 | G25: =_xlfn.XLOOKUP(D25,'consolidated tracker'!D:D,'consolidated tracker'!F:F) -> 466 | H25: =_xlfn.XLOOKUP(D25,'consolidated tracker'!D:D,'consolidated tracker'!G:G) -> 1.1651558e+09 | I25: =_xlfn.XLOOKUP(D25,'consolidated tracker'!D:D,'consolidated tracker'!H:H) -> 6.2495174e+08 | J25: =_xlfn.XLOOKUP(D25,'consolidated tracker'!D:D,'consolidated tracker'!I:I) -> 5.9597659e+08 | K25: =_xlfn.XLOOKUP(D25,'consolidated tracker'!D:D,'consolidated tracker'!J:J) -> 58976268 | L25: =_xlfn.XLOOKUP(D25,'consolidated tracker'!D:D,'consolidated tracker'!K:K) -> 0.95363619 | M25: =_xlfn.XLOOKUP('consolidated - Offplan'!D25,'consolidated tracker'!D:D,'consolidated tracker'!L:L) -> 28975145 | N25: =_xlfn.XLOOKUP($D25,'consolidated tracker'!$D:$D,'consolidated tracker'!M:M) -> 4.8122777e+08 | O25: =_xlfn.XLOOKUP($D25,'consolidated tracker'!$D:$D,'consolidated tracker'!N:N) -> 4.8080875e+08 | P25: =_xlfn.XLOOKUP($D25,'consolidated tracker'!$D:$D,'consolidated tracker'!O:O) -> 419015 | Q25: =_xlfn.XLOOKUP($D25,'consolidated tracker'!$D:$D,'consolidated tracker'!P:P) -> 0 | R25: =_xlfn.XLOOKUP($D25,'consolidated tracker'!$D:$D,'consolidated tracker'!Q:Q) -> 0 | S25: =_xlfn.XLOOKUP($D25,'consolidated tracker'!$D:$D,'consolidated tracker'!R:R) -> 0 | T25: =_xlfn.XLOOKUP($D25,'consolidated tracker'!$D:$D,'consolidated tracker'!S:S) -> 0 | U25: =_xlfn.XLOOKUP($D25,'consolidated tracker'!$D:$D,'consolidated tracker'!T:T) -> 0 | V25: =_xlfn.XLOOKUP($D25,'consolidated tracker'!$D:$D,'consolidated tracker'!U:U) -> 0 | W25: =_xlfn.XLOOKUP($D25,'consolidated tracker'!$D:$D,'consolidated tracker'!V:V) -> 0 | X25: =_xlfn.XLOOKUP($D25,'consolidated tracker'!$D:$D,'consolidated tracker'!W:W) -> 0
