Workbook

Sheet summary
B1: 2026 | C1: 2026 transactions Count | N1: 2026 | O1: 2026 transactions values
B2: Category | C2: CDM Payment | E2: Cheque payment | F2: Card Payment | H2: Sobha One | I2: Cash payment | J2: Wire Transfer Paymment | L2: Grand Total | N2: Category | O2: CDM Payment | Q2: Cheque payment | R2: Card Payment | T2: Sobha One | U2: Cash payment | V2: Wire Transfer Paymment | X2: Grand Total
C3: CDM Cash | D3: CDM Cheque | E3: Cheque | F3: Credit Card | G3: Website (Payment link) | H3: Sobha One App | I3: OTC Deposit | J3: DWT(Domestic) | K3: IWT(International) | O3: CDM Cash | P3: CDM Cheque | Q3: Cheque | R3: Credit Card | S3: Website (Payment link) | T3: Sobha One App | U3: OTC Deposit | V3: DWT(Domestic) | W3: IWT(International)
B4: New sales | C4: 47 | D4: 26 | E4: 299 | F4: 113 | G4: 2962 | H4: 266 | I4: 875 | J4: 836 | K4: 1300 | L4: =SUM(C4:K4) -> 6724 | N4: New sales | O4: 1589714 | P4: 3784772 | Q4: 62441290 | R4: 5028696 | S4: 138515101 | T4: 11791648 | U4: 147944071 | V4: 139710418 | W4: 186230923 | X4: =SUM(O4:W4) -> 697036633
B5: Registration | C5: 13 | D5: 15 | E5: 68 | F5: 18 | G5: 1150 | H5: 14 | I5: 392 | J5: 565 | K5: 518 | L5: =SUM(C5:K5) -> 2753 | N5: Registration | O5: 400440 | P5: 1545235 | Q5: 10944269 | R5: 229432 | S5: 30094201 | T5: 336876 | U5: 43130606 | V5: 32392605 | W5: 46550218 | X5: =SUM(O5:W5) -> 165623882
B6: Other charges | C6: 30 | D6: 6 | E6: 38 | F6: 27 | G6: 812 | H6: 13 | I6: 203 | J6: 851 | K6: 494 | L6: =SUM(C6:K6) -> 2474 | N6: Other charges | O6: 183975 | P6: 81517 | Q6: 602367 | R6: 246429 | S6: 5066986 | T6: 86572 | U6: 602210 | V6: 4804954 | W6: 1123385 | X6: =SUM(O6:W6) -> 12798395
B7: Due + Advance | C7: 1398 | D7: 182 | E7: 1388 | F7: 446 | G7: 4895 | H7: 7023 | I7: 469 | J7: 7441 | K7: 5274 | L7: =SUM(C7:K7) -> 28516 | N7: Due + Advance | O7: 66431584 | P7: 66772930 | Q7: 568112611 | R7: 19760509 | S7: 289155304 | T7: 355030883 | U7: 321420950 | V7: 1357021749 | W7: 880570420 | X7: =SUM(O7:W7) -> 3924276940
B8: Total amount | C8: 1474 | D8: 222 | E8: 1717 | F8: 597 | G8: 9584 | H8: 7268 | I8: 1899 | J8: 9469 | K8: 7220 | L8: =SUM(C8:K8) -> 39450 | N8: Total amount | O8: 68605774 | P8: 72184469 | Q8: 642100813 | R8: 25265124 | S8: 462833159 | T8: 367246294 | U8: 513098021 | V8: 1533930849 | W8: 1114477096 | X8: =SUM(O8:W8) -> 4799741599
B10: 2025 | C10: 2025 transactions Count | N10: 2025 | O10: 2025 transactions values
B11: Category | C11: CDM Payment | E11: Cheque payment | F11: Card Payment | H11: Sobha One | I11: Cash payment | J11: Wire Transfer Paymment | L11: Grand Total | N11: Category | O11: CDM Payment | Q11: Cheque payment | R11: Card Payment | T11: Sobha One | U11: Cash payment | V11: Wire Transfer Paymment | X11: Grand Total
C12: CDM Cash | D12: CDM Cheque | E12: Cheque | F12: Credit Card | G12: Website (Payment link) | H12: Sobha One App | I12: OTC Deposit | J12: DWT(Domestic) | K12: IWT(International) | O12: CDM Cash | P12: CDM Cheque | Q12: Cheque | R12: Credit Card | S12: Website (Payment link) | T12: Sobha One App | U12: OTC Deposit | V12: DWT(Domestic) | W12: IWT(International)
B13: New sales | C13: 498 | D13: 62 | E13: 1243 | F13: 817 | G13: 17721 | H13: 280 | I13: 6141 | J13: 4710 | K13: 9114 | L13: =SUM(C13:K13) -> 40586 | N13: New sales | O13: 22411024 | P13: 8723947 | Q13: 306760998 | R13: 34021178 | S13: 745066424 | T13: 16107517 | U13: 837151689 | V13: 640264013 | W13: 1210795248 | X13: =SUM(O13:W13) -> 3821302038
B14: Registration | C14: 46 | D14: 29 | E14: 342 | F14: 144 | G14: 4153 | H14: 14 | I14: 2704 | J14: 2469 | K14: 3200 | L14: =SUM(C14:K14) -> 13101 | N14: Registration | O14: 1571633 | P14: 1149075 | Q14: 41484545 | R14: 5666637 | S14: 134131868 | T14: 525913 | U14: 246214209 | V14: 144528443 | W14: 238873319 | X14: =SUM(O14:W14) -> 814145642
B15: Other charges | C15: 189 | D15: 19 | E15: 298 | F15: 166 | G15: 2526 | H15: 9 | I15: 830 | J15: 3530 | K15: 1863 | L15: =SUM(C15:K15) -> 9430 | N15: Other charges | O15: 1277706 | P15: 196354 | Q15: 3804443 | R15: 1390736 | S15: 15973888 | T15: 127499 | U15: 2511478 | V15: 18581680 | W15: 4715706 | X15: =SUM(O15:W15) -> 48579490
B16: Due + Advance | C16: 6722 | D16: 389 | E16: 7420 | F16: 1316 | G16: 22982 | H16: 5356 | I16: 420 | J16: 25415 | K16: 18346 | L16: =SUM(C16:K16) -> 88366 | N16: Due + Advance | O16: 344379790 | P16: 132327075 | Q16: 3277942482 | R16: 87636651 | S16: 1194268380 | T16: 234704242 | U16: 355104268 | V16: 4186760536 | W16: 3061219432 | X16: =SUM(O16:W16) -> 12874342856
B17: Total amount | C17: 7373 | D17: 477 | E17: 8869 | F17: 2411 | G17: 46381 | H17: 5613 | I17: 9892 | J17: 35103 | K17: 30352 | L17: =SUM(C17:K17) -> 146471 | N17: Total amount | O17: 369641411 | P17: 142396481 | Q17: 3629996955 | R17: 128715744 | S17: 2089456677 | T17: 251465574 | U17: 1440985051 | V17: 4990145826 | W17: 4515623859 | X17: =SUM(O17:W17) -> 17558427578
B19: 2024 | C19: 2024 transactions Count | N19: 2024 | O19: 2024 transactions Values
B20: Category | C20: CDM Payment | E20: Cheque payment | F20: Card Payment | H20: Sobha One | I20: Cash payment | J20: Wire Transfer Paymment | L20: Grand Total | N20: Category | O20: CDM Payment | Q20: Cheque payment | R20: Card Payment | T20: Sobha One | U20: Cash payment | V20: Wire Transfer Paymment | X20: Grand Total
C21: CDM Cash | D21: CDM Cheque | E21: Cheque | F21: Credit Card | G21: Website (Payment link) | H21: Sobha One App | I21: OTC Deposit | J21: DWT(Domestic) | K21: IWT(International) | O21: CDM Cash | P21: CDM Cheque | Q21: Cheque | R21: Credit Card | S21: Website (Payment link) | T21: Sobha One App | U21: OTC Deposit | V21: DWT(Domestic) | W21: IWT(International)
B22: New sales | C22: 1587 | D22: 179 | E22: 1673 | F22: 902 | G22: 10306 | H22: 1 | I22: 5658 | J22: 4369 | K22: 5699 | L22: =SUM(C22:K22) -> 30374 | N22: New sales | O22: 68908372 | P22: 27875255 | Q22: 438339867 | R22: 41480005 | S22: 441701601 | T22: 150000 | U22: 746714272 | V22: 567470768 | W22: 882797497 | X22: =SUM(O22:W22) -> 3215437637
B23: Registration | C23: 212 | D23: 57 | E23: 519 | F23: 155 | G23: 2575 | H23: 0 | I23: 2841 | J23: 1898 | K23: 2323 | L23: =SUM(C23:K23) -> 10580 | N23: Registration | O23: 6401543 | P23: 5053574 | Q23: 52718406 | R23: 6704311 | S23: 70147560 | T23: 0 | U23: 211687157 | V23: 114644670 | W23: 170577544 | X23: =SUM(O23:W23) -> 637934765
B24: Other charges | C24: 152 | D24: 10 | E24: 168 | F24: 25 | G24: 1038 | H24: 0 | I24: 411 | J24: 866 | K24: 65 | L24: =SUM(C24:K24) -> 2735 | N24: Other charges | O24: 1224705 | P24: 136490 | Q24: 2487905 | R24: 220732 | S24: 6040675 | T24: 0 | U24: 1509136 | V24: 6513662 | W24: 584955 | X24: =SUM(O24:W24) -> 18718260
B25: Due + Advance | C25: 7371 | D25: 302 | E25: 5855 | F25: 953 | G25: 10794 | H25: 47 | I25: 254 | J25: 12699 | K25: 9209 | L25: =SUM(C25:K25) -> 47484 | N25: Due + Advance | O25: 408462212 | P25: 119375841 | Q25: 2222664940 | R25: 72667793 | S25: 529730800 | T25: 2712424 | U25: 38718194 | V25: 2017092818 | W25: 1565824805 | X25: =SUM(O25:W25) -> 6977249827
B26: Total amount | C26: 9108 | D26: 504 | E26: 7714 | F26: 1991 | G26: 24112 | H26: 48 | I26: 8984 | J26: 19013 | K26: 16016 | L26: =SUM(C26:K26) -> 87490 | N26: Total amount | O26: 484999516 | P26: 152441564 | Q26: 2716215003 | R26: 121073038 | S26: 1047629739 | T26: 2862424 | U26: 998629782 | V26: 2705729782 | W26: 2619790909 | X26: =SUM(O26:W26) -> 10849371757
B28: 2023 | C28: 2023 transactions Count | N28: 2023 | O28: 2023 transactions values
B29: Category | C29: CDM Payment | E29: Cheque payment | F29: Card Payment | H29: Sobha One | I29: Cash payment | J29: Wire Transfer Paymment | L29: Grand Total | N29: Category | O29: CDM Payment | Q29: Cheque payment | R29: Card Payment | T29: Sobha One | U29: Cash payment | V29: Wire Transfer Paymment | X29: Grand Total
C30: CDM Cash | D30: CDM Cheque | E30: Cheque | F30: Credit Card | G30: Website (Payment link) | H30: Sobha One App | I30: OTC Deposit | J30: DWT(Domestic) | K30: IWT(International) | O30: CDM Cash | P30: CDM Cheque | Q30: Cheque | R30: Credit Card | S30: Website (Payment link) | T30: Sobha One App | U30: OTC Deposit | V30: DWT(Domestic) | W30: IWT(International)
B31: New sales | C31: 1591 | D31: 204 | E31: 1665 | F31: 1134 | G31: 4353 | H31: 0 | I31: 4492 | J31: 2225 | K31: 3829 | L31: =SUM(C31:K31) -> 19493 | N31: New sales | O31: 71009342 | P31: 31367357 | Q31: 504411131 | R31: 49922445 | S31: 184256775 | T31: 0 | U31: 678324105 | V31: 329515124 | W31: 618412051 | X31: =SUM(O31:W31) -> 2467218330
B32: Registration | C32: 363 | D32: 95 | E32: 568 | F32: 370 | G32: 2464 | H32: 0 | I32: 3163 | J32: 1496 | K32: 2219 | L32: =SUM(C32:K32) -> 10738 | N32: Registration | O32: 9717164 | P32: 8793718 | Q32: 63265194 | R32: 10413527 | S32: 44740583 | T32: 0 | U32: 241028755 | V32: 87002328 | W32: 172643956 | X32: =SUM(O32:W32) -> 637605225
B33: Other charges | C33: 143 | D33: 16 | E33: 128 | F33: 77 | G33: 1024 | H33: 0 | I33: 376 | J33: 677 | K33: 91 | L33: =SUM(C33:K33) -> 2532 | N33: Other charges | O33: 1011054 | P33: 177350 | Q33: 974252 | R33: 453482 | S33: 4330590 | T33: 0 | U33: 1170040 | V33: 4067705 | W33: 716758 | X33: =SUM(O33:W33) -> 12901231
B34: Due + Advance | C34: 6123 | D34: 337 | E34: 4638 | F34: 1220 | G34: 6251 | H34: 1 | I34: 698 | J34: 6058 | K34: 5998 | L34: =SUM(C34:K34) -> 31324 | N34: Due + Advance | O34: 299844462 | P34: 117778534 | Q34: 1951915207 | R34: 61775331 | S34: 300018728 | T34: 500 | U34: 80772806 | V34: 915480235 | W34: 965416231 | X34: =SUM(O34:W34) -> 4693002034
B35: Total amount | C35: 7923 | D35: 603 | E35: 6357 | F35: 2719 | G35: 13665 | H35: 1 | I35: 8418 | J35: 9921 | K35: 11071 | L35: =SUM(C35:K35) -> 60678 | N35: Total amount | O35: 381584979 | P35: 158117224 | Q35: 2520568742 | R35: 122564868 | S35: 533349171 | T35: 500 | U35: 1001296321 | V35: 1336067642 | W35: 1757192867 | X35: =SUM(O35:W35) -> 7810742314

Sheet %of category
B1: 2026 | C1: 2026 transactions Count% | N1: 2026 | O1: 2026 transactions values%
B2: Category | C2: CDM Payment | E2: Cheque payment | F2: Card Payment | H2: Sobha One | I2: Cash payment | J2: Wire Transfer Paymment | L2: Grand Total | N2: Category | O2: CDM Payment | Q2: Cheque payment | R2: Card Payment | T2: Sobha One | U2: Cash payment | V2: Wire Transfer Paymment | X2: Grand Total
C3: CDM Cash | D3: CDM Cheque | E3: Cheque | F3: Credit Card | G3: Website (Payment link) | H3: Sobha One App | I3: OTC Deposit | J3: DWT(Domestic) | K3: IWT(International) | O3: CDM Cash | P3: CDM Cheque | Q3: Cheque | R3: Credit Card | S3: Website (Payment link) | T3: Sobha One App | U3: OTC Deposit | V3: DWT(Domestic) | W3: IWT(International)
B4: New sales | C4: =summary!C4/summary!$L4 -> 0.006989887 | D4: =summary!D4/summary!$L4 -> 0.003866746 | E4: =summary!E4/summary!$L4 -> 0.044467579 | F4: =summary!F4/summary!$L4 -> 0.016805473 | G4: =summary!G4/summary!$L4 -> 0.4405116 | H4: =summary!H4/summary!$L4 -> 0.039559786 | I4: =summary!I4/summary!$L4 -> 0.13013087 | J4: =summary!J4/summary!$L4 -> 0.12433076 | K4: =summary!K4/summary!$L4 -> 0.1933373 | L4: =SUM(C4:K4) -> 1 | N4: New sales | O4: =summary!O4/summary!$X4 -> 0.002280675 | P4: =summary!P4/summary!$X4 -> 0.0054298036 | Q4: =summary!Q4/summary!$X4 -> 0.089581074 | R4: =summary!R4/summary!$X4 -> 0.0072143927 | S4: =summary!S4/summary!$X4 -> 0.19871997 | T4: =summary!T4/summary!$X4 -> 0.016916827 | U4: =summary!U4/summary!$X4 -> 0.2122472 | V4: =summary!V4/summary!$X4 -> 0.20043483 | W4: =summary!W4/summary!$X4 -> 0.26717523 | X4: =SUM(O4:W4) -> 1
B5: Registration | C5: =summary!C5/summary!$L5 -> 0.0047221213 | D5: =summary!D5/summary!$L5 -> 0.0054486015 | E5: =summary!E5/summary!$L5 -> 0.024700327 | F5: =summary!F5/summary!$L5 -> 0.0065383218 | G5: =summary!G5/summary!$L5 -> 0.41772612 | H5: =summary!H5/summary!$L5 -> 0.0050853614 | I5: =summary!I5/summary!$L5 -> 0.14239012 | J5: =summary!J5/summary!$L5 -> 0.20523066 | K5: =summary!K5/summary!$L5 -> 0.18815837 | L5: =SUM(C5:K5) -> 1 | N5: Registration | O5: =summary!O5/summary!$X5 -> 0.0024177673 | P5: =summary!P5/summary!$X5 -> 0.0093297837 | Q5: =summary!Q5/summary!$X5 -> 0.066079051 | R5: =summary!R5/summary!$X5 -> 0.0013852592 | S5: =summary!S5/summary!$X5 -> 0.18170206 | T5: =summary!T5/summary!$X5 -> 0.002033982 | U5: =summary!U5/summary!$X5 -> 0.26041296 | V5: =summary!V5/summary!$X5 -> 0.19557931 | W5: =summary!W5/summary!$X5 -> 0.28105982 | X5: =SUM(O5:W5) -> 1
B6: Other charges | C6: =summary!C6/summary!$L6 -> 0.012126112 | D6: =summary!D6/summary!$L6 -> 0.0024252223 | E6: =summary!E6/summary!$L6 -> 0.015359741 | F6: =summary!F6/summary!$L6 -> 0.0109135 | G6: =summary!G6/summary!$L6 -> 0.32821342 | H6: =summary!H6/summary!$L6 -> 0.0052546483 | I6: =summary!I6/summary!$L6 -> 0.082053355 | J6: =summary!J6/summary!$L6 -> 0.34397736 | K6: =summary!K6/summary!$L6 -> 0.19967664 | L6: =SUM(C6:K6) -> 1 | N6: Other charges | O6: =summary!O6/summary!$X6 -> 0.014374849 | P6: =summary!P6/summary!$X6 -> 0.0063693143 | Q6: =summary!Q6/summary!$X6 -> 0.047065823 | R6: =summary!R6/summary!$X6 -> 0.01925468 | S6: =summary!S6/summary!$X6 -> 0.39590792 | T6: =summary!T6/summary!$X6 -> 0.0067642857 | U6: =summary!U6/summary!$X6 -> 0.047053556 | V6: =summary!V6/summary!$X6 -> 0.37543411 | W6: =summary!W6/summary!$X6 -> 0.087775459 | X6: =SUM(O6:W6) -> 1
B7: Due + Advance | C7: =summary!C7/summary!$L7 -> 0.049025109 | D7: =summary!D7/summary!$L7 -> 0.0063823818 | E7: =summary!E7/summary!$L7 -> 0.048674428 | F7: =summary!F7/summary!$L7 -> 0.015640342 | G7: =summary!G7/summary!$L7 -> 0.17165802 | H7: =summary!H7/summary!$L7 -> 0.24628279 | I7: =summary!I7/summary!$L7 -> 0.016446907 | J7: =summary!J7/summary!$L7 -> 0.26094123 | K7: =summary!K7/summary!$L7 -> 0.1849488 | L7: =SUM(C7:K7) -> 1 | N7: Due + Advance | O7: =summary!O7/summary!$X7 -> 0.016928363 | P7: =summary!P7/summary!$X7 -> 0.017015346 | Q7: =summary!Q7/summary!$X7 -> 0.14476874 | R7: =summary!R7/summary!$X7 -> 0.0050354522 | S7: =summary!S7/summary!$X7 -> 0.073683715 | T7: =summary!T7/summary!$X7 -> 0.090470395 | U7: =summary!U7/summary!$X7 -> 0.081905777 | V7: =summary!V7/summary!$X7 -> 0.34580173 | W7: =summary!W7/summary!$X7 -> 0.22439049 | X7: =SUM(O7:W7) -> 1
B8: Total amount | C8: =summary!C8/summary!$L8 -> 0.037363752 | D8: =summary!D8/summary!$L8 -> 0.0056273764 | E8: =summary!E8/summary!$L8 -> 0.043523447 | F8: =summary!F8/summary!$L8 -> 0.01513308 | G8: =summary!G8/summary!$L8 -> 0.24294043 | H8: =summary!H8/summary!$L8 -> 0.18423321 | I8: =summary!I8/summary!$L8 -> 0.048136882 | J8: =summary!J8/summary!$L8 -> 0.24002535 | K8: =summary!K8/summary!$L8 -> 0.18301648 | L8: =SUM(C8:K8) -> 1 | N8: Total amount | O8: =summary!O8/summary!$X8 -> 0.014293639 | P8: =summary!P8/summary!$X8 -> 0.015039241 | Q8: =summary!Q8/summary!$X8 -> 0.1337782 | R8: =summary!R8/summary!$X8 -> 0.0052638509 | S8: =summary!S8/summary!$X8 -> 0.096428766 | T8: =summary!T8/summary!$X8 -> 0.076513764 | U8: =summary!U8/summary!$X8 -> 0.10690118 | V8: =summary!V8/summary!$X8 -> 0.31958613 | W8: =summary!W8/summary!$X8 -> 0.23219523 | X8: =SUM(O8:W8) -> 1
B12: 2025 | C12: 2025 transactions Count% | N12: 2025 | O12: 2025 transactions values%
B13: Category | C13: CDM Payment | E13: Cheque payment | F13: Card Payment | H13: Sobha One | I13: Cash payment | J13: Wire Transfer Paymment | L13: Grand Total | N13: Category | O13: CDM Payment | Q13: Cheque payment | R13: Card Payment | T13: Sobha One | U13: Cash payment | V13: Wire Transfer Paymment | X13: Grand Total
C14: CDM Cash | D14: CDM Cheque | E14: Cheque | F14: Credit Card | G14: Website (Payment link) | H14: Sobha One App | I14: OTC Deposit | J14: DWT(Domestic) | K14: IWT(International) | O14: CDM Cash | P14: CDM Cheque | Q14: Cheque | R14: Credit Card | S14: Website (Payment link) | T14: Sobha One App | U14: OTC Deposit | V14: DWT(Domestic) | W14: IWT(International)
B15: New sales | C15: =summary!C13/summary!$L13 -> 0.012270241 | D15: =summary!D13/summary!$L13 -> 0.0015276204 | E15: =summary!E13/summary!$L13 -> 0.030626324 | F15: =summary!F13/summary!$L13 -> 0.020130094 | G15: =summary!G13/summary!$L13 -> 0.43662839 | H15: =summary!H13/summary!$L13 -> 0.0068989307 | I15: =summary!I13/summary!$L13 -> 0.15130833 | J15: =summary!J13/summary!$L13 -> 0.11604987 | K15: =summary!K13/summary!$L13 -> 0.22456019 | L15: =SUM(C15:K15) -> 1 | N15: New sales | O15: =summary!O13/summary!$X13 -> 0.0058647612 | P15: =summary!P13/summary!$X13 -> 0.0022829776 | Q15: =summary!Q13/summary!$X13 -> 0.080276564 | R15: =summary!R13/summary!$X13 -> 0.008903033 | S15: =summary!S13/summary!$X13 -> 0.19497711 | T15: =summary!T13/summary!$X13 -> 0.0042151907 | U15: =summary!U13/summary!$X13 -> 0.21907499 | V15: =summary!V13/summary!$X13 -> 0.16755127 | W15: =summary!W13/summary!$X13 -> 0.31685411 | X15: =SUM(O15:W15) -> 1
B16: Registration | C16: =summary!C14/summary!$L14 -> 0.0035111824 | D16: =summary!D14/summary!$L14 -> 0.0022135715 | E16: =summary!E14/summary!$L14 -> 0.026104877 | F16: =summary!F14/summary!$L14 -> 0.010991527 | G16: =summary!G14/summary!$L14 -> 0.3169987 | H16: =summary!H14/summary!$L14 -> 0.0010686207 | I16: =summary!I14/summary!$L14 -> 0.20639646 | J16: =summary!J14/summary!$L14 -> 0.1884589 | K16: =summary!K14/summary!$L14 -> 0.24425616 | L16: =SUM(C16:K16) -> 1 | N16: Registration | O16: =summary!O14/summary!$X14 -> 0.0019304077 | P16: =summary!P14/summary!$X14 -> 0.0014113875 | Q16: =summary!Q14/summary!$X14 -> 0.050954698 | R16: =summary!R14/summary!$X14 -> 0.0069602252 | S16: =summary!S14/summary!$X14 -> 0.16475169 | T16: =summary!T14/summary!$X14 -> 0.00064596919 | U16: =summary!U14/summary!$X14 -> 0.30242035 | V16: =summary!V14/summary!$X14 -> 0.17752161 | W16: =summary!W14/summary!$X14 -> 0.29340367 | X16: =SUM(O16:W16) -> 1
B17: Other charges | C17: =summary!C15/summary!$L15 -> 0.020042418 | D17: =summary!D15/summary!$L15 -> 0.0020148462 | E17: =summary!E15/summary!$L15 -> 0.031601273 | F17: =summary!F15/summary!$L15 -> 0.017603393 | G17: =summary!G15/summary!$L15 -> 0.2678685 | H17: =summary!H15/summary!$L15 -> 0.00095440085 | I17: =summary!I15/summary!$L15 -> 0.088016967 | J17: =summary!J15/summary!$L15 -> 0.37433722 | K17: =summary!K15/summary!$L15 -> 0.19756098 | L17: =SUM(C17:K17) -> 1 | N17: Other charges | O17: =summary!O15/summary!$X15 -> 0.026301347 | P17: =summary!P15/summary!$X15 -> 0.0040419115 | Q17: =summary!Q15/summary!$X15 -> 0.07831377 | R17: =summary!R15/summary!$X15 -> 0.028628049 | S17: =summary!S15/summary!$X15 -> 0.32881959 | T17: =summary!T15/summary!$X15 -> 0.0026245438 | U17: =summary!U15/summary!$X15 -> 0.05169832 | V17: =summary!V15/summary!$X15 -> 0.38250052 | W17: =summary!W15/summary!$X15 -> 0.097071954 | X17: =SUM(O17:W17) -> 1
B18: Due + Advance | C18: =summary!C16/summary!$L16 -> 0.076069982 | D18: =summary!D16/summary!$L16 -> 0.0044021456 | E18: =summary!E16/summary!$L16 -> 0.083968947 | F18: =summary!F16/summary!$L16 -> 0.014892606 | G18: =summary!G16/summary!$L16 -> 0.26007741 | H18: =summary!H16/summary!$L16 -> 0.060611547 | I18: =summary!I16/summary!$L16 -> 0.0047529593 | J18: =summary!J16/summary!$L16 -> 0.28761062 | K18: =summary!K16/summary!$L16 -> 0.20761379 | L18: =SUM(C18:K18) -> 1 | N18: Due + Advance | O18: =summary!O16/summary!$X16 -> 0.02674931 | P18: =summary!P16/summary!$X16 -> 0.010278356 | Q18: =summary!Q16/summary!$X16 -> 0.25461047 | R18: =summary!R16/summary!$X16 -> 0.0068070776 | S18: =summary!S16/summary!$X16 -> 0.092763444 | T18: =summary!T16/summary!$X16 -> 0.018230386 | U18: =summary!U16/summary!$X16 -> 0.027582322 | V18: =summary!V16/summary!$X16 -> 0.32520188 | W18: =summary!W16/summary!$X16 -> 0.23777675 | X18: =SUM(O18:W18) -> 1
B19: Total amount | C19: =summary!C17/summary!$L17 -> 0.050337609 | D19: =summary!D17/summary!$L17 -> 0.0032566174 | E19: =summary!E17/summary!$L17 -> 0.060551235 | F19: =summary!F17/summary!$L17 -> 0.016460596 | G19: =summary!G17/summary!$L17 -> 0.31665654 | H19: =summary!H17/summary!$L17 -> 0.038321579 | I19: =summary!I17/summary!$L17 -> 0.067535553 | J19: =summary!J17/summary!$L17 -> 0.23965836 | K19: =summary!K17/summary!$L17 -> 0.20722191 | L19: =SUM(C19:K19) -> 1 | N19: Total amount | O19: =summary!O17/summary!$X17 -> 0.021052079 | P19: =summary!P17/summary!$X17 -> 0.0081098652 | Q19: =summary!Q17/summary!$X17 -> 0.20673816 | R19: =summary!R17/summary!$X17 -> 0.0073307102 | S19: =summary!S17/summary!$X17 -> 0.11900022 | T19: =summary!T17/summary!$X17 -> 0.014321645 | U19: =summary!U17/summary!$X17 -> 0.082068001 | V19: =summary!V17/summary!$X17 -> 0.28420232 | W19: =summary!W17/summary!$X17 -> 0.25717701 | X19: =SUM(O19:W19) -> 1
B23: 2024 | C23: 2024 transactions Count% | N23: 2024 | O23: 2024 transactions Values%
B24: Category | C24: CDM Payment | E24: Cheque payment | F24: Card Payment | H24: Sobha One | I24: Cash payment | J24: Wire Transfer Paymment | L24: Grand Total | N24: Category | O24: CDM Payment | Q24: Cheque payment | R24: Card Payment | T24: Sobha One | U24: Cash payment | V24: Wire Transfer Paymment | X24: Grand Total
C25: CDM Cash | D25: CDM Cheque | E25: Cheque | F25: Credit Card | G25: Website (Payment link) | H25: Sobha One App | I25: OTC Deposit | J25: DWT(Domestic) | K25: IWT(International) | O25: CDM Cash | P25: CDM Cheque | Q25: Cheque | R25: Credit Card | S25: Website (Payment link) | T25: Sobha One App | U25: OTC Deposit | V25: DWT(Domestic) | W25: IWT(International)
B26: New sales | C26: =summary!C22/summary!$L22 -> 0.052248634 | D26: =summary!D22/summary!$L22 -> 0.0058931981 | E26: =summary!E22/summary!$L22 -> 0.055080003 | F26: =summary!F22/summary!$L22 -> 0.029696451 | G26: =summary!G22/summary!$L22 -> 0.33930335 | H26: =summary!H22/summary!$L22 -> 3.2922895e-05 | I26: =summary!I22/summary!$L22 -> 0.18627774 | J26: =summary!J22/summary!$L22 -> 0.14384013 | K26: =summary!K22/summary!$L22 -> 0.18762758 | L26: =SUM(C26:K26) -> 1 | N26: New sales | O26: =summary!O22/summary!$X22 -> 0.02143048 | P26: =summary!P22/summary!$X22 -> 0.0086691947 | Q26: =summary!Q22/summary!$X22 -> 0.13632355 | R26: =summary!R22/summary!$X22 -> 0.012900267 | S26: =summary!S22/summary!$X22 -> 0.13736905 | T26: =summary!T22/summary!$X22 -> 4.6649948e-05 | U26: =summary!U22/summary!$X22 -> 0.23222788 | V26: =summary!V22/summary!$X22 -> 0.17648321 | W26: =summary!W22/summary!$X22 -> 0.27454972 | X26: =SUM(O26:W26) -> 1
B27: Registration | C27: =summary!C23/summary!$L23 -> 0.020037807 | D27: =summary!D23/summary!$L23 -> 0.0053875236 | E27: =summary!E23/summary!$L23 -> 0.04905482 | F27: =summary!F23/summary!$L23 -> 0.014650284 | G27: =summary!G23/summary!$L23 -> 0.24338374 | H27: =summary!H23/summary!$L23 -> 0 | I27: =summary!I23/summary!$L23 -> 0.26852552 | J27: =summary!J23/summary!$L23 -> 0.17939509 | K27: =summary!K23/summary!$L23 -> 0.21956522 | L27: =SUM(C27:K27) -> 1 | N27: Registration | O27: =summary!O23/summary!$X23 -> 0.010034793 | P27: =summary!P23/summary!$X23 -> 0.0079217724 | Q27: =summary!Q23/summary!$X23 -> 0.08263918 | R27: =summary!R23/summary!$X23 -> 0.010509399 | S27: =summary!S23/summary!$X23 -> 0.1099604 | T27: =summary!T23/summary!$X23 -> 0 | U27: =summary!U23/summary!$X23 -> 0.33183198 | V27: =summary!V23/summary!$X23 -> 0.17971222 | W27: =summary!W23/summary!$X23 -> 0.26739026 | X27: =SUM(O27:W27) -> 1
B28: Other charges | C28: =summary!C24/summary!$L24 -> 0.055575868 | D28: =summary!D24/summary!$L24 -> 0.0036563071 | E28: =summary!E24/summary!$L24 -> 0.06142596 | F28: =summary!F24/summary!$L24 -> 0.0091407678 | G28: =summary!G24/summary!$L24 -> 0.37952468 | H28: =summary!H24/summary!$L24 -> 0 | I28: =summary!I24/summary!$L24 -> 0.15027422 | J28: =summary!J24/summary!$L24 -> 0.3166362 | K28: =summary!K24/summary!$L24 -> 0.023765996 | L28: =SUM(C28:K28) -> 1 | N28: Other charges | O28: =summary!O24/summary!$X24 -> 0.065428357 | P28: =summary!P24/summary!$X24 -> 0.0072918102 | Q28: =summary!Q24/summary!$X24 -> 0.13291326 | R28: =summary!R24/summary!$X24 -> 0.011792335 | S28: =summary!S24/summary!$X24 -> 0.32271563 | T28: =summary!T24/summary!$X24 -> 0 | U28: =summary!U24/summary!$X24 -> 0.080623733 | V28: =summary!V24/summary!$X24 -> 0.34798437 | W28: =summary!W24/summary!$X24 -> 0.031250501 | X28: =SUM(O28:W28) -> 1
B29: Due + Advance | C29: =summary!C25/summary!$L25 -> 0.15523124 | D29: =summary!D25/summary!$L25 -> 0.0063600371 | E29: =summary!E25/summary!$L25 -> 0.12330469 | F29: =summary!F25/summary!$L25 -> 0.020069918 | G29: =summary!G25/summary!$L25 -> 0.22731868 | H29: =summary!H25/summary!$L25 -> 0.00098980709 | I29: =summary!I25/summary!$L25 -> 0.0053491702 | J29: =summary!J25/summary!$L25 -> 0.26743745 | K29: =summary!K25/summary!$L25 -> 0.19393901 | L29: =SUM(C29:K29) -> 1 | N29: Due + Advance | O29: =summary!O25/summary!$X25 -> 0.058542008 | P29: =summary!P25/summary!$X25 -> 0.017109297 | Q29: =summary!Q25/summary!$X25 -> 0.31855889 | R29: =summary!R25/summary!$X25 -> 0.010414962 | S29: =summary!S25/summary!$X25 -> 0.075922579 | T29: =summary!T25/summary!$X25 -> 0.0003887526 | U29: =summary!U25/summary!$X25 -> 0.0055492056 | V29: =summary!V25/summary!$X25 -> 0.28909568 | W29: =summary!W25/summary!$X25 -> 0.22441862 | X29: =SUM(O29:W29) -> 1
B30: Total amount | C30: =summary!C26/summary!$L26 -> 0.10410333 | D30: =summary!D26/summary!$L26 -> 0.0057606584 | E30: =summary!E26/summary!$L26 -> 0.088170077 | F30: =summary!F26/summary!$L26 -> 0.022756887 | G30: =summary!G26/summary!$L26 -> 0.27559721 | H30: =summary!H26/summary!$L26 -> 0.00054863413 | I30: =summary!I26/summary!$L26 -> 0.10268602 | J30: =summary!J26/summary!$L26 -> 0.21731626 | K30: =summary!K26/summary!$L26 -> 0.18306092 | L30: =SUM(C30:K30) -> 1 | N30: Total amount | O30: =summary!O26/summary!$X26 -> 0.044703005 | P30: =summary!P26/summary!$X26 -> 0.014050727 | Q30: =summary!Q26/summary!$X26 -> 0.25035689 | R30: =summary!R26/summary!$X26 -> 0.011159452 | S30: =summary!S26/summary!$X26 -> 0.096561327 | T30: =summary!T26/summary!$X26 -> 0.00026383316 | U30: =summary!U26/summary!$X26 -> 0.092044941 | V30: =summary!V26/summary!$X26 -> 0.24939046 | W30: =summary!W26/summary!$X26 -> 0.24146937 | X30: =SUM(O30:W30) -> 1
B34: 2023 | C34: 2023 transactions Count% | N34: 2023 | O34: 2023 transactions values%
B35: Category | C35: CDM Payment | E35: Cheque payment | F35: Card Payment | H35: Sobha One | I35: Cash payment | J35: Wire Transfer Paymment | L35: Grand Total | N35: Category | O35: CDM Payment | Q35: Cheque payment | R35: Card Payment | T35: Sobha One | U35: Cash payment | V35: Wire Transfer Paymment | X35: Grand Total
C36: CDM Cash | D36: CDM Cheque | E36: Cheque | F36: Credit Card | G36: Website (Payment link) | H36: Sobha One App | I36: OTC Deposit | J36: DWT(Domestic) | K36: IWT(International) | O36: CDM Cash | P36: CDM Cheque | Q36: Cheque | R36: Credit Card | S36: Website (Payment link) | T36: Sobha One App | U36: OTC Deposit | V36: DWT(Domestic) | W36: IWT(International)
B37: New sales | C37: =summary!C31/summary!$L31 -> 0.081619043 | D37: =summary!D31/summary!$L31 -> 0.010465295 | E37: =summary!E31/summary!$L31 -> 0.085415277 | F37: =summary!F31/summary!$L31 -> 0.058174729 | G37: =summary!G31/summary!$L31 -> 0.22331093 | H37: =summary!H31/summary!$L31 -> 0 | I37: =summary!I31/summary!$L31 -> 0.2304417 | J37: =summary!J31/summary!$L31 -> 0.11414354 | K37: =summary!K31/summary!$L31 -> 0.19642949 | L37: =SUM(C37:K37) -> 1 | N37: New sales | O37: =summary!O31/summary!$X31 -> 0.028781134 | P37: =summary!P31/summary!$X31 -> 0.012713653 | Q37: =summary!Q31/summary!$X31 -> 0.20444528 | R37: =summary!R31/summary!$X31 -> 0.020234304 | S37: =summary!S31/summary!$X31 -> 0.07468199 | T37: =summary!T31/summary!$X31 -> 0 | U37: =summary!U31/summary!$X31 -> 0.27493477 | V37: =summary!V31/summary!$X31 -> 0.13355734 | W37: =summary!W31/summary!$X31 -> 0.25065153 | X37: =SUM(O37:W37) -> 1
B38: Registration | C38: =summary!C32/summary!$L32 -> 0.033805178 | D38: =summary!D32/summary!$L32 -> 0.0088470851 | E38: =summary!E32/summary!$L32 -> 0.052896256 | F38: =summary!F32/summary!$L32 -> 0.034457068 | G38: =summary!G32/summary!$L32 -> 0.22946545 | H38: =summary!H32/summary!$L32 -> 0 | I38: =summary!I32/summary!$L32 -> 0.29456137 | J38: =summary!J32/summary!$L32 -> 0.13931831 | K38: =summary!K32/summary!$L32 -> 0.20664928 | L38: =SUM(C38:K38) -> 1 | N38: Registration | O38: =summary!O32/summary!$X32 -> 0.015240095 | P38: =summary!P32/summary!$X32 -> 0.013791791 | Q38: =summary!Q32/summary!$X32 -> 0.099223142 | R38: =summary!R32/summary!$X32 -> 0.016332249 | S38: =summary!S32/summary!$X32 -> 0.070169725 | T38: =summary!T32/summary!$X32 -> 0 | U38: =summary!U32/summary!$X32 -> 0.37802193 | V38: =summary!V32/summary!$X32 -> 0.13645172 | W38: =summary!W32/summary!$X32 -> 0.27076936 | X38: =SUM(O38:W38) -> 1
B39: Other charges | C39: =summary!C33/summary!$L33 -> 0.056477093 | D39: =summary!D33/summary!$L33 -> 0.0063191153 | E39: =summary!E33/summary!$L33 -> 0.050552923 | F39: =summary!F33/summary!$L33 -> 0.030410742 | G39: =summary!G33/summary!$L33 -> 0.40442338 | H39: =summary!H33/summary!$L33 -> 0 | I39: =summary!I33/summary!$L33 -> 0.14849921 | J39: =summary!J33/summary!$L33 -> 0.26737757 | K39: =summary!K33/summary!$L33 -> 0.035939968 | L39: =SUM(C39:K39) -> 1 | N39: Other charges | O39: =summary!O33/summary!$X33 -> 0.078368801 | P39: =summary!P33/summary!$X33 -> 0.01374675 | Q39: =summary!Q33/summary!$X33 -> 0.075516205 | R39: =summary!R33/summary!$X33 -> 0.035150289 | S39: =summary!S33/summary!$X33 -> 0.33567262 | T39: =summary!T33/summary!$X33 -> 0 | U39: =summary!U33/summary!$X33 -> 0.090692121 | V39: =summary!V33/summary!$X33 -> 0.31529588 | W39: =summary!W33/summary!$X33 -> 0.055557334 | X39: =SUM(O39:W39) -> 1
B40: Due + Advance | C40: =summary!C34/summary!$L34 -> 0.19547312 | D40: =summary!D34/summary!$L34 -> 0.010758524 | E40: =summary!E34/summary!$L34 -> 0.14806538 | F40: =summary!F34/summary!$L34 -> 0.038947772 | G40: =summary!G34/summary!$L34 -> 0.19955944 | H40: =summary!H34/summary!$L34 -> 3.1924403e-05 | I40: =summary!I34/summary!$L34 -> 0.022283233 | J40: =summary!J34/summary!$L34 -> 0.19339803 | K40: =summary!K34/summary!$L34 -> 0.19148257 | L40: =SUM(C40:K40) -> 1 | N40: Due + Advance | O40: =summary!O34/summary!$X34 -> 0.063891824 | P40: =summary!P34/summary!$X34 -> 0.02509663 | Q40: =summary!Q34/summary!$X34 -> 0.41592038 | R40: =summary!R34/summary!$X34 -> 0.013163287 | S40: =summary!S34/summary!$X34 -> 0.063928958 | T40: =summary!T34/summary!$X34 -> 1.0654161e-07 | U40: =summary!U34/summary!$X34 -> 0.01721133 | V40: =summary!V34/summary!$X34 -> 0.19507348 | W40: =summary!W34/summary!$X34 -> 0.205714 | X40: =SUM(O40:W40) -> 1
B41: Total amount | C41: =summary!C35/summary!$L35 -> 0.13057451 | D41: =summary!D35/summary!$L35 -> 0.0099377039 | E41: =summary!E35/summary!$L35 -> 0.10476614 | F41: =summary!F35/summary!$L35 -> 0.04481031 | G41: =summary!G35/summary!$L35 -> 0.22520518 | H41: =summary!H35/summary!$L35 -> 1.6480438e-05 | I41: =summary!I35/summary!$L35 -> 0.13873232 | J41: =summary!J35/summary!$L35 -> 0.16350242 | K41: =summary!K35/summary!$L35 -> 0.18245493 | L41: =SUM(C41:K41) -> 1 | N41: Total amount | O41: =summary!O35/summary!$X35 -> 0.048853869 | P41: =summary!P35/summary!$X35 -> 0.020243559 | Q41: =summary!Q35/summary!$X35 -> 0.3227054 | R41: =summary!R35/summary!$X35 -> 0.015691834 | S41: =summary!S35/summary!$X35 -> 0.068284057 | T41: =summary!T35/summary!$X35 -> 6.4014402e-08 | U41: =summary!U35/summary!$X35 -> 0.12819477 | V41: =summary!V35/summary!$X35 -> 0.17105514 | W41: =summary!W35/summary!$X35 -> 0.2249713 | X41: =SUM(O41:W41) -> 1

Sheet Receipt Count
A1: 2026 | M1: 2025 | Y1: 2024 | AK1: 2023
A2: =_xlfn.CONCAT("Receipt count ", A1) -> Receipt count 2026 | M2: =_xlfn.CONCAT("Receipt count ", M1) -> Receipt count 2025 | Y2: =_xlfn.CONCAT("Receipt count ", Y1) -> Receipt count 2024 | AK2: =_xlfn.CONCAT("Receipt count ", AK1) -> Receipt count 2023
A3: New sales | M3: New sales | Y3: New sales | AK3: New sales
A4: Month | B4: CDM Payment | D4: Cheque payment | E4: Card Payment | G4: Sobha One | H4: Cash payment | I4: Wire Transfer Paymment | K4: Grand Total | M4: Month | N4: CDM Payment | P4: Cheque payment | Q4: Card Payment | S4: Sobha One | T4: Cash payment | U4: Wire Transfer Paymment | W4: Grand Total | Y4: Month | Z4: CDM Payment | AB4: Cheque payment | AC4: Card Payment | AE4: Sobha One | AF4: Cash payment | AG4: Wire Transfer Paymment | AI4: Grand Total | AK4: Month | AL4: CDM Payment | AN4: Cheque payment | AO4: Card Payment | AQ4: Sobha One | AR4: Cash payment | AS4: Wire Transfer Paymment | AU4: Grand Total
B5: CDM Cash | C5: CDM Cheque | D5: Cheque | E5: Credit Card | F5: Website (Payment link) | G5: Sobha One App | H5: OTC Deposit | I5: DWT(Domestic) | J5: IWT(International) | N5: CDM Cash | O5: CDM Cheque | P5: Cheque | Q5: Credit Card | R5: Website (Payment link) | S5: Sobha One App | T5: OTC Deposit | U5: DWT(Domestic) | V5: IWT(International) | Z5: CDM Cash | AA5: CDM Cheque | AB5: Cheque | AC5: Credit Card | AD5: Website (Payment link) | AE5: Sobha One App | AF5: OTC Deposit | AG5: DWT(Domestic) | AH5: IWT(International) | AL5: CDM Cash | AM5: CDM Cheque | AN5: Cheque | AO5: Credit Card | AP5: Website (Payment link) | AQ5: Sobha One App | AR5: OTC Deposit | AS5: DWT(Domestic) | AT5: IWT(International)
A6: Jan | B6: 14 | C6: 3 | D6: 81 | E6: 58 | F6: 902 | G6: 66 | H6: 279 | I6: 270 | J6: 446 | K6: =SUM(B6:J6) -> 2119 | M6: Jan | N6: 65 | O6: 10 | P6: 123 | Q6: 95 | R6: 1341 | S6: 3 | T6: 614 | U6: 478 | V6: 740 | W6: =SUM(N6:V6) -> 3469 | Y6: Jan | Z6: 99 | AA6: 22 | AB6: 132 | AC6: 72 | AD6: 377 | AE6: 0 | AF6: 428 | AG6: 234 | AH6: 349 | AI6: =SUM(Z6:AH6) -> 1713 | AK6: Jan | AL6: 59 | AM6: 14 | AN6: 92 | AO6: 129 | AP6: 241 | AQ6: 0 | AR6: 344 | AS6: 95 | AT6: 371 | AU6: =SUM(AL6:AT6) -> 1345
A7: Feb | B7: 22 | C7: 2 | D7: 65 | E7: 42 | F7: 998 | G7: 88 | H7: 349 | I7: 284 | J7: 457 | K7: =SUM(B7:J7) -> 2307 | M7: Feb | N7: 105 | O7: 10 | P7: 123 | Q7: 103 | R7: 1561 | S7: 0 | T7: 631 | U7: 536 | V7: 811 | W7: =SUM(N7:V7) -> 3880 | Y7: Feb | Z7: 127 | AA7: 25 | AB7: 126 | AC7: 79 | AD7: 498 | AE7: 0 | AF7: 482 | AG7: 216 | AH7: 392 | AI7: =SUM(Z7:AH7) -> 1945 | AK7: Feb | AL7: 104 | AM7: 19 | AN7: 99 | AO7: 80 | AP7: 222 | AQ7: 0 | AR7: 269 | AS7: 87 | AT7: 281 | AU7: =SUM(AL7:AT7) -> 1161
A8: Mar | B8: 9 | C8: 0 | D8: 17 | E8: 6 | F8: 381 | G8: 51 | H8: 76 | I8: 75 | J8: 191 | K8: =SUM(B8:J8) -> 806 | M8: Mar | N8: 46 | O8: 11 | P8: 152 | Q8: 90 | R8: 1986 | S8: 1 | T8: 606 | U8: 502 | V8: 1031 | W8: =SUM(N8:V8) -> 4425 | Y8: Mar | Z8: 151 | AA8: 15 | AB8: 170 | AC8: 67 | AD8: 701 | AE8: 0 | AF8: 444 | AG8: 303 | AH8: 536 | AI8: =SUM(Z8:AH8) -> 2387 | AK8: Mar | AL8: 98 | AM8: 18 | AN8: 96 | AO8: 79 | AP8: 219 | AQ8: 0 | AR8: 342 | AS8: 127 | AT8: 445 | AU8: =SUM(AL8:AT8) -> 1424
A9: Apr | B9: 2 | C9: 21 | D9: 113 | E9: 7 | F9: 601 | G9: 48 | H9: 145 | I9: 180 | J9: 196 | K9: =SUM(B9:J9) -> 1313 | M9: Apr | N9: 64 | O9: 7 | P9: 135 | Q9: 57 | R9: 1631 | S9: 1 | T9: 574 | U9: 368 | V9: 936 | W9: =SUM(N9:V9) -> 3773 | Y9: Apr | Z9: 194 | AA9: 10 | AB9: 139 | AC9: 65 | AD9: 676 | AE9: 0 | AF9: 342 | AG9: 416 | AH9: 452 | AI9: =SUM(Z9:AH9) -> 2294 | AK9: Apr | AL9: 84 | AM9: 13 | AN9: 115 | AO9: 46 | AP9: 268 | AQ9: 0 | AR9: 305 | AS9: 131 | AT9: 250 | AU9: =SUM(AL9:AT9) -> 1212
A10: May | B10: 0 | C10: 0 | D10: 23 | E10: 0 | F10: 80 | G10: 13 | H10: 26 | I10: 27 | J10: 10 | K10: =SUM(B10:J10) -> 179 | M10: May | N10: 42 | O10: 5 | P10: 151 | Q10: 89 | R10: 2118 | S10: 8 | T10: 748 | U10: 657 | V10: 1118 | W10: =SUM(N10:V10) -> 4936 | Y10: May | Z10: 179 | AA10: 23 | AB10: 178 | AC10: 66 | AD10: 734 | AE10: 0 | AF10: 446 | AG10: 411 | AH10: 393 | AI10: =SUM(Z10:AH10) -> 2430 | AK10: May | AL10: 154 | AM10: 15 | AN10: 187 | AO10: 109 | AP10: 456 | AQ10: 0 | AR10: 547 | AS10: 161 | AT10: 350 | AU10: =SUM(AL10:AT10) -> 1979
A11: Jun | B11: 0 | C11: 0 | D11: 0 | E11: 0 | F11: 0 | G11: 0 | H11: 0 | I11: 0 | J11: 0 | K11: =SUM(B11:J11) -> 0 | M11: Jun | N11: 25 | O11: 3 | P11: 78 | Q11: 53 | R11: 1375 | S11: 12 | T11: 383 | U11: 431 | V11: 775 | W11: =SUM(N11:V11) -> 3135 | Y11: Jun | Z11: 124 | AA11: 10 | AB11: 125 | AC11: 48 | AD11: 570 | AE11: 0 | AF11: 293 | AG11: 285 | AH11: 367 | AI11: =SUM(Z11:AH11) -> 1822 | AK11: Jun | AL11: 145 | AM11: 24 | AN11: 142 | AO11: 77 | AP11: 334 | AQ11: 0 | AR11: 419 | AS11: 192 | AT11: 231 | AU11: =SUM(AL11:AT11) -> 1564
A12: Jul | B12: 0 | C12: 0 | D12: 0 | E12: 0 | F12: 0 | G12: 0 | H12: 0 | I12: 0 | J12: 0 | K12: =SUM(B12:J12) -> 0 | M12: Jul | N12: 28 | O12: 5 | P12: 99 | Q12: 65 | R12: 1295 | S12: 13 | T12: 457 | U12: 311 | V12: 647 | W12: =SUM(N12:V12) -> 2920 | Y12: Jul | Z12: 153 | AA12: 19 | AB12: 94 | AC12: 57 | AD12: 554 | AE12: 0 | AF12: 371 | AG12: 282 | AH12: 329 | AI12: =SUM(Z12:AH12) -> 1859 | AK12: Jul | AL12: 177 | AM12: 8 | AN12: 157 | AO12: 63 | AP12: 352 | AQ12: 0 | AR12: 378 | AS12: 253 | AT12: 347 | AU12: =SUM(AL12:AT12) -> 1735
A13: Aug | B13: 0 | C13: 0 | D13: 0 | E13: 0 | F13: 0 | G13: 0 | H13: 0 | I13: 0 | J13: 0 | K13: =SUM(B13:J13) -> 0 | M13: Aug | N13: 28 | O13: 0 | P13: 81 | Q13: 63 | R13: 1127 | S13: 43 | T13: 399 | U13: 268 | V13: 567 | W13: =SUM(N13:V13) -> 2576 | Y13: Aug | Z13: 173 | AA13: 25 | AB13: 125 | AC13: 58 | AD13: 948 | AE13: 0 | AF13: 420 | AG13: 385 | AH13: 408 | AI13: =SUM(Z13:AH13) -> 2542 | AK13: Aug | AL13: 156 | AM13: 13 | AN13: 188 | AO13: 93 | AP13: 420 | AQ13: 0 | AR13: 262 | AS13: 305 | AT13: 251 | AU13: =SUM(AL13:AT13) -> 1688
A14: Sep | B14: 0 | C14: 0 | D14: 0 | E14: 0 | F14: 0 | G14: 0 | H14: 0 | I14: 0 | J14: 0 | K14: =SUM(B14:J14) -> 0 | M14: Sep | N14: 24 | O14: 3 | P14: 67 | Q14: 55 | R14: 1353 | S14: 56 | T14: 457 | U14: 307 | V14: 652 | W14: =SUM(N14:V14) -> 2974 | Y14: Sep | Z14: 131 | AA14: 10 | AB14: 115 | AC14: 82 | AD14: 970 | AE14: 0 | AF14: 535 | AG14: 373 | AH14: 479 | AI14: =SUM(Z14:AH14) -> 2695 | AK14: Sep | AL14: 110 | AM14: 30 | AN14: 157 | AO14: 71 | AP14: 416 | AQ14: 0 | AR14: 379 | AS14: 236 | AT14: 290 | AU14: =SUM(AL14:AT14) -> 1689
A15: Oct | B15: 0 | C15: 0 | D15: 0 | E15: 0 | F15: 0 | G15: 0 | H15: 0 | I15: 0 | J15: 0 | K15: =SUM(B15:J15) -> 0 | M15: Oct | N15: 15 | O15: 1 | P15: 79 | Q15: 70 | R15: 1548 | S15: 59 | T15: 433 | U15: 322 | V15: 723 | W15: =SUM(N15:V15) -> 3250 | Y15: Oct | Z15: 89 | AA15: 6 | AB15: 172 | AC15: 91 | AD15: 1206 | AE15: 0 | AF15: 557 | AG15: 449 | AH15: 537 | AI15: =SUM(Z15:AH15) -> 3107 | AK15: Oct | AL15: 167 | AM15: 30 | AN15: 149 | AO15: 129 | AP15: 537 | AQ15: 0 | AR15: 419 | AS15: 218 | AT15: 408 | AU15: =SUM(AL15:AT15) -> 2057
A16: Nov | B16: 0 | C16: 0 | D16: 0 | E16: 0 | F16: 0 | G16: 0 | H16: 0 | I16: 0 | J16: 0 | K16: =SUM(B16:J16) -> 0 | M16: Nov | N16: 43 | O16: 3 | P16: 79 | Q16: 37 | R16: 1216 | S16: 39 | T16: 444 | U16: 269 | V16: 515 | W16: =SUM(N16:V16) -> 2645 | Y16: Nov | Z16: 88 | AA16: 10 | AB16: 150 | AC16: 104 | AD16: 1568 | AE16: 0 | AF16: 588 | AG16: 531 | AH16: 683 | AI16: =SUM(Z16:AH16) -> 3722 | AK16: Nov | AL16: 180 | AM16: 7 | AN16: 153 | AO16: 117 | AP16: 450 | AQ16: 0 | AR16: 452 | AS16: 211 | AT16: 331 | AU16: =SUM(AL16:AT16) -> 1901
A17: Dec | B17: 0 | C17: 0 | D17: 0 | E17: 0 | F17: 0 | G17: 0 | H17: 0 | I17: 0 | J17: 0 | K17: =SUM(B17:J17) -> 0 | M17: Dec | N17: 13 | O17: 4 | P17: 76 | Q17: 40 | R17: 1170 | S17: 45 | T17: 395 | U17: 261 | V17: 599 | W17: =SUM(N17:V17) -> 2603 | Y17: Dec | Z17: 79 | AA17: 4 | AB17: 147 | AC17: 113 | AD17: 1504 | AE17: 1 | AF17: 752 | AG17: 484 | AH17: 774 | AI17: =SUM(Z17:AH17) -> 3858 | AK17: Dec | AL17: 157 | AM17: 13 | AN17: 130 | AO17: 141 | AP17: 438 | AQ17: 0 | AR17: 376 | AS17: 209 | AT17: 274 | AU17: =SUM(AL17:AT17) -> 1738
A18: Grand Total | B18: =SUM(B6:B17) -> 47 | C18: =SUM(C6:C17) -> 26 | D18: =SUM(D6:D17) -> 299 | E18: =SUM(E6:E17) -> 113 | F18: =SUM(F6:F17) -> 2962 | G18: =SUM(G6:G17) -> 266 | H18: =SUM(H6:H17) -> 875 | I18: =SUM(I6:I17) -> 836 | ... K18: =SUM(K6:K17) -> 6724 | M18: Grand Total | N18: =SUM(N6:N17) -> 498 | O18: =SUM(O6:O17) -> 62 | P18: =SUM(P6:P17) -> 1243 | Q18: =SUM(Q6:Q17) -> 817 | R18: =SUM(R6:R17) -> 17721 | S18: =SUM(S6:S17) -> 280 | T18: =SUM(T6:T17) -> 6141 | U18: =SUM(U6:U17) -> 4710 | ... W18: =SUM(W6:W17) -> 40586 | Y18: Grand Total | Z18: =SUM(Z6:Z17) -> 1587 | AA18: =SUM(AA6:AA17) -> 179 | AB18: =SUM(AB6:AB17) -> 1673 | AC18: =SUM(AC6:AC17) -> 902 | AD18: =SUM(AD6:AD17) -> 10306 | AE18: =SUM(AE6:AE17) -> 1 | AF18: =SUM(AF6:AF17) -> 5658 | AG18: =SUM(AG6:AG17) -> 4369 | ... AI18: =SUM(AI6:AI17) -> 30374 | AK18: Grand Total | AL18: =SUM(AL6:AL17) -> 1591 | AM18: =SUM(AM6:AM17) -> 204 | AN18: =SUM(AN6:AN17) -> 1665 | AO18: =SUM(AO6:AO17) -> 1134 | AP18: =SUM(AP6:AP17) -> 4353 | AQ18: =SUM(AQ6:AQ17) -> 0 | AR18: =SUM(AR6:AR17) -> 4492 | AS18: =SUM(AS6:AS17) -> 2225 | ... AU18: =SUM(AU6:AU17) -> 19493
A19: % of mode from New sales | B19: =B18/$K18 -> 0.006989887 | C19: =C18/$K18 -> 0.003866746 | D19: =D18/$K18 -> 0.044467579 | E19: =E18/$K18 -> 0.016805473 | F19: =F18/$K18 -> 0.4405116 | G19: =G18/$K18 -> 0.039559786 | H19: =H18/$K18 -> 0.13013087 | I19: =I18/$K18 -> 0.12433076 | ... K19: =K18/$K18 -> 1 | M19: % of mode from New sales | N19: =N18/$W18 -> 0.012270241 | O19: =O18/$W18 -> 0.0015276204 | P19: =P18/$W18 -> 0.030626324 | Q19: =Q18/$W18 -> 0.020130094 | R19: =R18/$W18 -> 0.43662839 | S19: =S18/$W18 -> 0.0068989307 | T19: =T18/$W18 -> 0.15130833 | U19: =U18/$W18 -> 0.11604987 | ... W19: =W18/$W18 -> 1 | Y19: % of mode from New sales | Z19: =Z18/$AI18 -> 0.052248634 | AA19: =AA18/$AI18 -> 0.0058931981 | AB19: =AB18/$AI18 -> 0.055080003 | AC19: =AC18/$AI18 -> 0.029696451 | AD19: =AD18/$AI18 -> 0.33930335 | AE19: =AE18/$AI18 -> 3.2922895e-05 | AF19: =AF18/$AI18 -> 0.18627774 | AG19: =AG18/$AI18 -> 0.14384013 | ... AI19: =AI18/$AI18 -> 1 | AK19: % of mode from New sales | AL19: =AL18/$AU18 -> 0.081619043 | AM19: =AM18/$AU18 -> 0.010465295 | AN19: =AN18/$AU18 -> 0.085415277 | AO19: =AO18/$AU18 -> 0.058174729 | AP19: =AP18/$AU18 -> 0.22331093 | AQ19: =AQ18/$AU18 -> 0 | AR19: =AR18/$AU18 -> 0.2304417 | AS19: =AS18/$AU18 -> 0.11414354 | ... AU19: =AU18/$AU18 -> 1
A21: Registration | M21: Registration | Y21: Registration | AK21: Registration
A22: Month | B22: CDM Payment | D22: Cheque payment | E22: Card Payment | G22: Sobha One | H22: Cash payment | I22: Wire Transfer Paymment | K22: Grand Total | M22: Month | N22: CDM Payment | P22: Cheque payment | Q22: Card Payment | S22: Sobha One | T22: Cash payment | U22: Wire Transfer Paymment | W22: Grand Total | Y22: Month | Z22: CDM Payment | AB22: Cheque payment | AC22: Card Payment | AE22: Sobha One | AF22: Cash payment | AG22: Wire Transfer Paymment | AI22: Grand Total | AK22: Month | AL22: CDM Payment | AN22: Cheque payment | AO22: Card Payment | AQ22: Sobha One | AR22: Cash payment | AS22: Wire Transfer Paymment | AU22: Grand Total
B23: CDM Cash | C23: CDM Cheque | D23: Cheque | E23: Credit Card | F23: Website (Payment link) | G23: Sobha One App | H23: OTC Deposit | I23: DWT(Domestic) | J23: IWT(International) | N23: CDM Cash | O23: CDM Cheque | P23: Cheque | Q23: Credit Card | R23: Website (Payment link) | S23: Sobha One App | T23: OTC Deposit | U23: DWT(Domestic) | V23: IWT(International) | Z23: CDM Cash | AA23: CDM Cheque | AB23: Cheque | AC23: Credit Card | AD23: Website (Payment link) | AE23: Sobha One App | AF23: OTC Deposit | AG23: DWT(Domestic) | AH23: IWT(International) | AL23: CDM Cash | AM23: CDM Cheque | AN23: Cheque | AO23: Credit Card | AP23: Website (Payment link) | AQ23: Sobha One App | AR23: OTC Deposit | AS23: DWT(Domestic) | AT23: IWT(International)
A24: Jan | B24: 5 | C24: 0 | D24: 17 | E24: 6 | F24: 269 | G24: 2 | H24: 138 | I24: 139 | J24: 173 | K24: =SUM(B24:J24) -> 749 | M24: Jan | N24: 9 | O24: 4 | P24: 41 | Q24: 9 | R24: 261 | S24: 0 | T24: 238 | U24: 272 | V24: 221 | W24: =SUM(N24:V24) -> 1055 | Y24: Jan | Z24: 24 | AA24: 5 | AB24: 40 | AC24: 23 | AD24: 189 | AE24: 0 | AF24: 263 | AG24: 139 | AH24: 202 | AI24: =SUM(Z24:AH24) -> 885 | AK24: Jan | AL24: 30 | AM24: 4 | AN24: 60 | AO24: 72 | AP24: 112 | AQ24: 0 | AR24: 274 | AS24: 66 | AT24: 259 | AU24: =SUM(AL24:AT24) -> 877
A25: Feb | B25: 1 | C25: 14 | D25: 18 | E25: 2 | F25: 192 | G25: 4 | H25: 137 | I25: 115 | J25: 171 | K25: =SUM(B25:J25) -> 654 | M25: Feb | N25: 3 | O25: 1 | P25: 21 | Q25: 5 | R25: 268 | S25: 0 | T25: 249 | U25: 215 | V25: 217 | W25: =SUM(N25:V25) -> 979 | Y25: Feb | Z25: 21 | AA25: 7 | AB25: 49 | AC25: 18 | AD25: 229 | AE25: 0 | AF25: 306 | AG25: 148 | AH25: 218 | AI25: =SUM(Z25:AH25) -> 996 | AK25: Feb | AL25: 41 | AM25: 16 | AN25: 33 | AO25: 37 | AP25: 216 | AQ25: 0 | AR25: 157 | AS25: 60 | AT25: 184 | AU25: =SUM(AL25:AT25) -> 744
A26: Mar | B26: 2 | C26: 0 | D26: 22 | E26: 1 | F26: 192 | G26: 4 | H26: 49 | I26: 70 | J26: 93 | K26: =SUM(B26:J26) -> 433 | M26: Mar | N26: 5 | O26: 8 | P26: 40 | Q26: 13 | R26: 302 | S26: 0 | T26: 232 | U26: 223 | V26: 330 | W26: =SUM(N26:V26) -> 1153 | Y26: Mar | Z26: 23 | AA26: 6 | AB26: 58 | AC26: 17 | AD26: 228 | AE26: 0 | AF26: 301 | AG26: 135 | AH26: 246 | AI26: =SUM(Z26:AH26) -> 1014 | AK26: Mar | AL26: 27 | AM26: 8 | AN26: 38 | AO26: 41 | AP26: 233 | AQ26: 0 | AR26: 265 | AS26: 84 | AT26: 196 | AU26: =SUM(AL26:AT26) -> 892
A27: Apr | B27: 4 | C27: 1 | D27: 4 | E27: 8 | F27: 413 | G27: 4 | H27: 55 | I27: 224 | J27: 77 | K27: =SUM(B27:J27) -> 790 | M27: Apr | N27: 4 | O27: 2 | P27: 36 | Q27: 16 | R27: 359 | S27: 0 | T27: 274 | U27: 200 | V27: 365 | W27: =SUM(N27:V27) -> 1256 | Y27: Apr | Z27: 20 | AA27: 4 | AB27: 45 | AC27: 18 | AD27: 249 | AE27: 0 | AF27: 253 | AG27: 237 | AH27: 226 | AI27: =SUM(Z27:AH27) -> 1052 | AK27: Apr | AL27: 17 | AM27: 2 | AN27: 60 | AO27: 26 | AP27: 152 | AQ27: 0 | AR27: 236 | AS27: 85 | AT27: 160 | AU27: =SUM(AL27:AT27) -> 738
A28: May | B28: 1 | C28: 0 | D28: 7 | E28: 1 | F28: 84 | G28: 0 | H28: 13 | I28: 17 | J28: 4 | K28: =SUM(B28:J28) -> 127 | M28: May | N28: 4 | O28: 6 | P28: 38 | Q28: 24 | R28: 354 | S28: 1 | T28: 266 | U28: 239 | V28: 338 | W28: =SUM(N28:V28) -> 1270 | Y28: May | Z28: 31 | AA28: 15 | AB28: 65 | AC28: 12 | AD28: 260 | AE28: 0 | AF28: 295 | AG28: 213 | AH28: 222 | AI28: =SUM(Z28:AH28) -> 1113 | AK28: May | AL28: 34 | AM28: 6 | AN28: 63 | AO28: 28 | AP28: 284 | AQ28: 0 | AR28: 332 | AS28: 148 | AT28: 217 | AU28: =SUM(AL28:AT28) -> 1112
A29: Jun | B29: 0 | C29: 0 | D29: 0 | E29: 0 | F29: 0 | G29: 0 | H29: 0 | I29: 0 | J29: 0 | K29: =SUM(B29:J29) -> 0 | M29: Jun | N29: 3 | O29: 4 | P29: 23 | Q29: 7 | R29: 332 | S29: 0 | T29: 206 | U29: 269 | V29: 277 | W29: =SUM(N29:V29) -> 1121 | Y29: Jun | Z29: 21 | AA29: 1 | AB29: 47 | AC29: 9 | AD29: 196 | AE29: 0 | AF29: 206 | AG29: 176 | AH29: 153 | AI29: =SUM(Z29:AH29) -> 809 | AK29: Jun | AL29: 21 | AM29: 3 | AN29: 41 | AO29: 13 | AP29: 213 | AQ29: 0 | AR29: 249 | AS29: 123 | AT29: 175 | AU29: =SUM(AL29:AT29) -> 838
A30: Jul | B30: 0 | C30: 0 | D30: 0 | E30: 0 | F30: 0 | G30: 0 | H30: 0 | I30: 0 | J30: 0 | K30: =SUM(B30:J30) -> 0 | M30: Jul | N30: 3 | O30: 2 | P30: 42 | Q30: 17 | R30: 499 | S30: 0 | T30: 261 | U30: 251 | V30: 299 | W30: =SUM(N30:V30) -> 1374 | Y30: Jul | Z30: 26 | AA30: 3 | AB30: 33 | AC30: 8 | AD30: 189 | AE30: 0 | AF30: 210 | AG30: 153 | AH30: 220 | AI30: =SUM(Z30:AH30) -> 842 | AK30: Jul | AL30: 52 | AM30: 8 | AN30: 42 | AO30: 17 | AP30: 185 | AQ30: 0 | AR30: 295 | AS30: 161 | AT30: 177 | AU30: =SUM(AL30:AT30) -> 937
A31: Aug | B31: 0 | C31: 0 | D31: 0 | E31: 0 | F31: 0 | G31: 0 | H31: 0 | I31: 0 | J31: 0 | K31: =SUM(B31:J31) -> 0 | M31: Aug | N31: 5 | O31: 1 | P31: 17 | Q31: 13 | R31: 378 | S31: 2 | T31: 219 | U31: 194 | V31: 216 | W31: =SUM(N31:V31) -> 1045 | Y31: Aug | Z31: 15 | AA31: 2 | AB31: 41 | AC31: 13 | AD31: 211 | AE31: 0 | AF31: 170 | AG31: 118 | AH31: 161 | AI31: =SUM(Z31:AH31) -> 731 | AK31: Aug | AL31: 44 | AM31: 10 | AN31: 47 | AO31: 33 | AP31: 160 | AQ31: 0 | AR31: 202 | AS31: 192 | AT31: 145 | AU31: =SUM(AL31:AT31) -> 833
A32: Sep | B32: 0 | C32: 0 | D32: 0 | E32: 0 | F32: 0 | G32: 0 | H32: 0 | I32: 0 | J32: 0 | K32: =SUM(B32:J32) -> 0 | M32: Sep | N32: 0 | O32: 0 | P32: 25 | Q32: 13 | R32: 333 | S32: 5 | T32: 218 | U32: 185 | V32: 257 | W32: =SUM(N32:V32) -> 1036 | Y32: Sep | Z32: 10 | AA32: 5 | AB32: 26 | AC32: 13 | AD32: 163 | AE32: 0 | AF32: 207 | AG32: 140 | AH32: 136 | AI32: =SUM(Z32:AH32) -> 700 | AK32: Sep | AL32: 15 | AM32: 12 | AN32: 50 | AO32: 16 | AP32: 195 | AQ32: 0 | AR32: 257 | AS32: 138 | AT32: 162 | AU32: =SUM(AL32:AT32) -> 845
A33: Oct | B33: 0 | C33: 0 | D33: 0 | E33: 0 | F33: 0 | G33: 0 | H33: 0 | I33: 0 | J33: 0 | K33: =SUM(B33:J33) -> 0 | M33: Oct | N33: 1 | O33: 0 | P33: 22 | Q33: 10 | R33: 444 | S33: 2 | T33: 184 | U33: 151 | V33: 276 | W33: =SUM(N33:V33) -> 1090 | Y33: Oct | Z33: 2 | AA33: 2 | AB33: 38 | AC33: 6 | AD33: 200 | AE33: 0 | AF33: 201 | AG33: 128 | AH33: 168 | AI33: =SUM(Z33:AH33) -> 745 | AK33: Oct | AL33: 35 | AM33: 8 | AN33: 29 | AO33: 40 | AP33: 252 | AQ33: 0 | AR33: 288 | AS33: 149 | AT33: 218 | AU33: =SUM(AL33:AT33) -> 1019
A34: Nov | B34: 0 | C34: 0 | D34: 0 | E34: 0 | F34: 0 | G34: 0 | H34: 0 | I34: 0 | J34: 0 | K34: =SUM(B34:J34) -> 0 | M34: Nov | N34: 8 | O34: 1 | P34: 18 | Q34: 11 | R34: 294 | S34: 2 | T34: 164 | U34: 144 | V34: 185 | W34: =SUM(N34:V34) -> 827 | Y34: Nov | Z34: 8 | AA34: 4 | AB34: 49 | AC34: 6 | AD34: 219 | AE34: 0 | AF34: 191 | AG34: 170 | AH34: 158 | AI34: =SUM(Z34:AH34) -> 805 | AK34: Nov | AL34: 30 | AM34: 7 | AN34: 60 | AO34: 31 | AP34: 189 | AQ34: 0 | AR34: 315 | AS34: 164 | AT34: 174 | AU34: =SUM(AL34:AT34) -> 970
A35: Dec | B35: 0 | C35: 0 | D35: 0 | E35: 0 | F35: 0 | G35: 0 | H35: 0 | I35: 0 | J35: 0 | K35: =SUM(B35:J35) -> 0 | M35: Dec | N35: 1 | O35: 0 | P35: 19 | Q35: 6 | R35: 329 | S35: 2 | T35: 193 | U35: 126 | V35: 219 | W35: =SUM(N35:V35) -> 895 | Y35: Dec | Z35: 11 | AA35: 3 | AB35: 28 | AC35: 12 | AD35: 242 | AE35: 0 | AF35: 238 | AG35: 141 | AH35: 213 | AI35: =SUM(Z35:AH35) -> 888 | AK35: Dec | AL35: 17 | AM35: 11 | AN35: 45 | AO35: 16 | AP35: 273 | AQ35: 0 | AR35: 293 | AS35: 126 | AT35: 152 | AU35: =SUM(AL35:AT35) -> 933
A36: Grand Total | B36: =SUM(B24:B35) -> 13 | C36: =SUM(C24:C35) -> 15 | D36: =SUM(D24:D35) -> 68 | E36: =SUM(E24:E35) -> 18 | F36: =SUM(F24:F35) -> 1150 | G36: =SUM(G24:G35) -> 14 | H36: =SUM(H24:H35) -> 392 | I36: =SUM(I24:I35) -> 565 | ... K36: =SUM(K24:K35) -> 2753 | M36: Grand Total | N36: =SUM(N24:N35) -> 46 | O36: =SUM(O24:O35) -> 29 | P36: =SUM(P24:P35) -> 342 | Q36: =SUM(Q24:Q35) -> 144 | R36: =SUM(R24:R35) -> 4153 | S36: =SUM(S24:S35) -> 14 | T36: =SUM(T24:T35) -> 2704 | U36: =SUM(U24:U35) -> 2469 | ... W36: =SUM(W24:W35) -> 13101 | Y36: Grand Total | Z36: =SUM(Z24:Z35) -> 212 | AA36: =SUM(AA24:AA35) -> 57 | AB36: =SUM(AB24:AB35) -> 519 | AC36: =SUM(AC24:AC35) -> 155 | AD36: =SUM(AD24:AD35) -> 2575 | AE36: =SUM(AE24:AE35) -> 0 | AF36: =SUM(AF24:AF35) -> 2841 | AG36: =SUM(AG24:AG35) -> 1898 | ... AI36: =SUM(AI24:AI35) -> 10580 | AK36: Grand Total | AL36: =SUM(AL24:AL35) -> 363 | AM36: =SUM(AM24:AM35) -> 95 | AN36: =SUM(AN24:AN35) -> 568 | AO36: =SUM(AO24:AO35) -> 370 | AP36: =SUM(AP24:AP35) -> 2464 | AQ36: =SUM(AQ24:AQ35) -> 0 | AR36: =SUM(AR24:AR35) -> 3163 | AS36: =SUM(AS24:AS35) -> 1496 | ... AU36: =SUM(AU24:AU35) -> 10738
A37: % of Mode from Registration | B37: =B36/$K36 -> 0.0047221213 | C37: =C36/$K36 -> 0.0054486015 | D37: =D36/$K36 -> 0.024700327 | E37: =E36/$K36 -> 0.0065383218 | F37: =F36/$K36 -> 0.41772612 | G37: =G36/$K36 -> 0.0050853614 | H37: =H36/$K36 -> 0.14239012 | I37: =I36/$K36 -> 0.20523066 | ... K37: =K36/$K36 -> 1 | M37: % of Mode from Registration | N37: =N36/$W36 -> 0.0035111824 | O37: =O36/$W36 -> 0.0022135715 | P37: =P36/$W36 -> 0.026104877 | Q37: =Q36/$W36 -> 0.010991527 | R37: =R36/$W36 -> 0.3169987 | S37: =S36/$W36 -> 0.0010686207 | T37: =T36/$W36 -> 0.20639646 | U37: =U36/$W36 -> 0.1884589 | ... W37: =W36/$W36 -> 1 | Y37: % of Mode from Registration | Z37: =Z36/$AI36 -> 0.020037807 | AA37: =AA36/$AI36 -> 0.0053875236 | AB37: =AB36/$AI36 -> 0.04905482 | AC37: =AC36/$AI36 -> 0.014650284 | AD37: =AD36/$AI36 -> 0.24338374 | AE37: =AE36/$AI36 -> 0 | AF37: =AF36/$AI36 -> 0.26852552 | AG37: =AG36/$AI36 -> 0.17939509 | ... AI37: =AI36/$AI36 -> 1 | AK37: % of Mode from Registration | AL37: =AL36/$AU36 -> 0.033805178 | AM37: =AM36/$AU36 -> 0.0088470851 | AN37: =AN36/$AU36 -> 0.052896256 | AO37: =AO36/$AU36 -> 0.034457068 | AP37: =AP36/$AU36 -> 0.22946545 | AQ37: =AQ36/$AU36 -> 0 | AR37: =AR36/$AU36 -> 0.29456137 | AS37: =AS36/$AU36 -> 0.13931831 | ... AU37: =AU36/$AU36 -> 1
A39: Other charges | M39: Other charges | Y39: Other charges | AK39: Other charges
A40: Month | B40: CDM Payment | D40: Cheque payment | E40: Card Payment | G40: Sobha One | H40: Cash payment | I40: Wire Transfer Paymment | K40: Grand Total | M40: Month | N40: CDM Payment | P40: Cheque payment | Q40: Card Payment | S40: Sobha One | T40: Cash payment | U40: Wire Transfer Paymment | W40: Grand Total | Y40: Month | Z40: CDM Payment | AB40: Cheque payment | AC40: Card Payment | AE40: Sobha One | AF40: Cash payment | AG40: Wire Transfer Paymment | AI40: Grand Total | AK40: Month | AL40: CDM Payment | AN40: Cheque payment | AO40: Card Payment | AQ40: Sobha One | AR40: Cash payment | AS40: Wire Transfer Paymment | AU40: Grand Total
B41: CDM Cash | C41: CDM Cheque | D41: Cheque | E41: Credit Card | F41: Website (Payment link) | G41: Sobha One App | H41: OTC Deposit | I41: DWT(Domestic) | J41: IWT(International) | N41: CDM Cash | O41: CDM Cheque | P41: Cheque | Q41: Credit Card | R41: Website (Payment link) | S41: Sobha One App | T41: OTC Deposit | U41: DWT(Domestic) | V41: IWT(International) | Z41: CDM Cash | AA41: CDM Cheque | AB41: Cheque | AC41: Credit Card | AD41: Website (Payment link) | AE41: Sobha One App | AF41: OTC Deposit | AG41: DWT(Domestic) | AH41: IWT(International) | AL41: CDM Cash | AM41: CDM Cheque | AN41: Cheque | AO41: Credit Card | AP41: Website (Payment link) | AQ41: Sobha One App | AR41: OTC Deposit | AS41: DWT(Domestic) | AT41: IWT(International)
A42: Jan | B42: 4 | C42: 0 | D42: 9 | E42: 2 | F42: 167 | G42: 6 | H42: 42 | I42: 223 | J42: 192 | K42: =SUM(B42:J42) -> 645 | M42: Jan | N42: 22 | O42: 0 | P42: 16 | Q42: 0 | R42: 122 | S42: 0 | T42: 26 | U42: 183 | V42: 43 | W42: =SUM(N42:V42) -> 412 | Y42: Jan | Z42: 20 | AA42: 0 | AB42: 15 | AC42: 4 | AD42: 129 | AE42: 0 | AF42: 71 | AG42: 73 | AH42: 8 | AI42: =SUM(Z42:AH42) -> 320 | AK42: Jan | AL42: 4 | AM42: 0 | AN42: 1 | AO42: 14 | AP42: 11 | AQ42: 0 | AR42: 43 | AS42: 32 | AT42: 21 | AU42: =SUM(AL42:AT42) -> 126
...

Sheet Receipt Value
A1: 2026 | M1: 2025 | Y1: 2024 | AK1: 2023
A2: =_xlfn.CONCAT("Receipt Value -", A1) -> Receipt Value -2026 | M2: =_xlfn.CONCAT("Receipt Value -", M1) -> Receipt Value -2025 | Y2: =_xlfn.CONCAT("Receipt Value-", Y1) -> Receipt Value-2024 | AK2: =_xlfn.CONCAT("Receipt Value -", AK1) -> Receipt Value -2023
A3: New sales | M3: New sales | Y3: New sales | AK3: New sales
A4: Month | B4: CDM Payment | D4: Cheque payment | E4: Card Payment | H4: Cash payment | I4: Wire Transfer Paymment | K4: Grand Total | M4: Month | N4: CDM Payment | P4: Cheque payment | Q4: Card Payment | T4: Cash payment | U4: Wire Transfer Paymment | W4: Grand Total | Y4: Month | Z4: CDM Payment | AB4: Cheque payment | AC4: Card Payment | AF4: Cash payment | AG4: Wire Transfer Paymment | AI4: Grand Total | AK4: Month | AL4: CDM Payment | AN4: Cheque payment | AO4: Card Payment | AR4: Cash payment | AS4: Wire Transfer Paymment | AU4: Grand Total
B5: CDM Cash | C5: CDM Cheque | D5: Cheque | E5: Credit Card | F5: Website (Payment link) | G5: Sobha One App | H5: OTC Deposit | I5: DWT(Domestic) | J5: IWT(International) | N5: CDM Cash | O5: CDM Cheque | P5: Cheque | Q5: Credit Card | R5: Website (Payment link) | S5: Sobha One App | T5: OTC Deposit | U5: DWT(Domestic) | V5: IWT(International) | Z5: CDM Cash | AA5: CDM Cheque | AB5: Cheque | AC5: Credit Card | AD5: Website (Payment link) | AE5: Sobha One App | AF5: OTC Deposit | AG5: DWT(Domestic) | AH5: IWT(International) | AL5: CDM Cash | AM5: CDM Cheque | AN5: Cheque | AO5: Credit Card | AP5: Website (Payment link) | AQ5: Sobha One App | AR5: OTC Deposit | AS5: DWT(Domestic) | AT5: IWT(International)
A6: Jan | B6: 280556 | C6: 201998 | D6: 19663871 | E6: 3080676 | F6: 42563684 | G6: 3098603 | H6: 49118148 | I6: 48446307 | J6: 64998588 | K6: =SUM(B6:J6) -> 231452431 | M6: Jan | N6: 3608586 | O6: 3028661 | P6: 26219958 | Q6: 4814003 | R6: 53342547 | S6: 484257 | T6: 79789150 | U6: 63533617 | V6: 104022112 | W6: =SUM(N6:V6) -> 338842891 | Y6: Jan | Z6: 4626009 | AA6: 2003014 | AB6: 38299327 | AC6: 3488130 | AD6: 17542803 | AE6: 0 | AF6: 55397883 | AG6: 30405587 | AH6: 60238008 | AI6: =SUM(Z6:AH6) -> 212000761 | AK6: Jan | AL6: 2171623 | AM6: 2079223 | AN6: 23949169 | AO6: 5542318 | AP6: 11126818 | AQ6: 0 | AR6: 55772019 | AS6: 11066297 | AT6: 75493126 | AU6: =SUM(AL6:AT6) -> 187200593
A7: Feb | B7: 700840 | C7: 50000 | D7: 12435951 | E7: 1687982 | F7: 47570899 | G7: 4953235 | H7: 65034972 | I7: 43998558 | J7: 74747926 | K7: =SUM(B7:J7) -> 251180363 | M7: Feb | N7: 3469933 | O7: 1380195 | P7: 29150825 | Q7: 4478431 | R7: 63939232 | S7: 0 | T7: 78908738 | U7: 87752038 | V7: 109468063 | W7: =SUM(N7:V7) -> 378547455 | Y7: Feb | Z7: 6054163 | AA7: 2518853 | AB7: 38688214 | AC7: 3063797 | AD7: 23770353 | AE7: 0 | AF7: 65348154 | AG7: 31538154 | AH7: 68006323 | AI7: =SUM(Z7:AH7) -> 238988011 | AK7: Feb | AL7: 6198860 | AM7: 4003987 | AN7: 14543872 | AO7: 3429403 | AP7: 8354560 | AQ7: 0 | AR7: 50091387 | AS7: 14423923 | AT7: 52154023 | AU7: =SUM(AL7:AT7) -> 153200015
A8: Mar | B8: 352778 | C8: 0 | D8: 12188290 | E8: 171070 | F8: 16040649 | G8: 1211698 | H8: 9664640 | I8: 9439879 | J8: 24204724 | K8: =SUM(B8:J8) -> 73273728 | M8: Mar | N8: 2061728 | O8: 1890973 | P8: 34277104 | Q8: 3903283 | R8: 76026086 | S8: 866 | T8: 64014062 | U8: 61815614 | V8: 136933936 | W8: =SUM(N8:V8) -> 380923652 | Y8: Mar | Z8: 7164956 | AA8: 2198527 | AB8: 62826559 | AC8: 3514378 | AD8: 30227389 | AE8: 0 | AF8: 68487921 | AG8: 40183754 | AH8: 110900035 | AI8: =SUM(Z8:AH8) -> 325503519 | AK8: Mar | AL8: 4232412 | AM8: 1427888 | AN8: 10669447 | AO8: 4040501 | AP8: 9701884 | AQ8: 0 | AR8: 53542647 | AS8: 11825795 | AT8: 77518500 | AU8: =SUM(AL8:AT8) -> 172959074
A9: Apr | B9: 255540 | C9: 3532774 | D9: 14623731 | E9: 88968 | F9: 28783390 | G9: 2104288 | H9: 20004594 | I9: 31181264 | J9: 21144692 | K9: =SUM(B9:J9) -> 121719241 | M9: Apr | N9: 3700892 | O9: 705664 | P9: 45300364 | Q9: 2393548 | R9: 67438037 | S9: 194169 | T9: 72607988 | U9: 51190068 | V9: 123587495 | W9: =SUM(N9:V9) -> 367118225 | Y9: Apr | Z9: 7525361 | AA9: 1398936 | AB9: 37978574 | AC9: 3389093 | AD9: 31537703 | AE9: 0 | AF9: 51362174 | AG9: 44337898 | AH9: 70127804 | AI9: =SUM(Z9:AH9) -> 247657543 | AK9: Apr | AL9: 2662388 | AM9: 543038 | AN9: 27737141 | AO9: 2326943 | AP9: 11420554 | AQ9: 0 | AR9: 42268989 | AS9: 14843264 | AT9: 41202397 | AU9: =SUM(AL9:AT9) -> 143004714
A10: May | B10: 0 | C10: 0 | D10: 3529447 | E10: 0 | F10: 3556479 | G10: 423824 | H10: 4121717 | I10: 6644410 | J10: 1134993 | K10: =SUM(B10:J10) -> 19410870 | M10: May | N10: 2150244 | O10: 1143450 | P10: 32398457 | Q10: 3460395 | R10: 88224813 | S10: 740248 | T10: 121193088 | U10: 85891398 | V10: 150527688 | W10: =SUM(N10:V10) -> 485729781 | Y10: May | Z10: 8060785 | AA10: 2923100 | AB10: 36750872 | AC10: 3828716 | AD10: 32615176 | AE10: 0 | AF10: 58903619 | AG10: 50436958 | AH10: 50294977 | AI10: =SUM(Z10:AH10) -> 243814203 | AK10: May | AL10: 5812457 | AM10: 625944 | AN10: 58343549 | AO10: 4868840 | AP10: 17568373 | AQ10: 0 | AR10: 65687524 | AS10: 22722982 | AT10: 62908303 | AU10: =SUM(AL10:AT10) -> 238537972
