Workbook
Name Ak: #REF!
Name NOB: #REF!
Name Source: #REF!
Name SRCE: #REF!
Name Style: #REF!
Name TOS: #REF!
Name Type: #REF!
Name VLOOKUP: #REF!

Sheet Weekwise summary
A2: Collection Executive | B2: Week 1 | C2: Week 2 | D2: Week 3 | E2: Week 4 | F2: Week 5 | G2: Grand Total
A3: Dues
A4: Monish | B4: 7155724.4 | C4: 5763300 | D4: 0 | E4: 0 | F4: 0 | G4: =SUM(B4:F4) -> 12919024
A5: Melvyn | B5: 3459118.8 | C5: 7468102.6 | D5: 0 | E5: 0 | F5: 0 | G5: =SUM(B5:F5) -> 10927221
A6: Walid | B6: 7881000.9 | C6: 8410159.6 | D6: 0 | E6: 0 | F6: 0 | G6: =SUM(B6:F6) -> 16291161
A7: Anna | B7: 1325391.9 | C7: 1606659.9 | D7: 0 | E7: 0 | F7: 0 | G7: =SUM(B7:F7) -> 2932051.8
A8: UAQ Sub Total | B8: =SUM(B4:B7) -> 19821236 | C8: =SUM(C4:C7) -> 23248222 | D8: =SUM(D4:D7) -> 0 | E8: =SUM(E4:E7) -> 0 | F8: =SUM(F4:F7) -> 0 | G8: =SUM(B8:F8) -> 43069458
A9: Ruhul | B9: 498000 | C9: 1335821 | D9: 0 | E9: 0 | F9: 0 | G9: =SUM(B9:F9) -> 1833821
A10: Ali | B10: 3009971 | C10: 3907729 | D10: 0 | E10: 0 | F10: 0 | G10: =SUM(B10:F10) -> 6917700
A11: Anirudh | B11: 4491953.5 | C11: 5334775.2 | D11: 0 | E11: 0 | F11: 0 | G11: =SUM(B11:F11) -> 9826728.7
A12: Aqsa | B12: 5572975 | C12: 6186990.1 | D12: 0 | E12: 0 | F12: 0 | G12: =SUM(B12:F12) -> 11759965
A13: Karan | B13: 2647104 | C13: 4343823 | D13: 0 | E13: 0 | F13: 0 | G13: =SUM(B13:F13) -> 6990927
A14: Rajiv | B14: 4660561 | C14: 6841253 | D14: 0 | E14: 0 | F14: 0 | G14: =SUM(B14:F14) -> 11501814
A15: Vinod | B15: 431500 | C15: 1625439.4 | D15: 0 | E15: 0 | F15: 0 | G15: =SUM(B15:F15) -> 2056939.4
A16: Sarmad | B16: 5883054.9 | C16: 8708469.5 | D16: 0 | E16: 0 | F16: 0 | G16: =SUM(B16:F16) -> 14591524
A17: Zeba | B17: 4831508.7 | C17: 5672744.5 | D17: 0 | E17: 0 | F17: 0 | G17: =SUM(B17:F17) -> 10504253
A18: Oksana | B18: 4259004 | C18: 6132007 | D18: 0 | E18: 0 | F18: 0 | G18: =SUM(B18:F18) -> 10391011
A19: Omar | B19: 2739365.4 | C19: 7010906.2 | D19: 0 | E19: 0 | F19: 0 | G19: =SUM(B19:F19) -> 9750271.5
A20: Sid | B20: 4101645 | C20: 4682952.4 | D20: 0 | E20: 0 | F20: 0 | G20: =SUM(B20:F20) -> 8784597.4
... A30: Abdellatif | B30: 3923405.7 | C30: 5716735.7 | D30: 0 | E30: 0 | F30: 0 | G30: =SUM(B30:F30) -> 9640141.4
A31: SOBHA Sub Total | B31: =SUM(B9:B30) -> 69786823 | C31: =SUM(C9:C30) -> 1.0447751e+08 | D31: =SUM(D9:D30) -> 0 | E31: =SUM(E9:E30) -> 0 | F31: =SUM(F9:F30) -> 0 | G31: =SUM(B31:F31) -> 1.7426434e+08
A32: Total Dues | B32: =SUM(B31,B8) -> 89608059 | C32: =SUM(C31,C8) -> 1.2772573e+08 | D32: =SUM(D31,D8) -> 0 | E32: =SUM(E31,E8) -> 0 | F32: =SUM(F31,F8) -> 0 | G32: =SUM(B32:F32) -> 2.1733379e+08
A33: Advances
A34: Abdulla | B34: 1527000 | C34: 3000682 | D34: 0 | E34: 0 | F34: 0 | G34: =SUM(B34:F34) -> 4527682
A35: Ateev | B35: 4361320 | C35: 7551735 | D35: 0 | E35: 0 | F35: 0 | G35: =SUM(B35:F35) -> 11913055
A36: Ayari | B36: 3577590 | C36: 2781023 | D36: 0 | E36: 0 | F36: 0 | G36: =SUM(B36:F36) -> 6358613
A37: Nischitha | B37: 0 | C37: 0 | D37: 0 | E37: 0 | F37: 0 | G37: =SUM(B37:F37) -> 0
A38: Sherif | B38: 1778643 | C38: 3396199 | D38: 0 | E38: 0 | F38: 0 | G38: =SUM(B38:F38) -> 5174842
A39: Wael | B39: 2246551 | C39: 4503635 | D39: 0 | E39: 0 | F39: 0 | G39: =SUM(B39:F39) -> 6750186
A40: Yogesh | B40: 1236697 | C40: 1914006 | D40: 0 | E40: 0 | F40: 0 | G40: =SUM(B40:F40) -> 3150703
A41: Krizia | B41: 1814275 | C41: 2765789.6 | D41: 0 | E41: 0 | F41: 0 | G41: =SUM(B41:F41) -> 4580064.6
A42: Vijay | B42: 1700796 | C42: 2601344 | D42: 0 | E42: 0 | F42: 0 | G42: =SUM(B42:F42) -> 4302140
A43: Jaidev | B43: 1520232 | C43: 3888415.5 | D43: 0 | E43: 0 | F43: 0 | G43: =SUM(B43:F43) -> 5408647.5
A44: Basma | B44: 4555749 | C44: 6188354 | D44: 0 | E44: 0 | F44: 0 | G44: =SUM(B44:F44) -> 10744103
A45: Noha | B45: 3651990 | C45: 1561248.6 | D45: 0 | E45: 0 | F45: 0 | G45: =SUM(B45:F45) -> 5213238.6
A46: Total Advances | B46: =SUM(B34:B45) -> 27970843 | C46: =SUM(C34:C45) -> 40152432 | D46: =SUM(D34:D45) -> 0 | E46: =SUM(E34:E45) -> 0 | F46: =SUM(F34:F45) -> 0 | G46: =SUM(B46:F46) -> 68123275
A47: Grand Total | B47: =SUM(B32,B46) -> 1.175789e+08 | C47: =SUM(C32,C46) -> 1.6787817e+08 | D47: =SUM(D32,D46) -> 0 | E47: =SUM(E32,E46) -> 0 | F47: =SUM(F32,F46) -> 0 | G47: =SUM(B47:F47) -> 2.8545707e+08

Sheet Datewise Summary
A1: 46142
A2: Collection Executive | B2: =A1+1 -> 46143 | C2: =B2+1 -> 46144 | D2: =C2+1 -> 46145 | E2: =D2+1 -> 46146 | F2: =E2+1 -> 46147 | G2: =F2+1 -> 46148 | H2: =G2+1 -> 46149 | I2: =H2+1 -> 46150 | J2: =I2+1 -> 46151 | ... AF2: =AE2+1 -> 46173 | AG2: Grand Total
A3: Dues
A4: Monish | B4: 4098413.4 | C4: 0 | D4: 0 | E4: 3057311 | F4: 1572743 | G4: 1730345.1 | H4: 2460211.9 | I4: 0 | J4: 0 | K4: 0 | L4: 0 | M4: 0 | N4: 0 | O4: 0 | P4: 0 | Q4: 0 | R4: 0 | S4: 0 | T4: 0 | U4: 0 | V4: 0 | W4: 0 | X4: 0 | Y4: 0 | Z4: 0 | AA4: 0 | AB4: 0 | AC4: 0 | AD4: 0 | AE4: 0 | AF4: 0 | AG4: =SUM(B4:AF4) -> 12919024
A5: Walid | B5: 2879518.4 | C5: 0 | D5: 0 | E5: 5001482.6 | F5: 3818560.8 | G5: 2591192.1 | H5: 2000406.8 | I5: 0 | J5: 0 | K5: 0 | L5: 0 | M5: 0 | N5: 0 | O5: 0 | P5: 0 | Q5: 0 | R5: 0 | S5: 0 | T5: 0 | U5: 0 | V5: 0 | W5: 0 | X5: 0 | Y5: 0 | Z5: 0 | AA5: 0 | AB5: 0 | AC5: 0 | AD5: 0 | AE5: 0 | AF5: 0 | AG5: =SUM(B5:AF5) -> 16291161
A6: Melvyn | B6: 1145061.6 | C6: 0 | D6: 0 | E6: 2314057.3 | F6: 2340843 | G6: 2509495.1 | H6: 2617764.5 | I6: 0 | J6: 0 | K6: 0 | L6: 0 | M6: 0 | N6: 0 | O6: 0 | P6: 0 | Q6: 0 | R6: 0 | S6: 0 | T6: 0 | U6: 0 | V6: 0 | W6: 0 | X6: 0 | Y6: 0 | Z6: 0 | AA6: 0 | AB6: 0 | AC6: 0 | AD6: 0 | AE6: 0 | AF6: 0 | AG6: =SUM(B6:AF6) -> 10927221
A7: Anna | B7: 0 | C7: 0 | D7: 0 | E7: 1325391.9 | F7: 587649 | G7: 598975.15 | H7: 420035.73 | I7: 0 | J7: 0 | K7: 0 | L7: 0 | M7: 0 | N7: 0 | O7: 0 | P7: 0 | Q7: 0 | R7: 0 | S7: 0 | T7: 0 | U7: 0 | V7: 0 | W7: 0 | X7: 0 | Y7: 0 | Z7: 0 | AA7: 0 | AB7: 0 | AC7: 0 | AD7: 0 | AE7: 0 | AF7: 0 | AG7: =SUM(B7:AF7) -> 2932051.8
A8: UAQ Sub Total | B8: =SUM(B4:B7) -> 8122993.3 | C8: =SUM(C4:C7) -> 0 | D8: =SUM(D4:D7) -> 0 | E8: =SUM(E4:E7) -> 11698243 | F8: =SUM(F4:F7) -> 8319795.8 | G8: =SUM(G4:G7) -> 7430007.4 | H8: =SUM(H4:H7) -> 7498418.9 | I8: =SUM(I4:I7) -> 0 | ... AF8: =SUM(AF4:AF7) -> 0 | AG8: =SUM(B8:AF8) -> 43069458
A9: Ruhul | B9: 200000 | C9: 0 | D9: 0 | E9: 298000 | F9: 291447 | G9: 519864 | H9: 524510 | I9: 0 | J9: 0 | K9: 0 | L9: 0 | M9: 0 | N9: 0 | O9: 0 | P9: 0 | Q9: 0 | R9: 0 | S9: 0 | T9: 0 | U9: 0 | V9: 0 | W9: 0 | X9: 0 | Y9: 0 | Z9: 0 | AA9: 0 | AB9: 0 | AC9: 0 | AD9: 0 | AE9: 0 | AF9: 0 | AG9: =SUM(B9:AF9) -> 1833821
A10: Ali | B10: 1476660 | C10: 0 | D10: 0 | E10: 1533311 | F10: 1549723 | G10: 1575286 | H10: 782720 | I10: 0 | J10: 0 | K10: 0 | L10: 0 | M10: 0 | N10: 0 | O10: 0 | P10: 0 | Q10: 0 | R10: 0 | S10: 0 | T10: 0 | U10: 0 | V10: 0 | W10: 0 | X10: 0 | Y10: 0 | Z10: 0 | AA10: 0 | AB10: 0 | AC10: 0 | AD10: 0 | AE10: 0 | AF10: 0 | AG10: =SUM(B10:AF10) -> 6917700
A11: Anirudh | B11: 2487142.3 | C11: 0 | D11: 0 | E11: 2004811.2 | F11: 1716589.1 | G11: 1800817 | H11: 1817369.1 | I11: 0 | J11: 0 | K11: 0 | L11: 0 | M11: 0 | N11: 0 | O11: 0 | P11: 0 | Q11: 0 | R11: 0 | S11: 0 | T11: 0 | U11: 0 | V11: 0 | W11: 0 | X11: 0 | Y11: 0 | Z11: 0 | AA11: 0 | AB11: 0 | AC11: 0 | AD11: 0 | AE11: 0 | AF11: 0 | AG11: =SUM(B11:AF11) -> 9826728.7
A12: Aqsa | B12: 1471944 | C12: 0 | D12: 0 | E12: 4101031 | F12: 2272475.6 | G12: 1935737.5 | H12: 1978777 | I12: 0 | J12: 0 | K12: 0 | L12: 0 | M12: 0 | N12: 0 | O12: 0 | P12: 0 | Q12: 0 | R12: 0 | S12: 0 | T12: 0 | U12: 0 | V12: 0 | W12: 0 | X12: 0 | Y12: 0 | Z12: 0 | AA12: 0 | AB12: 0 | AC12: 0 | AD12: 0 | AE12: 0 | AF12: 0 | AG12: =SUM(B12:AF12) -> 11759965
A13: Karan | B13: 1426030 | C13: 0 | D13: 0 | E13: 1221074 | F13: 1621551 | G13: 1410721 | H13: 1311551 | I13: 0 | J13: 0 | K13: 0 | L13: 0 | M13: 0 | N13: 0 | O13: 0 | P13: 0 | Q13: 0 | R13: 0 | S13: 0 | T13: 0 | U13: 0 | V13: 0 | W13: 0 | X13: 0 | Y13: 0 | Z13: 0 | AA13: 0 | AB13: 0 | AC13: 0 | AD13: 0 | AE13: 0 | AF13: 0 | AG13: =SUM(B13:AF13) -> 6990927
A14: Rajiv | B14: 2541514 | C14: 0 | D14: 0 | E14: 2119047 | F14: 2211363 | G14: 2350313 | H14: 2279577 | I14: 0 | J14: 0 | K14: 0 | L14: 0 | M14: 0 | N14: 0 | O14: 0 | P14: 0 | Q14: 0 | R14: 0 | S14: 0 | T14: 0 | U14: 0 | V14: 0 | W14: 0 | X14: 0 | Y14: 0 | Z14: 0 | AA14: 0 | AB14: 0 | AC14: 0 | AD14: 0 | AE14: 0 | AF14: 0 | AG14: =SUM(B14:AF14) -> 11501814
A15: Vinod | B15: 202000 | C15: 0 | D15: 0 | E15: 229500 | F15: 1092125.9 | G15: 333313.5 | H15: 200000 | I15: 0 | J15: 0 | K15: 0 | L15: 0 | M15: 0 | N15: 0 | O15: 0 | P15: 0 | Q15: 0 | R15: 0 | S15: 0 | T15: 0 | U15: 0 | V15: 0 | W15: 0 | X15: 0 | Y15: 0 | Z15: 0 | AA15: 0 | AB15: 0 | AC15: 0 | AD15: 0 | AE15: 0 | AF15: 0 | AG15: =SUM(B15:AF15) -> 2056939.4
A16: Sarmad | B16: 2737489 | C16: 0 | D16: 0 | E16: 3145565.9 | F16: 3117450.5 | G16: 3092921 | H16: 2498098 | I16: 0 | J16: 0 | K16: 0 | L16: 0 | M16: 0 | N16: 0 | O16: 0 | P16: 0 | Q16: 0 | R16: 0 | S16: 0 | T16: 0 | U16: 0 | V16: 0 | W16: 0 | X16: 0 | Y16: 0 | Z16: 0 | AA16: 0 | AB16: 0 | AC16: 0 | AD16: 0 | AE16: 0 | AF16: 0 | AG16: =SUM(B16:AF16) -> 14591524
A17: Zeba | B17: 2555920.7 | C17: 0 | D17: 0 | E17: 2275588 | F17: 2008035.5 | G17: 2506470 | H17: 1158239 | I17: 0 | J17: 0 | K17: 0 | L17: 0 | M17: 0 | N17: 0 | O17: 0 | P17: 0 | Q17: 0 | R17: 0 | S17: 0 | T17: 0 | U17: 0 | V17: 0 | W17: 0 | X17: 0 | Y17: 0 | Z17: 0 | AA17: 0 | AB17: 0 | AC17: 0 | AD17: 0 | AE17: 0 | AF17: 0 | AG17: =SUM(B17:AF17) -> 10504253
A18: Oksana | B18: 2128529 | C18: 0 | D18: 0 | E18: 2130475 | F18: 2049878 | G18: 2022619 | H18: 2059510 | I18: 0 | J18: 0 | K18: 0 | L18: 0 | M18: 0 | N18: 0 | O18: 0 | P18: 0 | Q18: 0 | R18: 0 | S18: 0 | T18: 0 | U18: 0 | V18: 0 | W18: 0 | X18: 0 | Y18: 0 | Z18: 0 | AA18: 0 | AB18: 0 | AC18: 0 | AD18: 0 | AE18: 0 | AF18: 0 | AG18: =SUM(B18:AF18) -> 10391011
A19: Omar | B19: 669971 | C19: 0 | D19: 0 | E19: 2069394.4 | F19: 2116543.1 | G19: 2722870.3 | H19: 2171492.8 | I19: 0 | J19: 0 | K19: 0 | L19: 0 | M19: 0 | N19: 0 | O19: 0 | P19: 0 | Q19: 0 | R19: 0 | S19: 0 | T19: 0 | U19: 0 | V19: 0 | W19: 0 | X19: 0 | Y19: 0 | Z19: 0 | AA19: 0 | AB19: 0 | AC19: 0 | AD19: 0 | AE19: 0 | AF19: 0 | AG19: =SUM(B19:AF19) -> 9750271.5
A20: Yusuf | B20: 329528.08 | C20: 0 | D20: 0 | E20: 2004150.4 | F20: 1929236.1 | G20: 1590901.2 | H20: 1486579 | I20: 0 | J20: 0 | K20: 0 | L20: 0 | M20: 0 | N20: 0 | O20: 0 | P20: 0 | Q20: 0 | R20: 0 | S20: 0 | T20: 0 | U20: 0 | V20: 0 | W20: 0 | X20: 0 | Y20: 0 | Z20: 0 | AA20: 0 | AB20: 0 | AC20: 0 | AD20: 0 | AE20: 0 | AF20: 0 | AG20: =SUM(B20:AF20) -> 7340394.8
... A30: Moustafa | B30: 1584660 | C30: 0 | D30: 0 | E30: 1142000 | F30: 1014000 | G30: 1029590 | H30: 1101602 | I30: 0 | J30: 0 | K30: 0 | L30: 0 | M30: 0 | N30: 0 | O30: 0 | P30: 0 | Q30: 0 | R30: 0 | S30: 0 | T30: 0 | U30: 0 | V30: 0 | W30: 0 | X30: 0 | Y30: 0 | Z30: 0 | AA30: 0 | AB30: 0 | AC30: 0 | AD30: 0 | AE30: 0 | AF30: 0 | AG30: =SUM(B30:AF30) -> 5871852
A31: SOBHA Sub Total | B31: =SUM(B9:B30) -> 32261966 | C31: =SUM(C9:C30) -> 0 | D31: =SUM(D9:D30) -> 0 | E31: =SUM(E9:E30) -> 37524857 | F31: =SUM(F9:F30) -> 35199787 | G31: =SUM(G9:G30) -> 34839227 | H31: =SUM(H9:H30) -> 34438498 | I31: =SUM(I9:I30) -> 0 | ... AF31: =SUM(AF9:AF30) -> 0 | AG31: =SUM(B31:AF31) -> 1.7426434e+08
A32: Total Dues | B32: =SUM(B31,B8) -> 40384959 | C32: =SUM(C31,C8) -> 0 | D32: =SUM(D31,D8) -> 0 | E32: =SUM(E31,E8) -> 49223100 | F32: =SUM(F31,F8) -> 43519583 | G32: =SUM(G31,G8) -> 42269235 | H32: =SUM(H31,H8) -> 41936917 | I32: =SUM(I31,I8) -> 0 | ... AF32: =SUM(AF31,AF8) -> 0 | AG32: =SUM(B32:AF32) -> 2.1733379e+08
A33: Advances
A34: Abdulla | B34: 527000 | C34: 0 | D34: 0 | E34: 1000000 | F34: 1000629 | G34: 1000053 | H34: 1000000 | I34: 0 | J34: 0 | K34: 0 | L34: 0 | M34: 0 | N34: 0 | O34: 0 | P34: 0 | Q34: 0 | R34: 0 | S34: 0 | T34: 0 | U34: 0 | V34: 0 | W34: 0 | X34: 0 | Y34: 0 | Z34: 0 | AA34: 0 | AB34: 0 | AC34: 0 | AD34: 0 | AE34: 0 | AF34: 0 | AG34: =SUM(B34:AF34) -> 4527682
A35: Ateev | B35: 1903600 | C35: 0 | D35: 0 | E35: 2457720 | F35: 2603374 | G35: 2436483 | H35: 2511878 | I35: 0 | J35: 0 | K35: 0 | L35: 0 | M35: 0 | N35: 0 | O35: 0 | P35: 0 | Q35: 0 | R35: 0 | S35: 0 | T35: 0 | U35: 0 | V35: 0 | W35: 0 | X35: 0 | Y35: 0 | Z35: 0 | AA35: 0 | AB35: 0 | AC35: 0 | AD35: 0 | AE35: 0 | AF35: 0 | AG35: =SUM(B35:AF35) -> 11913055
A36: Ayari | B36: 2577558 | C36: 0 | D36: 0 | E36: 1000032 | F36: 1035731 | G36: 745292 | H36: 1000000 | I36: 0 | J36: 0 | K36: 0 | L36: 0 | M36: 0 | N36: 0 | O36: 0 | P36: 0 | Q36: 0 | R36: 0 | S36: 0 | T36: 0 | U36: 0 | V36: 0 | W36: 0 | X36: 0 | Y36: 0 | Z36: 0 | AA36: 0 | AB36: 0 | AC36: 0 | AD36: 0 | AE36: 0 | AF36: 0 | AG36: =SUM(B36:AF36) -> 6358613
A37: Nischitha | B37: 0 | C37: 0 | D37: 0 | E37: 0 | F37: 0 | G37: 0 | H37: 0 | I37: 0 | J37: 0 | K37: 0 | L37: 0 | M37: 0 | N37: 0 | O37: 0 | P37: 0 | Q37: 0 | R37: 0 | S37: 0 | T37: 0 | U37: 0 | V37: 0 | W37: 0 | X37: 0 | Y37: 0 | Z37: 0 | AA37: 0 | AB37: 0 | AC37: 0 | AD37: 0 | AE37: 0 | AF37: 0 | AG37: =SUM(B37:AF37) -> 0
A38: Basma | B38: 2008082 | C38: 0 | D38: 0 | E38: 2547667 | F38: 2011915 | G38: 2176439 | H38: 2000000 | I38: 0 | J38: 0 | K38: 0 | L38: 0 | M38: 0 | N38: 0 | O38: 0 | P38: 0 | Q38: 0 | R38: 0 | S38: 0 | T38: 0 | U38: 0 | V38: 0 | W38: 0 | X38: 0 | Y38: 0 | Z38: 0 | AA38: 0 | AB38: 0 | AC38: 0 | AD38: 0 | AE38: 0 | AF38: 0 | AG38: =SUM(B38:AF38) -> 10744103
A39: Sherif | B39: 1000589 | C39: 0 | D39: 0 | E39: 778054 | F39: 1000175 | G39: 1000000 | H39: 1396024 | I39: 0 | J39: 0 | K39: 0 | L39: 0 | M39: 0 | N39: 0 | O39: 0 | P39: 0 | Q39: 0 | R39: 0 | S39: 0 | T39: 0 | U39: 0 | V39: 0 | W39: 0 | X39: 0 | Y39: 0 | Z39: 0 | AA39: 0 | AB39: 0 | AC39: 0 | AD39: 0 | AE39: 0 | AF39: 0 | AG39: =SUM(B39:AF39) -> 5174842
A40: Wael | B40: 1036362 | C40: 0 | D40: 0 | E40: 1210189 | F40: 2001934 | G40: 1501564.6 | H40: 1000136.4 | I40: 0 | J40: 0 | K40: 0 | L40: 0 | M40: 0 | N40: 0 | O40: 0 | P40: 0 | Q40: 0 | R40: 0 | S40: 0 | T40: 0 | U40: 0 | V40: 0 | W40: 0 | X40: 0 | Y40: 0 | Z40: 0 | AA40: 0 | AB40: 0 | AC40: 0 | AD40: 0 | AE40: 0 | AF40: 0 | AG40: =SUM(B40:AF40) -> 6750186
A41: Yogesh | B41: 436577 | C41: 0 | D41: 0 | E41: 800120 | F41: 613976 | G41: 616706 | H41: 683324 | I41: 0 | J41: 0 | K41: 0 | L41: 0 | M41: 0 | N41: 0 | O41: 0 | P41: 0 | Q41: 0 | R41: 0 | S41: 0 | T41: 0 | U41: 0 | V41: 0 | W41: 0 | X41: 0 | Y41: 0 | Z41: 0 | AA41: 0 | AB41: 0 | AC41: 0 | AD41: 0 | AE41: 0 | AF41: 0 | AG41: =SUM(B41:AF41) -> 3150703
A42: Krizia | B42: 1113130 | C42: 0 | D42: 0 | E42: 701145 | F42: 509301 | G42: 509071.56 | H42: 1747417 | I42: 0 | J42: 0 | K42: 0 | L42: 0 | M42: 0 | N42: 0 | O42: 0 | P42: 0 | Q42: 0 | R42: 0 | S42: 0 | T42: 0 | U42: 0 | V42: 0 | W42: 0 | X42: 0 | Y42: 0 | Z42: 0 | AA42: 0 | AB42: 0 | AC42: 0 | AD42: 0 | AE42: 0 | AF42: 0 | AG42: =SUM(B42:AF42) -> 4580064.6
A43: Vijay | B43: 1000698 | C43: 0 | D43: 0 | E43: 700098 | F43: 601000 | G43: 1000215 | H43: 1000129 | I43: 0 | J43: 0 | K43: 0 | L43: 0 | M43: 0 | N43: 0 | O43: 0 | P43: 0 | Q43: 0 | R43: 0 | S43: 0 | T43: 0 | U43: 0 | V43: 0 | W43: 0 | X43: 0 | Y43: 0 | Z43: 0 | AA43: 0 | AB43: 0 | AC43: 0 | AD43: 0 | AE43: 0 | AF43: 0 | AG43: =SUM(B43:AF43) -> 4302140
A44: Jaidev | B44: 519046 | C44: 0 | D44: 0 | E44: 1001186 | F44: 1039578.5 | G44: 1004599 | H44: 1844238 | I44: 0 | J44: 0 | K44: 0 | L44: 0 | M44: 0 | N44: 0 | O44: 0 | P44: 0 | Q44: 0 | R44: 0 | S44: 0 | T44: 0 | U44: 0 | V44: 0 | W44: 0 | X44: 0 | Y44: 0 | Z44: 0 | AA44: 0 | AB44: 0 | AC44: 0 | AD44: 0 | AE44: 0 | AF44: 0 | AG44: =SUM(B44:AF44) -> 5408647.5
A45: Noha | B45: 1430954 | C45: 0 | D45: 0 | E45: 2221036 | F45: 551059.61 | G45: 358881 | H45: 651308 | I45: 0 | J45: 0 | K45: 0 | L45: 0 | M45: 0 | N45: 0 | O45: 0 | P45: 0 | Q45: 0 | R45: 0 | S45: 0 | T45: 0 | U45: 0 | V45: 0 | W45: 0 | X45: 0 | Y45: 0 | Z45: 0 | AA45: 0 | AB45: 0 | AC45: 0 | AD45: 0 | AE45: 0 | AF45: 0 | AG45: =SUM(B45:AF45) -> 5213238.6
A46: Total Advances | B46: =SUM(B34:B45) -> 13553596 | C46: =SUM(C34:C45) -> 0 | D46: =SUM(D34:D45) -> 0 | E46: =SUM(E34:E45) -> 14417247 | F46: =SUM(F34:F45) -> 12968673 | G46: =SUM(G34:G45) -> 12349304 | H46: =SUM(H34:H45) -> 14834454 | I46: =SUM(I34:I45) -> 0 | ... AF46: =SUM(AF34:AF45) -> 0 | AG46: =SUM(B46:AF46) -> 68123275
A47: Grand Total | B47: =SUM(B32,B46) -> 53938555 | C47: =SUM(C32,C46) -> 0 | D47: =SUM(D32,D46) -> 0 | E47: =SUM(E32,E46) -> 63640347 | F47: =SUM(F32,F46) -> 56488256 | G47: =SUM(G32,G46) -> 54618539 | H47: =SUM(H32,H46) -> 56771371 | I47: =SUM(I32,I46) -> 0 | ... AF47: =SUM(AF32,AF46) -> 0 | AG47: =SUM(B47:AF47) -> 2.8545707e+08

Sheet PR Report - SOBHA 
A2: Sobha | B2: As per Tracker | H2: PR
A3: Collection Executive | B3: Daily Target 07/05 | C3: Collected 07-05-26 | D3: Target (01/05 - 07/05) | E3: Achieved (01/05 - 07/05) | F3: Monthly Target | G3: Total Achieved % | H3: PR Approved | I3: PR Not Approved
A4: Dues
A5: Ali | B5: 2176503.6 | C5: 782720 | D5: 10882518 | E5: 6917700 | F5: 37000562 | G5: =IFERROR(E5/D5,0) -> 0.63567089 | H5: 6097448.4 | I5: =_xlfn.XLOOKUP(A5,$A$48:$A$70,$B$48:$B$70) -> 5003503.6
A6: Anirudh | B6: 2840497.8 | C6: 1817369.1 | D6: 14202489 | E6: 9826728.7 | F6: 48288463 | G6: =IFERROR(E6/D6,0) -> 0.69190187 | H6: 12626119 | I6: =_xlfn.XLOOKUP(A6,$A$48:$A$70,$B$48:$B$70) -> 4572457
A7: Ruhul | B7: 2774274.2 | C7: 524510 | D7: 13871371 | E7: 1833821 | F7: 47162662 | G7: =IFERROR(E7/D7,0) -> 0.13220185 | H7: 5649097.7 | I7: =_xlfn.XLOOKUP(A7,$A$48:$A$70,$B$48:$B$70) -> 4238208.5
A8: Karan | B8: 2554015.1 | C8: 1311551 | D8: 12770076 | E8: 6990927 | F8: 43418257 | G8: =IFERROR(E8/D8,0) -> 0.54744602 | H8: 1317193.7 | I8: =_xlfn.XLOOKUP(A8,$A$48:$A$70,$B$48:$B$70) -> 2640605.4
A9: Yusuf | B9: 2248108.4 | C9: 1486579 | D9: 11240542 | E9: 7340394.8 | F9: 38217843 | G9: =IFERROR(E9/D9,0) -> 0.65302854 | H9: 4090159.2 | I9: =_xlfn.XLOOKUP(A9,$A$48:$A$70,$B$48:$B$70) -> 8197132.9
A10: Sabah | B10: 1740757.5 | C10: 999311 | D10: 8703787.6 | E10: 5039866 | F10: 29592878 | G10: =IFERROR(E10/D10,0) -> 0.57904285 | H10: 3510870.3 | I10: =_xlfn.XLOOKUP(A10,$A$48:$A$70,$B$48:$B$70) -> 3034882.1
A11: Daria | B11: 1878569.9 | C11: 1513133 | D11: 9392849.7 | E11: 9617286 | F11: 31935689 | G11: =IFERROR(E11/D11,0) -> 1.0238944 | H11: 12317751 | I11: =_xlfn.XLOOKUP(A11,$A$48:$A$70,$B$48:$B$70) -> 1980461.2
A12: Rajiv | B12: 2238461.1 | C12: 2279577 | D12: 11192305 | E12: 11501814 | F12: 38053838 | G12: =IFERROR(E12/D12,0) -> 1.0276537 | H12: 5271884.8 | I12: =_xlfn.XLOOKUP(A12,$A$48:$A$70,$B$48:$B$70) -> 7215187.2
A13: Vinod | B13: 3230160.1 | C13: 200000 | D13: 16150800 | E13: 2056939.4 | F13: 54912721 | G13: =IFERROR(E13/D13,0) -> 0.12735836 | H13: 3957231.4 | I13: =_xlfn.XLOOKUP(A13,$A$48:$A$70,$B$48:$B$70) -> 4142840.9
A14: Omar | B14: 2458129.9 | C14: 2171492.8 | D14: 12290649 | E14: 9750271.5 | F14: 41788208 | G14: =IFERROR(E14/D14,0) -> 0.79330808 | H14: 20466705 | I14: =_xlfn.XLOOKUP(A14,$A$48:$A$70,$B$48:$B$70) -> 4744590
A15: Oksana | B15: 2106539.8 | C15: 2059510 | D15: 10532699 | E15: 10391011 | F15: 35811177 | G15: =IFERROR(E15/D15,0) -> 0.98654779 | H15: 5228871.5 | I15: =_xlfn.XLOOKUP(A15,$A$48:$A$70,$B$48:$B$70) -> 5422934.5
A16: Sarmad | B16: 3286315.3 | C16: 2498098 | D16: 16431576 | E16: 14591524 | F16: 55867360 | G16: =IFERROR(E16/D16,0) -> 0.88801731 | H16: 6509957 | I16: =_xlfn.XLOOKUP(A16,$A$48:$A$70,$B$48:$B$70) -> 8001301.3
... A26: Moustafa | B26: 1670123.7 | C26: 1101602 | D26: 8350618.5 | E26: 5871852 | F26: 28392103 | G26: =IFERROR(E26/D26,0) -> 0.70316372 | H26: 3612983.7 | I26: =_xlfn.XLOOKUP(A26,$A$48:$A$70,$B$48:$B$70) -> 4581377.6
A27: Total Dues | B27: =SUM(B5:B26) -> 50252771 | C27: =SUM(C5:C26) -> 34438498 | D27: =SUM(D5:D26) -> 2.5126385e+08 | E27: =SUM(E5:E26) -> 1.7426434e+08 | F27: =SUM(F5:F26) -> 854297104 | G27: =IFERROR(E27/D27,0) -> 0.69355115 | H27: =SUM(H5:H26) -> 1.2977049e+08 | I27: =SUM(I5:I26) -> 1.0721567e+08
A28: Advances
A29: Ayari | B29: 0 | C29: 1000000 | D29: 0 | E29: 6358613 | F29: 0 | G29: =IFERROR(E29/D29,0) -> 0 | H29: 5456392.9 | I29: =_xlfn.XLOOKUP(A29,$A$73:$A$84,$B$73:$B$84) -> 973340
A30: Ateev | B30: 0 | C30: 2511878 | D30: 0 | E30: 11913055 | F30: 0 | G30: =IFERROR(E30/D30,0) -> 0 | H30: 9493591 | I30: =_xlfn.XLOOKUP(A30,$A$73:$A$84,$B$73:$B$84) -> 3599020
A31: Abdulla | B31: 0 | C31: 1000000 | D31: 0 | E31: 4310770 | F31: 0 | G31: =IFERROR(E31/D31,0) -> 0 | H31: 3073221 | I31: =_xlfn.XLOOKUP(A31,$A$73:$A$84,$B$73:$B$84) -> 1563457
A32: Wael | B32: 0 | C32: 1000136.4 | D32: 0 | E32: 6750186 | F32: 0 | G32: =IFERROR(E32/D32,0) -> 0 | H32: 3920238 | I32: =_xlfn.XLOOKUP(A32,$A$73:$A$84,$B$73:$B$84) -> 2292038.6
A33: Nischitha | B33: 0 | C33: 0 | D33: 0 | E33: 0 | F33: 0 | G33: =IFERROR(E33/D33,0) -> 0 | H33: 0 | I33: =_xlfn.XLOOKUP(A33,$A$73:$A$84,$B$73:$B$84) -> 0
A34: Sherif | B34: 0 | C34: 637266 | D34: 0 | E34: 2560947 | F34: 0 | G34: =IFERROR(E34/D34,0) -> 0 | H34: 4680292.4 | I34: =_xlfn.XLOOKUP(A34,$A$73:$A$84,$B$73:$B$84) -> 840912
A35: Yogesh | B35: 0 | C35: 683324 | D35: 0 | E35: 1369006 | F35: 0 | G35: =IFERROR(E35/D35,0) -> 0 | H35: 1237047 | I35: =_xlfn.XLOOKUP(A35,$A$73:$A$84,$B$73:$B$84) -> 0
A36: Krizia | B36: 0 | C36: 0 | D36: 0 | E36: 1143453.6 | F36: 0 | G36: =IFERROR(E36/D36,0) -> 0 | H36: 561470 | I36: =_xlfn.XLOOKUP(A36,$A$73:$A$84,$B$73:$B$84) -> 860483.56
A37: Vijay | B37: 0 | C37: 1000129 | D37: 0 | E37: 4302140 | F37: 0 | G37: =IFERROR(E37/D37,0) -> 0 | H37: 1589332 | I37: =_xlfn.XLOOKUP(A37,$A$73:$A$84,$B$73:$B$84) -> 900324
A38: Jaidev | B38: 0 | C38: 1844238 | D38: 0 | E38: 5408647.5 | F38: 0 | G38: =IFERROR(E38/D38,0) -> 0 | H38: 3730663.7 | I38: =_xlfn.XLOOKUP(A38,$A$73:$A$84,$B$73:$B$84) -> 1672212
A39: Basma | B39: 0 | C39: 1477391 | D39: 0 | E39: 9515613 | F39: 0 | G39: =IFERROR(E39/D39,0) -> 0 | H39: 7291361 | I39: =_xlfn.XLOOKUP(A39,$A$73:$A$84,$B$73:$B$84) -> 7149935.5
A40: Noha | B40: 0 | C40: 586308 | D40: 0 | E40: 4823726.6 | F40: 0 | G40: =IFERROR(E40/D40,0) -> 0 | H40: 2924662.7 | I40: =_xlfn.XLOOKUP(A40,$A$73:$A$84,$B$73:$B$84) -> 1032657.9
A41: Total Advances | B41: =SUM(B29:B40) -> 0 | C41: =SUM(C29:C40) -> 11740670 | D41: =SUM(D29:D40) -> 0 | E41: =SUM(E29:E40) -> 58456158 | F41: =SUM(F29:F40) -> 0 | G41: =IFERROR(E41/D41,0) -> 0 | H41: =SUM(H29:H40) -> 43958272 | I41: =SUM(I29:I40) -> 20884381
A42: Grand Total | B42: =SUM(B27,B41) -> 50252771 | C42: =SUM(C27,C41) -> 46179169 | D42: =SUM(D27,D41) -> 2.5126385e+08 | E42: =SUM(E27,E41) -> 2.3272049e+08 | F42: =SUM(F27,F41) -> 854297104 | G42: =IFERROR(E42/D42,0) -> 0.92619965 | H42: =SUM(H27,H41) -> 1.7372877e+08 | I42: =SUM(I27,I41) -> 1.2810005e+08
A45: Sobha
A46: Collection Executive | B46: Not Approved | C46: In Process | D46: Resubmitted | E46: Rejected
A47: Dues
A48: Ali | B48: =SUM(C48:E48) -> 5003503.6 | C48: 1911450.8 | D48: 1035336 | E48: 2056716.9
A49: Anirudh | B49: =SUM(C49:E49) -> 4572457 | C49: 1415573 | D49: 388254 | E49: 2768630
A50: Ruhul | B50: =SUM(C50:E50) -> 4238208.5 | C50: 1282474.4 | D50: 2552809.1 | E50: 402925
A51: Karan | B51: =SUM(C51:E51) -> 2640605.4 | C51: 819291.03 | D51: 331587 | E51: 1489727.4
A52: Aqsa | B52: =SUM(C52:E52) -> 4216231.3 | C52: 527326 | D52: 481716 | E52: 3207189.3
...

Sheet PR Report - SINIYA
A2: Siniya | B2: As per Tracker | H2: PR
A3: Collection Executive | B3: Daily Target 07/05 | C3: Collected 07-05-26 | D3: Target (01/05 - 07/05) | E3: Achieved (01/05 - 07/05) | F3: Monthly Target | G3: Total Achieved % | H3: PR Approved | I3: PR Not Approved
A4: Dues
A5: Monish | B5: 3823529.4 | C5: 2460211.9 | D5: 19117647 | E5: 12919024 | F5: 65000000 | G5: =IFERROR(E5/D5,0) -> 0.67576435 | H5: 6517845.8 | I5: =_xlfn.XLOOKUP(A5,$A$41:$A$59,$B$41:$B$59) -> 5676444.3
A6: Melvyn | B6: 2647058.8 | C6: 2617764.5 | D6: 13235294 | E6: 10927221 | F6: 45000000 | G6: =IFERROR(E6/D6,0) -> 0.82561229 | H6: 5979287.7 | I6: =_xlfn.XLOOKUP(A6,$A$41:$A$59,$B$41:$B$59) -> 4265516.2
A7: Anna | B7: 1176470.6 | C7: 420035.73 | D7: 5882352.9 | E7: 2932051.8 | F7: 20000000 | G7: =IFERROR(E7/D7,0) -> 0.4984488 | H7: 2112020 | I7: =_xlfn.XLOOKUP(A7,$A$41:$A$59,$B$41:$B$59) -> 506236.11
A8: Ruhul | B8: 0 | C8: 0 | D8: 0 | E8: 0 | F8: 0 | G8: =IFERROR(E8/D8,0) -> 0 | H8: 0 | I8: =_xlfn.XLOOKUP(A8,$A$41:$A$59,$B$41:$B$59) -> 0
A9: Walid | B9: 2941176.5 | C9: 567088 | D9: 14705882 | E9: 9386458.1 | F9: 50000000 | G9: =IFERROR(E9/D9,0) -> 0.63827915 | H9: 6515834.5 | I9: =_xlfn.XLOOKUP(A9,$A$41:$A$59,$B$41:$B$59) -> 3546005
A10: Ali | B10: 0 | C10: 0 | D10: 0 | E10: 0 | G10: =IFERROR(E10/D10,0) -> 0 | H10: 0 | I10: =_xlfn.XLOOKUP(A10,$A$41:$A$59,$B$41:$B$59) -> 0
A11: Anirudh | B11: 0 | C11: 0 | D11: 0 | E11: 0 | G11: =IFERROR(E11/D11,0) -> 0 | H11: 0 | I11: =_xlfn.XLOOKUP(A11,$A$41:$A$59,$B$41:$B$59) -> 0
A12: Aqsa | B12: 0 | C12: 0 | D12: 0 | E12: 0 | G12: =IFERROR(E12/D12,0) -> 0 | H12: 0 | I12: =_xlfn.XLOOKUP(A12,$A$41:$A$59,$B$41:$B$59) -> 0
A13: Hussein | B13: 0 | C13: 0 | D13: 0 | E13: 0 | G13: =IFERROR(E13/D13,0) -> 0 | H13: 505555 | I13: =_xlfn.XLOOKUP(A13,$A$41:$A$59,$B$41:$B$59) -> 0
A14: Karan | B14: 0 | C14: 0 | D14: 0 | E14: 0 | G14: =IFERROR(E14/D14,0) -> 0 | H14: 0 | I14: =_xlfn.XLOOKUP(A14,$A$41:$A$59,$B$41:$B$59) -> 342501
A15: Rajiv | B15: 0 | C15: 0 | D15: 0 | E15: 0 | G15: =IFERROR(E15/D15,0) -> 0 | H15: 0 | I15: =_xlfn.XLOOKUP(A15,$A$41:$A$59,$B$41:$B$59) -> 0
A16: Vinod | B16: 0 | C16: 0 | D16: 0 | E16: 0 | G16: =IFERROR(E16/D16,0) -> 0 | H16: 0 | I16: =_xlfn.XLOOKUP(A16,$A$41:$A$59,$B$41:$B$59) -> 0
A17: Sarmad | B17: 0 | C17: 0 | D17: 0 | E17: 0 | G17: =IFERROR(E17/D17,0) -> 0 | H17: 0 | I17: =_xlfn.XLOOKUP(A17,$A$41:$A$59,$B$41:$B$59) -> 0
A18: Zeba | B18: 0 | C18: 0 | D18: 0 | E18: 0 | G18: =IFERROR(E18/D18,0) -> 0 | H18: 0 | I18: =_xlfn.XLOOKUP(A18,$A$41:$A$59,$B$41:$B$59) -> 0
A19: Sabah | B19: 0 | C19: 0 | D19: 0 | E19: 0 | G19: =IFERROR(E19/D19,0) -> 0 | H19: 0 | I19: =_xlfn.XLOOKUP(A19,$A$41:$A$59,$B$41:$B$59) -> 0
A20: Sid | B20: 0 | C20: 0 | D20: 0 | E20: 0 | G20: =IFERROR(E20/D20,0) -> 0 | H20: 0 | I20: =_xlfn.XLOOKUP(A20,$A$41:$A$59,$B$41:$B$59) -> 0
A21: Abdellatif | B21: 0 | C21: 0 | D21: 0 | E21: 0 | G21: =IFERROR(E21/D21,0) -> 0 | H21: 0 | I21: =_xlfn.XLOOKUP(A21,$A$41:$A$59,$B$41:$B$59) -> 0
A22: Total Dues | B22: =SUM(B5:B21) -> 10588235 | C22: =SUM(C5:C21) -> 6065100.1 | D22: =SUM(D5:D21) -> 52941176 | E22: =SUM(E5:E21) -> 36164756 | F22: =SUM(F5:F21) -> 180000000 | G22: =IFERROR((E22)/(D22),0) -> 0.68311205 | H22: =SUM(H5:H21) -> 21630543 | I22: =SUM(I5:I21) -> 14336703
A23: Advances
A24: Abdulla | B24: 0 | C24: 0 | D24: 0 | E24: 216912 | F24: 0 | G24: =IFERROR(E24/D24,0) -> 0 | H24: 288016 | I24: =_xlfn.XLOOKUP(A24,$A$62:$A$72,$B$62:$B$72) -> 0
A25: Noha | B25: 0 | C25: 65000 | D25: 0 | E25: 389512 | F25: 0 | G25: =IFERROR(E25/D25,0) -> 0 | H25: 246507.85 | I25: =_xlfn.XLOOKUP(A25,$A$62:$A$72,$B$62:$B$72) -> 388807.68
A26: Krizia | B26: 0 | C26: 1747417 | D26: 0 | E26: 3436611 | F26: 0 | G26: =IFERROR(E26/D26,0) -> 0 | H26: 2091049 | I26: =_xlfn.XLOOKUP(A26,$A$62:$A$72,$B$62:$B$72) -> 661137
A27: Ateev | B27: 0 | C27: 0 | D27: 0 | E27: 0 | F27: 0 | G27: =IFERROR(E27/D27,0) -> 0 | H27: 0 | I27: =_xlfn.XLOOKUP(A27,$A$62:$A$72,$B$62:$B$72) -> 0
A28: Ayari | B28: 0 | C28: 0 | D28: 0 | E28: 0 | F28: 0 | G28: =IFERROR(E28/D28,0) -> 0 | H28: 0 | I28: =_xlfn.XLOOKUP(A28,$A$62:$A$72,$B$62:$B$72) -> 0
A29: Nischitha | B29: 0 | C29: 0 | D29: 0 | E29: 0 | F29: 0 | G29: =IFERROR(E29/D29,0) -> 0 | H29: 0 | I29: =_xlfn.XLOOKUP(A29,$A$62:$A$72,$B$62:$B$72) -> 0
A30: Sherif | B30: 0 | C30: 428000 | D30: 0 | E30: 428000 | F30: 0 | G30: =IFERROR(E30/D30,0) -> 0 | H30: 0 | I30: =_xlfn.XLOOKUP(A30,$A$62:$A$72,$B$62:$B$72) -> 0
A31: Wael | B31: 0 | C31: 0 | D31: 0 | E31: 0 | F31: 0 | G31: =IFERROR(E31/D31,0) -> 0 | H31: 35775 | I31: =_xlfn.XLOOKUP(A31,$A$62:$A$72,$B$62:$B$72) -> 138572
A32: Jaidev | B32: 0 | C32: 0 | D32: 0 | E32: 0 | F32: 0 | G32: =IFERROR(E32/D32,0) -> 0 | H32: 0 | I32: =_xlfn.XLOOKUP(A32,$A$62:$A$72,$B$62:$B$72) -> 0
A33: Basma | B33: 0 | C33: 522609 | D33: 0 | E33: 1228490 | F33: 0 | G33: =IFERROR(E33/D33,0) -> 0 | H33: 749881 | I33: =_xlfn.XLOOKUP(A33,$A$62:$A$72,$B$62:$B$72) -> 0
A34: Yogesh | B34: 0 | C34: 0 | D34: 0 | E34: 1781697 | F34: 0 | G34: =IFERROR(E34/D34,0) -> 0 | H34: 40000 | I34: =_xlfn.XLOOKUP(A34,$A$62:$A$72,$B$62:$B$72) -> 674242
A35: Total Advances | B35: =SUM(B24:B34) -> 0 | C35: =SUM(C24:C34) -> 2763026 | D35: =SUM(D24:D34) -> 0 | E35: =SUM(E24:E34) -> 7481222 | F35: =SUM(F24:F34) -> 0 | G35: =IFERROR(E35/D35,0) -> 0 | H35: =SUM(H24:H34) -> 3451228.9 | I35: =SUM(I24:I34) -> 1862758.7
A36: Grand Total | B36: =SUM(B22,B35) -> 10588235 | C36: =SUM(C22,C35) -> 8828126.1 | D36: =SUM(D22,D35) -> 52941176 | E36: =SUM(E22,E35) -> 43645978 | F36: =SUM(F22,F35) -> 180000000 | G36: =IFERROR(E36/D36,0) -> 0.82442402 | H36: =SUM(H22,H35) -> 25081772 | I36: =SUM(I22,I35) -> 16199461
A38: Siniya
A39: Collection Executive | B39: Not Approved | C39: In Process | D39: Resubmitted | E39: Rejected
A40: Dues
A41: Ali | B41: =SUM(C41:E41) -> 0 | C41: 0 | D41: 0 | E41: 0
A42: Anirudh | B42: =SUM(C42:E42) -> 0 | C42: 0 | D42: 0 | E42: 0
...

Sheet PR Report - DOWNTOWN
A2: Downtown | B2: As per Tracker | H2: PR
A3: Collection Executive | B3: Daily Target 07/05 | C3: Collected 07-05-26 | D3: Target (01/05 - 07/05) | E3: Achieved (01/05 - 07/05) | F3: Monthly Target | G3: Total Achieved % | H3: PR Approved | I3: PR Not Approved
A4: Dues
A5: Monish | B5: 0 | C5: 0 | D5: 0 | E5: 0 | F5: 0 | G5: =IFERROR(E5/D5,0) -> 0 | H5: 0 | I5: =_xlfn.XLOOKUP(A5,$A$42:$A$59,$B$42:$B$59) -> 0
A6: Melvyn | B6: 0 | C6: 0 | D6: 0 | E6: 0 | F6: 0 | G6: =IFERROR(E6/D6,0) -> 0 | H6: 0 | I6: =_xlfn.XLOOKUP(A6,$A$42:$A$59,$B$42:$B$59) -> 0
A7: Anna | B7: 0 | C7: 0 | D7: 0 | E7: 0 | F7: 0 | G7: =IFERROR(E7/D7,0) -> 0 | H7: 0 | I7: =_xlfn.XLOOKUP(A7,$A$42:$A$59,$B$42:$B$59) -> 0
A8: Ruhul | B8: 0 | C8: 0 | D8: 0 | E8: 0 | F8: 0 | G8: =IFERROR(E8/D8,0) -> 0 | H8: 0 | I8: =_xlfn.XLOOKUP(A8,$A$42:$A$59,$B$42:$B$59) -> 0
A9: Walid | B9: 882352.94 | C9: 1433318.8 | D9: 4411764.7 | E9: 6904702.4 | F9: 15000000 | G9: =IFERROR(E9/D9,0) -> 1.5650659 | H9: 4017950.3 | I9: =_xlfn.XLOOKUP(A9,$A$42:$A$59,$B$42:$B$59) -> 4568723.6
A10: Ali | B10: 0 | C10: 0 | D10: 0 | E10: 0 | F10: 0 | G10: =IFERROR(E10/D10,0) -> 0 | H10: 0 | I10: =_xlfn.XLOOKUP(A10,$A$42:$A$59,$B$42:$B$59) -> 0
A11: Anirudh | B11: 0 | C11: 0 | D11: 0 | E11: 0 | F11: 0 | G11: =IFERROR(E11/D11,0) -> 0 | H11: 0 | I11: =_xlfn.XLOOKUP(A11,$A$42:$A$59,$B$42:$B$59) -> 0
A12: Aqsa | B12: 0 | C12: 0 | D12: 0 | E12: 0 | F12: 0 | G12: =IFERROR(E12/D12,0) -> 0 | H12: 0 | I12: =_xlfn.XLOOKUP(A12,$A$42:$A$59,$B$42:$B$59) -> 0
A13: Daria | B13: 0 | C13: 0 | D13: 0 | E13: 0 | F13: 0 | G13: =IFERROR(E13/D13,0) -> 0 | H13: 0 | I13: =_xlfn.XLOOKUP(A13,$A$42:$A$59,$B$42:$B$59) -> 0
A14: Hussein | B14: 0 | C14: 0 | D14: 0 | E14: 0 | F14: 0 | G14: =IFERROR(E14/D14,0) -> 0 | H14: 0 | I14: =_xlfn.XLOOKUP(A14,$A$42:$A$59,$B$42:$B$59) -> 0
A15: Karan | B15: 0 | C15: 0 | D15: 0 | E15: 0 | F15: 0 | G15: =IFERROR(E15/D15,0) -> 0 | H15: 0 | I15: =_xlfn.XLOOKUP(A15,$A$42:$A$59,$B$42:$B$59) -> 0
A16: Rajiv | B16: 0 | C16: 0 | D16: 0 | E16: 0 | F16: 0 | G16: =IFERROR(E16/D16,0) -> 0 | H16: 0 | I16: =_xlfn.XLOOKUP(A16,$A$42:$A$59,$B$42:$B$59) -> 0
... A22: Abdellatif | B22: 0 | C22: 0 | D22: 0 | E22: 0 | F22: 0 | G22: =IFERROR(E22/D22,0) -> 0 | H22: 0 | I22: =_xlfn.XLOOKUP(A22,$A$42:$A$59,$B$42:$B$59) -> 0
A23: Total Dues | B23: =SUM(B5:B22) -> 882352.94 | C23: =SUM(C5:C22) -> 1433318.8 | D23: =SUM(D5:D22) -> 4411764.7 | E23: =SUM(E5:E22) -> 6904702.4 | F23: =SUM(F5:F22) -> 15000000 | G23: =IFERROR((E23)/(D23),0) -> 1.5650659 | H23: =SUM(H5:H22) -> 4017950.3 | I23: =SUM(I5:I22) -> 4568723.6
A24: Advances
A25: Abdulla | B25: 0 | C25: 0 | D25: 0 | E25: 0 | F25: 0 | G25: =IFERROR(E25/D25,0) -> 0 | H25: 0 | I25: =_xlfn.XLOOKUP(A25,$A$62:$A$73,$B$62:$B$73) -> 0
A26: Krizia | B26: 0 | C26: 0 | D26: 0 | E26: 0 | F26: 0 | G26: =IFERROR(E26/D26,0) -> 0 | H26: 0 | I26: =_xlfn.XLOOKUP(A26,$A$62:$A$73,$B$62:$B$73) -> 0
A27: Ateev | B27: 0 | C27: 0 | D27: 0 | E27: 0 | F27: 0 | G27: =IFERROR(E27/D27,0) -> 0 | H27: 0 | I27: =_xlfn.XLOOKUP(A27,$A$62:$A$73,$B$62:$B$73) -> 0
A28: Ayari | B28: 0 | C28: 0 | D28: 0 | E28: 0 | F28: 0 | G28: =IFERROR(E28/D28,0) -> 0 | H28: 0 | I28: =_xlfn.XLOOKUP(A28,$A$62:$A$73,$B$62:$B$73) -> 0
A29: Nischitha | B29: 0 | C29: 0 | D29: 0 | E29: 0 | F29: 0 | G29: =IFERROR(E29/D29,0) -> 0 | H29: 0 | I29: =_xlfn.XLOOKUP(A29,$A$62:$A$73,$B$62:$B$73) -> 0
A30: Sherif | B30: 0 | C30: 300758 | D30: 0 | E30: 932004 | F30: 0 | G30: =IFERROR(E30/D30,0) -> 0 | H30: 604342 | I30: =_xlfn.XLOOKUP(A30,$A$62:$A$73,$B$62:$B$73) -> 141386
A31: Wael | B31: 0 | C31: 0 | D31: 0 | E31: 0 | F31: 0 | G31: =IFERROR(E31/D31,0) -> 0 | H31: 0 | I31: =_xlfn.XLOOKUP(A31,$A$62:$A$73,$B$62:$B$73) -> 0
A32: Noha | B32: 0 | C32: 0 | D32: 0 | E32: 0 | F32: 0 | G32: =IFERROR(E32/D32,0) -> 0 | H32: 0 | I32: =_xlfn.XLOOKUP(A32,$A$62:$A$73,$B$62:$B$73) -> 0
A33: Vijay | B33: 0 | C33: 0 | D33: 0 | E33: 0 | F33: 0 | G33: =IFERROR(E33/D33,0) -> 0 | H33: 0 | I33: =_xlfn.XLOOKUP(A33,$A$62:$A$73,$B$62:$B$73) -> 0
A34: Basma | B34: 0 | C34: 0 | D34: 0 | E34: 0 | F34: 0 | G34: =IFERROR(E34/D34,0) -> 0 | H34: 0 | I34: =_xlfn.XLOOKUP(A34,$A$62:$A$73,$B$62:$B$73) -> 0
A35: Yogesh | B35: 0 | C35: 0 | D35: 0 | E35: 0 | F35: 0 | G35: =IFERROR(E35/D35,0) -> 0 | H35: 0 | I35: =_xlfn.XLOOKUP(A35,$A$62:$A$73,$B$62:$B$73) -> 0
A36: Total Advances | B36: =SUM(B25:B35) -> 0 | C36: =SUM(C25:C35) -> 300758 | D36: =SUM(D25:D35) -> 0 | E36: =SUM(E25:E35) -> 932004 | F36: =SUM(F25:F35) -> 0 | G36: =IFERROR(E36/D36,0) -> 0 | H36: =SUM(H25:H35) -> 604342 | I36: =SUM(I25:I35) -> 141386
A37: Grand Total | B37: =SUM(B23,B36) -> 882352.94 | C37: =SUM(C23,C36) -> 1734076.8 | D37: =SUM(D23,D36) -> 4411764.7 | E37: =SUM(E23,E36) -> 7836706.4 | F37: =SUM(F23,F36) -> 15000000 | G37: =IFERROR(E37/D37,0) -> 1.7763201 | H37: =SUM(H23,H36) -> 4622292.3 | I37: =SUM(I23,I36) -> 4710109.6
A39: Downtown
A40: Collection Executive | B40: Not Approved | C40: In Process | D40: Resubmitted | E40: Rejected
A41: Dues
A42: Ali | B42: =SUM(C42:E42) -> 0 | C42: 0 | D42: 0 | E42: 0
A43: Anirudh | B43: =SUM(C43:E43) -> 0 | C43: 0 | D43: 0 | E43: 0
A44: Ruhul | B44: =SUM(C44:E44) -> 0 | C44: 0 | D44: 0 | E44: 0
A45: Karan | B45: =SUM(C45:E45) -> 0 | C45: 0 | D45: 0 | E45: 0
A46: Aqsa | B46: =SUM(C46:E46) -> 0 | C46: 0 | D46: 0 | E46: 0
A47: Sid | B47: =SUM(C47:E47) -> 0 | C47: 0 | D47: 0 | E47: 0
...

Sheet PR Report - SOBHA AUH
A1: Sobha AUH | B1: As per Tracker | H1: PR
A2: Collection Executive | B2: Daily Target 07/05 | C2: Collected 07-05-26 | D2: Target (01/05 - 07/05) | E2: Achieved (01/05 - 07/05) | F2: Monthly Target | G2: Total Achieved % | H2: PR Approved | I2: PR Not Approved
A3: Dues
A4: Monish | B4: 0 | C4: 0 | D4: 0 | E4: 0 | F4: 0 | G4: =IFERROR(E4/D4,0) -> 0 | H4: 0 | I4: =_xlfn.XLOOKUP(A4,$A$41:$A$58,$B$41:$B$58) -> 0
A5: Melvyn | B5: 0 | C5: 0 | D5: 0 | E5: 0 | F5: 0 | G5: =IFERROR(E5/D5,0) -> 0 | H5: 0 | I5: =_xlfn.XLOOKUP(A5,$A$41:$A$58,$B$41:$B$58) -> 0
A6: Anna | B6: 0 | C6: 0 | D6: 0 | E6: 0 | F6: 0 | G6: =IFERROR(E6/D6,0) -> 0 | H6: 0 | I6: =_xlfn.XLOOKUP(A6,$A$41:$A$58,$B$41:$B$58) -> 0
A7: Ruhul | B7: 0 | C7: 0 | D7: 0 | E7: 0 | F7: 0 | G7: =IFERROR(E7/D7,0) -> 0 | H7: 559683 | I7: =_xlfn.XLOOKUP(A7,$A$41:$A$58,$B$41:$B$58) -> 0
A8: Walid | B8: 0 | C8: 0 | D8: 0 | E8: 0 | F8: 0 | G8: =IFERROR(E8/D8,0) -> 0 | H8: 0 | I8: =_xlfn.XLOOKUP(A8,$A$41:$A$58,$B$41:$B$58) -> 0
A9: Ali | B9: 0 | C9: 0 | D9: 0 | E9: 0 | F9: 0 | G9: =IFERROR(E9/D9,0) -> 0 | H9: 0 | I9: =_xlfn.XLOOKUP(A9,$A$41:$A$58,$B$41:$B$58) -> 0
A10: Anirudh | B10: 0 | C10: 0 | D10: 0 | E10: 0 | F10: 0 | G10: =IFERROR(E10/D10,0) -> 0 | H10: 0 | I10: =_xlfn.XLOOKUP(A10,$A$41:$A$58,$B$41:$B$58) -> 0
A11: Aqsa | B11: 0 | C11: 0 | D11: 0 | E11: 0 | F11: 0 | G11: =IFERROR(E11/D11,0) -> 0 | H11: 0 | I11: =_xlfn.XLOOKUP(A11,$A$41:$A$58,$B$41:$B$58) -> 0
A12: Daria | B12: 0 | C12: 0 | D12: 0 | E12: 0 | F12: 0 | G12: =IFERROR(E12/D12,0) -> 0 | H12: 0 | I12: =_xlfn.XLOOKUP(A12,$A$41:$A$58,$B$41:$B$58) -> 0
A13: Hussein | B13: 0 | C13: 0 | D13: 0 | E13: 0 | F13: 0 | G13: =IFERROR(E13/D13,0) -> 0 | H13: 0 | I13: =_xlfn.XLOOKUP(A13,$A$41:$A$58,$B$41:$B$58) -> 0
A14: Karan | B14: 0 | C14: 0 | D14: 0 | E14: 0 | F14: 0 | G14: =IFERROR(E14/D14,0) -> 0 | H14: 0 | I14: =_xlfn.XLOOKUP(A14,$A$41:$A$58,$B$41:$B$58) -> 0
A15: Rajiv | B15: 0 | C15: 0 | D15: 0 | E15: 0 | F15: 0 | G15: =IFERROR(E15/D15,0) -> 0 | H15: 0 | I15: =_xlfn.XLOOKUP(A15,$A$41:$A$58,$B$41:$B$58) -> 0
... A21: Abdellatif | B21: 0 | C21: 0 | D21: 0 | E21: 0 | F21: 0 | G21: =IFERROR(E21/D21,0) -> 0 | H21: 0 | I21: =_xlfn.XLOOKUP(A21,$A$41:$A$58,$B$41:$B$58) -> 0
A22: Total Dues | B22: =SUM(B4:B21) -> 0 | C22: =SUM(C4:C21) -> 0 | D22: =SUM(D4:D21) -> 0 | E22: =SUM(E4:E21) -> 0 | F22: =SUM(F4:F21) -> 0 | G22: =IFERROR((E22)/(D22),0) -> 0 | H22: =SUM(H4:H21) -> 559683 | I22: =SUM(I4:I21) -> 0
A23: Advances
A24: Abdulla | B24: 0 | C24: 0 | D24: 0 | E24: 0 | F24: 0 | G24: =IFERROR(E24/D24,0) -> 0 | H24: 0 | I24: =_xlfn.XLOOKUP(A24,$A$61:$A$72,$B$61:$B$72) -> 0
A25: Krizia | B25: 0 | C25: 0 | D25: 0 | E25: 0 | F25: 0 | G25: =IFERROR(E25/D25,0) -> 0 | H25: 0 | I25: =_xlfn.XLOOKUP(A25,$A$61:$A$72,$B$61:$B$72) -> 0
A26: Ateev | B26: 0 | C26: 0 | D26: 0 | E26: 0 | F26: 0 | G26: =IFERROR(E26/D26,0) -> 0 | H26: 0 | I26: =_xlfn.XLOOKUP(A26,$A$61:$A$72,$B$61:$B$72) -> 0
A27: Ayari | B27: 0 | C27: 0 | D27: 0 | E27: 0 | F27: 0 | G27: =IFERROR(E27/D27,0) -> 0 | H27: 0 | I27: =_xlfn.XLOOKUP(A27,$A$61:$A$72,$B$61:$B$72) -> 0
A28: Nischitha | B28: 0 | C28: 0 | D28: 0 | E28: 0 | F28: 0 | G28: =IFERROR(E28/D28,0) -> 0 | H28: 0 | I28: =_xlfn.XLOOKUP(A28,$A$61:$A$72,$B$61:$B$72) -> 0
A29: Sherif | B29: 0 | C29: 30000 | D29: 0 | E29: 1253891 | F29: 0 | G29: =IFERROR(E29/D29,0) -> 0 | H29: 782197.82 | I29: =_xlfn.XLOOKUP(A29,$A$61:$A$72,$B$61:$B$72) -> 55000
A30: Wael | B30: 0 | C30: 0 | D30: 0 | E30: 0 | F30: 0 | G30: =IFERROR(E30/D30,0) -> 0 | H30: 0 | I30: =_xlfn.XLOOKUP(A30,$A$61:$A$72,$B$61:$B$72) -> 0
A31: Noha | B31: 0 | C31: 0 | D31: 0 | E31: 0 | F31: 0 | G31: =IFERROR(E31/D31,0) -> 0 | H31: 0 | I31: =_xlfn.XLOOKUP(A31,$A$61:$A$72,$B$61:$B$72) -> 0
A32: Vijay | B32: 0 | C32: 0 | D32: 0 | E32: 0 | F32: 0 | G32: =IFERROR(E32/D32,0) -> 0 | H32: 0 | I32: =_xlfn.XLOOKUP(A32,$A$61:$A$72,$B$61:$B$72) -> 0
A33: Basma | B33: 0 | C33: 0 | D33: 0 | E33: 0 | F33: 0 | G33: =IFERROR(E33/D33,0) -> 0 | H33: 0 | I33: =_xlfn.XLOOKUP(A33,$A$61:$A$72,$B$61:$B$72) -> 0
A34: Yogesh | B34: 0 | C34: 0 | D34: 0 | E34: 0 | F34: 0 | G34: =IFERROR(E34/D34,0) -> 0 | H34: 0 | I34: =_xlfn.XLOOKUP(A34,$A$61:$A$72,$B$61:$B$72) -> 0
A35: Total Advances | B35: =SUM(B24:B34) -> 0 | C35: =SUM(C24:C34) -> 30000 | D35: =SUM(D24:D34) -> 0 | E35: =SUM(E24:E34) -> 1253891 | F35: =SUM(F24:F34) -> 0 | G35: =IFERROR(E35/D35,0) -> 0 | H35: =SUM(H24:H34) -> 782197.82 | I35: =SUM(I24:I34) -> 55000
A36: Grand Total | B36: =SUM(B22,B35) -> 0 | C36: =SUM(C22,C35) -> 30000 | D36: =SUM(D22,D35) -> 0 | E36: =SUM(E22,E35) -> 1253891 | F36: =SUM(F22,F35) -> 0 | G36: =IFERROR(E36/D36,0) -> 0 | H36: =SUM(H22,H35) -> 1341880.8 | I36: =SUM(I22,I35) -> 55000
A38: Sobha AUH
A39: Collection Executive | B39: Not Approved | C39: In Process | D39: Resubmitted | E39: Rejected
A40: Dues
A41: Ali | B41: =SUM(C41:E41) -> 0 | C41: 0 | D41: 0 | E41: 0
A42: Anirudh | B42: =SUM(C42:E42) -> 0 | C42: 0 | D42: 0 | E42: 0
A43: Ruhul | B43: =SUM(C43:E43) -> 0 | C43: 0 | D43: 0 | E43: 0
A44: Karan | B44: =SUM(C44:E44) -> 0 | C44: 0 | D44: 0 | E44: 0
A45: Aqsa | B45: =SUM(C45:E45) -> 0 | C45: 0 | D45: 0 | E45: 0
A46: Sid | B46: =SUM(C46:E46) -> 0 | C46: 0 | D46: 0 | E46: 0
...

Sheet PR Report - Total
A2: TOTAL | B2: As per Tracker | H2: PR
A3: Collection Executive | B3: Daily Target 07/05 | C3: Collected 07-05-26 | D3: ='PR Report - SOBHA '!D3 -> Target (01/05 - 07/05) | E3: ='PR Report - SOBHA '!E3 -> Achieved (01/05 - 07/05) | F3: Monthly Target | G3: Total Achieved % | H3: PR Approved | I3: PR Not Approved
A4: Dues
A5: Monish | B5: =SUMIFS('PR Report - SINIYA'!$B$5:$B$21,'PR Report - SINIYA'!$A$5:$A$21,A5)+SUMIFS('PR Report - DOWNTOWN'!$B$5:$B$22,'PR Report - DOWNTOWN'!$A$5:$A$22,A5) -> 3823529.4 | C5: =SUMIFS('PR Report - SINIYA'!$C$5:$C$21,'PR Report - SINIYA'!$A$5:$A$21,$A5)+SUMIFS('PR Report - DOWNTOWN'!$C$5:$C$22,'PR Report - DOWNTOWN'!$A$5:$A$22,A5) -> 2460211.9 | D5: =SUMIFS('PR Report - SINIYA'!$D$5:$D$21,'PR Report - SINIYA'!$A$5:$A$21,$A5)+SUMIFS('PR Report - DOWNTOWN'!$D$5:$D$22,'PR Report - DOWNTOWN'!$A$5:$A$22,$A5) -> 19117647 | E5: =SUMIFS('PR Report - SINIYA'!$E$5:$E$21,'PR Report - SINIYA'!$A$5:$A$21,$A5)+SUMIFS('PR Report - SOBHA '!$E$5:$E$26,'PR Report - SOBHA '!$A$5:$A$26,$A5)+SUMIFS('PR Report - DOWNTOWN'!$E$5:$E$22,'PR Report - DOWNTOWN'!$A$5:$A$22,A5) -> 12919024 | F5: =SUMIFS('PR Report - SINIYA'!$F$5:$F$21,'PR Report - SINIYA'!$A$5:$A$21,$A5)+SUMIFS('PR Report - SOBHA '!$F$5:$F$26,'PR Report - SOBHA '!$A$5:$A$26,$A5)+SUMIFS('PR Report - DOWNTOWN'!$F$5:$F$22,'PR Report - DOWNTOWN'!$A$5:$A$22,A5) -> 65000000 | G5: =IFERROR(E5/D5,0) -> 0.67576435 | H5: =SUMIFS('PR Report - SINIYA'!$H$5:$H$21,'PR Report - SINIYA'!$A$5:$A$21,$A5)+SUMIFS('PR Report - SOBHA '!$H$5:$H$26,'PR Report - SOBHA '!$A$5:$A$26,$A5)+SUMIFS('PR Report - DOWNTOWN'!$H$5:$H$22,'PR Report - DOWNTOWN'!$A$5:$A$22,A5) -> 6517845.8 | I5: =SUMIFS('PR Report - SINIYA'!$I$5:$I$21,'PR Report - SINIYA'!$A$5:$A$21,$A5)+SUMIFS('PR Report - SOBHA '!$I$5:$I$26,'PR Report - SOBHA '!$A$5:$A$26,$A5)+SUMIFS('PR Report - DOWNTOWN'!$I$5:$I$22,'PR Report - DOWNTOWN'!$A$5:$A$22,A5) -> 5676444.3
A6: Walid | B6: =SUMIFS('PR Report - SINIYA'!$B$5:$B$21,'PR Report - SINIYA'!$A$5:$A$21,A6)+SUMIFS('PR Report - DOWNTOWN'!$B$5:$B$22,'PR Report - DOWNTOWN'!$A$5:$A$22,A6) -> 3823529.4 | C6: =SUMIFS('PR Report - SINIYA'!$C$5:$C$21,'PR Report - SINIYA'!$A$5:$A$21,$A6)+SUMIFS('PR Report - DOWNTOWN'!$C$5:$C$22,'PR Report - DOWNTOWN'!$A$5:$A$22,A6) -> 2000406.8 | D6: =SUMIFS('PR Report - SINIYA'!$D$5:$D$21,'PR Report - SINIYA'!$A$5:$A$21,$A6)+SUMIFS('PR Report - DOWNTOWN'!$D$5:$D$22,'PR Report - DOWNTOWN'!$A$5:$A$22,$A6) -> 19117647 | E6: =SUMIFS('PR Report - SINIYA'!$E$5:$E$21,'PR Report - SINIYA'!$A$5:$A$21,$A6)+SUMIFS('PR Report - DOWNTOWN'!$E$5:$E$22,'PR Report - DOWNTOWN'!$A$5:$A$22,A6) -> 16291161 | F6: =SUMIFS('PR Report - SINIYA'!$F$5:$F$21,'PR Report - SINIYA'!$A$5:$A$21,$A6)+SUMIFS('PR Report - DOWNTOWN'!$F$5:$F$22,'PR Report - DOWNTOWN'!$A$5:$A$22,A6) -> 65000000 | G6: =IFERROR(E6/D6,0) -> 0.85215301 | H6: =SUMIFS('PR Report - SINIYA'!$H$5:$H$21,'PR Report - SINIYA'!$A$5:$A$21,$A6)+SUMIFS('PR Report - DOWNTOWN'!$H$5:$H$22,'PR Report - DOWNTOWN'!$A$5:$A$22,A6) -> 10533785 | I6: =SUMIFS('PR Report - SINIYA'!$I$5:$I$21,'PR Report - SINIYA'!$A$5:$A$21,$A6)+SUMIFS('PR Report - DOWNTOWN'!$I$5:$I$22,'PR Report - DOWNTOWN'!$A$5:$A$22,A6) -> 8114728.6
A7: Melvyn | B7: =SUMIFS('PR Report - SINIYA'!$B$5:$B$21,'PR Report - SINIYA'!$A$5:$A$21,A7)+SUMIFS('PR Report - DOWNTOWN'!$B$5:$B$22,'PR Report - DOWNTOWN'!$A$5:$A$22,A7) -> 2647058.8 | C7: =SUMIFS('PR Report - SINIYA'!$C$5:$C$21,'PR Report - SINIYA'!$A$5:$A$21,$A7)+SUMIFS('PR Report - DOWNTOWN'!$C$5:$C$22,'PR Report - DOWNTOWN'!$A$5:$A$22,A7) -> 2617764.5 | D7: =SUMIFS('PR Report - SINIYA'!$D$5:$D$21,'PR Report - SINIYA'!$A$5:$A$21,$A7)+SUMIFS('PR Report - DOWNTOWN'!$D$5:$D$22,'PR Report - DOWNTOWN'!$A$5:$A$22,$A7) -> 13235294 | E7: =SUMIFS('PR Report - SINIYA'!$E$5:$E$21,'PR Report - SINIYA'!$A$5:$A$21,$A7)+SUMIFS('PR Report - SOBHA '!$E$5:$E$26,'PR Report - SOBHA '!$A$5:$A$26,$A7)+SUMIFS('PR Report - DOWNTOWN'!$E$5:$E$22,'PR Report - DOWNTOWN'!$A$5:$A$22,A7) -> 10927221 | F7: =SUMIFS('PR Report - SINIYA'!$F$5:$F$21,'PR Report - SINIYA'!$A$5:$A$21,$A7)+SUMIFS('PR Report - SOBHA '!$F$5:$F$26,'PR Report - SOBHA '!$A$5:$A$26,$A7)+SUMIFS('PR Report - DOWNTOWN'!$F$5:$F$22,'PR Report - DOWNTOWN'!$A$5:$A$22,A7) -> 45000000 | G7: =IFERROR(E7/D7,0) -> 0.82561229 | H7: =SUMIFS('PR Report - SINIYA'!$H$5:$H$21,'PR Report - SINIYA'!$A$5:$A$21,$A7)+SUMIFS('PR Report - SOBHA '!$H$5:$H$26,'PR Report - SOBHA '!$A$5:$A$26,$A7)+SUMIFS('PR Report - DOWNTOWN'!$H$5:$H$22,'PR Report - DOWNTOWN'!$A$5:$A$22,A7) -> 5979287.7 | I7: =SUMIFS('PR Report - SINIYA'!$I$5:$I$21,'PR Report - SINIYA'!$A$5:$A$21,$A7)+SUMIFS('PR Report - SOBHA '!$I$5:$I$26,'PR Report - SOBHA '!$A$5:$A$26,$A7)+SUMIFS('PR Report - DOWNTOWN'!$I$5:$I$22,'PR Report - DOWNTOWN'!$A$5:$A$22,A7) -> 4265516.2
A8: Anna | B8: =SUMIFS('PR Report - SINIYA'!$B$5:$B$21,'PR Report - SINIYA'!$A$5:$A$21,A8)+SUMIFS('PR Report - DOWNTOWN'!$B$5:$B$22,'PR Report - DOWNTOWN'!$A$5:$A$22,A8) -> 1176470.6 | C8: =SUMIFS('PR Report - SINIYA'!$C$5:$C$21,'PR Report - SINIYA'!$A$5:$A$21,$A8)+SUMIFS('PR Report - DOWNTOWN'!$C$5:$C$22,'PR Report - DOWNTOWN'!$A$5:$A$22,A8) -> 420035.73 | D8: =SUMIFS('PR Report - SINIYA'!$D$5:$D$21,'PR Report - SINIYA'!$A$5:$A$21,$A8)+SUMIFS('PR Report - DOWNTOWN'!$D$5:$D$22,'PR Report - DOWNTOWN'!$A$5:$A$22,$A8) -> 5882352.9 | E8: =SUMIFS('PR Report - SINIYA'!$E$5:$E$21,'PR Report - SINIYA'!$A$5:$A$21,$A8)+SUMIFS('PR Report - SOBHA '!$E$5:$E$26,'PR Report - SOBHA '!$A$5:$A$26,$A8)+SUMIFS('PR Report - DOWNTOWN'!$E$5:$E$22,'PR Report - DOWNTOWN'!$A$5:$A$22,A8) -> 2932051.8 | F8: =SUMIFS('PR Report - SINIYA'!$F$5:$F$21,'PR Report - SINIYA'!$A$5:$A$21,$A8)+SUMIFS('PR Report - SOBHA '!$F$5:$F$26,'PR Report - SOBHA '!$A$5:$A$26,$A8)+SUMIFS('PR Report - DOWNTOWN'!$F$5:$F$22,'PR Report - DOWNTOWN'!$A$5:$A$22,A8) -> 20000000 | G8: =IFERROR(E8/D8,0) -> 0.4984488 | H8: =SUMIFS('PR Report - SINIYA'!$H$5:$H$21,'PR Report - SINIYA'!$A$5:$A$21,$A8)+SUMIFS('PR Report - SOBHA '!$H$5:$H$26,'PR Report - SOBHA '!$A$5:$A$26,$A8)+SUMIFS('PR Report - DOWNTOWN'!$H$5:$H$22,'PR Report - DOWNTOWN'!$A$5:$A$22,A8) -> 2112020 | I8: =SUMIFS('PR Report - SINIYA'!$I$5:$I$21,'PR Report - SINIYA'!$A$5:$A$21,$A8)+SUMIFS('PR Report - SOBHA '!$I$5:$I$26,'PR Report - SOBHA '!$A$5:$A$26,$A8)+SUMIFS('PR Report - DOWNTOWN'!$I$5:$I$22,'PR Report - DOWNTOWN'!$A$5:$A$22,A8) -> 506236.11
A9: UAQ Sub Total | B9: =SUM(B5:B8) -> 11470588 | C9: =SUM(C5:C8) -> 7498418.9 | D9: =SUM(D5:D8) -> 57352941 | E9: =SUM(E5:E8) -> 43069458 | F9: =SUM(F5:F8) -> 195000000 | G9: =IFERROR(E9/D9,0) -> 0.75095465 | H9: =SUM(H5:H8) -> 25142938 | I9: =SUM(I5:I8) -> 18562925
A10: Ruhul | B10: =SUMIFS('PR Report - SOBHA '!$B$5:$B$26,'PR Report - SOBHA '!$A$5:$A$26,A10) -> 2774274.2 | C10: =SUMIFS('PR Report - SOBHA '!$C$5:$C$26,'PR Report - SOBHA '!$A$5:$A$26,$A10) -> 524510 | D10: =SUMIFS('PR Report - SOBHA '!$D$5:$D$26,'PR Report - SOBHA '!$A$5:$A$26,$A10) -> 13871371 | E10: =SUMIFS('PR Report - SOBHA '!$E$5:$E$26,'PR Report - SOBHA '!$A$5:$A$26,$A10) -> 1833821 | F10: =SUMIFS('PR Report - SOBHA '!$F$5:$F$26,'PR Report - SOBHA '!$A$5:$A$26,$A10) -> 47162662 | G10: =IFERROR(E10/D10,0) -> 0.13220185 | H10: =SUMIFS('PR Report - SOBHA '!$H$5:$H$26,'PR Report - SOBHA '!$A$5:$A$26,$A10) -> 5649097.7 | I10: =SUMIFS('PR Report - SOBHA '!$I$5:$I$26,'PR Report - SOBHA '!$A$5:$A$26,$A10) -> 4238208.5
A11: Ali | B11: =SUMIFS('PR Report - SOBHA '!$B$5:$B$26,'PR Report - SOBHA '!$A$5:$A$26,A11) -> 2176503.6 | C11: =SUMIFS('PR Report - SOBHA '!$C$5:$C$26,'PR Report - SOBHA '!$A$5:$A$26,$A11) -> 782720 | D11: =SUMIFS('PR Report - SOBHA '!$D$5:$D$26,'PR Report - SOBHA '!$A$5:$A$26,$A11) -> 10882518 | E11: =SUMIFS('PR Report - SOBHA '!$E$5:$E$26,'PR Report - SOBHA '!$A$5:$A$26,$A11) -> 6917700 | F11: =SUMIFS('PR Report - SOBHA '!$F$5:$F$26,'PR Report - SOBHA '!$A$5:$A$26,$A11) -> 37000562 | G11: =IFERROR(E11/D11,0) -> 0.63567089 | H11: =SUMIFS('PR Report - SOBHA '!$H$5:$H$26,'PR Report - SOBHA '!$A$5:$A$26,$A11) -> 6097448.4 | I11: =SUMIFS('PR Report - SOBHA '!$I$5:$I$26,'PR Report - SOBHA '!$A$5:$A$26,$A11) -> 5003503.6
A12: Anirudh | B12: =SUMIFS('PR Report - SOBHA '!$B$5:$B$26,'PR Report - SOBHA '!$A$5:$A$26,A12) -> 2840497.8 | C12: =SUMIFS('PR Report - SOBHA '!$C$5:$C$26,'PR Report - SOBHA '!$A$5:$A$26,$A12) -> 1817369.1 | D12: =SUMIFS('PR Report - SOBHA '!$D$5:$D$26,'PR Report - SOBHA '!$A$5:$A$26,$A12) -> 14202489 | E12: =SUMIFS('PR Report - SOBHA '!$E$5:$E$26,'PR Report - SOBHA '!$A$5:$A$26,$A12) -> 9826728.7 | F12: =SUMIFS('PR Report - SOBHA '!$F$5:$F$26,'PR Report - SOBHA '!$A$5:$A$26,$A12) -> 48288463 | G12: =IFERROR(E12/D12,0) -> 0.69190187 | H12: =SUMIFS('PR Report - SOBHA '!$H$5:$H$26,'PR Report - SOBHA '!$A$5:$A$26,$A12) -> 12626119 | I12: =SUMIFS('PR Report - SOBHA '!$I$5:$I$26,'PR Report - SOBHA '!$A$5:$A$26,$A12) -> 4572457
A13: Aqsa | B13: =SUMIFS('PR Report - SOBHA '!$B$5:$B$26,'PR Report - SOBHA '!$A$5:$A$26,A13) -> 3450528.4 | C13: =SUMIFS('PR Report - SOBHA '!$C$5:$C$26,'PR Report - SOBHA '!$A$5:$A$26,$A13) -> 1978777 | D13: =SUMIFS('PR Report - SOBHA '!$D$5:$D$26,'PR Report - SOBHA '!$A$5:$A$26,$A13) -> 17252642 | E13: =SUMIFS('PR Report - SOBHA '!$E$5:$E$26,'PR Report - SOBHA '!$A$5:$A$26,$A13) -> 11759965 | F13: =SUMIFS('PR Report - SOBHA '!$F$5:$F$26,'PR Report - SOBHA '!$A$5:$A$26,$A13) -> 58658983 | G13: =IFERROR(E13/D13,0) -> 0.68163271 | H13: =SUMIFS('PR Report - SOBHA '!$H$5:$H$26,'PR Report - SOBHA '!$A$5:$A$26,$A13) -> 5336207 | I13: =SUMIFS('PR Report - SOBHA '!$I$5:$I$26,'PR Report - SOBHA '!$A$5:$A$26,$A13) -> 4216231.3
A14: Karan | B14: =SUMIFS('PR Report - SOBHA '!$B$5:$B$26,'PR Report - SOBHA '!$A$5:$A$26,A14) -> 2554015.1 | C14: =SUMIFS('PR Report - SOBHA '!$C$5:$C$26,'PR Report - SOBHA '!$A$5:$A$26,$A14) -> 1311551 | D14: =SUMIFS('PR Report - SOBHA '!$D$5:$D$26,'PR Report - SOBHA '!$A$5:$A$26,$A14) -> 12770076 | E14: =SUMIFS('PR Report - SOBHA '!$E$5:$E$26,'PR Report - SOBHA '!$A$5:$A$26,$A14) -> 6990927 | F14: =SUMIFS('PR Report - SOBHA '!$F$5:$F$26,'PR Report - SOBHA '!$A$5:$A$26,$A14) -> 43418257 | G14: =IFERROR(E14/D14,0) -> 0.54744602 | H14: =SUMIFS('PR Report - SOBHA '!$H$5:$H$26,'PR Report - SOBHA '!$A$5:$A$26,$A14) -> 1317193.7 | I14: =SUMIFS('PR Report - SOBHA '!$I$5:$I$26,'PR Report - SOBHA '!$A$5:$A$26,$A14) -> 2640605.4
A15: Rajiv | B15: =SUMIFS('PR Report - SOBHA '!$B$5:$B$26,'PR Report - SOBHA '!$A$5:$A$26,A15) -> 2238461.1 | C15: =SUMIFS('PR Report - SOBHA '!$C$5:$C$26,'PR Report - SOBHA '!$A$5:$A$26,$A15) -> 2279577 | D15: =SUMIFS('PR Report - SOBHA '!$D$5:$D$26,'PR Report - SOBHA '!$A$5:$A$26,$A15) -> 11192305 | E15: =SUMIFS('PR Report - SOBHA '!$E$5:$E$26,'PR Report - SOBHA '!$A$5:$A$26,$A15) -> 11501814 | F15: =SUMIFS('PR Report - SOBHA '!$F$5:$F$26,'PR Report - SOBHA '!$A$5:$A$26,$A15) -> 38053838 | G15: =IFERROR(E15/D15,0) -> 1.0276537 | H15: =SUMIFS('PR Report - SOBHA '!$H$5:$H$26,'PR Report - SOBHA '!$A$5:$A$26,$A15) -> 5271884.8 | I15: =SUMIFS('PR Report - SOBHA '!$I$5:$I$26,'PR Report - SOBHA '!$A$5:$A$26,$A15) -> 7215187.2
A16: Vinod | B16: =SUMIFS('PR Report - SOBHA '!$B$5:$B$26,'PR Report - SOBHA '!$A$5:$A$26,A16) -> 3230160.1 | C16: =SUMIFS('PR Report - SOBHA '!$C$5:$C$26,'PR Report - SOBHA '!$A$5:$A$26,$A16) -> 200000 | D16: =SUMIFS('PR Report - SOBHA '!$D$5:$D$26,'PR Report - SOBHA '!$A$5:$A$26,$A16) -> 16150800 | E16: =SUMIFS('PR Report - SOBHA '!$E$5:$E$26,'PR Report - SOBHA '!$A$5:$A$26,$A16) -> 2056939.4 | F16: =SUMIFS('PR Report - SOBHA '!$F$5:$F$26,'PR Report - SOBHA '!$A$5:$A$26,$A16) -> 54912721 | G16: =IFERROR(E16/D16,0) -> 0.12735836 | H16: =SUMIFS('PR Report - SOBHA '!$H$5:$H$26,'PR Report - SOBHA '!$A$5:$A$26,$A16) -> 3957231.4 | I16: =SUMIFS('PR Report - SOBHA '!$I$5:$I$26,'PR Report - SOBHA '!$A$5:$A$26,$A16) -> 4142840.9
A17: Sarmad | B17: =SUMIFS('PR Report - SOBHA '!$B$5:$B$26,'PR Report - SOBHA '!$A$5:$A$26,A17) -> 3286315.3 | C17: =SUMIFS('PR Report - SOBHA '!$C$5:$C$26,'PR Report - SOBHA '!$A$5:$A$26,$A17) -> 2498098 | D17: =SUMIFS('PR Report - SOBHA '!$D$5:$D$26,'PR Report - SOBHA '!$A$5:$A$26,$A17) -> 16431576 | E17: =SUMIFS('PR Report - SOBHA '!$E$5:$E$26,'PR Report - SOBHA '!$A$5:$A$26,$A17) -> 14591524 | F17: =SUMIFS('PR Report - SOBHA '!$F$5:$F$26,'PR Report - SOBHA '!$A$5:$A$26,$A17) -> 55867360 | G17: =IFERROR(E17/D17,0) -> 0.88801731 | H17: =SUMIFS('PR Report - SOBHA '!$H$5:$H$26,'PR Report - SOBHA '!$A$5:$A$26,$A17) -> 6509957 | I17: =SUMIFS('PR Report - SOBHA '!$I$5:$I$26,'PR Report - SOBHA '!$A$5:$A$26,$A17) -> 8001301.3
A18: Zeba | B18: =SUMIFS('PR Report - SOBHA '!$B$5:$B$26,'PR Report - SOBHA '!$A$5:$A$26,A18) -> 2363747 | C18: =SUMIFS('PR Report - SOBHA '!$C$5:$C$26,'PR Report - SOBHA '!$A$5:$A$26,$A18) -> 1158239 | D18: =SUMIFS('PR Report - SOBHA '!$D$5:$D$26,'PR Report - SOBHA '!$A$5:$A$26,$A18) -> 11818735 | E18: =SUMIFS('PR Report - SOBHA '!$E$5:$E$26,'PR Report - SOBHA '!$A$5:$A$26,$A18) -> 10504253 | F18: =SUMIFS('PR Report - SOBHA '!$F$5:$F$26,'PR Report - SOBHA '!$A$5:$A$26,$A18) -> 40183699 | G18: =IFERROR(E18/D18,0) -> 0.88877983 | H18: =SUMIFS('PR Report - SOBHA '!$H$5:$H$26,'PR Report - SOBHA '!$A$5:$A$26,$A18) -> 5863137.4 | I18: =SUMIFS('PR Report - SOBHA '!$I$5:$I$26,'PR Report - SOBHA '!$A$5:$A$26,$A18) -> 6262318.3
A19: Oksana | B19: =SUMIFS('PR Report - SOBHA '!$B$5:$B$26,'PR Report - SOBHA '!$A$5:$A$26,A19) -> 2106539.8 | C19: =SUMIFS('PR Report - SOBHA '!$C$5:$C$26,'PR Report - SOBHA '!$A$5:$A$26,$A19) -> 2059510 | D19: =SUMIFS('PR Report - SOBHA '!$D$5:$D$26,'PR Report - SOBHA '!$A$5:$A$26,$A19) -> 10532699 | E19: =SUMIFS('PR Report - SOBHA '!$E$5:$E$26,'PR Report - SOBHA '!$A$5:$A$26,$A19) -> 10391011 | F19: =SUMIFS('PR Report - SOBHA '!$F$5:$F$26,'PR Report - SOBHA '!$A$5:$A$26,$A19) -> 35811177 | G19: =IFERROR(E19/D19,0) -> 0.98654779 | H19: =SUMIFS('PR Report - SOBHA '!$H$5:$H$26,'PR Report - SOBHA '!$A$5:$A$26,$A19) -> 5228871.5 | I19: =SUMIFS('PR Report - SOBHA '!$I$5:$I$26,'PR Report - SOBHA '!$A$5:$A$26,$A19) -> 5422934.5
A20: Omar | B20: =SUMIFS('PR Report - SOBHA '!$B$5:$B$26,'PR Report - SOBHA '!$A$5:$A$26,A20) -> 2458129.9 | C20: =SUMIFS('PR Report - SOBHA '!$C$5:$C$26,'PR Report - SOBHA '!$A$5:$A$26,$A20) -> 2171492.8 | D20: =SUMIFS('PR Report - SOBHA '!$D$5:$D$26,'PR Report - SOBHA '!$A$5:$A$26,$A20) -> 12290649 | E20: =SUMIFS('PR Report - SOBHA '!$E$5:$E$26,'PR Report - SOBHA '!$A$5:$A$26,$A20) -> 9750271.5 | F20: =SUMIFS('PR Report - SOBHA '!$F$5:$F$26,'PR Report - SOBHA '!$A$5:$A$26,$A20) -> 41788208 | G20: =IFERROR(E20/D20,0) -> 0.79330808 | H20: =SUMIFS('PR Report - SOBHA '!$H$5:$H$26,'PR Report - SOBHA '!$A$5:$A$26,$A20) -> 20466705 | I20: =SUMIFS('PR Report - SOBHA '!$I$5:$I$26,'PR Report - SOBHA '!$A$5:$A$26,$A20) -> 4744590
A21: Sabah | B21: =SUMIFS('PR Report - SOBHA '!$B$5:$B$26,'PR Report - SOBHA '!$A$5:$A$26,A21) -> 1740757.5 | C21: =SUMIFS('PR Report - SOBHA '!$C$5:$C$26,'PR Report - SOBHA '!$A$5:$A$26,$A21) -> 999311 | D21: =SUMIFS('PR Report - SOBHA '!$D$5:$D$26,'PR Report - SOBHA '!$A$5:$A$26,$A21) -> 8703787.6 | E21: =SUMIFS('PR Report - SOBHA '!$E$5:$E$26,'PR Report - SOBHA '!$A$5:$A$26,$A21) -> 5039866 | F21: =SUMIFS('PR Report - SOBHA '!$F$5:$F$26,'PR Report - SOBHA '!$A$5:$A$26,$A21) -> 29592878 | G21: =IFERROR(E21/D21,0) -> 0.57904285 | H21: =SUMIFS('PR Report - SOBHA '!$H$5:$H$26,'PR Report - SOBHA '!$A$5:$A$26,$A21) -> 3510870.3 | I21: =SUMIFS('PR Report - SOBHA '!$I$5:$I$26,'PR Report - SOBHA '!$A$5:$A$26,$A21) -> 3034882.1
... A31: Moustafa | B31: =SUMIFS('PR Report - SOBHA '!$B$5:$B$26,'PR Report - SOBHA '!$A$5:$A$26,A31) -> 1670123.7 | C31: =SUMIFS('PR Report - SOBHA '!$C$5:$C$26,'PR Report - SOBHA '!$A$5:$A$26,$A31) -> 1101602 | D31: =SUMIFS('PR Report - SOBHA '!$D$5:$D$26,'PR Report - SOBHA '!$A$5:$A$26,$A31) -> 8350618.5 | E31: =SUMIFS('PR Report - SOBHA '!$E$5:$E$26,'PR Report - SOBHA '!$A$5:$A$26,$A31) -> 5871852 | F31: =SUMIFS('PR Report - SOBHA '!$F$5:$F$26,'PR Report - SOBHA '!$A$5:$A$26,$A31) -> 28392103 | G31: =IFERROR(E31/D31,0) -> 0.70316372 | H31: =SUMIFS('PR Report - SOBHA '!$H$5:$H$26,'PR Report - SOBHA '!$A$5:$A$26,$A31) -> 3612983.7 | I31: =SUMIFS('PR Report - SOBHA '!$I$5:$I$26,'PR Report - SOBHA '!$A$5:$A$26,$A31) -> 4581377.6
A32: SOBHA Sub Total | B32: =SUM(B10:B31) -> 50252771 | C32: =SUM(C10:C31) -> 34438498 | D32: =SUM(D10:D31) -> 2.5126385e+08 | E32: =SUM(E10:E31) -> 1.7426434e+08 | F32: =SUM(F10:F31) -> 854297104 | G32: =IFERROR(E32/D32,0) -> 0.69355115 | H32: =SUM(H10:H31) -> 1.2977049e+08 | I32: =SUM(I10:I31) -> 1.0721567e+08
A33: Omar | B33: =SUMIFS('PR Report - SOBHA AUH'!B$4:B$21,'PR Report - SOBHA AUH'!$A$4:$A$21,$A33) -> 0 | C33: =SUMIFS('PR Report - SOBHA AUH'!C$4:C$21,'PR Report - SOBHA AUH'!$A$4:$A$21,$A$33) -> 0 | D33: =SUMIFS('PR Report - SOBHA AUH'!D$4:D$21,'PR Report - SOBHA AUH'!$A$4:$A$21,$A$33) -> 0 | E33: =SUMIFS('PR Report - SOBHA AUH'!E$4:E$21,'PR Report - SOBHA AUH'!$A$4:$A$21,$A$33) -> 0 | F33: =SUMIFS('PR Report - SOBHA AUH'!F$4:F$21,'PR Report - SOBHA AUH'!$A$4:$A$21,$A$33) -> 0 | G33: =IFERROR(E33/D33,0) -> 0 | H33: =SUMIFS('PR Report - SOBHA AUH'!H$4:H$21,'PR Report - SOBHA AUH'!$A$4:$A$21,$A$33) -> 0 | I33: =SUMIFS('PR Report - SOBHA AUH'!I$4:I$21,'PR Report - SOBHA AUH'!$A$4:$A$21,$A$33) -> 0
A34: Ruhul | B34: =SUMIFS('PR Report - SOBHA AUH'!B$4:B$21,'PR Report - SOBHA AUH'!$A$4:$A$21,$A34) -> 0 | C34: =SUMIFS('PR Report - SOBHA AUH'!C$4:C$21,'PR Report - SOBHA AUH'!$A$4:$A$21,$A34) -> 0 | D34: =SUMIFS('PR Report - SOBHA AUH'!D$4:D$21,'PR Report - SOBHA AUH'!$A$4:$A$21,$A34) -> 0 | E34: =SUMIFS('PR Report - SOBHA AUH'!E$4:E$21,'PR Report - SOBHA AUH'!$A$4:$A$21,$A34) -> 0 | F34: =SUMIFS('PR Report - SOBHA AUH'!F$4:F$21,'PR Report - SOBHA AUH'!$A$4:$A$21,$A34) -> 0 | G34: =IFERROR(E34/D34,0) -> 0 | H34: =SUMIFS('PR Report - SOBHA AUH'!H$4:H$21,'PR Report - SOBHA AUH'!$A$4:$A$21,$A34) -> 559683 | I34: =SUMIFS('PR Report - SOBHA AUH'!I$4:I$21,'PR Report - SOBHA AUH'!$A$4:$A$21,$A34) -> 0
A35: Vinod | B35: =SUMIFS('PR Report - SOBHA AUH'!B$4:B$21,'PR Report - SOBHA AUH'!$A$4:$A$21,$A35) -> 0 | C35: =SUMIFS('PR Report - SOBHA AUH'!C$4:C$21,'PR Report - SOBHA AUH'!$A$4:$A$21,$A35) -> 0 | D35: =SUMIFS('PR Report - SOBHA AUH'!D$4:D$21,'PR Report - SOBHA AUH'!$A$4:$A$21,$A35) -> 0 | E35: =SUMIFS('PR Report - SOBHA AUH'!E$4:E$21,'PR Report - SOBHA AUH'!$A$4:$A$21,$A35) -> 0 | F35: =SUMIFS('PR Report - SOBHA AUH'!F$4:F$21,'PR Report - SOBHA AUH'!$A$4:$A$21,$A35) -> 0 | G35: =IFERROR(E35/D35,0) -> 0 | H35: =SUMIFS('PR Report - SOBHA AUH'!H$4:H$21,'PR Report - SOBHA AUH'!$A$4:$A$21,$A35) -> 0 | I35: =SUMIFS('PR Report - SOBHA AUH'!I$4:I$21,'PR Report - SOBHA AUH'!$A$4:$A$21,$A35) -> 0
A36: SOBHA AUH Sub Total | B36: =SUM(B33:B35) -> 0 | C36: =SUM(C33:C35) -> 0 | D36: =SUM(D33:D35) -> 0 | E36: =SUM(E33:E35) -> 0 | F36: =SUM(F33:F35) -> 0 | G36: =SUM(G33:G35) -> 0 | H36: =SUM(H33:H35) -> 559683 | I36: =SUM(I33:I35) -> 0
A37: Total Dues | B37: =SUM(B32,B9,B36) -> 61723359 | C37: =SUM(C32,C9,C36) -> 41936917 | D37: =SUM(D32,D9,D36) -> 3.086168e+08 | E37: =SUM(E32,E9,E36) -> 2.1733379e+08 | F37: =SUM(F32,F9,F36) -> 1049297104 | G37: =IFERROR((E37)/(D37),0) -> 0.70421894 | H37: =SUM(H32,H9,H36) -> 1.5547312e+08 | I37: =SUM(I32,I9,I36) -> 1.2577859e+08
A38: Advances
A39: Abdulla | B39: =SUMIFS('PR Report - DOWNTOWN'!B$25:B$35,'PR Report - DOWNTOWN'!$A$25:$A$35,$A39)+SUMIFS('PR Report - SINIYA'!B$24:B$34,'PR Report - SINIYA'!$A$24:$A$34,$A39) -> 0 | C39: =SUMIFS('PR Report - DOWNTOWN'!C$25:C$35,'PR Report - DOWNTOWN'!$A$25:$A$35,$A39)+SUMIFS('PR Report - SINIYA'!C$24:C$34,'PR Report - SINIYA'!$A$24:$A$34,$A39) -> 0 | D39: =SUMIFS('PR Report - DOWNTOWN'!D$25:D$35,'PR Report - DOWNTOWN'!$A$25:$A$35,$A39)+SUMIFS('PR Report - SINIYA'!D$24:D$34,'PR Report - SINIYA'!$A$24:$A$34,$A39) -> 0 | E39: =SUMIFS('PR Report - DOWNTOWN'!E$25:E$35,'PR Report - DOWNTOWN'!$A$25:$A$35,$A39)+SUMIFS('PR Report - SINIYA'!E$24:E$34,'PR Report - SINIYA'!$A$24:$A$34,$A39) -> 216912 | F39: =SUMIFS('PR Report - DOWNTOWN'!F$25:F$35,'PR Report - DOWNTOWN'!$A$25:$A$35,$A39)+SUMIFS('PR Report - SINIYA'!F$24:F$34,'PR Report - SINIYA'!$A$24:$A$34,$A39) -> 0 | G39: =IFERROR(E39/D39,0) -> 0 | H39: =SUMIFS('PR Report - DOWNTOWN'!H$25:H$35,'PR Report - DOWNTOWN'!$A$25:$A$35,$A39)+SUMIFS('PR Report - SINIYA'!H$24:H$34,'PR Report - SINIYA'!$A$24:$A$34,$A39) -> 288016 | I39: =SUMIFS('PR Report - DOWNTOWN'!I$25:I$35,'PR Report - DOWNTOWN'!$A$25:$A$35,$A39)+SUMIFS('PR Report - SINIYA'!I$24:I$34,'PR Report - SINIYA'!$A$24:$A$34,$A39) -> 0
